Workbook

Sheet FINAL FINAL
C2: Results | E2: Morality metrics
B3: Name | C3: Avg. Score | D3: Wins (%) | E3: Cooperation Rating | F3: Good Partner Rating | G3: Eigenjesus Rating | H3: Eigenmoses Rating
B4: Fuzzy | C4: =VLOOKUP(B4,Kompilirano!T2:Z17,7,FALSE)/14/5 -> 550.78571 | D4: =VLOOKUP(B4,Kompilirano!J2:P17,7,FALSE)/14/5 -> 0.071428571 | E4: =VLOOKUP(B4,Kompilirano!AM2:AS17,7,FALSE) -> 0.84 (0.03) | F4: =VLOOKUP(B4,Kompilirano!AW2:BC17,7,FALSE) -> 0.93 (0.00) | G4: =VLOOKUP(B4,Kompilirano!BG2:BM17,7,FALSE) -> 0.31 (0.00) | H4: =VLOOKUP(B4,Kompilirano!BQ2:BW17,7,FALSE) -> 0.31 (0.01)
B5: GTFT | C5: =VLOOKUP(B5,Kompilirano!T3:Z18,7,FALSE)/14/5 -> 530.11429 | D5: =VLOOKUP(B5,Kompilirano!J3:P18,7,FALSE)/14/5 -> 0 | E5: =VLOOKUP(B5,Kompilirano!AM3:AS18,7,FALSE) -> 0.89 (0.00) | F5: =VLOOKUP(B5,Kompilirano!AW3:BC18,7,FALSE) -> 1.00 (0.00) | G5: =VLOOKUP(B5,Kompilirano!BG3:BM18,7,FALSE) -> 0.31 (0.00) | H5: =VLOOKUP(B5,Kompilirano!BQ3:BW18,7,FALSE) -> 0.30 (0.00)
B6: ZD-GTFT-2 | C6: =VLOOKUP(B6,Kompilirano!T6:Z21,7,FALSE)/14/5 -> 527.04286 | D6: =VLOOKUP(B6,Kompilirano!J6:P21,7,FALSE)/14/5 -> 0 | E6: =VLOOKUP(B6,Kompilirano!AM6:AS21,7,FALSE) -> 0.85 (0.01) | F6: =VLOOKUP(B6,Kompilirano!AW6:BC21,7,FALSE) -> 1.00 (0.00) | G6: =VLOOKUP(B6,Kompilirano!BG6:BM21,7,FALSE) -> 0.31 (0.00) | H6: =VLOOKUP(B6,Kompilirano!BQ6:BW21,7,FALSE) -> 0.30 (0.00)
B7: Cooperator | C7: =VLOOKUP(B7,Kompilirano!T4:Z19,7,FALSE)/14/5 -> 520.97143 | D7: =VLOOKUP(B7,Kompilirano!J4:P19,7,FALSE)/14/5 -> 0 | E7: =VLOOKUP(B7,Kompilirano!AM4:AS19,7,FALSE) -> 1.00 (0.00) | F7: =VLOOKUP(B7,Kompilirano!AW4:BC19,7,FALSE) -> 1.00 (0.00) | G7: =VLOOKUP(B7,Kompilirano!BG4:BM19,7,FALSE) -> 0.32 (0.00) | H7: =VLOOKUP(B7,Kompilirano!BQ4:BW19,7,FALSE) -> 0.26 (0.00)
B8: Hard Tit For 2 Tats | C8: =VLOOKUP(B8,Kompilirano!T5:Z20,7,FALSE)/14/5 -> 520.41429 | D8: =VLOOKUP(B8,Kompilirano!J5:P20,7,FALSE)/14/5 -> 0 | E8: =VLOOKUP(B8,Kompilirano!AM5:AS20,7,FALSE) -> 0.81 (0.03) | F8: =VLOOKUP(B8,Kompilirano!AW5:BC20,7,FALSE) -> 1.00 (0.00) | G8: =VLOOKUP(B8,Kompilirano!BG5:BM20,7,FALSE) -> 0.31 (0.01) | H8: =VLOOKUP(B8,Kompilirano!BQ5:BW20,7,FALSE) -> 0.32 (0.00)
B9: Tit For 2 Tats | C9: =VLOOKUP(B9,Kompilirano!T7:Z22,7,FALSE)/14/5 -> 519.67143 | D9: =VLOOKUP(B9,Kompilirano!J7:P22,7,FALSE)/14/5 -> 0 | E9: =VLOOKUP(B9,Kompilirano!AM7:AS22,7,FALSE) -> 0.83 (0.02) | F9: =VLOOKUP(B9,Kompilirano!AW7:BC22,7,FALSE) -> 1.00 (0.00) | G9: =VLOOKUP(B9,Kompilirano!BG7:BM22,7,FALSE) -> 0.31 (0.00) | H9: =VLOOKUP(B9,Kompilirano!BQ7:BW22,7,FALSE) -> 0.32 (0.00)
B10: Tit For Tat | C10: =VLOOKUP(B10,Kompilirano!T8:Z23,7,FALSE)/14/5 -> 501.44286 | D10: =VLOOKUP(B10,Kompilirano!J8:P23,7,FALSE)/14/5 -> 0 | E10: =VLOOKUP(B10,Kompilirano!AM8:AS23,7,FALSE) -> 0.73 (0.00) | F10: =VLOOKUP(B10,Kompilirano!AW8:BC23,7,FALSE) -> 1.00 (0.00) | G10: =VLOOKUP(B10,Kompilirano!BG8:BM23,7,FALSE) -> 0.29 (0.00) | H10: =VLOOKUP(B10,Kompilirano!BQ8:BW23,7,FALSE) -> 0.31 (0.00)
B11: Grudger | C11: =VLOOKUP(B11,Kompilirano!T9:Z24,7,FALSE)/14/5 -> 489.3 | D11: =VLOOKUP(B11,Kompilirano!J9:P24,7,FALSE)/14/5 -> 0.071428571 | E11: =VLOOKUP(B11,Kompilirano!AM9:AS24,7,FALSE) -> 0.65 (0.01) | F11: =VLOOKUP(B11,Kompilirano!AW9:BC24,7,FALSE) -> 0.93 (0.00) | G11: =VLOOKUP(B11,Kompilirano!BG9:BM24,7,FALSE) -> 0.27 (0.00) | H11: =VLOOKUP(B11,Kompilirano!BQ9:BW24,7,FALSE) -> 0.30 (0.00)
B12: Hard Tit For Tat | C12: =VLOOKUP(B12,Kompilirano!T10:Z25,7,FALSE)/14/5 -> 487.92857 | D12: =VLOOKUP(B12,Kompilirano!J10:P25,7,FALSE)/14/5 -> 0.085714286 | E12: =VLOOKUP(B12,Kompilirano!AM10:AS25,7,FALSE) -> 0.66 (0.00) | F12: =VLOOKUP(B12,Kompilirano!AW10:BC25,7,FALSE) -> 0.91 (0.03) | G12: =VLOOKUP(B12,Kompilirano!BG10:BM25,7,FALSE) -> 0.27 (0.00) | H12: =VLOOKUP(B12,Kompilirano!BQ10:BW25,7,FALSE) -> 0.30 (0.00)
B13: Win-Stay Lose-Shift | C13: =VLOOKUP(B13,Kompilirano!T11:Z26,7,FALSE)/14/5 -> 483.68571 | D13: =VLOOKUP(B13,Kompilirano!J11:P26,7,FALSE)/14/5 -> 0.014285714 | E13: =VLOOKUP(B13,Kompilirano!AM11:AS26,7,FALSE) -> 0.80 (0.00) | F13: =VLOOKUP(B13,Kompilirano!AW11:BC26,7,FALSE) -> 0.99 (0.03) | G13: =VLOOKUP(B13,Kompilirano!BG11:BM26,7,FALSE) -> 0.29 (0.00) | H13: =VLOOKUP(B13,Kompilirano!BQ11:BW26,7,FALSE) -> 0.28 (0.00)
B14: Hard Go By Majority | C14: =VLOOKUP(B14,Kompilirano!T12:Z27,7,FALSE)/14/5 -> 451.82857 | D14: =VLOOKUP(B14,Kompilirano!J12:P27,7,FALSE)/14/5 -> 0.51428571 | E14: =VLOOKUP(B14,Kompilirano!AM12:AS27,7,FALSE) -> 0.56 (0.06) | F14: =VLOOKUP(B14,Kompilirano!AW12:BC27,7,FALSE) -> 0.49 (0.03) | G14: =VLOOKUP(B14,Kompilirano!BG12:BM27,7,FALSE) -> 0.20 (0.01) | H14: =VLOOKUP(B14,Kompilirano!BQ12:BW27,7,FALSE) -> 0.09 (0.01)
B15: Random | C15: =VLOOKUP(B15,Kompilirano!T13:Z28,7,FALSE)/14/5 -> 414.47143 | D15: =VLOOKUP(B15,Kompilirano!J13:P28,7,FALSE)/14/5 -> 0.51428571 | E15: =VLOOKUP(B15,Kompilirano!AM13:AS28,7,FALSE) -> 0.50 (0.01) | F15: =VLOOKUP(B15,Kompilirano!AW13:BC28,7,FALSE) -> 0.49 (0.09) | G15: =VLOOKUP(B15,Kompilirano!BG13:BM28,7,FALSE) -> 0.16 (0.00) | H15: =VLOOKUP(B15,Kompilirano!BQ13:BW28,7,FALSE) -> 0.00 (0.00)
B16: Joss | C16: =VLOOKUP(B16,Kompilirano!T14:Z29,7,FALSE)/14/5 -> 407.95714 | D16: =VLOOKUP(B16,Kompilirano!J14:P29,7,FALSE)/14/5 -> 0.67142857 | E16: =VLOOKUP(B16,Kompilirano!AM14:AS29,7,FALSE) -> 0.40 (0.02) | F16: =VLOOKUP(B16,Kompilirano!AW14:BC29,7,FALSE) -> 0.33 (0.04) | G16: =VLOOKUP(B16,Kompilirano!BG14:BM29,7,FALSE) -> 0.15 (0.01) | H16: =VLOOKUP(B16,Kompilirano!BQ14:BW29,7,FALSE) -> 0.02 (0.02)
B17: ZD-Extort-2 | C17: =VLOOKUP(B17,Kompilirano!T15:Z30,7,FALSE)/14/5 -> 384.8 | D17: =VLOOKUP(B17,Kompilirano!J15:P30,7,FALSE)/14/5 -> 0.82857143 | E17: =VLOOKUP(B17,Kompilirano!AM15:AS30,7,FALSE) -> 0.28 (0.04) | F17: =VLOOKUP(B17,Kompilirano!AW15:BC30,7,FALSE) -> 0.17 (0.08) | G17: =VLOOKUP(B17,Kompilirano!BG15:BM30,7,FALSE) -> 0.10 (0.01) | H17: =VLOOKUP(B17,Kompilirano!BQ15:BW30,7,FALSE) -> -0.09 (0.02)
B18: Defector | C18: =VLOOKUP(B18,Kompilirano!T16:Z31,7,FALSE)/14/5 -> 350.68571 | D18: =VLOOKUP(B18,Kompilirano!J16:P31,7,FALSE)/14/5 -> 0.92857143 | E18: =VLOOKUP(B18,Kompilirano!AM16:AS31,7,FALSE) -> 0.00 (0.00) | F18: =VLOOKUP(B18,Kompilirano!AW16:BC31,7,FALSE) -> 0.07 (0.00) | G18: =VLOOKUP(B18,Kompilirano!BG16:BM31,7,FALSE) -> 0.00 (0.00) | H18: =VLOOKUP(B18,Kompilirano!BQ16:BW31,7,FALSE) -> -0.26 (0.00)

Sheet Kompilirano
A2: Name | B2: Rank 1 | C2: Rank 2 | D2: Rank 3 | E2: Rank 4 | F2: Rank 5 | H2: Avg | J2: Name | K2: Wins 1 | L2: Wins 2 | M2: Wins 3 | N2: Wins 4 | O2: Wins 5 | Q2: Avg | R2: SD | T2: Name | U2: Total Score 1 | V2: Total Score 2 | W2: Total Score 3 | X2: Total Score 4 | Y2: Total Score 5 | AA2: Avg | AB2: SD | AD2: Name | AE2: #Cooperations 1 | AF2: #Cooperations 2 | AG2: #Cooperations 3 | AH2: #Cooperations 4 | AI2: #Cooperations 5 | AJ2: Avg | AK2: SD | AM2: Name | AN2: CoopRating 1 | AO2: CoopRating 2 | AP2: CoopRating 3 | AQ2: CoopRating 4 | AR2: CoopRating 5 | AT2: Avg | AU2: SD | AW2: Name | AX2: GP Rating 1 | AY2: GP Rating 2 | AZ2: GP Rating 3 | BA2: GP Rating 4 | BB2: GP Rating 5 | BD2: Avg | BE2: SD | BG2: Name | BH2: EJ Rating 1 | BI2: EJ Rating 2 | BJ2: EJ Rating 3 | BK2: EJ Rating 4 | BL2: EJ Rating 5 | BN2: Avg | BO2: SD | BQ2: Name | BR2: EM Rating 1 | BS2: EM Rating 2 | BT2: EM Rating 3 | BU2: EM Rating 4 | BV2: EM Rating 5 | BX2: Avg | BY2: SD
A3: Fuzzy | B3: =+VLOOKUP($A3,INDIRECT(Adrese!B$2),2,FALSE) -> 1 | C3: =+VLOOKUP($A3,INDIRECT(Adrese!C$2),2,FALSE) -> 1 | D3: =+VLOOKUP($A3,INDIRECT(Adrese!D$2),2,FALSE) -> 1 | E3: =+VLOOKUP($A3,INDIRECT(Adrese!E$2),2,FALSE) -> 1 | F3: =+VLOOKUP($A3,INDIRECT(Adrese!F$2),2,FALSE) -> 1 | H3: =AVERAGE(B3:F3) -> 1 | J3: Fuzzy | K3: =+VLOOKUP($A3,INDIRECT(Adrese!B$2),3,FALSE) -> 1 | L3: =+VLOOKUP($A3,INDIRECT(Adrese!C$2),3,FALSE) -> 1 | M3: =+VLOOKUP($A3,INDIRECT(Adrese!D$2),3,FALSE) -> 1 | N3: =+VLOOKUP($A3,INDIRECT(Adrese!E$2),3,FALSE) -> 1 | O3: =+VLOOKUP($A3,INDIRECT(Adrese!F$2),3,FALSE) -> 1 | P3: =SUM(K3:O3) -> 5 | Q3: =AVERAGE(K3:O3) -> 1 | R3: =+_xlfn.STDEV.S(K3:O3) -> 0 | T3: Fuzzy | U3: =+VLOOKUP($T3,INDIRECT(Adrese!B$2),4,FALSE) -> 7772 | V3: =+VLOOKUP($T3,INDIRECT(Adrese!C$2),4,FALSE) -> 7735 | W3: =+VLOOKUP($T3,INDIRECT(Adrese!D$2),4,FALSE) -> 7543 | X3: =+VLOOKUP($T3,INDIRECT(Adrese!E$2),4,FALSE) -> 7754 | Y3: =+VLOOKUP($T3,INDIRECT(Adrese!F$2),4,FALSE) -> 7751 | Z3: =SUM(U3:Y3) -> 38555 | AA3: =AVERAGE(U3:Y3) -> 7711 | AB3: =+_xlfn.STDEV.S(U3:Y3) -> 94.828793 | AD3: Fuzzy | AE3: =+VLOOKUP($A3,INDIRECT(Adrese!B$2),5,FALSE) -> 2595 | AF3: =+VLOOKUP($A3,INDIRECT(Adrese!C$2),5,FALSE) -> 2591 | AG3: =+VLOOKUP($A3,INDIRECT(Adrese!D$2),5,FALSE) -> 2414 | AH3: =+VLOOKUP($A3,INDIRECT(Adrese!E$2),5,FALSE) -> 2590 | AI3: =+VLOOKUP($A3,INDIRECT(Adrese!F$2),5,FALSE) -> 2592 | AJ3: =AVERAGE(AE3:AI3) -> 2556.4 | AK3: =+_xlfn.STDEV.S(AE3:AI3) -> 79.626001 | AM3: Fuzzy | AN3: =+VLOOKUP($A3,INDIRECT(Adrese!B$2),6,FALSE) -> 0.85535714 | AO3: =+VLOOKUP($A3,INDIRECT(Adrese!C$2),6,FALSE) -> 0.85392857 | AP3: =+VLOOKUP($A3,INDIRECT(Adrese!D$2),6,FALSE) -> 0.79071429 | AQ3: =+VLOOKUP($A3,INDIRECT(Adrese!E$2),6,FALSE) -> 0.85357143 | AR3: =+VLOOKUP($A3,INDIRECT(Adrese!F$2),6,FALSE) -> 0.85428571 | AS3: =TEXT(AT3,"0.00")&" ("&TEXT(AU3,"0.00")&")" -> 0.84 (0.03) | AT3: =AVERAGE(AN3:AR3) -> 0.84157143 | AU3: =+_xlfn.STDEV.S(AN3:AR3) -> 0.028437857 | AW3: Fuzzy | AX3: =+VLOOKUP($A3,INDIRECT(Adrese!B$2),7,FALSE) -> 0.92857143 | AY3: =+VLOOKUP($A3,INDIRECT(Adrese!C$2),7,FALSE) -> 0.92857143 | AZ3: =+VLOOKUP($A3,INDIRECT(Adrese!D$2),7,FALSE) -> 0.92857143 | BA3: =+VLOOKUP($A3,INDIRECT(Adrese!E$2),7,FALSE) -> 0.92857143 | BB3: =+VLOOKUP($A3,INDIRECT(Adrese!F$2),7,FALSE) -> 0.92857143 | BC3: =TEXT(BD3,"0.00")&" ("&TEXT(BE3,"0.00")&")" -> 0.93 (0.00) | BD3: =AVERAGE(AX3:BB3) -> 0.92857143 | BE3: =+_xlfn.STDEV.S(AX3:BB3) -> 0 | BG3: Fuzzy | BH3: =+VLOOKUP($BG3,INDIRECT(Adrese!B$2),8,FALSE) -> 0.31023771 | BI3: =+VLOOKUP($BG3,INDIRECT(Adrese!C$2),8,FALSE) -> 0.3096826 | BJ3: =+VLOOKUP($BG3,INDIRECT(Adrese!D$2),8,FALSE) -> 0.30204718 | BK3: =+VLOOKUP($BG3,INDIRECT(Adrese!E$2),8,FALSE) -> 0.30840147 | BL3: =+VLOOKUP($BG3,INDIRECT(Adrese!F$2),8,FALSE) -> 0.30922885 | BM3: =TEXT(BN3,"0.00")&" ("&TEXT(BO3,"0.00")&")" -> 0.31 (0.00) | BN3: =AVERAGE(BH3:BL3) -> 0.30791956 | BO3: =+_xlfn.STDEV.S(BH3:BL3) -> 0.0033508771 | BQ3: Fuzzy | BR3: =+VLOOKUP($BG3,INDIRECT(Adrese!B$2),9,FALSE) -> 0.30521964 | BS3: =+VLOOKUP($BG3,INDIRECT(Adrese!C$2),9,FALSE) -> 0.31218277 | BT3: =+VLOOKUP($BG3,INDIRECT(Adrese!D$2),9,FALSE) -> 0.32391756 | BU3: =+VLOOKUP($BG3,INDIRECT(Adrese!E$2),9,FALSE) -> 0.31103561 | BV3: =+VLOOKUP($BG3,INDIRECT(Adrese!F$2),9,FALSE) -> 0.30517258 | BW3: =TEXT(BX3,"0.00")&" ("&TEXT(BY3,"0.00")&")" -> 0.31 (0.01) | BX3: =AVERAGE(BR3:BV3) -> 0.31150563 | BY3: =+_xlfn.STDEV.S(BR3:BV3) -> 0.0076543575
A4: GTFT | B4: =+VLOOKUP($A4,INDIRECT(Adrese!B$2),2,FALSE) -> 2 | C4: =+VLOOKUP($A4,INDIRECT(Adrese!C$2),2,FALSE) -> 3 | D4: =+VLOOKUP($A4,INDIRECT(Adrese!D$2),2,FALSE) -> 2 | E4: =+VLOOKUP($A4,INDIRECT(Adrese!E$2),2,FALSE) -> 3 | F4: =+VLOOKUP($A4,INDIRECT(Adrese!F$2),2,FALSE) -> 2 | H4: =AVERAGE(B4:F4) -> 2.4 | J4: GTFT | K4: =+VLOOKUP($A4,INDIRECT(Adrese!B$2),3,FALSE) -> 0 | L4: =+VLOOKUP($A4,INDIRECT(Adrese!C$2),3,FALSE) -> 0 | M4: =+VLOOKUP($A4,INDIRECT(Adrese!D$2),3,FALSE) -> 0 | N4: =+VLOOKUP($A4,INDIRECT(Adrese!E$2),3,FALSE) -> 0 | O4: =+VLOOKUP($A4,INDIRECT(Adrese!F$2),3,FALSE) -> 0 | P4: =SUM(K4:O4) -> 0 | Q4: =AVERAGE(K4:O4) -> 0 | R4: =+_xlfn.STDEV.S(K4:O4) -> 0 | T4: GTFT | U4: =+VLOOKUP($T4,INDIRECT(Adrese!B$2),4,FALSE) -> 7415 | V4: =+VLOOKUP($T4,INDIRECT(Adrese!C$2),4,FALSE) -> 7450 | W4: =+VLOOKUP($T4,INDIRECT(Adrese!D$2),4,FALSE) -> 7448 | X4: =+VLOOKUP($T4,INDIRECT(Adrese!E$2),4,FALSE) -> 7375 | Y4: =+VLOOKUP($T4,INDIRECT(Adrese!F$2),4,FALSE) -> 7420 | Z4: =SUM(U4:Y4) -> 37108 | AA4: =AVERAGE(U4:Y4) -> 7421.6 | AB4: =+_xlfn.STDEV.S(U4:Y4) -> 30.50082 | AD4: GTFT | AE4: =+VLOOKUP($A4,INDIRECT(Adrese!B$2),5,FALSE) -> 2701 | AF4: =+VLOOKUP($A4,INDIRECT(Adrese!C$2),5,FALSE) -> 2696 | AG4: =+VLOOKUP($A4,INDIRECT(Adrese!D$2),5,FALSE) -> 2695 | AH4: =+VLOOKUP($A4,INDIRECT(Adrese!E$2),5,FALSE) -> 2684 | AI4: =+VLOOKUP($A4,INDIRECT(Adrese!F$2),5,FALSE) -> 2675 | AJ4: =AVERAGE(AE4:AI4) -> 2690.2 | AK4: =+_xlfn.STDEV.S(AE4:AI4) -> 10.521407 | AM4: GTFT | AN4: =+VLOOKUP($A4,INDIRECT(Adrese!B$2),6,FALSE) -> 0.89321429 | AO4: =+VLOOKUP($A4,INDIRECT(Adrese!C$2),6,FALSE) -> 0.89142857 | AP4: =+VLOOKUP($A4,INDIRECT(Adrese!D$2),6,FALSE) -> 0.89107143 | AQ4: =+VLOOKUP($A4,INDIRECT(Adrese!E$2),6,FALSE) -> 0.88714286 | AR4: =+VLOOKUP($A4,INDIRECT(Adrese!F$2),6,FALSE) -> 0.88392857 | AS4: =TEXT(AT4,"0.00")&" ("&TEXT(AU4,"0.00")&")" -> 0.89 (0.00) | AT4: =AVERAGE(AN4:AR4) -> 0.88935714 | AU4: =+_xlfn.STDEV.S(AN4:AR4) -> 0.0037576453 | AW4: GTFT | AX4: =+VLOOKUP($A4,INDIRECT(Adrese!B$2),7,FALSE) -> 1 | AY4: =+VLOOKUP($A4,INDIRECT(Adrese!C$2),7,FALSE) -> 1 | AZ4: =+VLOOKUP($A4,INDIRECT(Adrese!D$2),7,FALSE) -> 1 | BA4: =+VLOOKUP($A4,INDIRECT(Adrese!E$2),7,FALSE) -> 1 | BB4: =+VLOOKUP($A4,INDIRECT(Adrese!F$2),7,FALSE) -> 1 | BC4: =TEXT(BD4,"0.00")&" ("&TEXT(BE4,"0.00")&")" -> 1.00 (0.00) | BD4: =AVERAGE(AX4:BB4) -> 1 | BE4: =+_xlfn.STDEV.S(AX4:BB4) -> 0 | BG4: GTFT | BH4: =+VLOOKUP($BG4,INDIRECT(Adrese!B$2),8,FALSE) -> 0.31570079 | BI4: =+VLOOKUP($BG4,INDIRECT(Adrese!C$2),8,FALSE) -> 0.31443837 | BJ4: =+VLOOKUP($BG4,INDIRECT(Adrese!D$2),8,FALSE) -> 0.31367554 | BK4: =+VLOOKUP($BG4,INDIRECT(Adrese!E$2),8,FALSE) -> 0.31230402 | BL4: =+VLOOKUP($BG4,INDIRECT(Adrese!F$2),8,FALSE) -> 0.31399068 | BM4: =TEXT(BN4,"0.00")&" ("&TEXT(BO4,"0.00")&")" -> 0.31 (0.00) | BN4: =AVERAGE(BH4:BL4) -> 0.31402188 | BO4: =+_xlfn.STDEV.S(BH4:BL4) -> 0.0012312763 | BQ4: GTFT | BR4: =+VLOOKUP($BG4,INDIRECT(Adrese!B$2),9,FALSE) -> 0.29607899 | BS4: =+VLOOKUP($BG4,INDIRECT(Adrese!C$2),9,FALSE) -> 0.30093917 | BT4: =+VLOOKUP($BG4,INDIRECT(Adrese!D$2),9,FALSE) -> 0.29352763 | BU4: =+VLOOKUP($BG4,INDIRECT(Adrese!E$2),9,FALSE) -> 0.29858916 | BV4: =+VLOOKUP($BG4,INDIRECT(Adrese!F$2),9,FALSE) -> 0.29950858 | BW4: =TEXT(BX4,"0.00")&" ("&TEXT(BY4,"0.00")&")" -> 0.30 (0.00) | BX4: =AVERAGE(BR4:BV4) -> 0.29772871 | BY4: =+_xlfn.STDEV.S(BR4:BV4) -> 0.0029404954
A5: Hard Tit For 2 Tats | B5: =+VLOOKUP($A5,INDIRECT(Adrese!B$2),2,FALSE) -> 6 | C5: =+VLOOKUP($A5,INDIRECT(Adrese!C$2),2,FALSE) -> 6 | D5: =+VLOOKUP($A5,INDIRECT(Adrese!D$2),2,FALSE) -> 3 | E5: =+VLOOKUP($A5,INDIRECT(Adrese!E$2),2,FALSE) -> 4 | F5: =+VLOOKUP($A5,INDIRECT(Adrese!F$2),2,FALSE) -> 3 | H5: =AVERAGE(B5:F5) -> 4.4 | J5: Hard Tit For 2 Tats | K5: =+VLOOKUP($A5,INDIRECT(Adrese!B$2),3,FALSE) -> 0 | L5: =+VLOOKUP($A5,INDIRECT(Adrese!C$2),3,FALSE) -> 0 | M5: =+VLOOKUP($A5,INDIRECT(Adrese!D$2),3,FALSE) -> 0 | N5: =+VLOOKUP($A5,INDIRECT(Adrese!E$2),3,FALSE) -> 0 | O5: =+VLOOKUP($A5,INDIRECT(Adrese!F$2),3,FALSE) -> 0 | P5: =SUM(K5:O5) -> 0 | Q5: =AVERAGE(K5:O5) -> 0 | R5: =+_xlfn.STDEV.S(K5:O5) -> 0 | T5: Hard Tit For 2 Tats | U5: =+VLOOKUP($T5,INDIRECT(Adrese!B$2),4,FALSE) -> 7064 | V5: =+VLOOKUP($T5,INDIRECT(Adrese!C$2),4,FALSE) -> 7189 | W5: =+VLOOKUP($T5,INDIRECT(Adrese!D$2),4,FALSE) -> 7433 | X5: =+VLOOKUP($T5,INDIRECT(Adrese!E$2),4,FALSE) -> 7367 | Y5: =+VLOOKUP($T5,INDIRECT(Adrese!F$2),4,FALSE) -> 7376 | Z5: =SUM(U5:Y5) -> 36429 | AA5: =AVERAGE(U5:Y5) -> 7285.8 | AB5: =+_xlfn.STDEV.S(U5:Y5) -> 154.08017 | AD5: Hard Tit For 2 Tats | AE5: =+VLOOKUP($A5,INDIRECT(Adrese!B$2),5,FALSE) -> 2359 | AF5: =+VLOOKUP($A5,INDIRECT(Adrese!C$2),5,FALSE) -> 2419 | AG5: =+VLOOKUP($A5,INDIRECT(Adrese!D$2),5,FALSE) -> 2567 | AH5: =+VLOOKUP($A5,INDIRECT(Adrese!E$2),5,FALSE) -> 2532 | AI5: =+VLOOKUP($A5,INDIRECT(Adrese!F$2),5,FALSE) -> 2530 | AJ5: =AVERAGE(AE5:AI5) -> 2481.4 | AK5: =+_xlfn.STDEV.S(AE5:AI5) -> 88.211677 | AM5: Hard Tit For 2 Tats | AN5: =+VLOOKUP($A5,INDIRECT(Adrese!B$2),6,FALSE) -> 0.77107143 | AO5: =+VLOOKUP($A5,INDIRECT(Adrese!C$2),6,FALSE) -> 0.7925 | AP5: =+VLOOKUP($A5,INDIRECT(Adrese!D$2),6,FALSE) -> 0.84535714 | AQ5: =+VLOOKUP($A5,INDIRECT(Adrese!E$2),6,FALSE) -> 0.83285714 | AR5: =+VLOOKUP($A5,INDIRECT(Adrese!F$2),6,FALSE) -> 0.83214286 | AS5: =TEXT(AT5,"0.00")&" ("&TEXT(AU5,"0.00")&")" -> 0.81 (0.03) | AT5: =AVERAGE(AN5:AR5) -> 0.81478571 | AU5: =+_xlfn.STDEV.S(AN5:AR5) -> 0.03150417 | AW5: Hard Tit For 2 Tats | AX5: =+VLOOKUP($A5,INDIRECT(Adrese!B$2),7,FALSE) -> 1 | AY5: =+VLOOKUP($A5,INDIRECT(Adrese!C$2),7,FALSE) -> 1 | AZ5: =+VLOOKUP($A5,INDIRECT(Adrese!D$2),7,FALSE) -> 1 | BA5: =+VLOOKUP($A5,INDIRECT(Adrese!E$2),7,FALSE) -> 1 | BB5: =+VLOOKUP($A5,INDIRECT(Adrese!F$2),7,FALSE) -> 1 | BC5: =TEXT(BD5,"0.00")&" ("&TEXT(BE5,"0.00")&")" -> 1.00 (0.00) | BD5: =AVERAGE(AX5:BB5) -> 1 | BE5: =+_xlfn.STDEV.S(AX5:BB5) -> 0 | BG5: Hard Tit For 2 Tats | BH5: =+VLOOKUP($BG5,INDIRECT(Adrese!B$2),8,FALSE) -> 0.30022113 | BI5: =+VLOOKUP($BG5,INDIRECT(Adrese!C$2),8,FALSE) -> 0.30154468 | BJ5: =+VLOOKUP($BG5,INDIRECT(Adrese!D$2),8,FALSE) -> 0.31267097 | BK5: =+VLOOKUP($BG5,INDIRECT(Adrese!E$2),8,FALSE) -> 0.30860859 | BL5: =+VLOOKUP($BG5,INDIRECT(Adrese!F$2),8,FALSE) -> 0.31047726 | BM5: =TEXT(BN5,"0.00")&" ("&TEXT(BO5,"0.00")&")" -> 0.31 (0.01) | BN5: =AVERAGE(BH5:BL5) -> 0.30670453 | BO5: =+_xlfn.STDEV.S(BH5:BL5) -> 0.005525302 | BQ5: Hard Tit For 2 Tats | BR5: =+VLOOKUP($BG5,INDIRECT(Adrese!B$2),9,FALSE) -> 0.32162477 | BS5: =+VLOOKUP($BG5,INDIRECT(Adrese!C$2),9,FALSE) -> 0.31932264 | BT5: =+VLOOKUP($BG5,INDIRECT(Adrese!D$2),9,FALSE) -> 0.32224228 | BU5: =+VLOOKUP($BG5,INDIRECT(Adrese!E$2),9,FALSE) -> 0.32499815 | BV5: =+VLOOKUP($BG5,INDIRECT(Adrese!F$2),9,FALSE) -> 0.3236889 | BW5: =TEXT(BX5,"0.00")&" ("&TEXT(BY5,"0.00")&")" -> 0.32 (0.00) | BX5: =AVERAGE(BR5:BV5) -> 0.32237535 | BY5: =+_xlfn.STDEV.S(BR5:BV5) -> 0.0021508523
A6: ZD-GTFT-2 | B6: =+VLOOKUP($A6,INDIRECT(Adrese!B$2),2,FALSE) -> 3 | C6: =+VLOOKUP($A6,INDIRECT(Adrese!C$2),2,FALSE) -> 2 | D6: =+VLOOKUP($A6,INDIRECT(Adrese!D$2),2,FALSE) -> 5 | E6: =+VLOOKUP($A6,INDIRECT(Adrese!E$2),2,FALSE) -> 2 | F6: =+VLOOKUP($A6,INDIRECT(Adrese!F$2),2,FALSE) -> 4 | H6: =AVERAGE(B6:F6) -> 3.2 | J6: ZD-GTFT-2 | K6: =+VLOOKUP($A6,INDIRECT(Adrese!B$2),3,FALSE) -> 0 | L6: =+VLOOKUP($A6,INDIRECT(Adrese!C$2),3,FALSE) -> 0 | M6: =+VLOOKUP($A6,INDIRECT(Adrese!D$2),3,FALSE) -> 0 | N6: =+VLOOKUP($A6,INDIRECT(Adrese!E$2),3,FALSE) -> 0 | O6: =+VLOOKUP($A6,INDIRECT(Adrese!F$2),3,FALSE) -> 0 | P6: =SUM(K6:O6) -> 0 | Q6: =AVERAGE(K6:O6) -> 0 | R6: =+_xlfn.STDEV.S(K6:O6) -> 0 | T6: ZD-GTFT-2 | U6: =+VLOOKUP($T6,INDIRECT(Adrese!B$2),4,FALSE) -> 7367 | V6: =+VLOOKUP($T6,INDIRECT(Adrese!C$2),4,FALSE) -> 7454 | W6: =+VLOOKUP($T6,INDIRECT(Adrese!D$2),4,FALSE) -> 7318 | X6: =+VLOOKUP($T6,INDIRECT(Adrese!E$2),4,FALSE) -> 7385 | Y6: =+VLOOKUP($T6,INDIRECT(Adrese!F$2),4,FALSE) -> 7369 | Z6: =SUM(U6:Y6) -> 36893 | AA6: =AVERAGE(U6:Y6) -> 7378.6 | AB6: =+_xlfn.STDEV.S(U6:Y6) -> 49.054052 | AD6: ZD-GTFT-2 | AE6: =+VLOOKUP($A6,INDIRECT(Adrese!B$2),5,FALSE) -> 2604 | AF6: =+VLOOKUP($A6,INDIRECT(Adrese!C$2),5,FALSE) -> 2632 | AG6: =+VLOOKUP($A6,INDIRECT(Adrese!D$2),5,FALSE) -> 2575 | AH6: =+VLOOKUP($A6,INDIRECT(Adrese!E$2),5,FALSE) -> 2590 | AI6: =+VLOOKUP($A6,INDIRECT(Adrese!F$2),5,FALSE) -> 2563 | AJ6: =AVERAGE(AE6:AI6) -> 2592.8 | AK6: =+_xlfn.STDEV.S(AE6:AI6) -> 26.808581 | AM6: ZD-GTFT-2 | AN6: =+VLOOKUP($A6,INDIRECT(Adrese!B$2),6,FALSE) -> 0.85857143 | AO6: =+VLOOKUP($A6,INDIRECT(Adrese!C$2),6,FALSE) -> 0.86857143 | AP6: =+VLOOKUP($A6,INDIRECT(Adrese!D$2),6,FALSE) -> 0.84821429 | AQ6: =+VLOOKUP($A6,INDIRECT(Adrese!E$2),6,FALSE) -> 0.85357143 | AR6: =+VLOOKUP($A6,INDIRECT(Adrese!F$2),6,FALSE) -> 0.84392857 | AS6: =TEXT(AT6,"0.00")&" ("&TEXT(AU6,"0.00")&")" -> 0.85 (0.01) | AT6: =AVERAGE(AN6:AR6) -> 0.85457143 | AU6: =+_xlfn.STDEV.S(AN6:AR6) -> 0.0095744931 | AW6: ZD-GTFT-2 | AX6: =+VLOOKUP($A6,INDIRECT(Adrese!B$2),7,FALSE) -> 1 | AY6: =+VLOOKUP($A6,INDIRECT(Adrese!C$2),7,FALSE) -> 1 | AZ6: =+VLOOKUP($A6,INDIRECT(Adrese!D$2),7,FALSE) -> 1 | BA6: =+VLOOKUP($A6,INDIRECT(Adrese!E$2),7,FALSE) -> 1 | BB6: =+VLOOKUP($A6,INDIRECT(Adrese!F$2),7,FALSE) -> 1 | BC6: =TEXT(BD6,"0.00")&" ("&TEXT(BE6,"0.00")&")" -> 1.00 (0.00) | BD6: =AVERAGE(AX6:BB6) -> 1 | BE6: =+_xlfn.STDEV.S(AX6:BB6) -> 0 | BG6: ZD-GTFT-2 | BH6: =+VLOOKUP($BG6,INDIRECT(Adrese!B$2),8,FALSE) -> 0.31178633 | BI6: =+VLOOKUP($BG6,INDIRECT(Adrese!C$2),8,FALSE) -> 0.31009942 | BJ6: =+VLOOKUP($BG6,INDIRECT(Adrese!D$2),8,FALSE) -> 0.30779576 | BK6: =+VLOOKUP($BG6,INDIRECT(Adrese!E$2),8,FALSE) -> 0.30687622 | BL6: =+VLOOKUP($BG6,INDIRECT(Adrese!F$2),8,FALSE) -> 0.30813892 | BM6: =TEXT(BN6,"0.00")&" ("&TEXT(BO6,"0.00")&")" -> 0.31 (0.00) | BN6: =AVERAGE(BH6:BL6) -> 0.30893933 | BO6: =+_xlfn.STDEV.S(BH6:BL6) -> 0.0019783855 | BQ6: ZD-GTFT-2 | BR6: =+VLOOKUP($BG6,INDIRECT(Adrese!B$2),9,FALSE) -> 0.30549745 | BS6: =+VLOOKUP($BG6,INDIRECT(Adrese!C$2),9,FALSE) -> 0.30024948 | BT6: =+VLOOKUP($BG6,INDIRECT(Adrese!D$2),9,FALSE) -> 0.30071843 | BU6: =+VLOOKUP($BG6,INDIRECT(Adrese!E$2),9,FALSE) -> 0.30168723 | BV6: =+VLOOKUP($BG6,INDIRECT(Adrese!F$2),9,FALSE) -> 0.30509595 | BW6: =TEXT(BX6,"0.00")&" ("&TEXT(BY6,"0.00")&")" -> 0.30 (0.00) | BX6: =AVERAGE(BR6:BV6) -> 0.30264971 | BY6: =+_xlfn.STDEV.S(BR6:BV6) -> 0.002475431
A7: Cooperator | B7: =+VLOOKUP($A7,INDIRECT(Adrese!B$2),2,FALSE) -> 5 | C7: =+VLOOKUP($A7,INDIRECT(Adrese!C$2),2,FALSE) -> 4 | D7: =+VLOOKUP($A7,INDIRECT(Adrese!D$2),2,FALSE) -> 6 | E7: =+VLOOKUP($A7,INDIRECT(Adrese!E$2),2,FALSE) -> 6 | F7: =+VLOOKUP($A7,INDIRECT(Adrese!F$2),2,FALSE) -> 5 | H7: =AVERAGE(B7:F7) -> 5.2 | J7: Cooperator | K7: =+VLOOKUP($A7,INDIRECT(Adrese!B$2),3,FALSE) -> 0 | L7: =+VLOOKUP($A7,INDIRECT(Adrese!C$2),3,FALSE) -> 0 | M7: =+VLOOKUP($A7,INDIRECT(Adrese!D$2),3,FALSE) -> 0 | N7: =+VLOOKUP($A7,INDIRECT(Adrese!E$2),3,FALSE) -> 0 | O7: =+VLOOKUP($A7,INDIRECT(Adrese!F$2),3,FALSE) -> 0 | P7: =SUM(K7:O7) -> 0 | Q7: =AVERAGE(K7:O7) -> 0 | R7: =+_xlfn.STDEV.S(K7:O7) -> 0 | T7: Cooperator | U7: =+VLOOKUP($T7,INDIRECT(Adrese!B$2),4,FALSE) -> 7278 | V7: =+VLOOKUP($T7,INDIRECT(Adrese!C$2),4,FALSE) -> 7329 | W7: =+VLOOKUP($T7,INDIRECT(Adrese!D$2),4,FALSE) -> 7299 | X7: =+VLOOKUP($T7,INDIRECT(Adrese!E$2),4,FALSE) -> 7272 | Y7: =+VLOOKUP($T7,INDIRECT(Adrese!F$2),4,FALSE) -> 7290 | Z7: =SUM(U7:Y7) -> 36468 | AA7: =AVERAGE(U7:Y7) -> 7293.6 | AB7: =+_xlfn.STDEV.S(U7:Y7) -> 22.38973 | AD7: Cooperator | AE7: =+VLOOKUP($A7,INDIRECT(Adrese!B$2),5,FALSE) -> 3000 | AF7: =+VLOOKUP($A7,INDIRECT(Adrese!C$2),5,FALSE) -> 3000 | AG7: =+VLOOKUP($A7,INDIRECT(Adrese!D$2),5,FALSE) -> 3000 | AH7: =+VLOOKUP($A7,INDIRECT(Adrese!E$2),5,FALSE) -> 3000 | AI7: =+VLOOKUP($A7,INDIRECT(Adrese!F$2),5,FALSE) -> 3000 | AJ7: =AVERAGE(AE7:AI7) -> 3000 | AK7: =+_xlfn.STDEV.S(AE7:AI7) -> 0 | AM7: Cooperator | AN7: =+VLOOKUP($A7,INDIRECT(Adrese!B$2),6,FALSE) -> 1 | AO7: =+VLOOKUP($A7,INDIRECT(Adrese!C$2),6,FALSE) -> 1 | AP7: =+VLOOKUP($A7,INDIRECT(Adrese!D$2),6,FALSE) -> 1 | AQ7: =+VLOOKUP($A7,INDIRECT(Adrese!E$2),6,FALSE) -> 1 | AR7: =+VLOOKUP($A7,INDIRECT(Adrese!F$2),6,FALSE) -> 1 | AS7: =TEXT(AT7,"0.00")&" ("&TEXT(AU7,"0.00")&")" -> 1.00 (0.00) | AT7: =AVERAGE(AN7:AR7) -> 1 | AU7: =+_xlfn.STDEV.S(AN7:AR7) -> 0 | AW7: Cooperator | AX7: =+VLOOKUP($A7,INDIRECT(Adrese!B$2),7,FALSE) -> 1 | AY7: =+VLOOKUP($A7,INDIRECT(Adrese!C$2),7,FALSE) -> 1 | AZ7: =+VLOOKUP($A7,INDIRECT(Adrese!D$2),7,FALSE) -> 1 | BA7: =+VLOOKUP($A7,INDIRECT(Adrese!E$2),7,FALSE) -> 1 | BB7: =+VLOOKUP($A7,INDIRECT(Adrese!F$2),7,FALSE) -> 1 | BC7: =TEXT(BD7,"0.00")&" ("&TEXT(BE7,"0.00")&")" -> 1.00 (0.00) | BD7: =AVERAGE(AX7:BB7) -> 1 | BE7: =+_xlfn.STDEV.S(AX7:BB7) -> 0 | BG7: Cooperator | BH7: =+VLOOKUP($BG7,INDIRECT(Adrese!B$2),8,FALSE) -> 0.32552496 | BI7: =+VLOOKUP($BG7,INDIRECT(Adrese!C$2),8,FALSE) -> 0.32497495 | BJ7: =+VLOOKUP($BG7,INDIRECT(Adrese!D$2),8,FALSE) -> 0.32362759 | BK7: =+VLOOKUP($BG7,INDIRECT(Adrese!E$2),8,FALSE) -> 0.32372652 | BL7: =+VLOOKUP($BG7,INDIRECT(Adrese!F$2),8,FALSE) -> 0.32459665 | BM7: =TEXT(BN7,"0.00")&" ("&TEXT(BO7,"0.00")&")" -> 0.32 (0.00) | BN7: =AVERAGE(BH7:BL7) -> 0.32449013 | BO7: =+_xlfn.STDEV.S(BH7:BL7) -> 0.00081307275 | BQ7: Cooperator | BR7: =+VLOOKUP($BG7,INDIRECT(Adrese!B$2),9,FALSE) -> 0.25824264 | BS7: =+VLOOKUP($BG7,INDIRECT(Adrese!C$2),9,FALSE) -> 0.26266231 | BT7: =+VLOOKUP($BG7,INDIRECT(Adrese!D$2),9,FALSE) -> 0.25560459 | BU7: =+VLOOKUP($BG7,INDIRECT(Adrese!E$2),9,FALSE) -> 0.26257921 | BV7: =+VLOOKUP($BG7,INDIRECT(Adrese!F$2),9,FALSE) -> 0.25757332 | BW7: =TEXT(BX7,"0.00")&" ("&TEXT(BY7,"0.00")&")" -> 0.26 (0.00) | BX7: =AVERAGE(BR7:BV7) -> 0.25933241 | BY7: =+_xlfn.STDEV.S(BR7:BV7) -> 0.0031547017
A8: Tit For 2 Tats | B8: =+VLOOKUP($A8,INDIRECT(Adrese!B$2),2,FALSE) -> 4 | C8: =+VLOOKUP($A8,INDIRECT(Adrese!C$2),2,FALSE) -> 5 | D8: =+VLOOKUP($A8,INDIRECT(Adrese!D$2),2,FALSE) -> 4 | E8: =+VLOOKUP($A8,INDIRECT(Adrese!E$2),2,FALSE) -> 5 | F8: =+VLOOKUP($A8,INDIRECT(Adrese!F$2),2,FALSE) -> 6 | H8: =AVERAGE(B8:F8) -> 4.8 | J8: Tit For 2 Tats | K8: =+VLOOKUP($A8,INDIRECT(Adrese!B$2),3,FALSE) -> 0 | L8: =+VLOOKUP($A8,INDIRECT(Adrese!C$2),3,FALSE) -> 0 | M8: =+VLOOKUP($A8,INDIRECT(Adrese!D$2),3,FALSE) -> 0 | N8: =+VLOOKUP($A8,INDIRECT(Adrese!E$2),3,FALSE) -> 0 | O8: =+VLOOKUP($A8,INDIRECT(Adrese!F$2),3,FALSE) -> 0 | P8: =SUM(K8:O8) -> 0 | Q8: =AVERAGE(K8:O8) -> 0 | R8: =+_xlfn.STDEV.S(K8:O8) -> 0 | T8: Tit For 2 Tats | U8: =+VLOOKUP($T8,INDIRECT(Adrese!B$2),4,FALSE) -> 7336 | V8: =+VLOOKUP($T8,INDIRECT(Adrese!C$2),4,FALSE) -> 7312 | W8: =+VLOOKUP($T8,INDIRECT(Adrese!D$2),4,FALSE) -> 7337 | X8: =+VLOOKUP($T8,INDIRECT(Adrese!E$2),4,FALSE) -> 7314 | Y8: =+VLOOKUP($T8,INDIRECT(Adrese!F$2),4,FALSE) -> 7078 | Z8: =SUM(U8:Y8) -> 36377 | AA8: =AVERAGE(U8:Y8) -> 7275.4 | AB8: =+_xlfn.STDEV.S(U8:Y8) -> 110.97657 | AD8: Tit For 2 Tats | AE8: =+VLOOKUP($A8,INDIRECT(Adrese!B$2),5,FALSE) -> 2575 | AF8: =+VLOOKUP($A8,INDIRECT(Adrese!C$2),5,FALSE) -> 2553 | AG8: =+VLOOKUP($A8,INDIRECT(Adrese!D$2),5,FALSE) -> 2565 | AH8: =+VLOOKUP($A8,INDIRECT(Adrese!E$2),5,FALSE) -> 2558 | AI8: =+VLOOKUP($A8,INDIRECT(Adrese!F$2),5,FALSE) -> 2416 | AJ8: =AVERAGE(AE8:AI8) -> 2533.4 | AK8: =+_xlfn.STDEV.S(AE8:AI8) -> 66.146051 | AM8: Tit For 2 Tats | AN8: =+VLOOKUP($A8,INDIRECT(Adrese!B$2),6,FALSE) -> 0.84821429 | AO8: =+VLOOKUP($A8,INDIRECT(Adrese!C$2),6,FALSE) -> 0.84035714 | AP8: =+VLOOKUP($A8,INDIRECT(Adrese!D$2),6,FALSE) -> 0.84464286 | AQ8: =+VLOOKUP($A8,INDIRECT(Adrese!E$2),6,FALSE) -> 0.84214286 | AR8: =+VLOOKUP($A8,INDIRECT(Adrese!F$2),6,FALSE) -> 0.79142857 | AS8: =TEXT(AT8,"0.00")&" ("&TEXT(AU8,"0.00")&")" -> 0.83 (0.02) | AT8: =AVERAGE(AN8:AR8) -> 0.83335714 | AU8: =+_xlfn.STDEV.S(AN8:AR8) -> 0.023623589 | AW8: Tit For 2 Tats | AX8: =+VLOOKUP($A8,INDIRECT(Adrese!B$2),7,FALSE) -> 1 | AY8: =+VLOOKUP($A8,INDIRECT(Adrese!C$2),7,FALSE) -> 1 | AZ8: =+VLOOKUP($A8,INDIRECT(Adrese!D$2),7,FALSE) -> 1 | BA8: =+VLOOKUP($A8,INDIRECT(Adrese!E$2),7,FALSE) -> 1 | BB8: =+VLOOKUP($A8,INDIRECT(Adrese!F$2),7,FALSE) -> 1 | BC8: =TEXT(BD8,"0.00")&" ("&TEXT(BE8,"0.00")&")" -> 1.00 (0.00) | BD8: =AVERAGE(AX8:BB8) -> 1 | BE8: =+_xlfn.STDEV.S(AX8:BB8) -> 0 | BG8: Tit For 2 Tats | BH8: =+VLOOKUP($BG8,INDIRECT(Adrese!B$2),8,FALSE) -> 0.31496907 | BI8: =+VLOOKUP($BG8,INDIRECT(Adrese!C$2),8,FALSE) -> 0.31079159 | BJ8: =+VLOOKUP($BG8,INDIRECT(Adrese!D$2),8,FALSE) -> 0.31266331 | BK8: =+VLOOKUP($BG8,INDIRECT(Adrese!E$2),8,FALSE) -> 0.31003267 | BL8: =+VLOOKUP($BG8,INDIRECT(Adrese!F$2),8,FALSE) -> 0.3032629 | BM8: =TEXT(BN8,"0.00")&" ("&TEXT(BO8,"0.00")&")" -> 0.31 (0.00) | BN8: =AVERAGE(BH8:BL8) -> 0.31034391 | BO8: =+_xlfn.STDEV.S(BH8:BL8) -> 0.0043934534 | BQ8: Tit For 2 Tats | BR8: =+VLOOKUP($BG8,INDIRECT(Adrese!B$2),9,FALSE) -> 0.32326403 | BS8: =+VLOOKUP($BG8,INDIRECT(Adrese!C$2),9,FALSE) -> 0.32307921 | BT8: =+VLOOKUP($BG8,INDIRECT(Adrese!D$2),9,FALSE) -> 0.32262424 | BU8: =+VLOOKUP($BG8,INDIRECT(Adrese!E$2),9,FALSE) -> 0.32179762 | BV8: =+VLOOKUP($BG8,INDIRECT(Adrese!F$2),9,FALSE) -> 0.32190543 | BW8: =TEXT(BX8,"0.00")&" ("&TEXT(BY8,"0.00")&")" -> 0.32 (0.00) | BX8: =AVERAGE(BR8:BV8) -> 0.32253411 | BY8: =+_xlfn.STDEV.S(BR8:BV8) -> 0.00066627582
A9: Tit For Tat | B9: =+VLOOKUP($A9,INDIRECT(Adrese!B$2),2,FALSE) -> 7 | C9: =+VLOOKUP($A9,INDIRECT(Adrese!C$2),2,FALSE) -> 7 | D9: =+VLOOKUP($A9,INDIRECT(Adrese!D$2),2,FALSE) -> 7 | E9: =+VLOOKUP($A9,INDIRECT(Adrese!E$2),2,FALSE) -> 7 | F9: =+VLOOKUP($A9,INDIRECT(Adrese!F$2),2,FALSE) -> 7 | H9: =AVERAGE(B9:F9) -> 7 | J9: Tit For Tat | K9: =+VLOOKUP($A9,INDIRECT(Adrese!B$2),3,FALSE) -> 0 | L9: =+VLOOKUP($A9,INDIRECT(Adrese!C$2),3,FALSE) -> 0 | M9: =+VLOOKUP($A9,INDIRECT(Adrese!D$2),3,FALSE) -> 0 | N9: =+VLOOKUP($A9,INDIRECT(Adrese!E$2),3,FALSE) -> 0 | O9: =+VLOOKUP($A9,INDIRECT(Adrese!F$2),3,FALSE) -> 0 | P9: =SUM(K9:O9) -> 0 | Q9: =AVERAGE(K9:O9) -> 0 | R9: =+_xlfn.STDEV.S(K9:O9) -> 0 | T9: Tit For Tat | U9: =+VLOOKUP($T9,INDIRECT(Adrese!B$2),4,FALSE) -> 6993 | V9: =+VLOOKUP($T9,INDIRECT(Adrese!C$2),4,FALSE) -> 7045 | W9: =+VLOOKUP($T9,INDIRECT(Adrese!D$2),4,FALSE) -> 7031 | X9: =+VLOOKUP($T9,INDIRECT(Adrese!E$2),4,FALSE) -> 7028 | Y9: =+VLOOKUP($T9,INDIRECT(Adrese!F$2),4,FALSE) -> 7004 | Z9: =SUM(U9:Y9) -> 35101 | AA9: =AVERAGE(U9:Y9) -> 7020.2 | AB9: =+_xlfn.STDEV.S(U9:Y9) -> 21.18254 | AD9: Tit For Tat | AE9: =+VLOOKUP($A9,INDIRECT(Adrese!B$2),5,FALSE) -> 2222 | AF9: =+VLOOKUP($A9,INDIRECT(Adrese!C$2),5,FALSE) -> 2249 | AG9: =+VLOOKUP($A9,INDIRECT(Adrese!D$2),5,FALSE) -> 2239 | AH9: =+VLOOKUP($A9,INDIRECT(Adrese!E$2),5,FALSE) -> 2239 | AI9: =+VLOOKUP($A9,INDIRECT(Adrese!F$2),5,FALSE) -> 2231 | AJ9: =AVERAGE(AE9:AI9) -> 2236 | AK9: =+_xlfn.STDEV.S(AE9:AI9) -> 10.099505 | AM9: Tit For Tat | AN9: =+VLOOKUP($A9,INDIRECT(Adrese!B$2),6,FALSE) -> 0.72214286 | AO9: =+VLOOKUP($A9,INDIRECT(Adrese!C$2),6,FALSE) -> 0.73178571 | AP9: =+VLOOKUP($A9,INDIRECT(Adrese!D$2),6,FALSE) -> 0.72821429 | AQ9: =+VLOOKUP($A9,INDIRECT(Adrese!E$2),6,FALSE) -> 0.72821429 | AR9: =+VLOOKUP($A9,INDIRECT(Adrese!F$2),6,FALSE) -> 0.72535714 | AS9: =TEXT(AT9,"0.00")&" ("&TEXT(AU9,"0.00")&")" -> 0.73 (0.00) | AT9: =AVERAGE(AN9:AR9) -> 0.72714286 | AU9: =+_xlfn.STDEV.S(AN9:AR9) -> 0.003606966 | AW9: Tit For Tat | AX9: =+VLOOKUP($A9,INDIRECT(Adrese!B$2),7,FALSE) -> 1 | AY9: =+VLOOKUP($A9,INDIRECT(Adrese!C$2),7,FALSE) -> 1 | AZ9: =+VLOOKUP($A9,INDIRECT(Adrese!D$2),7,FALSE) -> 1 | BA9: =+VLOOKUP($A9,INDIRECT(Adrese!E$2),7,FALSE) -> 1 | BB9: =+VLOOKUP($A9,INDIRECT(Adrese!F$2),7,FALSE) -> 1 | BC9: =TEXT(BD9,"0.00")&" ("&TEXT(BE9,"0.00")&")" -> 1.00 (0.00) | BD9: =AVERAGE(AX9:BB9) -> 1 | BE9: =+_xlfn.STDEV.S(AX9:BB9) -> 0 | BG9: Tit For Tat | BH9: =+VLOOKUP($BG9,INDIRECT(Adrese!B$2),8,FALSE) -> 0.28992592 | BI9: =+VLOOKUP($BG9,INDIRECT(Adrese!C$2),8,FALSE) -> 0.28804653 | BJ9: =+VLOOKUP($BG9,INDIRECT(Adrese!D$2),8,FALSE) -> 0.28816843 | BK9: =+VLOOKUP($BG9,INDIRECT(Adrese!E$2),8,FALSE) -> 0.28640832 | BL9: =+VLOOKUP($BG9,INDIRECT(Adrese!F$2),8,FALSE) -> 0.28835277 | BM9: =TEXT(BN9,"0.00")&" ("&TEXT(BO9,"0.00")&")" -> 0.29 (0.00) | BN9: =AVERAGE(BH9:BL9) -> 0.2881804 | BO9: =+_xlfn.STDEV.S(BH9:BL9) -> 0.001248488 | BQ9: Tit For Tat | BR9: =+VLOOKUP($BG9,INDIRECT(Adrese!B$2),9,FALSE) -> 0.31366568 | BS9: =+VLOOKUP($BG9,INDIRECT(Adrese!C$2),9,FALSE) -> 0.31149053 | BT9: =+VLOOKUP($BG9,INDIRECT(Adrese!D$2),9,FALSE) -> 0.30947262 | BU9: =+VLOOKUP($BG9,INDIRECT(Adrese!E$2),9,FALSE) -> 0.31104471 | BV9: =+VLOOKUP($BG9,INDIRECT(Adrese!F$2),9,FALSE) -> 0.31359761 | BW9: =TEXT(BX9,"0.00")&" ("&TEXT(BY9,"0.00")&")" -> 0.31 (0.00) | BX9: =AVERAGE(BR9:BV9) -> 0.31185423 | BY9: =+_xlfn.STDEV.S(BR9:BV9) -> 0.0017874811
A10: Grudger | B10: =+VLOOKUP($A10,INDIRECT(Adrese!B$2),2,FALSE) -> 8 | C10: =+VLOOKUP($A10,INDIRECT(Adrese!C$2),2,FALSE) -> 8 | D10: =+VLOOKUP($A10,INDIRECT(Adrese!D$2),2,FALSE) -> 9 | E10: =+VLOOKUP($A10,INDIRECT(Adrese!E$2),2,FALSE) -> 8 | F10: =+VLOOKUP($A10,INDIRECT(Adrese!F$2),2,FALSE) -> 8 | H10: =AVERAGE(B10:F10) -> 8.2 | J10: Grudger | K10: =+VLOOKUP($A10,INDIRECT(Adrese!B$2),3,FALSE) -> 1 | L10: =+VLOOKUP($A10,INDIRECT(Adrese!C$2),3,FALSE) -> 1 | M10: =+VLOOKUP($A10,INDIRECT(Adrese!D$2),3,FALSE) -> 1 | N10: =+VLOOKUP($A10,INDIRECT(Adrese!E$2),3,FALSE) -> 1 | O10: =+VLOOKUP($A10,INDIRECT(Adrese!F$2),3,FALSE) -> 1 | P10: =SUM(K10:O10) -> 5 | Q10: =AVERAGE(K10:O10) -> 1 | R10: =+_xlfn.STDEV.S(K10:O10) -> 0 | T10: Grudger | U10: =+VLOOKUP($T10,INDIRECT(Adrese!B$2),4,FALSE) -> 6865 | V10: =+VLOOKUP($T10,INDIRECT(Adrese!C$2),4,FALSE) -> 6835 | W10: =+VLOOKUP($T10,INDIRECT(Adrese!D$2),4,FALSE) -> 6797 | X10: =+VLOOKUP($T10,INDIRECT(Adrese!E$2),4,FALSE) -> 6903 | Y10: =+VLOOKUP($T10,INDIRECT(Adrese!F$2),4,FALSE) -> 6851 | Z10: =SUM(U10:Y10) -> 34251 | AA10: =AVERAGE(U10:Y10) -> 6850.2 | AB10: =+_xlfn.STDEV.S(U10:Y10) -> 38.951252 | AD10: Grudger | AE10: =+VLOOKUP($A10,INDIRECT(Adrese!B$2),5,FALSE) -> 2016 | AF10: =+VLOOKUP($A10,INDIRECT(Adrese!C$2),5,FALSE) -> 2019 | AG10: =+VLOOKUP($A10,INDIRECT(Adrese!D$2),5,FALSE) -> 2016 | AH10: =+VLOOKUP($A10,INDIRECT(Adrese!E$2),5,FALSE) -> 2057 | AI10: =+VLOOKUP($A10,INDIRECT(Adrese!F$2),5,FALSE) -> 2027 | AJ10: =AVERAGE(AE10:AI10) -> 2027 | AK10: =+_xlfn.STDEV.S(AE10:AI10) -> 17.363755 | AM10: Grudger | AN10: =+VLOOKUP($A10,INDIRECT(Adrese!B$2),6,FALSE) -> 0.64857143 | AO10: =+VLOOKUP($A10,INDIRECT(Adrese!C$2),6,FALSE) -> 0.64964286 | AP10: =+VLOOKUP($A10,INDIRECT(Adrese!D$2),6,FALSE) -> 0.64857143 | AQ10: =+VLOOKUP($A10,INDIRECT(Adrese!E$2),6,FALSE) -> 0.66321429 | AR10: =+VLOOKUP($A10,INDIRECT(Adrese!F$2),6,FALSE) -> 0.6525 | AS10: =TEXT(AT10,"0.00")&" ("&TEXT(AU10,"0.00")&")" -> 0.65 (0.01) | AT10: =AVERAGE(AN10:AR10) -> 0.6525 | AU10: =+_xlfn.STDEV.S(AN10:AR10) -> 0.0062013412 | AW10: Grudger | AX10: =+VLOOKUP($A10,INDIRECT(Adrese!B$2),7,FALSE) -> 0.92857143 | AY10: =+VLOOKUP($A10,INDIRECT(Adrese!C$2),7,FALSE) -> 0.92857143 | AZ10: =+VLOOKUP($A10,INDIRECT(Adrese!D$2),7,FALSE) -> 0.92857143 | BA10: =+VLOOKUP($A10,INDIRECT(Adrese!E$2),7,FALSE) -> 0.92857143 | BB10: =+VLOOKUP($A10,INDIRECT(Adrese!F$2),7,FALSE) -> 0.92857143 | BC10: =TEXT(BD10,"0.00")&" ("&TEXT(BE10,"0.00")&")" -> 0.93 (0.00) | BD10: =AVERAGE(AX10:BB10) -> 0.92857143 | BE10: =+_xlfn.STDEV.S(AX10:BB10) -> 0 | BG10: Grudger | BH10: =+VLOOKUP($BG10,INDIRECT(Adrese!B$2),8,FALSE) -> 0.27403475 | BI10: =+VLOOKUP($BG10,INDIRECT(Adrese!C$2),8,FALSE) -> 0.27063418 | BJ10: =+VLOOKUP($BG10,INDIRECT(Adrese!D$2),8,FALSE) -> 0.27032693 | BK10: =+VLOOKUP($BG10,INDIRECT(Adrese!E$2),8,FALSE) -> 0.27161107 | BL10: =+VLOOKUP($BG10,INDIRECT(Adrese!F$2),8,FALSE) -> 0.2714038 | BM10: =TEXT(BN10,"0.00")&" ("&TEXT(BO10,"0.00")&")" -> 0.27 (0.00) | BN10: =AVERAGE(BH10:BL10) -> 0.27160215 | BO10: =+_xlfn.STDEV.S(BH10:BL10) -> 0.0014594618 | BQ10: Grudger | BR10: =+VLOOKUP($BG10,INDIRECT(Adrese!B$2),9,FALSE) -> 0.30427045 | BS10: =+VLOOKUP($BG10,INDIRECT(Adrese!C$2),9,FALSE) -> 0.30647528 | BT10: =+VLOOKUP($BG10,INDIRECT(Adrese!D$2),9,FALSE) -> 0.30155823 | BU10: =+VLOOKUP($BG10,INDIRECT(Adrese!E$2),9,FALSE) -> 0.30379732 | BV10: =+VLOOKUP($BG10,INDIRECT(Adrese!F$2),9,FALSE) -> 0.30472153 | BW10: =TEXT(BX10,"0.00")&" ("&TEXT(BY10,"0.00")&")" -> 0.30 (0.00) | BX10: =AVERAGE(BR10:BV10) -> 0.30416456 | BY10: =+_xlfn.STDEV.S(BR10:BV10) -> 0.0017740276
A11: Hard Tit For Tat | B11: =+VLOOKUP($A11,INDIRECT(Adrese!B$2),2,FALSE) -> 9 | C11: =+VLOOKUP($A11,INDIRECT(Adrese!C$2),2,FALSE) -> 10 | D11: =+VLOOKUP($A11,INDIRECT(Adrese!D$2),2,FALSE) -> 8 | E11: =+VLOOKUP($A11,INDIRECT(Adrese!E$2),2,FALSE) -> 9 | F11: =+VLOOKUP($A11,INDIRECT(Adrese!F$2),2,FALSE) -> 9 | H11: =AVERAGE(B11:F11) -> 9 | J11: Hard Tit For Tat | K11: =+VLOOKUP($A11,INDIRECT(Adrese!B$2),3,FALSE) -> 1 | L11: =+VLOOKUP($A11,INDIRECT(Adrese!C$2),3,FALSE) -> 2 | M11: =+VLOOKUP($A11,INDIRECT(Adrese!D$2),3,FALSE) -> 1 | N11: =+VLOOKUP($A11,INDIRECT(Adrese!E$2),3,FALSE) -> 1 | O11: =+VLOOKUP($A11,INDIRECT(Adrese!F$2),3,FALSE) -> 1 | P11: =SUM(K11:O11) -> 6 | Q11: =AVERAGE(K11:O11) -> 1.2 | R11: =+_xlfn.STDEV.S(K11:O11) -> 0.4472136 | T11: Hard Tit For Tat | U11: =+VLOOKUP($T11,INDIRECT(Adrese!B$2),4,FALSE) -> 6850 | V11: =+VLOOKUP($T11,INDIRECT(Adrese!C$2),4,FALSE) -> 6787 | W11: =+VLOOKUP($T11,INDIRECT(Adrese!D$2),4,FALSE) -> 6858 | X11: =+VLOOKUP($T11,INDIRECT(Adrese!E$2),4,FALSE) -> 6839 | Y11: =+VLOOKUP($T11,INDIRECT(Adrese!F$2),4,FALSE) -> 6821 | Z11: =SUM(U11:Y11) -> 34155 | AA11: =AVERAGE(U11:Y11) -> 6831 | AB11: =+_xlfn.STDEV.S(U11:Y11) -> 28.240042 | AD11: Hard Tit For Tat | AE11: =+VLOOKUP($A11,INDIRECT(Adrese!B$2),5,FALSE) -> 2054 | AF11: =+VLOOKUP($A11,INDIRECT(Adrese!C$2),5,FALSE) -> 2052 | AG11: =+VLOOKUP($A11,INDIRECT(Adrese!D$2),5,FALSE) -> 2069 | AH11: =+VLOOKUP($A11,INDIRECT(Adrese!E$2),5,FALSE) -> 2057 | AI11: =+VLOOKUP($A11,INDIRECT(Adrese!F$2),5,FALSE) -> 2055 | AJ11: =AVERAGE(AE11:AI11) -> 2057.4 | AK11: =+_xlfn.STDEV.S(AE11:AI11) -> 6.7305275 | AM11: Hard Tit For Tat | AN11: =+VLOOKUP($A11,INDIRECT(Adrese!B$2),6,FALSE) -> 0.66214286 | AO11: =+VLOOKUP($A11,INDIRECT(Adrese!C$2),6,FALSE) -> 0.66142857 | AP11: =+VLOOKUP($A11,INDIRECT(Adrese!D$2),6,FALSE) -> 0.6675 | AQ11: =+VLOOKUP($A11,INDIRECT(Adrese!E$2),6,FALSE) -> 0.66321429 | AR11: =+VLOOKUP($A11,INDIRECT(Adrese!F$2),6,FALSE) -> 0.6625 | AS11: =TEXT(AT11,"0.00")&" ("&TEXT(AU11,"0.00")&")" -> 0.66 (0.00) | AT11: =AVERAGE(AN11:AR11) -> 0.66335714 | AU11: =+_xlfn.STDEV.S(AN11:AR11) -> 0.0024037598 | AW11: Hard Tit For Tat | AX11: =+VLOOKUP($A11,INDIRECT(Adrese!B$2),7,FALSE) -> 0.92857143 | AY11: =+VLOOKUP($A11,INDIRECT(Adrese!C$2),7,FALSE) -> 0.85714286 | AZ11: =+VLOOKUP($A11,INDIRECT(Adrese!D$2),7,FALSE) -> 0.92857143 | BA11: =+VLOOKUP($A11,INDIRECT(Adrese!E$2),7,FALSE) -> 0.92857143 | BB11: =+VLOOKUP($A11,INDIRECT(Adrese!F$2),7,FALSE) -> 0.92857143 | BC11: =TEXT(BD11,"0.00")&" ("&TEXT(BE11,"0.00")&")" -> 0.91 (0.03) | BD11: =AVERAGE(AX11:BB11) -> 0.91428571 | BE11: =+_xlfn.STDEV.S(AX11:BB11) -> 0.031943828 | BG11: Hard Tit For Tat | BH11: =+VLOOKUP($BG11,INDIRECT(Adrese!B$2),8,FALSE) -> 0.27655893 | BI11: =+VLOOKUP($BG11,INDIRECT(Adrese!C$2),8,FALSE) -> 0.27293383 | BJ11: =+VLOOKUP($BG11,INDIRECT(Adrese!D$2),8,FALSE) -> 0.27365088 | BK11: =+VLOOKUP($BG11,INDIRECT(Adrese!E$2),8,FALSE) -> 0.2716127 | BL11: =+VLOOKUP($BG11,INDIRECT(Adrese!F$2),8,FALSE) -> 0.27358404 | BM11: =TEXT(BN11,"0.00")&" ("&TEXT(BO11,"0.00")&")" -> 0.27 (0.00) | BN11: =AVERAGE(BH11:BL11) -> 0.27366808 | BO11: =+_xlfn.STDEV.S(BH11:BL11) -> 0.0018116313 | BQ11: Hard Tit For Tat | BR11: =+VLOOKUP($BG11,INDIRECT(Adrese!B$2),9,FALSE) -> 0.30369702 | BS11: =+VLOOKUP($BG11,INDIRECT(Adrese!C$2),9,FALSE) -> 0.3058995 | BT11: =+VLOOKUP($BG11,INDIRECT(Adrese!D$2),9,FALSE) -> 0.30080112 | BU11: =+VLOOKUP($BG11,INDIRECT(Adrese!E$2),9,FALSE) -> 0.30225575 | BV11: =+VLOOKUP($BG11,INDIRECT(Adrese!F$2),9,FALSE) -> 0.3053378 | BW11: =TEXT(BX11,"0.00")&" ("&TEXT(BY11,"0.00")&")" -> 0.30 (0.00) | BX11: =AVERAGE(BR11:BV11) -> 0.30359824 | BY11: =+_xlfn.STDEV.S(BR11:BV11) -> 0.0021188328
A12: Win-Stay Lose-Shift | B12: =+VLOOKUP($A12,INDIRECT(Adrese!B$2),2,FALSE) -> 10 | C12: =+VLOOKUP($A12,INDIRECT(Adrese!C$2),2,FALSE) -> 9 | D12: =+VLOOKUP($A12,INDIRECT(Adrese!D$2),2,FALSE) -> 10 | E12: =+VLOOKUP($A12,INDIRECT(Adrese!E$2),2,FALSE) -> 10 | F12: =+VLOOKUP($A12,INDIRECT(Adrese!F$2),2,FALSE) -> 10 | H12: =AVERAGE(B12:F12) -> 9.8 | J12: Win-Stay Lose-Shift | K12: =+VLOOKUP($A12,INDIRECT(Adrese!B$2),3,FALSE) -> 1 | L12: =+VLOOKUP($A12,INDIRECT(Adrese!C$2),3,FALSE) -> 0 | M12: =+VLOOKUP($A12,INDIRECT(Adrese!D$2),3,FALSE) -> 0 | N12: =+VLOOKUP($A12,INDIRECT(Adrese!E$2),3,FALSE) -> 0 | O12: =+VLOOKUP($A12,INDIRECT(Adrese!F$2),3,FALSE) -> 0 | P12: =SUM(K12:O12) -> 1 | Q12: =AVERAGE(K12:O12) -> 0.2 | R12: =+_xlfn.STDEV.S(K12:O12) -> 0.4472136 | T12: Win-Stay Lose-Shift | U12: =+VLOOKUP($T12,INDIRECT(Adrese!B$2),4,FALSE) -> 6818 | V12: =+VLOOKUP($T12,INDIRECT(Adrese!C$2),4,FALSE) -> 6794 | W12: =+VLOOKUP($T12,INDIRECT(Adrese!D$2),4,FALSE) -> 6739 | X12: =+VLOOKUP($T12,INDIRECT(Adrese!E$2),4,FALSE) -> 6784 | Y12: =+VLOOKUP($T12,INDIRECT(Adrese!F$2),4,FALSE) -> 6723 | Z12: =SUM(U12:Y12) -> 33858 | AA12: =AVERAGE(U12:Y12) -> 6771.6 | AB12: =+_xlfn.STDEV.S(U12:Y12) -> 39.475309 | AD12: Win-Stay Lose-Shift | AE12: =+VLOOKUP($A12,INDIRECT(Adrese!B$2),5,FALSE) -> 2444 | AF12: =+VLOOKUP($A12,INDIRECT(Adrese!C$2),5,FALSE) -> 2451 | AG12: =+VLOOKUP($A12,INDIRECT(Adrese!D$2),5,FALSE) -> 2447 | AH12: =+VLOOKUP($A12,INDIRECT(Adrese!E$2),5,FALSE) -> 2461 | AI12: =+VLOOKUP($A12,INDIRECT(Adrese!F$2),5,FALSE) -> 2464 | AJ12: =AVERAGE(AE12:AI12) -> 2453.4 | AK12: =+_xlfn.STDEV.S(AE12:AI12) -> 8.7349871 | AM12: Win-Stay Lose-Shift | AN12: =+VLOOKUP($A12,INDIRECT(Adrese!B$2),6,FALSE) -> 0.80142857 | AO12: =+VLOOKUP($A12,INDIRECT(Adrese!C$2),6,FALSE) -> 0.80392857 | AP12: =+VLOOKUP($A12,INDIRECT(Adrese!D$2),6,FALSE) -> 0.8025 | AQ12: =+VLOOKUP($A12,INDIRECT(Adrese!E$2),6,FALSE) -> 0.8075 | AR12: =+VLOOKUP($A12,INDIRECT(Adrese!F$2),6,FALSE) -> 0.80857143 | AS12: =TEXT(AT12,"0.00")&" ("&TEXT(AU12,"0.00")&")" -> 0.80 (0.00) | AT12: =AVERAGE(AN12:AR12) -> 0.80478571 | AU12: =+_xlfn.STDEV.S(AN12:AR12) -> 0.0031196383 | AW12: Win-Stay Lose-Shift | AX12: =+VLOOKUP($A12,INDIRECT(Adrese!B$2),7,FALSE) -> 0.92857143 | AY12: =+VLOOKUP($A12,INDIRECT(Adrese!C$2),7,FALSE) -> 1 | AZ12: =+VLOOKUP($A12,INDIRECT(Adrese!D$2),7,FALSE) -> 1 | BA12: =+VLOOKUP($A12,INDIRECT(Adrese!E$2),7,FALSE) -> 1 | BB12: =+VLOOKUP($A12,INDIRECT(Adrese!F$2),7,FALSE) -> 1 | BC12: =TEXT(BD12,"0.00")&" ("&TEXT(BE12,"0.00")&")" -> 0.99 (0.03) | BD12: =AVERAGE(AX12:BB12) -> 0.98571429 | BE12: =+_xlfn.STDEV.S(AX12:BB12) -> 0.031943828 | BG12: Win-Stay Lose-Shift | BH12: =+VLOOKUP($BG12,INDIRECT(Adrese!B$2),8,FALSE) -> 0.29623306 | BI12: =+VLOOKUP($BG12,INDIRECT(Adrese!C$2),8,FALSE) -> 0.29446796 | BJ12: =+VLOOKUP($BG12,INDIRECT(Adrese!D$2),8,FALSE) -> 0.29336624 | BK12: =+VLOOKUP($BG12,INDIRECT(Adrese!E$2),8,FALSE) -> 0.29361133 | BL12: =+VLOOKUP($BG12,INDIRECT(Adrese!F$2),8,FALSE) -> 0.29529474 | BM12: =TEXT(BN12,"0.00")&" ("&TEXT(BO12,"0.00")&")" -> 0.29 (0.00) | BN12: =AVERAGE(BH12:BL12) -> 0.29459467 | BO12: =+_xlfn.STDEV.S(BH12:BL12) -> 0.0011902162 | BQ12: Win-Stay Lose-Shift | BR12: =+VLOOKUP($BG12,INDIRECT(Adrese!B$2),9,FALSE) -> 0.28373465 | BS12: =+VLOOKUP($BG12,INDIRECT(Adrese!C$2),9,FALSE) -> 0.2860204 | BT12: =+VLOOKUP($BG12,INDIRECT(Adrese!D$2),9,FALSE) -> 0.27942475 | BU12: =+VLOOKUP($BG12,INDIRECT(Adrese!E$2),9,FALSE) -> 0.28370098 | BV12: =+VLOOKUP($BG12,INDIRECT(Adrese!F$2),9,FALSE) -> 0.28267782 | BW12: =TEXT(BX12,"0.00")&" ("&TEXT(BY12,"0.00")&")" -> 0.28 (0.00) | BX12: =AVERAGE(BR12:BV12) -> 0.28311172 | BY12: =+_xlfn.STDEV.S(BR12:BV12) -> 0.0023967557
A13: Hard Go By Majority | B13: =+VLOOKUP($A13,INDIRECT(Adrese!B$2),2,FALSE) -> 11 | C13: =+VLOOKUP($A13,INDIRECT(Adrese!C$2),2,FALSE) -> 11 | D13: =+VLOOKUP($A13,INDIRECT(Adrese!D$2),2,FALSE) -> 11 | E13: =+VLOOKUP($A13,INDIRECT(Adrese!E$2),2,FALSE) -> 11 | F13: =+VLOOKUP($A13,INDIRECT(Adrese!F$2),2,FALSE) -> 11 | H13: =AVERAGE(B13:F13) -> 11 | J13: Hard Go By Majority | K13: =+VLOOKUP($A13,INDIRECT(Adrese!B$2),3,FALSE) -> 8 | L13: =+VLOOKUP($A13,INDIRECT(Adrese!C$2),3,FALSE) -> 7 | M13: =+VLOOKUP($A13,INDIRECT(Adrese!D$2),3,FALSE) -> 7 | N13: =+VLOOKUP($A13,INDIRECT(Adrese!E$2),3,FALSE) -> 7 | O13: =+VLOOKUP($A13,INDIRECT(Adrese!F$2),3,FALSE) -> 7 | P13: =SUM(K13:O13) -> 36 | Q13: =AVERAGE(K13:O13) -> 7.2 | R13: =+_xlfn.STDEV.S(K13:O13) -> 0.4472136 | T13: Hard Go By Majority | U13: =+VLOOKUP($T13,INDIRECT(Adrese!B$2),4,FALSE) -> 6299 | V13: =+VLOOKUP($T13,INDIRECT(Adrese!C$2),4,FALSE) -> 6382 | W13: =+VLOOKUP($T13,INDIRECT(Adrese!D$2),4,FALSE) -> 6247 | X13: =+VLOOKUP($T13,INDIRECT(Adrese!E$2),4,FALSE) -> 6388 | Y13: =+VLOOKUP($T13,INDIRECT(Adrese!F$2),4,FALSE) -> 6312 | Z13: =SUM(U13:Y13) -> 31628 | AA13: =AVERAGE(U13:Y13) -> 6325.6 | AB13: =+_xlfn.STDEV.S(U13:Y13) -> 59.466797 | AD13: Hard Go By Majority | AE13: =+VLOOKUP($A13,INDIRECT(Adrese!B$2),5,FALSE) -> 1298 | AF13: =+VLOOKUP($A13,INDIRECT(Adrese!C$2),5,FALSE) -> 1585 | AG13: =+VLOOKUP($A13,INDIRECT(Adrese!D$2),5,FALSE) -> 1687 | AH13: =+VLOOKUP($A13,INDIRECT(Adrese!E$2),5,FALSE) -> 1625 | AI13: =+VLOOKUP($A13,INDIRECT(Adrese!F$2),5,FALSE) -> 1687 | AJ13: =AVERAGE(AE13:AI13) -> 1576.4 | AK13: =+_xlfn.STDEV.S(AE13:AI13) -> 161.56051 | AM13: Hard Go By Majority | AN13: =+VLOOKUP($A13,INDIRECT(Adrese!B$2),6,FALSE) -> 0.46357143 | AO13: =+VLOOKUP($A13,INDIRECT(Adrese!C$2),6,FALSE) -> 0.56607143 | AP13: =+VLOOKUP($A13,INDIRECT(Adrese!D$2),6,FALSE) -> 0.6025 | AQ13: =+VLOOKUP($A13,INDIRECT(Adrese!E$2),6,FALSE) -> 0.58035714 | AR13: =+VLOOKUP($A13,INDIRECT(Adrese!F$2),6,FALSE) -> 0.6025 | AS13: =TEXT(AT13,"0.00")&" ("&TEXT(AU13,"0.00")&")" -> 0.56 (0.06) | AT13: =AVERAGE(AN13:AR13) -> 0.563 | AU13: =+_xlfn.STDEV.S(AN13:AR13) -> 0.057700184 | AW13: Hard Go By Majority | AX13: =+VLOOKUP($A13,INDIRECT(Adrese!B$2),7,FALSE) -> 0.42857143 | AY13: =+VLOOKUP($A13,INDIRECT(Adrese!C$2),7,FALSE) -> 0.5 | AZ13: =+VLOOKUP($A13,INDIRECT(Adrese!D$2),7,FALSE) -> 0.5 | BA13: =+VLOOKUP($A13,INDIRECT(Adrese!E$2),7,FALSE) -> 0.5 | BB13: =+VLOOKUP($A13,INDIRECT(Adrese!F$2),7,FALSE) -> 0.5 | BC13: =TEXT(BD13,"0.00")&" ("&TEXT(BE13,"0.00")&")" -> 0.49 (0.03) | BD13: =AVERAGE(AX13:BB13) -> 0.48571429 | BE13: =+_xlfn.STDEV.S(AX13:BB13) -> 0.031943828 | BG13: Hard Go By Majority | BH13: =+VLOOKUP($BG13,INDIRECT(Adrese!B$2),8,FALSE) -> 0.18204178 | BI13: =+VLOOKUP($BG13,INDIRECT(Adrese!C$2),8,FALSE) -> 0.19490171 | BJ13: =+VLOOKUP($BG13,INDIRECT(Adrese!D$2),8,FALSE) -> 0.20079667 | BK13: =+VLOOKUP($BG13,INDIRECT(Adrese!E$2),8,FALSE) -> 0.19727808 | BL13: =+VLOOKUP($BG13,INDIRECT(Adrese!F$2),8,FALSE) -> 0.20213631 | BM13: =TEXT(BN13,"0.00")&" ("&TEXT(BO13,"0.00")&")" -> 0.20 (0.01) | BN13: =AVERAGE(BH13:BL13) -> 0.19543091 | BO13: =+_xlfn.STDEV.S(BH13:BL13) -> 0.0080111582 | BQ13: Hard Go By Majority | BR13: =+VLOOKUP($BG13,INDIRECT(Adrese!B$2),9,FALSE) -> 0.10476292 | BS13: =+VLOOKUP($BG13,INDIRECT(Adrese!C$2),9,FALSE) -> 0.084120656 | BT13: =+VLOOKUP($BG13,INDIRECT(Adrese!D$2),9,FALSE) -> 0.080951476 | BU13: =+VLOOKUP($BG13,INDIRECT(Adrese!E$2),9,FALSE) -> 0.085690996 | BV13: =+VLOOKUP($BG13,INDIRECT(Adrese!F$2),9,FALSE) -> 0.084674453 | BW13: =TEXT(BX13,"0.00")&" ("&TEXT(BY13,"0.00")&")" -> 0.09 (0.01) | BX13: =AVERAGE(BR13:BV13) -> 0.088040101 | BY13: =+_xlfn.STDEV.S(BR13:BV13) -> 0.0095145841
A14: Random | B14: =+VLOOKUP($A14,INDIRECT(Adrese!B$2),2,FALSE) -> 13 | C14: =+VLOOKUP($A14,INDIRECT(Adrese!C$2),2,FALSE) -> 12 | D14: =+VLOOKUP($A14,INDIRECT(Adrese!D$2),2,FALSE) -> 12 | E14: =+VLOOKUP($A14,INDIRECT(Adrese!E$2),2,FALSE) -> 12 | F14: =+VLOOKUP($A14,INDIRECT(Adrese!F$2),2,FALSE) -> 12 | H14: =AVERAGE(B14:F14) -> 12.2 | J14: Random | K14: =+VLOOKUP($A14,INDIRECT(Adrese!B$2),3,FALSE) -> 5 | L14: =+VLOOKUP($A14,INDIRECT(Adrese!C$2),3,FALSE) -> 8 | M14: =+VLOOKUP($A14,INDIRECT(Adrese!D$2),3,FALSE) -> 7 | N14: =+VLOOKUP($A14,INDIRECT(Adrese!E$2),3,FALSE) -> 8 | O14: =+VLOOKUP($A14,INDIRECT(Adrese!F$2),3,FALSE) -> 8 | P14: =SUM(K14:O14) -> 36 | Q14: =AVERAGE(K14:O14) -> 7.2 | R14: =+_xlfn.STDEV.S(K14:O14) -> 1.3038405 | T14: Random | U14: =+VLOOKUP($T14,INDIRECT(Adrese!B$2),4,FALSE) -> 5361 | V14: =+VLOOKUP($T14,INDIRECT(Adrese!C$2),4,FALSE) -> 5822 | W14: =+VLOOKUP($T14,INDIRECT(Adrese!D$2),4,FALSE) -> 5940 | X14: =+VLOOKUP($T14,INDIRECT(Adrese!E$2),4,FALSE) -> 5896 | Y14: =+VLOOKUP($T14,INDIRECT(Adrese!F$2),4,FALSE) -> 5994 | Z14: =SUM(U14:Y14) -> 29013 | AA14: =AVERAGE(U14:Y14) -> 5802.6 | AB14: =+_xlfn.STDEV.S(U14:Y14) -> 254.76617 | AD14: Random | AE14: =+VLOOKUP($A14,INDIRECT(Adrese!B$2),5,FALSE) -> 1522 | AF14: =+VLOOKUP($A14,INDIRECT(Adrese!C$2),5,FALSE) -> 1509 | AG14: =+VLOOKUP($A14,INDIRECT(Adrese!D$2),5,FALSE) -> 1483 | AH14: =+VLOOKUP($A14,INDIRECT(Adrese!E$2),5,FALSE) -> 1506 | AI14: =+VLOOKUP($A14,INDIRECT(Adrese!F$2),5,FALSE) -> 1525 | AJ14: =AVERAGE(AE14:AI14) -> 1509 | AK14: =+_xlfn.STDEV.S(AE14:AI14) -> 16.658331 | AM14: Random | AN14: =+VLOOKUP($A14,INDIRECT(Adrese!B$2),6,FALSE) -> 0.50821429 | AO14: =+VLOOKUP($A14,INDIRECT(Adrese!C$2),6,FALSE) -> 0.50321429 | AP14: =+VLOOKUP($A14,INDIRECT(Adrese!D$2),6,FALSE) -> 0.49357143 | AQ14: =+VLOOKUP($A14,INDIRECT(Adrese!E$2),6,FALSE) -> 0.50285714 | AR14: =+VLOOKUP($A14,INDIRECT(Adrese!F$2),6,FALSE) -> 0.50892857 | AS14: =TEXT(AT14,"0.00")&" ("&TEXT(AU14,"0.00")&")" -> 0.50 (0.01) | AT14: =AVERAGE(AN14:AR14) -> 0.50335714 | AU14: =+_xlfn.STDEV.S(AN14:AR14) -> 0.0061372483 | AW14: Random | AX14: =+VLOOKUP($A14,INDIRECT(Adrese!B$2),7,FALSE) -> 0.64285714 | AY14: =+VLOOKUP($A14,INDIRECT(Adrese!C$2),7,FALSE) -> 0.42857143 | AZ14: =+VLOOKUP($A14,INDIRECT(Adrese!D$2),7,FALSE) -> 0.5 | BA14: =+VLOOKUP($A14,INDIRECT(Adrese!E$2),7,FALSE) -> 0.42857143 | BB14: =+VLOOKUP($A14,INDIRECT(Adrese!F$2),7,FALSE) -> 0.42857143 | BC14: =TEXT(BD14,"0.00")&" ("&TEXT(BE14,"0.00")&")" -> 0.49 (0.09) | BD14: =AVERAGE(AX14:BB14) -> 0.48571429 | BE14: =+_xlfn.STDEV.S(AX14:BB14) -> 0.093131463 | BG14: Random | BH14: =+VLOOKUP($BG14,INDIRECT(Adrese!B$2),8,FALSE) -> 0.16480223 | BI14: =+VLOOKUP($BG14,INDIRECT(Adrese!C$2),8,FALSE) -> 0.16199766 | BJ14: =+VLOOKUP($BG14,INDIRECT(Adrese!D$2),8,FALSE) -> 0.1588506 | BK14: =+VLOOKUP($BG14,INDIRECT(Adrese!E$2),8,FALSE) -> 0.16216641 | BL14: =+VLOOKUP($BG14,INDIRECT(Adrese!F$2),8,FALSE) -> 0.16420569 | BM14: =TEXT(BN14,"0.00")&" ("&TEXT(BO14,"0.00")&")" -> 0.16 (0.00) | BN14: =AVERAGE(BH14:BL14) -> 0.16240452 | BO14: =+_xlfn.STDEV.S(BH14:BL14) -> 0.0023369754 | BQ14: Random | BR14: =+VLOOKUP($BG14,INDIRECT(Adrese!B$2),9,FALSE) -> 0.0035935766 | BS14: =+VLOOKUP($BG14,INDIRECT(Adrese!C$2),9,FALSE) -> -0.0037054132 | BT14: =+VLOOKUP($BG14,INDIRECT(Adrese!D$2),9,FALSE) -> -0.007386882 | BU14: =+VLOOKUP($BG14,INDIRECT(Adrese!E$2),9,FALSE) -> 0.00023713966 | BV14: =+VLOOKUP($BG14,INDIRECT(Adrese!F$2),9,FALSE) -> 0.00068649546 | BW14: =TEXT(BX14,"0.00")&" ("&TEXT(BY14,"0.00")&")" -> 0.00 (0.00) | BX14: =AVERAGE(BR14:BV14) -> -0.0013150167 | BY14: =+_xlfn.STDEV.S(BR14:BV14) -> 0.0042746658
... A17: Defector | B17: =+VLOOKUP($A17,INDIRECT(Adrese!B$2),2,FALSE) -> 15 | C17: =+VLOOKUP($A17,INDIRECT(Adrese!C$2),2,FALSE) -> 15 | D17: =+VLOOKUP($A17,INDIRECT(Adrese!D$2),2,FALSE) -> 15 | E17: =+VLOOKUP($A17,INDIRECT(Adrese!E$2),2,FALSE) -> 15 | F17: =+VLOOKUP($A17,INDIRECT(Adrese!F$2),2,FALSE) -> 15 | H17: =AVERAGE(B17:F17) -> 15 | J17: Defector | K17: =+VLOOKUP($A17,INDIRECT(Adrese!B$2),3,FALSE) -> 13 | L17: =+VLOOKUP($A17,INDIRECT(Adrese!C$2),3,FALSE) -> 13 | M17: =+VLOOKUP($A17,INDIRECT(Adrese!D$2),3,FALSE) -> 13 | N17: =+VLOOKUP($A17,INDIRECT(Adrese!E$2),3,FALSE) -> 13 | O17: =+VLOOKUP($A17,INDIRECT(Adrese!F$2),3,FALSE) -> 13 | P17: =SUM(K17:O17) -> 65 | Q17: =AVERAGE(K17:O17) -> 13 | R17: =+_xlfn.STDEV.S(K17:O17) -> 0 | T17: Defector | U17: =+VLOOKUP($T17,INDIRECT(Adrese!B$2),4,FALSE) -> 4868 | V17: =+VLOOKUP($T17,INDIRECT(Adrese!C$2),4,FALSE) -> 4956 | W17: =+VLOOKUP($T17,INDIRECT(Adrese!D$2),4,FALSE) -> 4952 | X17: =+VLOOKUP($T17,INDIRECT(Adrese!E$2),4,FALSE) -> 4948 | Y17: =+VLOOKUP($T17,INDIRECT(Adrese!F$2),4,FALSE) -> 4824 | Z17: =SUM(U17:Y17) -> 24548 | AA17: =AVERAGE(U17:Y17) -> 4909.6 | AB17: =+_xlfn.STDEV.S(U17:Y17) -> 60.173084 | AD17: Defector | AE17: =+VLOOKUP($A17,INDIRECT(Adrese!B$2),5,FALSE) -> 0 | AF17: =+VLOOKUP($A17,INDIRECT(Adrese!C$2),5,FALSE) -> 0 | AG17: =+VLOOKUP($A17,INDIRECT(Adrese!D$2),5,FALSE) -> 0 | AH17: =+VLOOKUP($A17,INDIRECT(Adrese!E$2),5,FALSE) -> 0 | AI17: =+VLOOKUP($A17,INDIRECT(Adrese!F$2),5,FALSE) -> 0 | AJ17: =AVERAGE(AE17:AI17) -> 0 | AK17: =+_xlfn.STDEV.S(AE17:AI17) -> 0 | AM17: Defector | AN17: =+VLOOKUP($A17,INDIRECT(Adrese!B$2),6,FALSE) -> 0 | AO17: =+VLOOKUP($A17,INDIRECT(Adrese!C$2),6,FALSE) -> 0 | AP17: =+VLOOKUP($A17,INDIRECT(Adrese!D$2),6,FALSE) -> 0 | AQ17: =+VLOOKUP($A17,INDIRECT(Adrese!E$2),6,FALSE) -> 0 | AR17: =+VLOOKUP($A17,INDIRECT(Adrese!F$2),6,FALSE) -> 0 | AS17: =TEXT(AT17,"0.00")&" ("&TEXT(AU17,"0.00")&")" -> 0.00 (0.00) | AT17: =AVERAGE(AN17:AR17) -> 0 | AU17: =+_xlfn.STDEV.S(AN17:AR17) -> 0 | AW17: Defector | AX17: =+VLOOKUP($A17,INDIRECT(Adrese!B$2),7,FALSE) -> 0.071428571 | AY17: =+VLOOKUP($A17,INDIRECT(Adrese!C$2),7,FALSE) -> 0.071428571 | AZ17: =+VLOOKUP($A17,INDIRECT(Adrese!D$2),7,FALSE) -> 0.071428571 | BA17: =+VLOOKUP($A17,INDIRECT(Adrese!E$2),7,FALSE) -> 0.071428571 | BB17: =+VLOOKUP($A17,INDIRECT(Adrese!F$2),7,FALSE) -> 0.071428571 | BC17: =TEXT(BD17,"0.00")&" ("&TEXT(BE17,"0.00")&")" -> 0.07 (0.00) | BD17: =AVERAGE(AX17:BB17) -> 0.071428571 | BE17: =+_xlfn.STDEV.S(AX17:BB17) -> 0 | BG17: Defector | BH17: =+VLOOKUP($BG17,INDIRECT(Adrese!B$2),8,FALSE) -> 0 | BI17: =+VLOOKUP($BG17,INDIRECT(Adrese!C$2),8,FALSE) -> 0 | BJ17: =+VLOOKUP($BG17,INDIRECT(Adrese!D$2),8,FALSE) -> 0 | BK17: =+VLOOKUP($BG17,INDIRECT(Adrese!E$2),8,FALSE) -> 0 | BL17: =+VLOOKUP($BG17,INDIRECT(Adrese!F$2),8,FALSE) -> 0 | BM17: =TEXT(BN17,"0.00")&" ("&TEXT(BO17,"0.00")&")" -> 0.00 (0.00) | BN17: =AVERAGE(BH17:BL17) -> 0 | BO17: =+_xlfn.STDEV.S(BH17:BL17) -> 0 | BQ17: Defector | BR17: =+VLOOKUP($BG17,INDIRECT(Adrese!B$2),9,FALSE) -> -0.25824264 | BS17: =+VLOOKUP($BG17,INDIRECT(Adrese!C$2),9,FALSE) -> -0.26266231 | BT17: =+VLOOKUP($BG17,INDIRECT(Adrese!D$2),9,FALSE) -> -0.25560459 | BU17: =+VLOOKUP($BG17,INDIRECT(Adrese!E$2),9,FALSE) -> -0.26257921 | BV17: =+VLOOKUP($BG17,INDIRECT(Adrese!F$2),9,FALSE) -> -0.25757332 | BW17: =TEXT(BX17,"0.00")&" ("&TEXT(BY17,"0.00")&")" -> -0.26 (0.00) | BX17: =AVERAGE(BR17:BV17) -> -0.25933241 | BY17: =+_xlfn.STDEV.S(BR17:BV17) -> 0.0031547017

Sheet Svi
A1: Name | C1: #Wins | D1: TotalScore | E1: #Cooperations | F1: CooperationRating | G1: GoodPartnerRating | H1: EigenJesusRating | I1: EigenMosesRating
A2: Fuzzy | B2: 1 | C2: 1 | D2: 7772 | E2: 2595 | F2: 0.85535714 | G2: 0.92857143 | H2: 0.31023771 | I2: 0.30521964
A3: GTFT | B3: 2 | C3: 0 | D3: 7415 | E3: 2701 | F3: 0.89321429 | G3: 1 | H3: 0.31570079 | I3: 0.29607899
A4: ZD-GTFT-2 | B4: 3 | C4: 0 | D4: 7367 | E4: 2604 | F4: 0.85857143 | G4: 1 | H4: 0.31178633 | I4: 0.30549745
A5: Tit For 2 Tats | B5: 4 | C5: 0 | D5: 7336 | E5: 2575 | F5: 0.84821429 | G5: 1 | H5: 0.31496907 | I5: 0.32326403
A6: Cooperator | B6: 5 | C6: 0 | D6: 7278 | E6: 3000 | F6: 1 | G6: 1 | H6: 0.32552496 | I6: 0.25824264
A7: Hard Tit For 2 Tats | B7: 6 | C7: 0 | D7: 7064 | E7: 2359 | F7: 0.77107143 | G7: 1 | H7: 0.30022113 | I7: 0.32162477
A8: Tit For Tat | B8: 7 | C8: 0 | D8: 6993 | E8: 2222 | F8: 0.72214286 | G8: 1 | H8: 0.28992592 | I8: 0.31366568
A9: Grudger | B9: 8 | C9: 1 | D9: 6865 | E9: 2016 | F9: 0.64857143 | G9: 0.92857143 | H9: 0.27403475 | I9: 0.30427045
A10: Hard Tit For Tat | B10: 9 | C10: 1 | D10: 6850 | E10: 2054 | F10: 0.66214286 | G10: 0.92857143 | H10: 0.27655893 | I10: 0.30369702
A11: Win-Stay Lose-Shift | B11: 10 | C11: 1 | D11: 6818 | E11: 2444 | F11: 0.80142857 | G11: 0.92857143 | H11: 0.29623306 | I11: 0.28373465
A12: Hard Go By Majority | B12: 11 | C12: 8 | D12: 6299 | E12: 1298 | F12: 0.46357143 | G12: 0.42857143 | H12: 0.18204178 | I12: 0.10476292
A13: Joss | B13: 12 | C13: 9 | D13: 5573 | E13: 1053 | F13: 0.37428571 | G13: 0.35714286 | H13: 0.14029995 | I13: -0.0015914528
... A16: Defector | B16: 15 | C16: 13 | D16: 4868 | E16: 0 | F16: 0 | G16: 0.071428571 | H16: 0 | I16: -0.25824264
A18: Name | C18: #Wins | D18: TotalScore | E18: #Cooperations | F18: CooperationRating | G18: GoodPartnerRating | H18: EigenJesusRating | I18: EigenMosesRating
A19: Fuzzy | B19: 1 | C19: 1 | D19: 7735 | E19: 2591 | F19: 0.85392857 | G19: 0.92857143 | H19: 0.3096826 | I19: 0.31218277
A20: ZD-GTFT-2 | B20: 2 | C20: 0 | D20: 7454 | E20: 2632 | F20: 0.86857143 | G20: 1 | H20: 0.31009942 | I20: 0.30024948
A21: GTFT | B21: 3 | C21: 0 | D21: 7450 | E21: 2696 | F21: 0.89142857 | G21: 1 | H21: 0.31443837 | I21: 0.30093917
A22: Cooperator | B22: 4 | C22: 0 | D22: 7329 | E22: 3000 | F22: 1 | G22: 1 | H22: 0.32497495 | I22: 0.26266231
A23: Tit For 2 Tats | B23: 5 | C23: 0 | D23: 7312 | E23: 2553 | F23: 0.84035714 | G23: 1 | H23: 0.31079159 | I23: 0.32307921
A24: Hard Tit For 2 Tats | B24: 6 | C24: 0 | D24: 7189 | E24: 2419 | F24: 0.7925 | G24: 1 | H24: 0.30154468 | I24: 0.31932264
A25: Tit For Tat | B25: 7 | C25: 0 | D25: 7045 | E25: 2249 | F25: 0.73178571 | G25: 1 | H25: 0.28804653 | I25: 0.31149053
A26: Grudger | B26: 8 | C26: 1 | D26: 6835 | E26: 2019 | F26: 0.64964286 | G26: 0.92857143 | H26: 0.27063418 | I26: 0.30647528
A27: Win-Stay Lose-Shift | B27: 9 | C27: 0 | D27: 6794 | E27: 2451 | F27: 0.80392857 | G27: 1 | H27: 0.29446796 | I27: 0.2860204
A28: Hard Tit For Tat | B28: 10 | C28: 2 | D28: 6787 | E28: 2052 | F28: 0.66142857 | G28: 0.85714286 | H28: 0.27293383 | I28: 0.3058995
A29: Hard Go By Majority | B29: 11 | C29: 7 | D29: 6382 | E29: 1585 | F29: 0.56607143 | G29: 0.5 | H29: 0.19490171 | I29: 0.084120656
A30: Random | B30: 12 | C30: 8 | D30: 5822 | E30: 1509 | F30: 0.50321429 | G30: 0.42857143 | H30: 0.16199766 | I30: -0.0037054132
... A33: Defector | B33: 15 | C33: 13 | D33: 4956 | E33: 0 | F33: 0 | G33: 0.071428571 | H33: 0 | I33: -0.26266231
A35: Name | C35: #Wins | D35: TotalScore | E35: #Cooperations | F35: CooperationRating | G35: GoodPartnerRating | H35: EigenJesusRating | I35: EigenMosesRating
A36: Fuzzy | B36: 1 | C36: 1 | D36: 7543 | E36: 2414 | F36: 0.79071429 | G36: 0.92857143 | H36: 0.30204718 | I36: 0.32391756
A37: GTFT | B37: 2 | C37: 0 | D37: 7448 | E37: 2695 | F37: 0.89107143 | G37: 1 | H37: 0.31367554 | I37: 0.29352763
A38: Hard Tit For 2 Tats | B38: 3 | C38: 0 | D38: 7433 | E38: 2567 | F38: 0.84535714 | G38: 1 | H38: 0.31267097 | I38: 0.32224228
A39: Tit For 2 Tats | B39: 4 | C39: 0 | D39: 7337 | E39: 2565 | F39: 0.84464286 | G39: 1 | H39: 0.31266331 | I39: 0.32262424
A40: ZD-GTFT-2 | B40: 5 | C40: 0 | D40: 7318 | E40: 2575 | F40: 0.84821429 | G40: 1 | H40: 0.30779576 | I40: 0.30071843
A41: Cooperator | B41: 6 | C41: 0 | D41: 7299 | E41: 3000 | F41: 1 | G41: 1 | H41: 0.32362759 | I41: 0.25560459
A42: Tit For Tat | B42: 7 | C42: 0 | D42: 7031 | E42: 2239 | F42: 0.72821429 | G42: 1 | H42: 0.28816843 | I42: 0.30947262
A43: Hard Tit For Tat | B43: 8 | C43: 1 | D43: 6858 | E43: 2069 | F43: 0.6675 | G43: 0.92857143 | H43: 0.27365088 | I43: 0.30080112
A44: Grudger | B44: 9 | C44: 1 | D44: 6797 | E44: 2016 | F44: 0.64857143 | G44: 0.92857143 | H44: 0.27032693 | I44: 0.30155823
A45: Win-Stay Lose-Shift | B45: 10 | C45: 0 | D45: 6739 | E45: 2447 | F45: 0.8025 | G45: 1 | H45: 0.29336624 | I45: 0.27942475
A46: Hard Go By Majority | B46: 11 | C46: 7 | D46: 6247 | E46: 1687 | F46: 0.6025 | G46: 0.5 | H46: 0.20079667 | I46: 0.080951476
...

Sheet Adrese
B1: 1 | C1: 2 | D1: 3 | E1: 4 | F1: 5
B2: Svi!$A$2:$I$16 | C2: Svi!$A$18:$I$33 | D2: Svi!$A$35:$I$50 | E2: Svi!$A$53:$I$67 | F2: Svi!$A$70:$I$84

Sheet Final
C2: Avg. Score | D2: Wins (%) | E2: Cooperation (%) | F2: Avg. Good Partner Rating (SD) | G2: Avg. Eigenjesus Rating | H2: Avg. Eigenmoses Rating
B3: Fuzzy | C3: =+SUM(Kompilirano!U3:Y3)/(5*14) -> 550.78571 | D3: =+SUM(Kompilirano!K3:O3)/(14*5) -> 0.071428571 | E3: =SUM(Kompilirano!AE3:AI3)/(200*15*5) -> 0.85213333 | F3: =Kompilirano!BD3 -> 0.92857143 | G3: =Kompilirano!BN3 -> 0.30791956 | H3: =Kompilirano!BX3 -> 0.31150563
B4: GTFT | C4: =+SUM(Kompilirano!U4:Y4)/(5*14) -> 530.11429 | D4: =+SUM(Kompilirano!K4:O4)/(14*5) -> 0 | E4: =SUM(Kompilirano!AE4:AI4)/(200*15*5) -> 0.89673333 | F4: =Kompilirano!BD4 -> 1 | G4: =Kompilirano!BN4 -> 0.31402188 | H4: =Kompilirano!BX4 -> 0.29772871
B5: ZD-GTFT-2 | C5: =+SUM(Kompilirano!U5:Y5)/(5*14) -> 520.41429 | D5: =+SUM(Kompilirano!K5:O5)/(14*5) -> 0 | E5: =SUM(Kompilirano!AE5:AI5)/(200*15*5) -> 0.82713333 | F5: =Kompilirano!BD6 -> 1 | G5: =Kompilirano!BN6 -> 0.30893933 | H5: =Kompilirano!BX6 -> 0.30264971
B6: Cooperator | C6: =+SUM(Kompilirano!U6:Y6)/(5*14) -> 527.04286 | D6: =+SUM(Kompilirano!K6:O6)/(14*5) -> 0 | E6: =SUM(Kompilirano!AE6:AI6)/(200*15*5) -> 0.86426667 | F6: =Kompilirano!BD7 -> 1 | G6: =Kompilirano!BN7 -> 0.32449013 | H6: =Kompilirano!BX7 -> 0.25933241
B7: Hard Tit For 2 Tats | C7: =+SUM(Kompilirano!U7:Y7)/(5*14) -> 520.97143 | D7: =+SUM(Kompilirano!K7:O7)/(14*5) -> 0 | E7: =SUM(Kompilirano!AE7:AI7)/(200*15*5) -> 1 | F7: =Kompilirano!BD5 -> 1 | G7: =Kompilirano!BN5 -> 0.30670453 | H7: =Kompilirano!BX5 -> 0.32237535
B8: Tit For 2 Tats | C8: =+SUM(Kompilirano!U8:Y8)/(5*14) -> 519.67143 | D8: =+SUM(Kompilirano!K8:O8)/(14*5) -> 0 | E8: =SUM(Kompilirano!AE8:AI8)/(200*15*5) -> 0.84446667 | F8: =Kompilirano!BD8 -> 1 | G8: =Kompilirano!BN8 -> 0.31034391 | H8: =Kompilirano!BX8 -> 0.32253411
