Workbook

Sheet FINAL FINAL
C2: Results | E2: Morality metrics
B3: Name | C3: Avg. Score | D3: Wins (%) | E3: Cooperation Rating | F3: Good Partner Rating | G3: Eigenjesus Rating | H3: Eigenmoses Rating
B4: Evolved FSM 6 | C4: =VLOOKUP(B4,Kompilirano!T:Z,7,FALSE)/226/5 -> 577.07611 | D4: =VLOOKUP(B4,Kompilirano!J:P,7,FALSE)/226/5 -> 0.034513274 | E4: =VLOOKUP(B4,Kompilirano!AM:AS,7,FALSE) -> 0.79 (0.00) | F4: =VLOOKUP(B4,Kompilirano!AW:BD,7,FALSE) -> 0.83 (0.00) | G4: =VLOOKUP(B4,Kompilirano!BG:BM,7,FALSE) -> 0.08 (0.00) | H4: =VLOOKUP(B4,Kompilirano!BQ:BW,7,FALSE) -> 0.08 (0.00)
B5: EvolvedLookerUp2_2_2 | C5: =VLOOKUP(B5,Kompilirano!T:Z,7,FALSE)/226/5 -> 575.93097 | D5: =VLOOKUP(B5,Kompilirano!J:P,7,FALSE)/226/5 -> 0.043539823 | E5: =VLOOKUP(B5,Kompilirano!AM:AS,7,FALSE) -> 0.75 (0.01) | F5: =VLOOKUP(B5,Kompilirano!AW:BD,7,FALSE) -> 0.78 (0.01) | G5: =VLOOKUP(B5,Kompilirano!BG:BM,7,FALSE) -> 0.07 (0.00) | H5: =VLOOKUP(B5,Kompilirano!BQ:BW,7,FALSE) -> 0.07 (0.00)
B6: Fuzzy | C6: =VLOOKUP(B6,Kompilirano!T:Z,7,FALSE)/226/5 -> 575.57522 | D6: =VLOOKUP(B6,Kompilirano!J:P,7,FALSE)/226/5 -> 0.043185841 | E6: =VLOOKUP(B6,Kompilirano!AM:AS,7,FALSE) -> 0.75 (0.01) | F6: =VLOOKUP(B6,Kompilirano!AW:BD,7,FALSE) -> 0.78 (0.01) | G6: =VLOOKUP(B6,Kompilirano!BG:BM,7,FALSE) -> 0.07 (0.00) | H6: =VLOOKUP(B6,Kompilirano!BQ:BW,7,FALSE) -> 0.07 (0.00)
B7: Evolved HMM 5 | C7: =VLOOKUP(B7,Kompilirano!T:Z,7,FALSE)/226/5 -> 571.0708 | D7: =VLOOKUP(B7,Kompilirano!J:P,7,FALSE)/226/5 -> 0.039469027 | E7: =VLOOKUP(B7,Kompilirano!AM:AS,7,FALSE) -> 0.76 (0.01) | F7: =VLOOKUP(B7,Kompilirano!AW:BD,7,FALSE) -> 0.80 (0.01) | G7: =VLOOKUP(B7,Kompilirano!BG:BM,7,FALSE) -> 0.07 (0.00) | H7: =VLOOKUP(B7,Kompilirano!BQ:BW,7,FALSE) -> 0.07 (0.00)
B8: Evolved FSM 16 | C8: =VLOOKUP(B8,Kompilirano!T:Z,7,FALSE)/226/5 -> 569.92743 | D8: =VLOOKUP(B8,Kompilirano!J:P,7,FALSE)/226/5 -> 0.056106195 | E8: =VLOOKUP(B8,Kompilirano!AM:AS,7,FALSE) -> 0.72 (0.00) | F8: =VLOOKUP(B8,Kompilirano!AW:BD,7,FALSE) -> 0.72 (0.01) | G8: =VLOOKUP(B8,Kompilirano!BG:BM,7,FALSE) -> 0.07 (0.00) | H8: =VLOOKUP(B8,Kompilirano!BQ:BW,7,FALSE) -> 0.07 (0.00)
B9: PSO Gambler 1_1_1 | C9: =VLOOKUP(B9,Kompilirano!T:Z,7,FALSE)/226/5 -> 568.48407 | D9: =VLOOKUP(B9,Kompilirano!J:P,7,FALSE)/226/5 -> 0.045132743 | E9: =VLOOKUP(B9,Kompilirano!AM:AS,7,FALSE) -> 0.72 (0.01) | F9: =VLOOKUP(B9,Kompilirano!AW:BD,7,FALSE) -> 0.77 (0.01) | G9: =VLOOKUP(B9,Kompilirano!BG:BM,7,FALSE) -> 0.07 (0.00) | H9: =VLOOKUP(B9,Kompilirano!BQ:BW,7,FALSE) -> 0.08 (0.00)
B10: Evolved ANN | C10: =VLOOKUP(B10,Kompilirano!T:Z,7,FALSE)/226/5 -> 568.23717 | D10: =VLOOKUP(B10,Kompilirano!J:P,7,FALSE)/226/5 -> 0.040176991 | E10: =VLOOKUP(B10,Kompilirano!AM:AS,7,FALSE) -> 0.74 (0.00) | F10: =VLOOKUP(B10,Kompilirano!AW:BD,7,FALSE) -> 0.80 (0.00) | G10: =VLOOKUP(B10,Kompilirano!BG:BM,7,FALSE) -> 0.08 (0.00) | H10: =VLOOKUP(B10,Kompilirano!BQ:BW,7,FALSE) -> 0.09 (0.00)
B11: Evolved FSM 16 Noise 05 | C11: =VLOOKUP(B11,Kompilirano!T:Z,7,FALSE)/226/5 -> 567.85221 | D11: =VLOOKUP(B11,Kompilirano!J:P,7,FALSE)/226/5 -> 0.040353982 | E11: =VLOOKUP(B11,Kompilirano!AM:AS,7,FALSE) -> 0.73 (0.00) | F11: =VLOOKUP(B11,Kompilirano!AW:BD,7,FALSE) -> 0.80 (0.01) | G11: =VLOOKUP(B11,Kompilirano!BG:BM,7,FALSE) -> 0.07 (0.00) | H11: =VLOOKUP(B11,Kompilirano!BQ:BW,7,FALSE) -> 0.08 (0.00)
B12: Evolved ANN 5 | C12: =VLOOKUP(B12,Kompilirano!T:Z,7,FALSE)/226/5 -> 565.76991 | D12: =VLOOKUP(B12,Kompilirano!J:P,7,FALSE)/226/5 -> 0.039292035 | E12: =VLOOKUP(B12,Kompilirano!AM:AS,7,FALSE) -> 0.72 (0.01) | F12: =VLOOKUP(B12,Kompilirano!AW:BD,7,FALSE) -> 0.80 (0.01) | G12: =VLOOKUP(B12,Kompilirano!BG:BM,7,FALSE) -> 0.07 (0.00) | H12: =VLOOKUP(B12,Kompilirano!BQ:BW,7,FALSE) -> 0.08 (0.00)
B13: Evolved FSM 4 | C13: =VLOOKUP(B13,Kompilirano!T:Z,7,FALSE)/226/5 -> 564.26106 | D13: =VLOOKUP(B13,Kompilirano!J:P,7,FALSE)/226/5 -> 0.033097345 | E13: =VLOOKUP(B13,Kompilirano!AM:AS,7,FALSE) -> 0.79 (0.00) | F13: =VLOOKUP(B13,Kompilirano!AW:BD,7,FALSE) -> 0.83 (0.01) | G13: =VLOOKUP(B13,Kompilirano!BG:BM,7,FALSE) -> 0.07 (0.00) | H13: =VLOOKUP(B13,Kompilirano!BQ:BW,7,FALSE) -> 0.07 (0.00)
B14: PSO Gambler 2_2_2 | C14: =VLOOKUP(B14,Kompilirano!T:Z,7,FALSE)/226/5 -> 563.56018 | D14: =VLOOKUP(B14,Kompilirano!J:P,7,FALSE)/226/5 -> 0.037699115 | E14: =VLOOKUP(B14,Kompilirano!AM:AS,7,FALSE) -> 0.70 (0.01) | F14: =VLOOKUP(B14,Kompilirano!AW:BD,7,FALSE) -> 0.81 (0.00) | G14: =VLOOKUP(B14,Kompilirano!BG:BM,7,FALSE) -> 0.07 (0.00) | H14: =VLOOKUP(B14,Kompilirano!BQ:BW,7,FALSE) -> 0.07 (0.00)
B15: PSO Gambler Mem1 | C15: =VLOOKUP(B15,Kompilirano!T:Z,7,FALSE)/226/5 -> 560.42832 | D15: =VLOOKUP(B15,Kompilirano!J:P,7,FALSE)/226/5 -> 0.040707965 | E15: =VLOOKUP(B15,Kompilirano!AM:AS,7,FALSE) -> 0.74 (0.01) | F15: =VLOOKUP(B15,Kompilirano!AW:BD,7,FALSE) -> 0.80 (0.01) | G15: =VLOOKUP(B15,Kompilirano!BG:BM,7,FALSE) -> 0.07 (0.00) | H15: =VLOOKUP(B15,Kompilirano!BQ:BW,7,FALSE) -> 0.08 (0.00)
... B230: Defector | C230: =VLOOKUP(B230,Kompilirano!T:Z,7,FALSE)/226/5 -> 359.18584 | D230: =VLOOKUP(B230,Kompilirano!J:P,7,FALSE)/226/5 -> 0.18672566 | E230: =VLOOKUP(B230,Kompilirano!AM:AS,7,FALSE) -> 0.00 (0.00) | F230: =VLOOKUP(B230,Kompilirano!AW:BD,7,FALSE) -> 0.07 (0.00) | G230: =VLOOKUP(B230,Kompilirano!BG:BM,7,FALSE) -> 0.00 (0.00) | H230: =VLOOKUP(B230,Kompilirano!BQ:BW,7,FALSE) -> -0.08 (0.00)

Sheet Kompilirano
A2: Name | B2: Rank 1 | C2: Rank 2 | D2: Rank 3 | E2: Rank 4 | F2: Rank 5 | G2: Avg | H2: SD | J2: Name | K2: Wins 1 | L2: Wins 2 | M2: Wins 3 | N2: Wins 4 | O2: Wins 5 | P2: Avg | Q2: SD | T2: Name | U2: Total Score 1 | V2: Total Score 2 | W2: Total Score 3 | X2: Total Score 4 | Y2: Total Score 5 | AA2: Avg | AB2: SD | AD2: Name | AE2: #Cooperations 1 | AF2: #Cooperations 2 | AG2: #Cooperations 3 | AH2: #Cooperations 4 | AI2: #Cooperations 5 | AJ2: Avg | AK2: SD | AM2: Name | AN2: CoopRating 1 | AO2: CoopRating 2 | AP2: CoopRating 3 | AQ2: CoopRating 4 | AR2: CoopRating 5 | AT2: Avg | AU2: SD | AW2: Name | AX2: GP Rating 1 | AY2: GP Rating 2 | AZ2: GP Rating 3 | BA2: GP Rating 4 | BB2: GP Rating 5 | BD2: Avg | BE2: SD | BG2: Name | BH2: EJ Rating 1 | BI2: EJ Rating 2 | BJ2: EJ Rating 3 | BK2: EJ Rating 4 | BL2: EJ Rating 5 | BN2: Avg | BO2: SD | BQ2: Name | BR2: EM Rating 1 | BS2: EM Rating 2 | BT2: EM Rating 3 | BU2: EM Rating 4 | BV2: EM Rating 5 | BX2: Avg | BY2: SD
A3: Evolved FSM 6 | B3: =+VLOOKUP($A3,INDIRECT(Adrese!B$2),2,FALSE) -> 1 | C3: =+VLOOKUP($A3,INDIRECT(Adrese!C$2),2,FALSE) -> 1 | D3: =+VLOOKUP($A3,INDIRECT(Adrese!D$2),2,FALSE) -> 3 | E3: =+VLOOKUP($A3,INDIRECT(Adrese!E$2),2,FALSE) -> 1 | F3: =+VLOOKUP($A3,INDIRECT(Adrese!F$2),2,FALSE) -> 1 | G3: =AVERAGE(B3:F3) -> 1.4 | H3: =+_xlfn.STDEV.S(B3:F3) -> 0.89442719 | J3: Evolved FSM 6 | K3: =+VLOOKUP($A3,INDIRECT(Adrese!B$2),3,FALSE) -> 39 | L3: =+VLOOKUP($A3,INDIRECT(Adrese!C$2),3,FALSE) -> 40 | M3: =+VLOOKUP($A3,INDIRECT(Adrese!D$2),3,FALSE) -> 38 | N3: =+VLOOKUP($A3,INDIRECT(Adrese!E$2),3,FALSE) -> 38 | O3: =+VLOOKUP($A3,INDIRECT(Adrese!F$2),3,FALSE) -> 40 | P3: =AVERAGE(K3:O3) -> 39 | Q3: =+_xlfn.STDEV.S(K3:O3) -> 1 | T3: Evolved FSM 6 | U3: =+VLOOKUP($T3,INDIRECT(Adrese!B$2),4,FALSE) -> 130681 | V3: =+VLOOKUP($T3,INDIRECT(Adrese!C$2),4,FALSE) -> 130763 | W3: =+VLOOKUP($T3,INDIRECT(Adrese!D$2),4,FALSE) -> 130318 | X3: =+VLOOKUP($T3,INDIRECT(Adrese!E$2),4,FALSE) -> 130483 | Y3: =+VLOOKUP($T3,INDIRECT(Adrese!F$2),4,FALSE) -> 129851 | Z3: =SUM(U3:Y3) -> 652096 | AA3: =AVERAGE(U3:Y3) -> 130419.2 | AB3: =+_xlfn.STDEV.S(U3:Y3) -> 361.90496 | AD3: Evolved FSM 6 | AE3: =+VLOOKUP($A3,INDIRECT(Adrese!B$2),5,FALSE) -> 36331 | AF3: =+VLOOKUP($A3,INDIRECT(Adrese!C$2),5,FALSE) -> 36067 | AG3: =+VLOOKUP($A3,INDIRECT(Adrese!D$2),5,FALSE) -> 36177 | AH3: =+VLOOKUP($A3,INDIRECT(Adrese!E$2),5,FALSE) -> 35976 | AI3: =+VLOOKUP($A3,INDIRECT(Adrese!F$2),5,FALSE) -> 36095 | AJ3: =AVERAGE(AE3:AI3) -> 36129.2 | AK3: =+_xlfn.STDEV.S(AE3:AI3) -> 133.71313 | AM3: Evolved FSM 6 | AN3: =+VLOOKUP($A3,INDIRECT(Adrese!B$2),6,FALSE) -> 0.79935841 | AO3: =+VLOOKUP($A3,INDIRECT(Adrese!C$2),6,FALSE) -> 0.7935177 | AP3: =+VLOOKUP($A3,INDIRECT(Adrese!D$2),6,FALSE) -> 0.79595133 | AQ3: =+VLOOKUP($A3,INDIRECT(Adrese!E$2),6,FALSE) -> 0.79150442 | AR3: =+VLOOKUP($A3,INDIRECT(Adrese!F$2),6,FALSE) -> 0.79413717 | AS3: =TEXT(AT3,"0.00")&" ("&TEXT(AU3,"0.00")&")" -> 0.79 (0.00) | AT3: =AVERAGE(AN3:AR3) -> 0.79489381 | AU3: =+_xlfn.STDEV.S(AN3:AR3) -> 0.0029582549 | AW3: Evolved FSM 6 | AX3: =+VLOOKUP($A3,INDIRECT(Adrese!B$2),7,FALSE) -> 0.82743363 | AY3: =+VLOOKUP($A3,INDIRECT(Adrese!C$2),7,FALSE) -> 0.82300885 | AZ3: =+VLOOKUP($A3,INDIRECT(Adrese!D$2),7,FALSE) -> 0.83185841 | BA3: =+VLOOKUP($A3,INDIRECT(Adrese!E$2),7,FALSE) -> 0.83185841 | BB3: =+VLOOKUP($A3,INDIRECT(Adrese!F$2),7,FALSE) -> 0.82300885 | BC3: =TEXT(BD3,"0.00")&" ("&TEXT(BE3,"0.00")&")" -> 0.83 (0.00) | BD3: =AVERAGE(AX3:BB3) -> 0.82743363 | BE3: =+_xlfn.STDEV.S(AX3:BB3) -> 0.0044247785 | BG3: Evolved FSM 6 | BH3: =+VLOOKUP($BG3,INDIRECT(Adrese!B$2),8,FALSE) -> 0.077202708 | BI3: =+VLOOKUP($BG3,INDIRECT(Adrese!C$2),8,FALSE) -> 0.076545565 | BJ3: =+VLOOKUP($BG3,INDIRECT(Adrese!D$2),8,FALSE) -> 0.076963271 | BK3: =+VLOOKUP($BG3,INDIRECT(Adrese!E$2),8,FALSE) -> 0.076409529 | BL3: =+VLOOKUP($BG3,INDIRECT(Adrese!F$2),8,FALSE) -> 0.076995128 | BM3: =TEXT(BN3,"0.00")&" ("&TEXT(BO3,"0.00")&")" -> 0.08 (0.00) | BN3: =AVERAGE(BH3:BL3) -> 0.07682324 | BO3: =+_xlfn.STDEV.S(BH3:BL3) -> 0.0003321937 | BQ3: Evolved FSM 6 | BR3: =+VLOOKUP($BG3,INDIRECT(Adrese!B$2),9,FALSE) -> 0.076680846 | BS3: =+VLOOKUP($BG3,INDIRECT(Adrese!C$2),9,FALSE) -> 0.075418539 | BT3: =+VLOOKUP($BG3,INDIRECT(Adrese!D$2),9,FALSE) -> 0.076136473 | BU3: =+VLOOKUP($BG3,INDIRECT(Adrese!E$2),9,FALSE) -> 0.075411405 | BV3: =+VLOOKUP($BG3,INDIRECT(Adrese!F$2),9,FALSE) -> 0.07690471 | BW3: =TEXT(BX3,"0.00")&" ("&TEXT(BY3,"0.00")&")" -> 0.08 (0.00) | BX3: =AVERAGE(BR3:BV3) -> 0.076110395 | BY3: =+_xlfn.STDEV.S(BR3:BV3) -> 0.00069359252
A4: EvolvedLookerUp2_2_2 | B4: =+VLOOKUP($A4,INDIRECT(Adrese!B$2),2,FALSE) -> 3 | C4: =+VLOOKUP($A4,INDIRECT(Adrese!C$2),2,FALSE) -> 2 | D4: =+VLOOKUP($A4,INDIRECT(Adrese!D$2),2,FALSE) -> 1 | E4: =+VLOOKUP($A4,INDIRECT(Adrese!E$2),2,FALSE) -> 4 | F4: =+VLOOKUP($A4,INDIRECT(Adrese!F$2),2,FALSE) -> 2 | G4: =AVERAGE(B4:F4) -> 2.4 | H4: =+_xlfn.STDEV.S(B4:F4) -> 1.1401754 | J4: EvolvedLookerUp2_2_2 | K4: =+VLOOKUP($A4,INDIRECT(Adrese!B$2),3,FALSE) -> 46 | L4: =+VLOOKUP($A4,INDIRECT(Adrese!C$2),3,FALSE) -> 50 | M4: =+VLOOKUP($A4,INDIRECT(Adrese!D$2),3,FALSE) -> 49 | N4: =+VLOOKUP($A4,INDIRECT(Adrese!E$2),3,FALSE) -> 51 | O4: =+VLOOKUP($A4,INDIRECT(Adrese!F$2),3,FALSE) -> 50 | P4: =AVERAGE(K4:O4) -> 49.2 | Q4: =+_xlfn.STDEV.S(K4:O4) -> 1.9235384 | T4: EvolvedLookerUp2_2_2 | U4: =+VLOOKUP($T4,INDIRECT(Adrese!B$2),4,FALSE) -> 130248 | V4: =+VLOOKUP($T4,INDIRECT(Adrese!C$2),4,FALSE) -> 130131 | W4: =+VLOOKUP($T4,INDIRECT(Adrese!D$2),4,FALSE) -> 130631 | X4: =+VLOOKUP($T4,INDIRECT(Adrese!E$2),4,FALSE) -> 130042 | Y4: =+VLOOKUP($T4,INDIRECT(Adrese!F$2),4,FALSE) -> 129750 | Z4: =SUM(U4:Y4) -> 650802 | AA4: =AVERAGE(U4:Y4) -> 130160.4 | AB4: =+_xlfn.STDEV.S(U4:Y4) -> 321.11104 | AD4: EvolvedLookerUp2_2_2 | AE4: =+VLOOKUP($A4,INDIRECT(Adrese!B$2),5,FALSE) -> 34404 | AF4: =+VLOOKUP($A4,INDIRECT(Adrese!C$2),5,FALSE) -> 33876 | AG4: =+VLOOKUP($A4,INDIRECT(Adrese!D$2),5,FALSE) -> 34206 | AH4: =+VLOOKUP($A4,INDIRECT(Adrese!E$2),5,FALSE) -> 33518 | AI4: =+VLOOKUP($A4,INDIRECT(Adrese!F$2),5,FALSE) -> 33871 | AJ4: =AVERAGE(AE4:AI4) -> 33975 | AK4: =+_xlfn.STDEV.S(AE4:AI4) -> 341.6387 | AM4: EvolvedLookerUp2_2_2 | AN4: =+VLOOKUP($A4,INDIRECT(Adrese!B$2),6,FALSE) -> 0.75672566 | AO4: =+VLOOKUP($A4,INDIRECT(Adrese!C$2),6,FALSE) -> 0.74504425 | AP4: =+VLOOKUP($A4,INDIRECT(Adrese!D$2),6,FALSE) -> 0.75234513 | AQ4: =+VLOOKUP($A4,INDIRECT(Adrese!E$2),6,FALSE) -> 0.73712389 | AR4: =+VLOOKUP($A4,INDIRECT(Adrese!F$2),6,FALSE) -> 0.74493363 | AS4: =TEXT(AT4,"0.00")&" ("&TEXT(AU4,"0.00")&")" -> 0.75 (0.01) | AT4: =AVERAGE(AN4:AR4) -> 0.74723451 | AU4: =+_xlfn.STDEV.S(AN4:AR4) -> 0.0075583783 | AW4: EvolvedLookerUp2_2_2 | AX4: =+VLOOKUP($A4,INDIRECT(Adrese!B$2),7,FALSE) -> 0.79646018 | AY4: =+VLOOKUP($A4,INDIRECT(Adrese!C$2),7,FALSE) -> 0.77876106 | AZ4: =+VLOOKUP($A4,INDIRECT(Adrese!D$2),7,FALSE) -> 0.78318584 | BA4: =+VLOOKUP($A4,INDIRECT(Adrese!E$2),7,FALSE) -> 0.77433628 | BB4: =+VLOOKUP($A4,INDIRECT(Adrese!F$2),7,FALSE) -> 0.77876106 | BC4: =TEXT(BD4,"0.00")&" ("&TEXT(BE4,"0.00")&")" -> 0.78 (0.01) | BD4: =AVERAGE(AX4:BB4) -> 0.78230088 | BE4: =+_xlfn.STDEV.S(AX4:BB4) -> 0.0085112319 | BG4: EvolvedLookerUp2_2_2 | BH4: =+VLOOKUP($BG4,INDIRECT(Adrese!B$2),8,FALSE) -> 0.073698667 | BI4: =+VLOOKUP($BG4,INDIRECT(Adrese!C$2),8,FALSE) -> 0.072603384 | BJ4: =+VLOOKUP($BG4,INDIRECT(Adrese!D$2),8,FALSE) -> 0.073274058 | BK4: =+VLOOKUP($BG4,INDIRECT(Adrese!E$2),8,FALSE) -> 0.072419428 | BL4: =+VLOOKUP($BG4,INDIRECT(Adrese!F$2),8,FALSE) -> 0.07311383 | BM4: =TEXT(BN4,"0.00")&" ("&TEXT(BO4,"0.00")&")" -> 0.07 (0.00) | BN4: =AVERAGE(BH4:BL4) -> 0.073021873 | BO4: =+_xlfn.STDEV.S(BH4:BL4) -> 0.00051676307 | BQ4: EvolvedLookerUp2_2_2 | BR4: =+VLOOKUP($BG4,INDIRECT(Adrese!B$2),9,FALSE) -> 0.072413107 | BS4: =+VLOOKUP($BG4,INDIRECT(Adrese!C$2),9,FALSE) -> 0.070961915 | BT4: =+VLOOKUP($BG4,INDIRECT(Adrese!D$2),9,FALSE) -> 0.07146657 | BU4: =+VLOOKUP($BG4,INDIRECT(Adrese!E$2),9,FALSE) -> 0.072007053 | BV4: =+VLOOKUP($BG4,INDIRECT(Adrese!F$2),9,FALSE) -> 0.072808787 | BW4: =TEXT(BX4,"0.00")&" ("&TEXT(BY4,"0.00")&")" -> 0.07 (0.00) | BX4: =AVERAGE(BR4:BV4) -> 0.071931486 | BY4: =+_xlfn.STDEV.S(BR4:BV4) -> 0.00073544907
A5: Fuzzy | B5: =+VLOOKUP($A5,INDIRECT(Adrese!B$2),2,FALSE) -> 2 | C5: =+VLOOKUP($A5,INDIRECT(Adrese!C$2),2,FALSE) -> 3 | D5: =+VLOOKUP($A5,INDIRECT(Adrese!D$2),2,FALSE) -> 2 | E5: =+VLOOKUP($A5,INDIRECT(Adrese!E$2),2,FALSE) -> 3 | F5: =+VLOOKUP($A5,INDIRECT(Adrese!F$2),2,FALSE) -> 3 | G5: =AVERAGE(B5:F5) -> 2.6 | H5: =+_xlfn.STDEV.S(B5:F5) -> 0.54772256 | J5: Fuzzy | K5: =+VLOOKUP($A5,INDIRECT(Adrese!B$2),3,FALSE) -> 47 | L5: =+VLOOKUP($A5,INDIRECT(Adrese!C$2),3,FALSE) -> 50 | M5: =+VLOOKUP($A5,INDIRECT(Adrese!D$2),3,FALSE) -> 47 | N5: =+VLOOKUP($A5,INDIRECT(Adrese!E$2),3,FALSE) -> 51 | O5: =+VLOOKUP($A5,INDIRECT(Adrese!F$2),3,FALSE) -> 49 | P5: =AVERAGE(K5:O5) -> 48.8 | Q5: =+_xlfn.STDEV.S(K5:O5) -> 1.7888544 | T5: Fuzzy | U5: =+VLOOKUP($T5,INDIRECT(Adrese!B$2),4,FALSE) -> 130630 | V5: =+VLOOKUP($T5,INDIRECT(Adrese!C$2),4,FALSE) -> 129322 | W5: =+VLOOKUP($T5,INDIRECT(Adrese!D$2),4,FALSE) -> 130591 | X5: =+VLOOKUP($T5,INDIRECT(Adrese!E$2),4,FALSE) -> 130138 | Y5: =+VLOOKUP($T5,INDIRECT(Adrese!F$2),4,FALSE) -> 129719 | Z5: =SUM(U5:Y5) -> 650400 | AA5: =AVERAGE(U5:Y5) -> 130080 | AB5: =+_xlfn.STDEV.S(U5:Y5) -> 563.88607 | AD5: Fuzzy | AE5: =+VLOOKUP($A5,INDIRECT(Adrese!B$2),5,FALSE) -> 34561 | AF5: =+VLOOKUP($A5,INDIRECT(Adrese!C$2),5,FALSE) -> 33658 | AG5: =+VLOOKUP($A5,INDIRECT(Adrese!D$2),5,FALSE) -> 34055 | AH5: =+VLOOKUP($A5,INDIRECT(Adrese!E$2),5,FALSE) -> 33648 | AI5: =+VLOOKUP($A5,INDIRECT(Adrese!F$2),5,FALSE) -> 34151 | AJ5: =AVERAGE(AE5:AI5) -> 34014.6 | AK5: =+_xlfn.STDEV.S(AE5:AI5) -> 380.90327 | AM5: Fuzzy | AN5: =+VLOOKUP($A5,INDIRECT(Adrese!B$2),6,FALSE) -> 0.76019912 | AO5: =+VLOOKUP($A5,INDIRECT(Adrese!C$2),6,FALSE) -> 0.74022124 | AP5: =+VLOOKUP($A5,INDIRECT(Adrese!D$2),6,FALSE) -> 0.74900442 | AQ5: =+VLOOKUP($A5,INDIRECT(Adrese!E$2),6,FALSE) -> 0.74 | AR5: =+VLOOKUP($A5,INDIRECT(Adrese!F$2),6,FALSE) -> 0.75112832 | AS5: =TEXT(AT5,"0.00")&" ("&TEXT(AU5,"0.00")&")" -> 0.75 (0.01) | AT5: =AVERAGE(AN5:AR5) -> 0.74811062 | AU5: =+_xlfn.STDEV.S(AN5:AR5) -> 0.0084270635 | AW5: Fuzzy | AX5: =+VLOOKUP($A5,INDIRECT(Adrese!B$2),7,FALSE) -> 0.7920354 | AY5: =+VLOOKUP($A5,INDIRECT(Adrese!C$2),7,FALSE) -> 0.77876106 | AZ5: =+VLOOKUP($A5,INDIRECT(Adrese!D$2),7,FALSE) -> 0.7920354 | BA5: =+VLOOKUP($A5,INDIRECT(Adrese!E$2),7,FALSE) -> 0.77433628 | BB5: =+VLOOKUP($A5,INDIRECT(Adrese!F$2),7,FALSE) -> 0.78318584 | BC5: =TEXT(BD5,"0.00")&" ("&TEXT(BE5,"0.00")&")" -> 0.78 (0.01) | BD5: =AVERAGE(AX5:BB5) -> 0.7840708 | BE5: =+_xlfn.STDEV.S(AX5:BB5) -> 0.0079152849 | BG5: Fuzzy | BH5: =+VLOOKUP($BG5,INDIRECT(Adrese!B$2),8,FALSE) -> 0.074616941 | BI5: =+VLOOKUP($BG5,INDIRECT(Adrese!C$2),8,FALSE) -> 0.072782783 | BJ5: =+VLOOKUP($BG5,INDIRECT(Adrese!D$2),8,FALSE) -> 0.07337504 | BK5: =+VLOOKUP($BG5,INDIRECT(Adrese!E$2),8,FALSE) -> 0.072646936 | BL5: =+VLOOKUP($BG5,INDIRECT(Adrese!F$2),8,FALSE) -> 0.073348804 | BM5: =TEXT(BN5,"0.00")&" ("&TEXT(BO5,"0.00")&")" -> 0.07 (0.00) | BN5: =AVERAGE(BH5:BL5) -> 0.073354101 | BO5: =+_xlfn.STDEV.S(BH5:BL5) -> 0.00077809338 | BQ5: Fuzzy | BR5: =+VLOOKUP($BG5,INDIRECT(Adrese!B$2),9,FALSE) -> 0.075916952 | BS5: =+VLOOKUP($BG5,INDIRECT(Adrese!C$2),9,FALSE) -> 0.073557862 | BT5: =+VLOOKUP($BG5,INDIRECT(Adrese!D$2),9,FALSE) -> 0.073468015 | BU5: =+VLOOKUP($BG5,INDIRECT(Adrese!E$2),9,FALSE) -> 0.073133582 | BV5: =+VLOOKUP($BG5,INDIRECT(Adrese!F$2),9,FALSE) -> 0.072831141 | BW5: =TEXT(BX5,"0.00")&" ("&TEXT(BY5,"0.00")&")" -> 0.07 (0.00) | BX5: =AVERAGE(BR5:BV5) -> 0.07378151 | BY5: =+_xlfn.STDEV.S(BR5:BV5) -> 0.0012279477
A6: Evolved HMM 5 | B6: =+VLOOKUP($A6,INDIRECT(Adrese!B$2),2,FALSE) -> 4 | C6: =+VLOOKUP($A6,INDIRECT(Adrese!C$2),2,FALSE) -> 4 | D6: =+VLOOKUP($A6,INDIRECT(Adrese!D$2),2,FALSE) -> 5 | E6: =+VLOOKUP($A6,INDIRECT(Adrese!E$2),2,FALSE) -> 2 | F6: =+VLOOKUP($A6,INDIRECT(Adrese!F$2),2,FALSE) -> 10 | G6: =AVERAGE(B6:F6) -> 5 | H6: =+_xlfn.STDEV.S(B6:F6) -> 3 | J6: Evolved HMM 5 | K6: =+VLOOKUP($A6,INDIRECT(Adrese!B$2),3,FALSE) -> 44 | L6: =+VLOOKUP($A6,INDIRECT(Adrese!C$2),3,FALSE) -> 48 | M6: =+VLOOKUP($A6,INDIRECT(Adrese!D$2),3,FALSE) -> 44 | N6: =+VLOOKUP($A6,INDIRECT(Adrese!E$2),3,FALSE) -> 43 | O6: =+VLOOKUP($A6,INDIRECT(Adrese!F$2),3,FALSE) -> 44 | P6: =AVERAGE(K6:O6) -> 44.6 | Q6: =+_xlfn.STDEV.S(K6:O6) -> 1.9493589 | T6: Evolved HMM 5 | U6: =+VLOOKUP($T6,INDIRECT(Adrese!B$2),4,FALSE) -> 129913 | V6: =+VLOOKUP($T6,INDIRECT(Adrese!C$2),4,FALSE) -> 129306 | W6: =+VLOOKUP($T6,INDIRECT(Adrese!D$2),4,FALSE) -> 128469 | X6: =+VLOOKUP($T6,INDIRECT(Adrese!E$2),4,FALSE) -> 130151 | Y6: =+VLOOKUP($T6,INDIRECT(Adrese!F$2),4,FALSE) -> 127471 | Z6: =SUM(U6:Y6) -> 645310 | AA6: =AVERAGE(U6:Y6) -> 129062 | AB6: =+_xlfn.STDEV.S(U6:Y6) -> 1101.4295 | AD6: Evolved HMM 5 | AE6: =+VLOOKUP($A6,INDIRECT(Adrese!B$2),5,FALSE) -> 34485 | AF6: =+VLOOKUP($A6,INDIRECT(Adrese!C$2),5,FALSE) -> 34017 | AG6: =+VLOOKUP($A6,INDIRECT(Adrese!D$2),5,FALSE) -> 34437 | AH6: =+VLOOKUP($A6,INDIRECT(Adrese!E$2),5,FALSE) -> 34767 | AI6: =+VLOOKUP($A6,INDIRECT(Adrese!F$2),5,FALSE) -> 34165 | AJ6: =AVERAGE(AE6:AI6) -> 34374.2 | AK6: =+_xlfn.STDEV.S(AE6:AI6) -> 292.34774 | AM6: Evolved HMM 5 | AN6: =+VLOOKUP($A6,INDIRECT(Adrese!B$2),6,FALSE) -> 0.7585177 | AO6: =+VLOOKUP($A6,INDIRECT(Adrese!C$2),6,FALSE) -> 0.74816372 | AP6: =+VLOOKUP($A6,INDIRECT(Adrese!D$2),6,FALSE) -> 0.75745575 | AQ6: =+VLOOKUP($A6,INDIRECT(Adrese!E$2),6,FALSE) -> 0.76475664 | AR6: =+VLOOKUP($A6,INDIRECT(Adrese!F$2),6,FALSE) -> 0.75143805 | AS6: =TEXT(AT6,"0.00")&" ("&TEXT(AU6,"0.00")&")" -> 0.76 (0.01) | AT6: =AVERAGE(AN6:AR6) -> 0.75606637 | AU6: =+_xlfn.STDEV.S(AN6:AR6) -> 0.0064678702 | AW6: Evolved HMM 5 | AX6: =+VLOOKUP($A6,INDIRECT(Adrese!B$2),7,FALSE) -> 0.80530973 | AY6: =+VLOOKUP($A6,INDIRECT(Adrese!C$2),7,FALSE) -> 0.78761062 | AZ6: =+VLOOKUP($A6,INDIRECT(Adrese!D$2),7,FALSE) -> 0.80530974 | BA6: =+VLOOKUP($A6,INDIRECT(Adrese!E$2),7,FALSE) -> 0.80973451 | BB6: =+VLOOKUP($A6,INDIRECT(Adrese!F$2),7,FALSE) -> 0.80530974 | BC6: =TEXT(BD6,"0.00")&" ("&TEXT(BE6,"0.00")&")" -> 0.80 (0.01) | BD6: =AVERAGE(AX6:BB6) -> 0.80265487 | BE6: =+_xlfn.STDEV.S(AX6:BB6) -> 0.0086254819 | BG6: Evolved HMM 5 | BH6: =+VLOOKUP($BG6,INDIRECT(Adrese!B$2),8,FALSE) -> 0.074128798 | BI6: =+VLOOKUP($BG6,INDIRECT(Adrese!C$2),8,FALSE) -> 0.073469565 | BJ6: =+VLOOKUP($BG6,INDIRECT(Adrese!D$2),8,FALSE) -> 0.074360905 | BK6: =+VLOOKUP($BG6,INDIRECT(Adrese!E$2),8,FALSE) -> 0.074522093 | BL6: =+VLOOKUP($BG6,INDIRECT(Adrese!F$2),8,FALSE) -> 0.07377705 | BM6: =TEXT(BN6,"0.00")&" ("&TEXT(BO6,"0.00")&")" -> 0.07 (0.00) | BN6: =AVERAGE(BH6:BL6) -> 0.074051682 | BO6: =+_xlfn.STDEV.S(BH6:BL6) -> 0.00042928289 | BQ6: Evolved HMM 5 | BR6: =+VLOOKUP($BG6,INDIRECT(Adrese!B$2),9,FALSE) -> 0.074430934 | BS6: =+VLOOKUP($BG6,INDIRECT(Adrese!C$2),9,FALSE) -> 0.074426252 | BT6: =+VLOOKUP($BG6,INDIRECT(Adrese!D$2),9,FALSE) -> 0.075455245 | BU6: =+VLOOKUP($BG6,INDIRECT(Adrese!E$2),9,FALSE) -> 0.074685259 | BV6: =+VLOOKUP($BG6,INDIRECT(Adrese!F$2),9,FALSE) -> 0.074520972 | BW6: =TEXT(BX6,"0.00")&" ("&TEXT(BY6,"0.00")&")" -> 0.07 (0.00) | BX6: =AVERAGE(BR6:BV6) -> 0.074703732 | BY6: =+_xlfn.STDEV.S(BR6:BV6) -> 0.00043299202
A7: Evolved FSM 16 | B7: =+VLOOKUP($A7,INDIRECT(Adrese!B$2),2,FALSE) -> 5 | C7: =+VLOOKUP($A7,INDIRECT(Adrese!C$2),2,FALSE) -> 6 | D7: =+VLOOKUP($A7,INDIRECT(Adrese!D$2),2,FALSE) -> 4 | E7: =+VLOOKUP($A7,INDIRECT(Adrese!E$2),2,FALSE) -> 8 | F7: =+VLOOKUP($A7,INDIRECT(Adrese!F$2),2,FALSE) -> 4 | G7: =AVERAGE(B7:F7) -> 5.4 | H7: =+_xlfn.STDEV.S(B7:F7) -> 1.6733201 | J7: Evolved FSM 16 | K7: =+VLOOKUP($A7,INDIRECT(Adrese!B$2),3,FALSE) -> 62 | L7: =+VLOOKUP($A7,INDIRECT(Adrese!C$2),3,FALSE) -> 62 | M7: =+VLOOKUP($A7,INDIRECT(Adrese!D$2),3,FALSE) -> 64 | N7: =+VLOOKUP($A7,INDIRECT(Adrese!E$2),3,FALSE) -> 64 | O7: =+VLOOKUP($A7,INDIRECT(Adrese!F$2),3,FALSE) -> 65 | P7: =AVERAGE(K7:O7) -> 63.4 | Q7: =+_xlfn.STDEV.S(K7:O7) -> 1.3416408 | T7: Evolved FSM 16 | U7: =+VLOOKUP($T7,INDIRECT(Adrese!B$2),4,FALSE) -> 129208 | V7: =+VLOOKUP($T7,INDIRECT(Adrese!C$2),4,FALSE) -> 128662 | W7: =+VLOOKUP($T7,INDIRECT(Adrese!D$2),4,FALSE) -> 129190 | X7: =+VLOOKUP($T7,INDIRECT(Adrese!E$2),4,FALSE) -> 128299 | Y7: =+VLOOKUP($T7,INDIRECT(Adrese!F$2),4,FALSE) -> 128659 | Z7: =SUM(U7:Y7) -> 644018 | AA7: =AVERAGE(U7:Y7) -> 128803.6 | AB7: =+_xlfn.STDEV.S(U7:Y7) -> 390.00808 | AD7: Evolved FSM 16 | AE7: =+VLOOKUP($A7,INDIRECT(Adrese!B$2),5,FALSE) -> 32767 | AF7: =+VLOOKUP($A7,INDIRECT(Adrese!C$2),5,FALSE) -> 32811 | AG7: =+VLOOKUP($A7,INDIRECT(Adrese!D$2),5,FALSE) -> 32718 | AH7: =+VLOOKUP($A7,INDIRECT(Adrese!E$2),5,FALSE) -> 32884 | AI7: =+VLOOKUP($A7,INDIRECT(Adrese!F$2),5,FALSE) -> 32618 | AJ7: =AVERAGE(AE7:AI7) -> 32759.6 | AK7: =+_xlfn.STDEV.S(AE7:AI7) -> 99.941483 | AM7: Evolved FSM 16 | AN7: =+VLOOKUP($A7,INDIRECT(Adrese!B$2),6,FALSE) -> 0.72050885 | AO7: =+VLOOKUP($A7,INDIRECT(Adrese!C$2),6,FALSE) -> 0.7214823 | AP7: =+VLOOKUP($A7,INDIRECT(Adrese!D$2),6,FALSE) -> 0.71942478 | AQ7: =+VLOOKUP($A7,INDIRECT(Adrese!E$2),6,FALSE) -> 0.72309735 | AR7: =+VLOOKUP($A7,INDIRECT(Adrese!F$2),6,FALSE) -> 0.71721239 | AS7: =TEXT(AT7,"0.00")&" ("&TEXT(AU7,"0.00")&")" -> 0.72 (0.00) | AT7: =AVERAGE(AN7:AR7) -> 0.72034513 | AU7: =+_xlfn.STDEV.S(AN7:AR7) -> 0.0022110948 | AW7: Evolved FSM 16 | AX7: =+VLOOKUP($A7,INDIRECT(Adrese!B$2),7,FALSE) -> 0.72566372 | AY7: =+VLOOKUP($A7,INDIRECT(Adrese!C$2),7,FALSE) -> 0.72566372 | AZ7: =+VLOOKUP($A7,INDIRECT(Adrese!D$2),7,FALSE) -> 0.71681416 | BA7: =+VLOOKUP($A7,INDIRECT(Adrese!E$2),7,FALSE) -> 0.71681416 | BB7: =+VLOOKUP($A7,INDIRECT(Adrese!F$2),7,FALSE) -> 0.71238938 | BC7: =TEXT(BD7,"0.00")&" ("&TEXT(BE7,"0.00")&")" -> 0.72 (0.01) | BD7: =AVERAGE(AX7:BB7) -> 0.71946903 | BE7: =+_xlfn.STDEV.S(AX7:BB7) -> 0.0059364636 | BG7: Evolved FSM 16 | BH7: =+VLOOKUP($BG7,INDIRECT(Adrese!B$2),8,FALSE) -> 0.070108469 | BI7: =+VLOOKUP($BG7,INDIRECT(Adrese!C$2),8,FALSE) -> 0.070181328 | BJ7: =+VLOOKUP($BG7,INDIRECT(Adrese!D$2),8,FALSE) -> 0.07009061 | BK7: =+VLOOKUP($BG7,INDIRECT(Adrese!E$2),8,FALSE) -> 0.070407925 | BL7: =+VLOOKUP($BG7,INDIRECT(Adrese!F$2),8,FALSE) -> 0.070040165 | BM7: =TEXT(BN7,"0.00")&" ("&TEXT(BO7,"0.00")&")" -> 0.07 (0.00) | BN7: =AVERAGE(BH7:BL7) -> 0.070165699 | BO7: =+_xlfn.STDEV.S(BH7:BL7) -> 0.00014455981 | BQ7: Evolved FSM 16 | BR7: =+VLOOKUP($BG7,INDIRECT(Adrese!B$2),9,FALSE) -> 0.066746666 | BS7: =+VLOOKUP($BG7,INDIRECT(Adrese!C$2),9,FALSE) -> 0.066772286 | BT7: =+VLOOKUP($BG7,INDIRECT(Adrese!D$2),9,FALSE) -> 0.066757733 | BU7: =+VLOOKUP($BG7,INDIRECT(Adrese!E$2),9,FALSE) -> 0.067489967 | BV7: =+VLOOKUP($BG7,INDIRECT(Adrese!F$2),9,FALSE) -> 0.066914373 | BW7: =TEXT(BX7,"0.00")&" ("&TEXT(BY7,"0.00")&")" -> 0.07 (0.00) | BX7: =AVERAGE(BR7:BV7) -> 0.066936205 | BY7: =+_xlfn.STDEV.S(BR7:BV7) -> 0.00031692896
A8: PSO Gambler 1_1_1 | B8: =+VLOOKUP($A8,INDIRECT(Adrese!B$2),2,FALSE) -> 6 | C8: =+VLOOKUP($A8,INDIRECT(Adrese!C$2),2,FALSE) -> 8 | D8: =+VLOOKUP($A8,INDIRECT(Adrese!D$2),2,FALSE) -> 8 | E8: =+VLOOKUP($A8,INDIRECT(Adrese!E$2),2,FALSE) -> 6 | F8: =+VLOOKUP($A8,INDIRECT(Adrese!F$2),2,FALSE) -> 5 | G8: =AVERAGE(B8:F8) -> 6.6 | H8: =+_xlfn.STDEV.S(B8:F8) -> 1.3416408 | J8: PSO Gambler 1_1_1 | K8: =+VLOOKUP($A8,INDIRECT(Adrese!B$2),3,FALSE) -> 51 | L8: =+VLOOKUP($A8,INDIRECT(Adrese!C$2),3,FALSE) -> 52 | M8: =+VLOOKUP($A8,INDIRECT(Adrese!D$2),3,FALSE) -> 51 | N8: =+VLOOKUP($A8,INDIRECT(Adrese!E$2),3,FALSE) -> 49 | O8: =+VLOOKUP($A8,INDIRECT(Adrese!F$2),3,FALSE) -> 52 | P8: =AVERAGE(K8:O8) -> 51 | Q8: =+_xlfn.STDEV.S(K8:O8) -> 1.2247449 | T8: PSO Gambler 1_1_1 | U8: =+VLOOKUP($T8,INDIRECT(Adrese!B$2),4,FALSE) -> 128912 | V8: =+VLOOKUP($T8,INDIRECT(Adrese!C$2),4,FALSE) -> 128370 | W8: =+VLOOKUP($T8,INDIRECT(Adrese!D$2),4,FALSE) -> 127740 | X8: =+VLOOKUP($T8,INDIRECT(Adrese!E$2),4,FALSE) -> 129055 | Y8: =+VLOOKUP($T8,INDIRECT(Adrese!F$2),4,FALSE) -> 128310 | Z8: =SUM(U8:Y8) -> 642387 | AA8: =AVERAGE(U8:Y8) -> 128477.4 | AB8: =+_xlfn.STDEV.S(U8:Y8) -> 525.78874 | AD8: PSO Gambler 1_1_1 | AE8: =+VLOOKUP($A8,INDIRECT(Adrese!B$2),5,FALSE) -> 32603 | AF8: =+VLOOKUP($A8,INDIRECT(Adrese!C$2),5,FALSE) -> 32789 | AG8: =+VLOOKUP($A8,INDIRECT(Adrese!D$2),5,FALSE) -> 32092 | AH8: =+VLOOKUP($A8,INDIRECT(Adrese!E$2),5,FALSE) -> 32821 | AI8: =+VLOOKUP($A8,INDIRECT(Adrese!F$2),5,FALSE) -> 32542 | AJ8: =AVERAGE(AE8:AI8) -> 32569.4 | AK8: =+_xlfn.STDEV.S(AE8:AI8) -> 292.11179 | AM8: PSO Gambler 1_1_1 | AN8: =+VLOOKUP($A8,INDIRECT(Adrese!B$2),6,FALSE) -> 0.71688053 | AO8: =+VLOOKUP($A8,INDIRECT(Adrese!C$2),6,FALSE) -> 0.72099557 | AP8: =+VLOOKUP($A8,INDIRECT(Adrese!D$2),6,FALSE) -> 0.70557522 | AQ8: =+VLOOKUP($A8,INDIRECT(Adrese!E$2),6,FALSE) -> 0.72170354 | AR8: =+VLOOKUP($A8,INDIRECT(Adrese!F$2),6,FALSE) -> 0.71553097 | AS8: =TEXT(AT8,"0.00")&" ("&TEXT(AU8,"0.00")&")" -> 0.72 (0.01) | AT8: =AVERAGE(AN8:AR8) -> 0.71613717 | AU8: =+_xlfn.STDEV.S(AN8:AR8) -> 0.0064626504 | AW8: PSO Gambler 1_1_1 | AX8: =+VLOOKUP($A8,INDIRECT(Adrese!B$2),7,FALSE) -> 0.77433628 | AY8: =+VLOOKUP($A8,INDIRECT(Adrese!C$2),7,FALSE) -> 0.7699115 | AZ8: =+VLOOKUP($A8,INDIRECT(Adrese!D$2),7,FALSE) -> 0.77433628 | BA8: =+VLOOKUP($A8,INDIRECT(Adrese!E$2),7,FALSE) -> 0.78318584 | BB8: =+VLOOKUP($A8,INDIRECT(Adrese!F$2),7,FALSE) -> 0.7699115 | BC8: =TEXT(BD8,"0.00")&" ("&TEXT(BE8,"0.00")&")" -> 0.77 (0.01) | BD8: =AVERAGE(AX8:BB8) -> 0.77433628 | BE8: =+_xlfn.STDEV.S(AX8:BB8) -> 0.0054192254 | BG8: PSO Gambler 1_1_1 | BH8: =+VLOOKUP($BG8,INDIRECT(Adrese!B$2),8,FALSE) -> 0.072026931 | BI8: =+VLOOKUP($BG8,INDIRECT(Adrese!C$2),8,FALSE) -> 0.072270271 | BJ8: =+VLOOKUP($BG8,INDIRECT(Adrese!D$2),8,FALSE) -> 0.071261197 | BK8: =+VLOOKUP($BG8,INDIRECT(Adrese!E$2),8,FALSE) -> 0.072017958 | BL8: =+VLOOKUP($BG8,INDIRECT(Adrese!F$2),8,FALSE) -> 0.071939301 | BM8: =TEXT(BN8,"0.00")&" ("&TEXT(BO8,"0.00")&")" -> 0.07 (0.00) | BN8: =AVERAGE(BH8:BL8) -> 0.071903132 | BO8: =+_xlfn.STDEV.S(BH8:BL8) -> 0.00037970086 | BQ8: PSO Gambler 1_1_1 | BR8: =+VLOOKUP($BG8,INDIRECT(Adrese!B$2),9,FALSE) -> 0.07575804 | BS8: =+VLOOKUP($BG8,INDIRECT(Adrese!C$2),9,FALSE) -> 0.075995524 | BT8: =+VLOOKUP($BG8,INDIRECT(Adrese!D$2),9,FALSE) -> 0.07481221 | BU8: =+VLOOKUP($BG8,INDIRECT(Adrese!E$2),9,FALSE) -> 0.074376339 | BV8: =+VLOOKUP($BG8,INDIRECT(Adrese!F$2),9,FALSE) -> 0.075478143 | BW8: =TEXT(BX8,"0.00")&" ("&TEXT(BY8,"0.00")&")" -> 0.08 (0.00) | BX8: =AVERAGE(BR8:BV8) -> 0.075284051 | BY8: =+_xlfn.STDEV.S(BR8:BV8) -> 0.00067362938
A9: Evolved FSM 16 Noise 05 | B9: =+VLOOKUP($A9,INDIRECT(Adrese!B$2),2,FALSE) -> 7 | C9: =+VLOOKUP($A9,INDIRECT(Adrese!C$2),2,FALSE) -> 7 | D9: =+VLOOKUP($A9,INDIRECT(Adrese!D$2),2,FALSE) -> 7 | E9: =+VLOOKUP($A9,INDIRECT(Adrese!E$2),2,FALSE) -> 5 | F9: =+VLOOKUP($A9,INDIRECT(Adrese!F$2),2,FALSE) -> 9 | G9: =AVERAGE(B9:F9) -> 7 | H9: =+_xlfn.STDEV.S(B9:F9) -> 1.4142136 | J9: Evolved FSM 16 Noise 05 | K9: =+VLOOKUP($A9,INDIRECT(Adrese!B$2),3,FALSE) -> 48 | L9: =+VLOOKUP($A9,INDIRECT(Adrese!C$2),3,FALSE) -> 43 | M9: =+VLOOKUP($A9,INDIRECT(Adrese!D$2),3,FALSE) -> 46 | N9: =+VLOOKUP($A9,INDIRECT(Adrese!E$2),3,FALSE) -> 47 | O9: =+VLOOKUP($A9,INDIRECT(Adrese!F$2),3,FALSE) -> 44 | P9: =AVERAGE(K9:O9) -> 45.6 | Q9: =+_xlfn.STDEV.S(K9:O9) -> 2.0736441 | T9: Evolved FSM 16 Noise 05 | U9: =+VLOOKUP($T9,INDIRECT(Adrese!B$2),4,FALSE) -> 128227 | V9: =+VLOOKUP($T9,INDIRECT(Adrese!C$2),4,FALSE) -> 128404 | W9: =+VLOOKUP($T9,INDIRECT(Adrese!D$2),4,FALSE) -> 127970 | X9: =+VLOOKUP($T9,INDIRECT(Adrese!E$2),4,FALSE) -> 129237 | Y9: =+VLOOKUP($T9,INDIRECT(Adrese!F$2),4,FALSE) -> 127835 | Z9: =SUM(U9:Y9) -> 641673 | AA9: =AVERAGE(U9:Y9) -> 128334.6 | AB9: =+_xlfn.STDEV.S(U9:Y9) -> 550.73887 | AD9: Evolved FSM 16 Noise 05 | AE9: =+VLOOKUP($A9,INDIRECT(Adrese!B$2),5,FALSE) -> 33058 | AF9: =+VLOOKUP($A9,INDIRECT(Adrese!C$2),5,FALSE) -> 33140 | AG9: =+VLOOKUP($A9,INDIRECT(Adrese!D$2),5,FALSE) -> 33086 | AH9: =+VLOOKUP($A9,INDIRECT(Adrese!E$2),5,FALSE) -> 33556 | AI9: =+VLOOKUP($A9,INDIRECT(Adrese!F$2),5,FALSE) -> 33091 | AJ9: =AVERAGE(AE9:AI9) -> 33186.2 | AK9: =+_xlfn.STDEV.S(AE9:AI9) -> 208.82098 | AM9: Evolved FSM 16 Noise 05 | AN9: =+VLOOKUP($A9,INDIRECT(Adrese!B$2),6,FALSE) -> 0.7269469 | AO9: =+VLOOKUP($A9,INDIRECT(Adrese!C$2),6,FALSE) -> 0.72876106 | AP9: =+VLOOKUP($A9,INDIRECT(Adrese!D$2),6,FALSE) -> 0.72756637 | AQ9: =+VLOOKUP($A9,INDIRECT(Adrese!E$2),6,FALSE) -> 0.7379646 | AR9: =+VLOOKUP($A9,INDIRECT(Adrese!F$2),6,FALSE) -> 0.72767699 | AS9: =TEXT(AT9,"0.00")&" ("&TEXT(AU9,"0.00")&")" -> 0.73 (0.00) | AT9: =AVERAGE(AN9:AR9) -> 0.72978319 | AU9: =+_xlfn.STDEV.S(AN9:AR9) -> 0.0046199332 | AW9: Evolved FSM 16 Noise 05 | AX9: =+VLOOKUP($A9,INDIRECT(Adrese!B$2),7,FALSE) -> 0.78761062 | AY9: =+VLOOKUP($A9,INDIRECT(Adrese!C$2),7,FALSE) -> 0.80973451 | AZ9: =+VLOOKUP($A9,INDIRECT(Adrese!D$2),7,FALSE) -> 0.79646018 | BA9: =+VLOOKUP($A9,INDIRECT(Adrese!E$2),7,FALSE) -> 0.7920354 | BB9: =+VLOOKUP($A9,INDIRECT(Adrese!F$2),7,FALSE) -> 0.80530974 | BC9: =TEXT(BD9,"0.00")&" ("&TEXT(BE9,"0.00")&")" -> 0.80 (0.01) | BD9: =AVERAGE(AX9:BB9) -> 0.79823009 | BE9: =+_xlfn.STDEV.S(AX9:BB9) -> 0.0091754166 | BG9: Evolved FSM 16 Noise 05 | BH9: =+VLOOKUP($BG9,INDIRECT(Adrese!B$2),8,FALSE) -> 0.073902367 | BI9: =+VLOOKUP($BG9,INDIRECT(Adrese!C$2),8,FALSE) -> 0.073995285 | BJ9: =+VLOOKUP($BG9,INDIRECT(Adrese!D$2),8,FALSE) -> 0.07390397 | BK9: =+VLOOKUP($BG9,INDIRECT(Adrese!E$2),8,FALSE) -> 0.074593361 | BL9: =+VLOOKUP($BG9,INDIRECT(Adrese!F$2),8,FALSE) -> 0.07421175 | BM9: =TEXT(BN9,"0.00")&" ("&TEXT(BO9,"0.00")&")" -> 0.07 (0.00) | BN9: =AVERAGE(BH9:BL9) -> 0.074121347 | BO9: =+_xlfn.STDEV.S(BH9:BL9) -> 0.00029243219 | BQ9: Evolved FSM 16 Noise 05 | BR9: =+VLOOKUP($BG9,INDIRECT(Adrese!B$2),9,FALSE) -> 0.080896687 | BS9: =+VLOOKUP($BG9,INDIRECT(Adrese!C$2),9,FALSE) -> 0.08126278 | BT9: =+VLOOKUP($BG9,INDIRECT(Adrese!D$2),9,FALSE) -> 0.080677698 | BU9: =+VLOOKUP($BG9,INDIRECT(Adrese!E$2),9,FALSE) -> 0.081333508 | BV9: =+VLOOKUP($BG9,INDIRECT(Adrese!F$2),9,FALSE) -> 0.082055922 | BW9: =TEXT(BX9,"0.00")&" ("&TEXT(BY9,"0.00")&")" -> 0.08 (0.00) | BX9: =AVERAGE(BR9:BV9) -> 0.081245319 | BY9: =+_xlfn.STDEV.S(BR9:BV9) -> 0.00052652092
A10: Evolved ANN | B10: =+VLOOKUP($A10,INDIRECT(Adrese!B$2),2,FALSE) -> 8 | C10: =+VLOOKUP($A10,INDIRECT(Adrese!C$2),2,FALSE) -> 5 | D10: =+VLOOKUP($A10,INDIRECT(Adrese!D$2),2,FALSE) -> 6 | E10: =+VLOOKUP($A10,INDIRECT(Adrese!E$2),2,FALSE) -> 7 | F10: =+VLOOKUP($A10,INDIRECT(Adrese!F$2),2,FALSE) -> 6 | G10: =AVERAGE(B10:F10) -> 6.4 | H10: =+_xlfn.STDEV.S(B10:F10) -> 1.1401754 | J10: Evolved ANN | K10: =+VLOOKUP($A10,INDIRECT(Adrese!B$2),3,FALSE) -> 46 | L10: =+VLOOKUP($A10,INDIRECT(Adrese!C$2),3,FALSE) -> 45 | M10: =+VLOOKUP($A10,INDIRECT(Adrese!D$2),3,FALSE) -> 45 | N10: =+VLOOKUP($A10,INDIRECT(Adrese!E$2),3,FALSE) -> 46 | O10: =+VLOOKUP($A10,INDIRECT(Adrese!F$2),3,FALSE) -> 45 | P10: =AVERAGE(K10:O10) -> 45.4 | Q10: =+_xlfn.STDEV.S(K10:O10) -> 0.54772256 | T10: Evolved ANN | U10: =+VLOOKUP($T10,INDIRECT(Adrese!B$2),4,FALSE) -> 128023 | V10: =+VLOOKUP($T10,INDIRECT(Adrese!C$2),4,FALSE) -> 128831 | W10: =+VLOOKUP($T10,INDIRECT(Adrese!D$2),4,FALSE) -> 128090 | X10: =+VLOOKUP($T10,INDIRECT(Adrese!E$2),4,FALSE) -> 128940 | Y10: =+VLOOKUP($T10,INDIRECT(Adrese!F$2),4,FALSE) -> 128224 | Z10: =SUM(U10:Y10) -> 642108 | AA10: =AVERAGE(U10:Y10) -> 128421.6 | AB10: =+_xlfn.STDEV.S(U10:Y10) -> 431.34476 | AD10: Evolved ANN | AE10: =+VLOOKUP($A10,INDIRECT(Adrese!B$2),5,FALSE) -> 33186 | AF10: =+VLOOKUP($A10,INDIRECT(Adrese!C$2),5,FALSE) -> 33556 | AG10: =+VLOOKUP($A10,INDIRECT(Adrese!D$2),5,FALSE) -> 33418 | AH10: =+VLOOKUP($A10,INDIRECT(Adrese!E$2),5,FALSE) -> 33676 | AI10: =+VLOOKUP($A10,INDIRECT(Adrese!F$2),5,FALSE) -> 33518 | AJ10: =AVERAGE(AE10:AI10) -> 33470.8 | AK10: =+_xlfn.STDEV.S(AE10:AI10) -> 184.04673 | AM10: Evolved ANN | AN10: =+VLOOKUP($A10,INDIRECT(Adrese!B$2),6,FALSE) -> 0.72977876 | AO10: =+VLOOKUP($A10,INDIRECT(Adrese!C$2),6,FALSE) -> 0.7379646 | AP10: =+VLOOKUP($A10,INDIRECT(Adrese!D$2),6,FALSE) -> 0.7349115 | AQ10: =+VLOOKUP($A10,INDIRECT(Adrese!E$2),6,FALSE) -> 0.74061947 | AR10: =+VLOOKUP($A10,INDIRECT(Adrese!F$2),6,FALSE) -> 0.73712389 | AS10: =TEXT(AT10,"0.00")&" ("&TEXT(AU10,"0.00")&")" -> 0.74 (0.00) | AT10: =AVERAGE(AN10:AR10) -> 0.73607965 | AU10: =+_xlfn.STDEV.S(AN10:AR10) -> 0.0040718304 | AW10: Evolved ANN | AX10: =+VLOOKUP($A10,INDIRECT(Adrese!B$2),7,FALSE) -> 0.79646018 | AY10: =+VLOOKUP($A10,INDIRECT(Adrese!C$2),7,FALSE) -> 0.80088496 | AZ10: =+VLOOKUP($A10,INDIRECT(Adrese!D$2),7,FALSE) -> 0.80088496 | BA10: =+VLOOKUP($A10,INDIRECT(Adrese!E$2),7,FALSE) -> 0.79646018 | BB10: =+VLOOKUP($A10,INDIRECT(Adrese!F$2),7,FALSE) -> 0.80088496 | BC10: =TEXT(BD10,"0.00")&" ("&TEXT(BE10,"0.00")&")" -> 0.80 (0.00) | BD10: =AVERAGE(AX10:BB10) -> 0.79911504 | BE10: =+_xlfn.STDEV.S(AX10:BB10) -> 0.0024235513 | BG10: Evolved ANN | BH10: =+VLOOKUP($BG10,INDIRECT(Adrese!B$2),8,FALSE) -> 0.07512316 | BI10: =+VLOOKUP($BG10,INDIRECT(Adrese!C$2),8,FALSE) -> 0.075586355 | BJ10: =+VLOOKUP($BG10,INDIRECT(Adrese!D$2),8,FALSE) -> 0.075509794 | BK10: =+VLOOKUP($BG10,INDIRECT(Adrese!E$2),8,FALSE) -> 0.075734416 | BL10: =+VLOOKUP($BG10,INDIRECT(Adrese!F$2),8,FALSE) -> 0.075698898 | BM10: =TEXT(BN10,"0.00")&" ("&TEXT(BO10,"0.00")&")" -> 0.08 (0.00) | BN10: =AVERAGE(BH10:BL10) -> 0.075530525 | BO10: =+_xlfn.STDEV.S(BH10:BL10) -> 0.0002446498 | BQ10: Evolved ANN | BR10: =+VLOOKUP($BG10,INDIRECT(Adrese!B$2),9,FALSE) -> 0.085277743 | BS10: =+VLOOKUP($BG10,INDIRECT(Adrese!C$2),9,FALSE) -> 0.085409572 | BT10: =+VLOOKUP($BG10,INDIRECT(Adrese!D$2),9,FALSE) -> 0.085572882 | BU10: =+VLOOKUP($BG10,INDIRECT(Adrese!E$2),9,FALSE) -> 0.085222136 | BV10: =+VLOOKUP($BG10,INDIRECT(Adrese!F$2),9,FALSE) -> 0.085821031 | BW10: =TEXT(BX10,"0.00")&" ("&TEXT(BY10,"0.00")&")" -> 0.09 (0.00) | BX10: =AVERAGE(BR10:BV10) -> 0.085460673 | BY10: =+_xlfn.STDEV.S(BR10:BV10) -> 0.00024260231
A11: Evolved ANN 5 | B11: =+VLOOKUP($A11,INDIRECT(Adrese!B$2),2,FALSE) -> 9 | C11: =+VLOOKUP($A11,INDIRECT(Adrese!C$2),2,FALSE) -> 9 | D11: =+VLOOKUP($A11,INDIRECT(Adrese!D$2),2,FALSE) -> 11 | E11: =+VLOOKUP($A11,INDIRECT(Adrese!E$2),2,FALSE) -> 9 | F11: =+VLOOKUP($A11,INDIRECT(Adrese!F$2),2,FALSE) -> 8 | G11: =AVERAGE(B11:F11) -> 9.2 | H11: =+_xlfn.STDEV.S(B11:F11) -> 1.0954451 | J11: Evolved ANN 5 | K11: =+VLOOKUP($A11,INDIRECT(Adrese!B$2),3,FALSE) -> 42 | L11: =+VLOOKUP($A11,INDIRECT(Adrese!C$2),3,FALSE) -> 44 | M11: =+VLOOKUP($A11,INDIRECT(Adrese!D$2),3,FALSE) -> 42 | N11: =+VLOOKUP($A11,INDIRECT(Adrese!E$2),3,FALSE) -> 47 | O11: =+VLOOKUP($A11,INDIRECT(Adrese!F$2),3,FALSE) -> 47 | P11: =AVERAGE(K11:O11) -> 44.4 | Q11: =+_xlfn.STDEV.S(K11:O11) -> 2.5099801 | T11: Evolved ANN 5 | U11: =+VLOOKUP($T11,INDIRECT(Adrese!B$2),4,FALSE) -> 127587 | V11: =+VLOOKUP($T11,INDIRECT(Adrese!C$2),4,FALSE) -> 128307 | W11: =+VLOOKUP($T11,INDIRECT(Adrese!D$2),4,FALSE) -> 127363 | X11: =+VLOOKUP($T11,INDIRECT(Adrese!E$2),4,FALSE) -> 128112 | Y11: =+VLOOKUP($T11,INDIRECT(Adrese!F$2),4,FALSE) -> 127951 | Z11: =SUM(U11:Y11) -> 639320 | AA11: =AVERAGE(U11:Y11) -> 127864 | AB11: =+_xlfn.STDEV.S(U11:Y11) -> 385.04935 | AD11: Evolved ANN 5 | AE11: =+VLOOKUP($A11,INDIRECT(Adrese!B$2),5,FALSE) -> 33011 | AF11: =+VLOOKUP($A11,INDIRECT(Adrese!C$2),5,FALSE) -> 33118 | AG11: =+VLOOKUP($A11,INDIRECT(Adrese!D$2),5,FALSE) -> 32859 | AH11: =+VLOOKUP($A11,INDIRECT(Adrese!E$2),5,FALSE) -> 32790 | AI11: =+VLOOKUP($A11,INDIRECT(Adrese!F$2),5,FALSE) -> 32421 | AJ11: =AVERAGE(AE11:AI11) -> 32839.8 | AK11: =+_xlfn.STDEV.S(AE11:AI11) -> 266.90204 | AM11: Evolved ANN 5 | AN11: =+VLOOKUP($A11,INDIRECT(Adrese!B$2),6,FALSE) -> 0.72590708 | AO11: =+VLOOKUP($A11,INDIRECT(Adrese!C$2),6,FALSE) -> 0.72827434 | AP11: =+VLOOKUP($A11,INDIRECT(Adrese!D$2),6,FALSE) -> 0.72254425 | AQ11: =+VLOOKUP($A11,INDIRECT(Adrese!E$2),6,FALSE) -> 0.7210177 | AR11: =+VLOOKUP($A11,INDIRECT(Adrese!F$2),6,FALSE) -> 0.71285398 | AS11: =TEXT(AT11,"0.00")&" ("&TEXT(AU11,"0.00")&")" -> 0.72 (0.01) | AT11: =AVERAGE(AN11:AR11) -> 0.72211947 | AU11: =+_xlfn.STDEV.S(AN11:AR11) -> 0.0059049125 | AW11: Evolved ANN 5 | AX11: =+VLOOKUP($A11,INDIRECT(Adrese!B$2),7,FALSE) -> 0.81415929 | AY11: =+VLOOKUP($A11,INDIRECT(Adrese!C$2),7,FALSE) -> 0.80530974 | AZ11: =+VLOOKUP($A11,INDIRECT(Adrese!D$2),7,FALSE) -> 0.81415929 | BA11: =+VLOOKUP($A11,INDIRECT(Adrese!E$2),7,FALSE) -> 0.7920354 | BB11: =+VLOOKUP($A11,INDIRECT(Adrese!F$2),7,FALSE) -> 0.7920354 | BC11: =TEXT(BD11,"0.00")&" ("&TEXT(BE11,"0.00")&")" -> 0.80 (0.01) | BD11: =AVERAGE(AX11:BB11) -> 0.80353982 | BE11: =+_xlfn.STDEV.S(AX11:BB11) -> 0.011106107 | BG11: Evolved ANN 5 | BH11: =+VLOOKUP($BG11,INDIRECT(Adrese!B$2),8,FALSE) -> 0.074337678 | BI11: =+VLOOKUP($BG11,INDIRECT(Adrese!C$2),8,FALSE) -> 0.074674702 | BJ11: =+VLOOKUP($BG11,INDIRECT(Adrese!D$2),8,FALSE) -> 0.074189344 | BK11: =+VLOOKUP($BG11,INDIRECT(Adrese!E$2),8,FALSE) -> 0.073831363 | BL11: =+VLOOKUP($BG11,INDIRECT(Adrese!F$2),8,FALSE) -> 0.073224163 | BM11: =TEXT(BN11,"0.00")&" ("&TEXT(BO11,"0.00")&")" -> 0.07 (0.00) | BN11: =AVERAGE(BH11:BL11) -> 0.07405145 | BO11: =+_xlfn.STDEV.S(BH11:BL11) -> 0.00055277173 | BQ11: Evolved ANN 5 | BR11: =+VLOOKUP($BG11,INDIRECT(Adrese!B$2),9,FALSE) -> 0.08333406 | BS11: =+VLOOKUP($BG11,INDIRECT(Adrese!C$2),9,FALSE) -> 0.084279284 | BT11: =+VLOOKUP($BG11,INDIRECT(Adrese!D$2),9,FALSE) -> 0.083349243 | BU11: =+VLOOKUP($BG11,INDIRECT(Adrese!E$2),9,FALSE) -> 0.08248192 | BV11: =+VLOOKUP($BG11,INDIRECT(Adrese!F$2),9,FALSE) -> 0.081808475 | BW11: =TEXT(BX11,"0.00")&" ("&TEXT(BY11,"0.00")&")" -> 0.08 (0.00) | BX11: =AVERAGE(BR11:BV11) -> 0.083050596 | BY11: =+_xlfn.STDEV.S(BR11:BV11) -> 0.00094147131
A12: Evolved FSM 4 | B12: =+VLOOKUP($A12,INDIRECT(Adrese!B$2),2,FALSE) -> 10 | C12: =+VLOOKUP($A12,INDIRECT(Adrese!C$2),2,FALSE) -> 11 | D12: =+VLOOKUP($A12,INDIRECT(Adrese!D$2),2,FALSE) -> 9 | E12: =+VLOOKUP($A12,INDIRECT(Adrese!E$2),2,FALSE) -> 11 | F12: =+VLOOKUP($A12,INDIRECT(Adrese!F$2),2,FALSE) -> 7 | G12: =AVERAGE(B12:F12) -> 9.6 | H12: =+_xlfn.STDEV.S(B12:F12) -> 1.6733201 | J12: Evolved FSM 4 | K12: =+VLOOKUP($A12,INDIRECT(Adrese!B$2),3,FALSE) -> 37 | L12: =+VLOOKUP($A12,INDIRECT(Adrese!C$2),3,FALSE) -> 38 | M12: =+VLOOKUP($A12,INDIRECT(Adrese!D$2),3,FALSE) -> 37 | N12: =+VLOOKUP($A12,INDIRECT(Adrese!E$2),3,FALSE) -> 36 | O12: =+VLOOKUP($A12,INDIRECT(Adrese!F$2),3,FALSE) -> 39 | P12: =AVERAGE(K12:O12) -> 37.4 | Q12: =+_xlfn.STDEV.S(K12:O12) -> 1.1401754 | T12: Evolved FSM 4 | U12: =+VLOOKUP($T12,INDIRECT(Adrese!B$2),4,FALSE) -> 127572 | V12: =+VLOOKUP($T12,INDIRECT(Adrese!C$2),4,FALSE) -> 127184 | W12: =+VLOOKUP($T12,INDIRECT(Adrese!D$2),4,FALSE) -> 127689 | X12: =+VLOOKUP($T12,INDIRECT(Adrese!E$2),4,FALSE) -> 127169 | Y12: =+VLOOKUP($T12,INDIRECT(Adrese!F$2),4,FALSE) -> 128001 | Z12: =SUM(U12:Y12) -> 637615 | AA12: =AVERAGE(U12:Y12) -> 127523 | AB12: =+_xlfn.STDEV.S(U12:Y12) -> 353.08568 | AD12: Evolved FSM 4 | AE12: =+VLOOKUP($A12,INDIRECT(Adrese!B$2),5,FALSE) -> 35631 | AF12: =+VLOOKUP($A12,INDIRECT(Adrese!C$2),5,FALSE) -> 35594 | AG12: =+VLOOKUP($A12,INDIRECT(Adrese!D$2),5,FALSE) -> 36014 | AH12: =+VLOOKUP($A12,INDIRECT(Adrese!E$2),5,FALSE) -> 35741 | AI12: =+VLOOKUP($A12,INDIRECT(Adrese!F$2),5,FALSE) -> 35720 | AJ12: =AVERAGE(AE12:AI12) -> 35740 | AK12: =+_xlfn.STDEV.S(AE12:AI12) -> 164.8287 | AM12: Evolved FSM 4 | AN12: =+VLOOKUP($A12,INDIRECT(Adrese!B$2),6,FALSE) -> 0.78387168 | AO12: =+VLOOKUP($A12,INDIRECT(Adrese!C$2),6,FALSE) -> 0.7830531 | AP12: =+VLOOKUP($A12,INDIRECT(Adrese!D$2),6,FALSE) -> 0.79234513 | AQ12: =+VLOOKUP($A12,INDIRECT(Adrese!E$2),6,FALSE) -> 0.78630531 | AR12: =+VLOOKUP($A12,INDIRECT(Adrese!F$2),6,FALSE) -> 0.78584071 | AS12: =TEXT(AT12,"0.00")&" ("&TEXT(AU12,"0.00")&")" -> 0.79 (0.00) | AT12: =AVERAGE(AN12:AR12) -> 0.78628319 | AU12: =+_xlfn.STDEV.S(AN12:AR12) -> 0.0036466528 | AW12: Evolved FSM 4 | AX12: =+VLOOKUP($A12,INDIRECT(Adrese!B$2),7,FALSE) -> 0.83628319 | AY12: =+VLOOKUP($A12,INDIRECT(Adrese!C$2),7,FALSE) -> 0.83185841 | AZ12: =+VLOOKUP($A12,INDIRECT(Adrese!D$2),7,FALSE) -> 0.83628319 | BA12: =+VLOOKUP($A12,INDIRECT(Adrese!E$2),7,FALSE) -> 0.84070797 | BB12: =+VLOOKUP($A12,INDIRECT(Adrese!F$2),7,FALSE) -> 0.82743363 | BC12: =TEXT(BD12,"0.00")&" ("&TEXT(BE12,"0.00")&")" -> 0.83 (0.01) | BD12: =AVERAGE(AX12:BB12) -> 0.83451327 | BE12: =+_xlfn.STDEV.S(AX12:BB12) -> 0.0050450243 | BG12: Evolved FSM 4 | BH12: =+VLOOKUP($BG12,INDIRECT(Adrese!B$2),8,FALSE) -> 0.073776871 | BI12: =+VLOOKUP($BG12,INDIRECT(Adrese!C$2),8,FALSE) -> 0.073636386 | BJ12: =+VLOOKUP($BG12,INDIRECT(Adrese!D$2),8,FALSE) -> 0.074642341 | BK12: =+VLOOKUP($BG12,INDIRECT(Adrese!E$2),8,FALSE) -> 0.074008515 | BL12: =+VLOOKUP($BG12,INDIRECT(Adrese!F$2),8,FALSE) -> 0.073980868 | BM12: =TEXT(BN12,"0.00")&" ("&TEXT(BO12,"0.00")&")" -> 0.07 (0.00) | BN12: =AVERAGE(BH12:BL12) -> 0.074008996 | BO12: =+_xlfn.STDEV.S(BH12:BL12) -> 0.00038556376 | BQ12: Evolved FSM 4 | BR12: =+VLOOKUP($BG12,INDIRECT(Adrese!B$2),9,FALSE) -> 0.066555901 | BS12: =+VLOOKUP($BG12,INDIRECT(Adrese!C$2),9,FALSE) -> 0.066318781 | BT12: =+VLOOKUP($BG12,INDIRECT(Adrese!D$2),9,FALSE) -> 0.067737164 | BU12: =+VLOOKUP($BG12,INDIRECT(Adrese!E$2),9,FALSE) -> 0.066920248 | BV12: =+VLOOKUP($BG12,INDIRECT(Adrese!F$2),9,FALSE) -> 0.066679811 | BW12: =TEXT(BX12,"0.00")&" ("&TEXT(BY12,"0.00")&")" -> 0.07 (0.00) | BX12: =AVERAGE(BR12:BV12) -> 0.066842381 | BY12: =+_xlfn.STDEV.S(BR12:BV12) -> 0.00054528813
A13: PSO Gambler 2_2_2 | B13: =+VLOOKUP($A13,INDIRECT(Adrese!B$2),2,FALSE) -> 11 | C13: =+VLOOKUP($A13,INDIRECT(Adrese!C$2),2,FALSE) -> 10 | D13: =+VLOOKUP($A13,INDIRECT(Adrese!D$2),2,FALSE) -> 10 | E13: =+VLOOKUP($A13,INDIRECT(Adrese!E$2),2,FALSE) -> 12 | F13: =+VLOOKUP($A13,INDIRECT(Adrese!F$2),2,FALSE) -> 12 | G13: =AVERAGE(B13:F13) -> 11 | H13: =+_xlfn.STDEV.S(B13:F13) -> 1 | J13: PSO Gambler 2_2_2 | K13: =+VLOOKUP($A13,INDIRECT(Adrese!B$2),3,FALSE) -> 44 | L13: =+VLOOKUP($A13,INDIRECT(Adrese!C$2),3,FALSE) -> 42 | M13: =+VLOOKUP($A13,INDIRECT(Adrese!D$2),3,FALSE) -> 42 | N13: =+VLOOKUP($A13,INDIRECT(Adrese!E$2),3,FALSE) -> 43 | O13: =+VLOOKUP($A13,INDIRECT(Adrese!F$2),3,FALSE) -> 42 | P13: =AVERAGE(K13:O13) -> 42.6 | Q13: =+_xlfn.STDEV.S(K13:O13) -> 0.89442719 | T13: PSO Gambler 2_2_2 | U13: =+VLOOKUP($T13,INDIRECT(Adrese!B$2),4,FALSE) -> 127313 | V13: =+VLOOKUP($T13,INDIRECT(Adrese!C$2),4,FALSE) -> 127869 | W13: =+VLOOKUP($T13,INDIRECT(Adrese!D$2),4,FALSE) -> 127626 | X13: =+VLOOKUP($T13,INDIRECT(Adrese!E$2),4,FALSE) -> 127164 | Y13: =+VLOOKUP($T13,INDIRECT(Adrese!F$2),4,FALSE) -> 126851 | Z13: =SUM(U13:Y13) -> 636823 | AA13: =AVERAGE(U13:Y13) -> 127364.6 | AB13: =+_xlfn.STDEV.S(U13:Y13) -> 396.68539 | AD13: PSO Gambler 2_2_2 | AE13: =+VLOOKUP($A13,INDIRECT(Adrese!B$2),5,FALSE) -> 31469 | AF13: =+VLOOKUP($A13,INDIRECT(Adrese!C$2),5,FALSE) -> 32187 | AG13: =+VLOOKUP($A13,INDIRECT(Adrese!D$2),5,FALSE) -> 31812 | AH13: =+VLOOKUP($A13,INDIRECT(Adrese!E$2),5,FALSE) -> 31707 | AI13: =+VLOOKUP($A13,INDIRECT(Adrese!F$2),5,FALSE) -> 31851 | AJ13: =AVERAGE(AE13:AI13) -> 31805.2 | AK13: =+_xlfn.STDEV.S(AE13:AI13) -> 260.09075 | AM13: PSO Gambler 2_2_2 | AN13: =+VLOOKUP($A13,INDIRECT(Adrese!B$2),6,FALSE) -> 0.69179204 | AO13: =+VLOOKUP($A13,INDIRECT(Adrese!C$2),6,FALSE) -> 0.70767699 | AP13: =+VLOOKUP($A13,INDIRECT(Adrese!D$2),6,FALSE) -> 0.69938053 | AQ13: =+VLOOKUP($A13,INDIRECT(Adrese!E$2),6,FALSE) -> 0.69705752 | AR13: =+VLOOKUP($A13,INDIRECT(Adrese!F$2),6,FALSE) -> 0.70024336 | AS13: =TEXT(AT13,"0.00")&" ("&TEXT(AU13,"0.00")&")" -> 0.70 (0.01) | AT13: =AVERAGE(AN13:AR13) -> 0.69923009 | AU13: =+_xlfn.STDEV.S(AN13:AR13) -> 0.0057542202 | AW13: PSO Gambler 2_2_2 | AX13: =+VLOOKUP($A13,INDIRECT(Adrese!B$2),7,FALSE) -> 0.80530973 | AY13: =+VLOOKUP($A13,INDIRECT(Adrese!C$2),7,FALSE) -> 0.81415929 | AZ13: =+VLOOKUP($A13,INDIRECT(Adrese!D$2),7,FALSE) -> 0.81415929 | BA13: =+VLOOKUP($A13,INDIRECT(Adrese!E$2),7,FALSE) -> 0.80973451 | BB13: =+VLOOKUP($A13,INDIRECT(Adrese!F$2),7,FALSE) -> 0.81415929 | BC13: =TEXT(BD13,"0.00")&" ("&TEXT(BE13,"0.00")&")" -> 0.81 (0.00) | BD13: =AVERAGE(AX13:BB13) -> 0.81150442 | BE13: =+_xlfn.STDEV.S(AX13:BB13) -> 0.0039576425 | BG13: PSO Gambler 2_2_2 | BH13: =+VLOOKUP($BG13,INDIRECT(Adrese!B$2),8,FALSE) -> 0.06969915 | BI13: =+VLOOKUP($BG13,INDIRECT(Adrese!C$2),8,FALSE) -> 0.07095259 | BJ13: =+VLOOKUP($BG13,INDIRECT(Adrese!D$2),8,FALSE) -> 0.070378176 | BK13: =+VLOOKUP($BG13,INDIRECT(Adrese!E$2),8,FALSE) -> 0.06991502 | BL13: =+VLOOKUP($BG13,INDIRECT(Adrese!F$2),8,FALSE) -> 0.070311967 | BM13: =TEXT(BN13,"0.00")&" ("&TEXT(BO13,"0.00")&")" -> 0.07 (0.00) | BN13: =AVERAGE(BH13:BL13) -> 0.070251381 | BO13: =+_xlfn.STDEV.S(BH13:BL13) -> 0.0004820632 | BQ13: PSO Gambler 2_2_2 | BR13: =+VLOOKUP($BG13,INDIRECT(Adrese!B$2),9,FALSE) -> 0.072303676 | BS13: =+VLOOKUP($BG13,INDIRECT(Adrese!C$2),9,FALSE) -> 0.07368738 | BT13: =+VLOOKUP($BG13,INDIRECT(Adrese!D$2),9,FALSE) -> 0.073180578 | BU13: =+VLOOKUP($BG13,INDIRECT(Adrese!E$2),9,FALSE) -> 0.071882014 | BV13: =+VLOOKUP($BG13,INDIRECT(Adrese!F$2),9,FALSE) -> 0.072435171 | BW13: =TEXT(BX13,"0.00")&" ("&TEXT(BY13,"0.00")&")" -> 0.07 (0.00) | BX13: =AVERAGE(BR13:BV13) -> 0.072697764 | BY13: =+_xlfn.STDEV.S(BR13:BV13) -> 0.00072494103
A14: PSO Gambler Mem1 | B14: =+VLOOKUP($A14,INDIRECT(Adrese!B$2),2,FALSE) -> 12 | C14: =+VLOOKUP($A14,INDIRECT(Adrese!C$2),2,FALSE) -> 14 | D14: =+VLOOKUP($A14,INDIRECT(Adrese!D$2),2,FALSE) -> 17 | E14: =+VLOOKUP($A14,INDIRECT(Adrese!E$2),2,FALSE) -> 10 | F14: =+VLOOKUP($A14,INDIRECT(Adrese!F$2),2,FALSE) -> 11 | G14: =AVERAGE(B14:F14) -> 12.8 | H14: =+_xlfn.STDEV.S(B14:F14) -> 2.7748874 | J14: PSO Gambler Mem1 | K14: =+VLOOKUP($A14,INDIRECT(Adrese!B$2),3,FALSE) -> 47 | L14: =+VLOOKUP($A14,INDIRECT(Adrese!C$2),3,FALSE) -> 45 | M14: =+VLOOKUP($A14,INDIRECT(Adrese!D$2),3,FALSE) -> 45 | N14: =+VLOOKUP($A14,INDIRECT(Adrese!E$2),3,FALSE) -> 49 | O14: =+VLOOKUP($A14,INDIRECT(Adrese!F$2),3,FALSE) -> 44 | P14: =AVERAGE(K14:O14) -> 46 | Q14: =+_xlfn.STDEV.S(K14:O14) -> 2 | T14: PSO Gambler Mem1 | U14: =+VLOOKUP($T14,INDIRECT(Adrese!B$2),4,FALSE) -> 127058 | V14: =+VLOOKUP($T14,INDIRECT(Adrese!C$2),4,FALSE) -> 126158 | W14: =+VLOOKUP($T14,INDIRECT(Adrese!D$2),4,FALSE) -> 125358 | X14: =+VLOOKUP($T14,INDIRECT(Adrese!E$2),4,FALSE) -> 127442 | Y14: =+VLOOKUP($T14,INDIRECT(Adrese!F$2),4,FALSE) -> 127268 | Z14: =SUM(U14:Y14) -> 633284 | AA14: =AVERAGE(U14:Y14) -> 126656.8 | AB14: =+_xlfn.STDEV.S(U14:Y14) -> 878.45728 | AD14: PSO Gambler Mem1 | AE14: =+VLOOKUP($A14,INDIRECT(Adrese!B$2),5,FALSE) -> 33395 | AF14: =+VLOOKUP($A14,INDIRECT(Adrese!C$2),5,FALSE) -> 32929 | AG14: =+VLOOKUP($A14,INDIRECT(Adrese!D$2),5,FALSE) -> 33670 | AH14: =+VLOOKUP($A14,INDIRECT(Adrese!E$2),5,FALSE) -> 33280 | AI14: =+VLOOKUP($A14,INDIRECT(Adrese!F$2),5,FALSE) -> 33869 | AJ14: =AVERAGE(AE14:AI14) -> 33428.6 | AK14: =+_xlfn.STDEV.S(AE14:AI14) -> 362.29725 | AM14: PSO Gambler Mem1 | AN14: =+VLOOKUP($A14,INDIRECT(Adrese!B$2),6,FALSE) -> 0.73440265 | AO14: =+VLOOKUP($A14,INDIRECT(Adrese!C$2),6,FALSE) -> 0.72409292 | AP14: =+VLOOKUP($A14,INDIRECT(Adrese!D$2),6,FALSE) -> 0.74048673 | AQ14: =+VLOOKUP($A14,INDIRECT(Adrese!E$2),6,FALSE) -> 0.73185841 | AR14: =+VLOOKUP($A14,INDIRECT(Adrese!F$2),6,FALSE) -> 0.74488938 | AS14: =TEXT(AT14,"0.00")&" ("&TEXT(AU14,"0.00")&")" -> 0.74 (0.01) | AT14: =AVERAGE(AN14:AR14) -> 0.73514602 | AU14: =+_xlfn.STDEV.S(AN14:AR14) -> 0.0080154263 | AW14: PSO Gambler Mem1 | AX14: =+VLOOKUP($A14,INDIRECT(Adrese!B$2),7,FALSE) -> 0.7920354 | AY14: =+VLOOKUP($A14,INDIRECT(Adrese!C$2),7,FALSE) -> 0.80088496 | AZ14: =+VLOOKUP($A14,INDIRECT(Adrese!D$2),7,FALSE) -> 0.80088496 | BA14: =+VLOOKUP($A14,INDIRECT(Adrese!E$2),7,FALSE) -> 0.78318584 | BB14: =+VLOOKUP($A14,INDIRECT(Adrese!F$2),7,FALSE) -> 0.80530974 | BC14: =TEXT(BD14,"0.00")&" ("&TEXT(BE14,"0.00")&")" -> 0.80 (0.01) | BD14: =AVERAGE(AX14:BB14) -> 0.79646018 | BE14: =+_xlfn.STDEV.S(AX14:BB14) -> 0.0088495576 | BG14: PSO Gambler Mem1 | BH14: =+VLOOKUP($BG14,INDIRECT(Adrese!B$2),8,FALSE) -> 0.07292655 | BI14: =+VLOOKUP($BG14,INDIRECT(Adrese!C$2),8,FALSE) -> 0.072447192 | BJ14: =+VLOOKUP($BG14,INDIRECT(Adrese!D$2),8,FALSE) -> 0.073943371 | BK14: =+VLOOKUP($BG14,INDIRECT(Adrese!E$2),8,FALSE) -> 0.072517922 | BL14: =+VLOOKUP($BG14,INDIRECT(Adrese!F$2),8,FALSE) -> 0.074195193 | BM14: =TEXT(BN14,"0.00")&" ("&TEXT(BO14,"0.00")&")" -> 0.07 (0.00) | BN14: =AVERAGE(BH14:BL14) -> 0.073206046 | BO14: =+_xlfn.STDEV.S(BH14:BL14) -> 0.00081387221 | BQ14: PSO Gambler Mem1 | BR14: =+VLOOKUP($BG14,INDIRECT(Adrese!B$2),9,FALSE) -> 0.074944551 | BS14: =+VLOOKUP($BG14,INDIRECT(Adrese!C$2),9,FALSE) -> 0.075699839 | BT14: =+VLOOKUP($BG14,INDIRECT(Adrese!D$2),9,FALSE) -> 0.077401133 | BU14: =+VLOOKUP($BG14,INDIRECT(Adrese!E$2),9,FALSE) -> 0.073702843 | BV14: =+VLOOKUP($BG14,INDIRECT(Adrese!F$2),9,FALSE) -> 0.077370648 | BW14: =TEXT(BX14,"0.00")&" ("&TEXT(BY14,"0.00")&")" -> 0.08 (0.00) | BX14: =AVERAGE(BR14:BV14) -> 0.075823803 | BY14: =+_xlfn.STDEV.S(BR14:BV14) -> 0.0015943354
... A229: Defector | B229: =+VLOOKUP($A229,INDIRECT(Adrese!B$2),2,FALSE) -> 227 | C229: =+VLOOKUP($A229,INDIRECT(Adrese!C$2),2,FALSE) -> 227 | D229: =+VLOOKUP($A229,INDIRECT(Adrese!D$2),2,FALSE) -> 226 | E229: =+VLOOKUP($A229,INDIRECT(Adrese!E$2),2,FALSE) -> 227 | F229: =+VLOOKUP($A229,INDIRECT(Adrese!F$2),2,FALSE) -> 226 | G229: =AVERAGE(B229:F229) -> 226.6 | H229: =+_xlfn.STDEV.S(B229:F229) -> 0.54772256 | J229: Defector | K229: =+VLOOKUP($A229,INDIRECT(Adrese!B$2),3,FALSE) -> 210 | L229: =+VLOOKUP($A229,INDIRECT(Adrese!C$2),3,FALSE) -> 211 | M229: =+VLOOKUP($A229,INDIRECT(Adrese!D$2),3,FALSE) -> 212 | N229: =+VLOOKUP($A229,INDIRECT(Adrese!E$2),3,FALSE) -> 211 | O229: =+VLOOKUP($A229,INDIRECT(Adrese!F$2),3,FALSE) -> 211 | P229: =AVERAGE(K229:O229) -> 211 | Q229: =+_xlfn.STDEV.S(K229:O229) -> 0.70710678 | T229: Defector | U229: =+VLOOKUP($T229,INDIRECT(Adrese!B$2),4,FALSE) -> 81060 | V229: =+VLOOKUP($T229,INDIRECT(Adrese!C$2),4,FALSE) -> 80712 | W229: =+VLOOKUP($T229,INDIRECT(Adrese!D$2),4,FALSE) -> 81684 | X229: =+VLOOKUP($T229,INDIRECT(Adrese!E$2),4,FALSE) -> 80668 | Y229: =+VLOOKUP($T229,INDIRECT(Adrese!F$2),4,FALSE) -> 81756 | Z229: =SUM(U229:Y229) -> 405880 | AA229: =AVERAGE(U229:Y229) -> 81176 | AB229: =+_xlfn.STDEV.S(U229:Y229) -> 519.92307 | AD229: Defector | AE229: =+VLOOKUP($A229,INDIRECT(Adrese!B$2),5,FALSE) -> 0 | AF229: =+VLOOKUP($A229,INDIRECT(Adrese!C$2),5,FALSE) -> 0 | AG229: =+VLOOKUP($A229,INDIRECT(Adrese!D$2),5,FALSE) -> 0 | AH229: =+VLOOKUP($A229,INDIRECT(Adrese!E$2),5,FALSE) -> 0 | AI229: =+VLOOKUP($A229,INDIRECT(Adrese!F$2),5,FALSE) -> 0 | AJ229: =AVERAGE(AE229:AI229) -> 0 | AK229: =+_xlfn.STDEV.S(AE229:AI229) -> 0 | AM229: Defector | AN229: =+VLOOKUP($A229,INDIRECT(Adrese!B$2),6,FALSE) -> 0 | AO229: =+VLOOKUP($A229,INDIRECT(Adrese!C$2),6,FALSE) -> 0 | AP229: =+VLOOKUP($A229,INDIRECT(Adrese!D$2),6,FALSE) -> 0 | AQ229: =+VLOOKUP($A229,INDIRECT(Adrese!E$2),6,FALSE) -> 0 | AR229: =+VLOOKUP($A229,INDIRECT(Adrese!F$2),6,FALSE) -> 0 | AS229: =TEXT(AT229,"0.00")&" ("&TEXT(AU229,"0.00")&")" -> 0.00 (0.00) | AT229: =AVERAGE(AN229:AR229) -> 0 | AU229: =+_xlfn.STDEV.S(AN229:AR229) -> 0 | AW229: Defector | AX229: =+VLOOKUP($A229,INDIRECT(Adrese!B$2),7,FALSE) -> 0.07079646 | AY229: =+VLOOKUP($A229,INDIRECT(Adrese!C$2),7,FALSE) -> 0.066371681 | AZ229: =+VLOOKUP($A229,INDIRECT(Adrese!D$2),7,FALSE) -> 0.061946903 | BA229: =+VLOOKUP($A229,INDIRECT(Adrese!E$2),7,FALSE) -> 0.066371681 | BB229: =+VLOOKUP($A229,INDIRECT(Adrese!F$2),7,FALSE) -> 0.066371681 | BC229: =TEXT(BD229,"0.00")&" ("&TEXT(BE229,"0.00")&")" -> 0.07 (0.00) | BD229: =AVERAGE(AX229:BB229) -> 0.066371681 | BE229: =+_xlfn.STDEV.S(AX229:BB229) -> 0.0031287909 | BG229: Defector | BH229: =+VLOOKUP($BG229,INDIRECT(Adrese!B$2),8,FALSE) -> 0 | BI229: =+VLOOKUP($BG229,INDIRECT(Adrese!C$2),8,FALSE) -> 0 | BJ229: =+VLOOKUP($BG229,INDIRECT(Adrese!D$2),8,FALSE) -> 0 | BK229: =+VLOOKUP($BG229,INDIRECT(Adrese!E$2),8,FALSE) -> 0 | BL229: =+VLOOKUP($BG229,INDIRECT(Adrese!F$2),8,FALSE) -> 0 | BM229: =TEXT(BN229,"0.00")&" ("&TEXT(BO229,"0.00")&")" -> 0.00 (0.00) | BN229: =AVERAGE(BH229:BL229) -> 0 | BO229: =+_xlfn.STDEV.S(BH229:BL229) -> 0 | BQ229: Defector | BR229: =+VLOOKUP($BG229,INDIRECT(Adrese!B$2),9,FALSE) -> -0.076727464 | BS229: =+VLOOKUP($BG229,INDIRECT(Adrese!C$2),9,FALSE) -> -0.076809085 | BT229: =+VLOOKUP($BG229,INDIRECT(Adrese!D$2),9,FALSE) -> -0.07652017 | BU229: =+VLOOKUP($BG229,INDIRECT(Adrese!E$2),9,FALSE) -> -0.076815119 | BV229: =+VLOOKUP($BG229,INDIRECT(Adrese!F$2),9,FALSE) -> -0.07693071 | BW229: =TEXT(BX229,"0.00")&" ("&TEXT(BY229,"0.00")&")" -> -0.08 (0.00) | BX229: =AVERAGE(BR229:BV229) -> -0.07676051 | BY229: =+_xlfn.STDEV.S(BR229:BV229) -> 0.00015261477

Sheet Svi
A1: Name | C1: #Wins | D1: TotalScore | E1: #Cooperations | F1: CooperationRating | G1: GoodPartnerRating | H1: EigenJesusRating | I1: EigenMosesRating
A2: Evolved FSM 6 | B2: 1 | C2: 39 | D2: 130681 | E2: 36331 | F2: 0.79935841 | G2: 0.82743363 | H2: 0.077202708 | I2: 0.076680846
A3: Fuzzy | B3: 2 | C3: 47 | D3: 130630 | E3: 34561 | F3: 0.76019912 | G3: 0.7920354 | H3: 0.074616941 | I3: 0.075916952
A4: EvolvedLookerUp2_2_2 | B4: 3 | C4: 46 | D4: 130248 | E4: 34404 | F4: 0.75672566 | G4: 0.79646018 | H4: 0.073698667 | I4: 0.072413107
A5: Evolved HMM 5 | B5: 4 | C5: 44 | D5: 129913 | E5: 34485 | F5: 0.7585177 | G5: 0.80530973 | H5: 0.074128798 | I5: 0.074430934
A6: Evolved FSM 16 | B6: 5 | C6: 62 | D6: 129208 | E6: 32767 | F6: 0.72050885 | G6: 0.72566372 | H6: 0.070108469 | I6: 0.066746666
A7: PSO Gambler 1_1_1 | B7: 6 | C7: 51 | D7: 128912 | E7: 32603 | F7: 0.71688053 | G7: 0.77433628 | H7: 0.072026931 | I7: 0.07575804
A8: Evolved FSM 16 Noise 05 | B8: 7 | C8: 48 | D8: 128227 | E8: 33058 | F8: 0.7269469 | G8: 0.78761062 | H8: 0.073902367 | I8: 0.080896687
A9: Evolved ANN | B9: 8 | C9: 46 | D9: 128023 | E9: 33186 | F9: 0.72977876 | G9: 0.79646018 | H9: 0.07512316 | I9: 0.085277743
A10: Evolved ANN 5 | B10: 9 | C10: 42 | D10: 127587 | E10: 33011 | F10: 0.72590708 | G10: 0.81415929 | H10: 0.074337678 | I10: 0.08333406
A11: Evolved FSM 4 | B11: 10 | C11: 37 | D11: 127572 | E11: 35631 | F11: 0.78387168 | G11: 0.83628319 | H11: 0.073776871 | I11: 0.066555901
A12: PSO Gambler 2_2_2 | B12: 11 | C12: 44 | D12: 127313 | E12: 31469 | F12: 0.69179204 | G12: 0.80530973 | H12: 0.06969915 | I12: 0.072303676
A13: PSO Gambler Mem1 | B13: 12 | C13: 47 | D13: 127058 | E13: 33395 | F13: 0.73440265 | G13: 0.7920354 | H13: 0.07292655 | I13: 0.074944551
... A228: Defector | B228: 227 | C228: 210 | D228: 81060 | E228: 0 | F228: 0 | G228: 0.07079646 | H228: 0 | I228: -0.076727464
A230: Name | C230: #Wins | D230: TotalScore | E230: #Cooperations | F230: CooperationRating | G230: GoodPartnerRating | H230: EigenJesusRating | I230: EigenMosesRating
A231: Evolved FSM 6 | B231: 1 | C231: 40 | D231: 130763 | E231: 36067 | F231: 0.7935177 | G231: 0.82300885 | H231: 0.076545565 | I231: 0.075418539
A232: EvolvedLookerUp2_2_2 | B232: 2 | C232: 50 | D232: 130131 | E232: 33876 | F232: 0.74504425 | G232: 0.77876106 | H232: 0.072603384 | I232: 0.070961915
A233: Fuzzy | B233: 3 | C233: 50 | D233: 129322 | E233: 33658 | F233: 0.74022124 | G233: 0.77876106 | H233: 0.072782783 | I233: 0.073557862
A234: Evolved HMM 5 | B234: 4 | C234: 48 | D234: 129306 | E234: 34017 | F234: 0.74816372 | G234: 0.78761062 | H234: 0.073469565 | I234: 0.074426252
A235: Evolved ANN | B235: 5 | C235: 45 | D235: 128831 | E235: 33556 | F235: 0.7379646 | G235: 0.80088496 | H235: 0.075586355 | I235: 0.085409572
A236: Evolved FSM 16 | B236: 6 | C236: 62 | D236: 128662 | E236: 32811 | F236: 0.7214823 | G236: 0.72566372 | H236: 0.070181328 | I236: 0.066772286
A237: Evolved FSM 16 Noise 05 | B237: 7 | C237: 43 | D237: 128404 | E237: 33140 | F237: 0.72876106 | G237: 0.80973451 | H237: 0.073995285 | I237: 0.08126278
A238: PSO Gambler 1_1_1 | B238: 8 | C238: 52 | D238: 128370 | E238: 32789 | F238: 0.72099557 | G238: 0.7699115 | H238: 0.072270271 | I238: 0.075995524
A239: Evolved ANN 5 | B239: 9 | C239: 44 | D239: 128307 | E239: 33118 | F239: 0.72827434 | G239: 0.80530974 | H239: 0.074674702 | I239: 0.084279284
A240: PSO Gambler 2_2_2 | B240: 10 | C240: 42 | D240: 127869 | E240: 32187 | F240: 0.70767699 | G240: 0.81415929 | H240: 0.07095259 | I240: 0.07368738
A241: Evolved FSM 4 | B241: 11 | C241: 38 | D241: 127184 | E241: 35594 | F241: 0.7830531 | G241: 0.83185841 | H241: 0.073636386 | I241: 0.066318781
A242: Omega TFT | B242: 12 | C242: 38 | D242: 126691 | E242: 33572 | F242: 0.73831858 | G242: 0.83185841 | H242: 0.076232358 | I242: 0.087387166
... A457: Defector | B457: 227 | C457: 211 | D457: 80712 | E457: 0 | F457: 0 | G457: 0.066371681 | H457: 0 | I457: -0.076809085
A459: Name | C459: #Wins | D459: TotalScore | E459: #Cooperations | F459: CooperationRating | G459: GoodPartnerRating | H459: EigenJesusRating | I459: EigenMosesRating
A460: EvolvedLookerUp2_2_2 | B460: 1 | C460: 49 | D460: 130631 | E460: 34206 | F460: 0.75234513 | G460: 0.78318584 | H460: 0.073274058 | I460: 0.07146657
A461: Fuzzy | B461: 2 | C461: 47 | D461: 130591 | E461: 34055 | F461: 0.74900442 | G461: 0.7920354 | H461: 0.07337504 | I461: 0.073468015
A462: Evolved FSM 6 | B462: 3 | C462: 38 | D462: 130318 | E462: 36177 | F462: 0.79595133 | G462: 0.83185841 | H462: 0.076963271 | I462: 0.076136473
A463: Evolved FSM 16 | B463: 4 | C463: 64 | D463: 129190 | E463: 32718 | F463: 0.71942478 | G463: 0.71681416 | H463: 0.07009061 | I463: 0.066757733
A464: Evolved HMM 5 | B464: 5 | C464: 44 | D464: 128469 | E464: 34437 | F464: 0.75745575 | G464: 0.80530974 | H464: 0.074360905 | I464: 0.075455245
A465: Evolved ANN | B465: 6 | C465: 45 | D465: 128090 | E465: 33418 | F465: 0.7349115 | G465: 0.80088496 | H465: 0.075509794 | I465: 0.085572882
A466: Evolved FSM 16 Noise 05 | B466: 7 | C466: 46 | D466: 127970 | E466: 33086 | F466: 0.72756637 | G466: 0.79646018 | H466: 0.07390397 | I466: 0.080677698
A467: PSO Gambler 1_1_1 | B467: 8 | C467: 51 | D467: 127740 | E467: 32092 | F467: 0.70557522 | G467: 0.77433628 | H467: 0.071261197 | I467: 0.07481221
A468: Evolved FSM 4 | B468: 9 | C468: 37 | D468: 127689 | E468: 36014 | F468: 0.79234513 | G468: 0.83628319 | H468: 0.074642341 | I468: 0.067737164
A469: PSO Gambler 2_2_2 | B469: 10 | C469: 42 | D469: 127626 | E469: 31812 | F469: 0.69938053 | G469: 0.81415929 | H469: 0.070378176 | I469: 0.073180578
A470: Evolved ANN 5 | B470: 11 | C470: 42 | D470: 127363 | E470: 32859 | F470: 0.72254425 | G470: 0.81415929 | H470: 0.074189344 | I470: 0.083349243
...

Sheet Adrese
B1: 1 | C1: 2 | D1: 3 | E1: 4 | F1: 5
B2: Svi!$A$2:$I$228 | C2: Svi!$A$231:$I$457 | D2: Svi!$A$460:$I$686 | E2: Svi!$A$689:$I$915 | F2: Svi!$A$918:$I$1144

Sheet Final
C3: Rank | D3: Avg. Score | E3: TotalScore | F3: #Wins | G3: #Cooperations | H3: Cooperation Rating | I3: Good Partner Rating | J3: Eigenjesus Rating | K3: Eigenmoses Rating
