Workbook

Sheet FINAL FINAL
C2: Results | E2: Morality metrics
B3: Name | C3: Avg. Score | D3: Wins (%) | E3: Cooperation Rating | F3: Good Partner Rating | G3: Eigenjesus Rating | H3: Eigenmoses Rating
B4: Evolved ANN 5 Noise 05 | C4: =VLOOKUP(B4,Kompilirano!T:Z,7,FALSE)/226/5 -> 472.29823 | D4: =VLOOKUP(B4,Kompilirano!J:P,7,FALSE)/226/5 -> 0.56637168 | E4: =VLOOKUP(B4,Kompilirano!AM:AS,7,FALSE) -> 0.44 (0.01) | F4: =VLOOKUP(B4,Kompilirano!AW:BD,7,FALSE) -> 0.43 (0.01) | G4: =VLOOKUP(B4,Kompilirano!BG:BM,7,FALSE) -> 0.07 (0.00) | H4: =VLOOKUP(B4,Kompilirano!BQ:BW,7,FALSE) -> 0.03 (0.01)
B5: Fuzzy | C5: =VLOOKUP(B5,Kompilirano!T:Z,7,FALSE)/226/5 -> 465.89115 | D5: =VLOOKUP(B5,Kompilirano!J:P,7,FALSE)/226/5 -> 0.39469027 | E5: =VLOOKUP(B5,Kompilirano!AM:AS,7,FALSE) -> 0.47 (0.01) | F5: =VLOOKUP(B5,Kompilirano!AW:BD,7,FALSE) -> 0.61 (0.03) | G5: =VLOOKUP(B5,Kompilirano!BG:BM,7,FALSE) -> 0.06 (0.00) | H5: =VLOOKUP(B5,Kompilirano!BQ:BW,7,FALSE) -> -0.04 (0.01)
B6: Revised Downing | C6: =VLOOKUP(B6,Kompilirano!T:Z,7,FALSE)/226/5 -> 463.28761 | D6: =VLOOKUP(B6,Kompilirano!J:P,7,FALSE)/226/5 -> 0.5619469 | E6: =VLOOKUP(B6,Kompilirano!AM:AS,7,FALSE) -> 0.34 (0.01) | F6: =VLOOKUP(B6,Kompilirano!AW:BD,7,FALSE) -> 0.44 (0.01) | G6: =VLOOKUP(B6,Kompilirano!BG:BM,7,FALSE) -> 0.04 (0.00) | H6: =VLOOKUP(B6,Kompilirano!BQ:BW,7,FALSE) -> 0.00 (0.00)
B7: Second by RichardHufford | C7: =VLOOKUP(B7,Kompilirano!T:Z,7,FALSE)/226/5 -> 461.09204 | D7: =VLOOKUP(B7,Kompilirano!J:P,7,FALSE)/226/5 -> 0.54867257 | E7: =VLOOKUP(B7,Kompilirano!AM:AS,7,FALSE) -> 0.34 (0.01) | F7: =VLOOKUP(B7,Kompilirano!AW:BD,7,FALSE) -> 0.45 (0.01) | G7: =VLOOKUP(B7,Kompilirano!BG:BM,7,FALSE) -> 0.05 (0.00) | H7: =VLOOKUP(B7,Kompilirano!BQ:BW,7,FALSE) -> 0.03 (0.00)
B8: First by Downing | C8: =VLOOKUP(B8,Kompilirano!T:Z,7,FALSE)/226/5 -> 459.20354 | D8: =VLOOKUP(B8,Kompilirano!J:P,7,FALSE)/226/5 -> 0.62123894 | E8: =VLOOKUP(B8,Kompilirano!AM:AS,7,FALSE) -> 0.30 (0.01) | F8: =VLOOKUP(B8,Kompilirano!AW:BD,7,FALSE) -> 0.38 (0.02) | G8: =VLOOKUP(B8,Kompilirano!BG:BM,7,FALSE) -> 0.04 (0.00) | H8: =VLOOKUP(B8,Kompilirano!BQ:BW,7,FALSE) -> 0.02 (0.00)
B9: Evolved FSM 16 Noise 05 | C9: =VLOOKUP(B9,Kompilirano!T:Z,7,FALSE)/226/5 -> 451.51504 | D9: =VLOOKUP(B9,Kompilirano!J:P,7,FALSE)/226/5 -> 0.47079646 | E9: =VLOOKUP(B9,Kompilirano!AM:AS,7,FALSE) -> 0.38 (0.01) | F9: =VLOOKUP(B9,Kompilirano!AW:BD,7,FALSE) -> 0.53 (0.02) | G9: =VLOOKUP(B9,Kompilirano!BG:BM,7,FALSE) -> 0.05 (0.00) | H9: =VLOOKUP(B9,Kompilirano!BQ:BW,7,FALSE) -> 0.02 (0.00)
B10: Evolved ANN | C10: =VLOOKUP(B10,Kompilirano!T:Z,7,FALSE)/226/5 -> 451.32035 | D10: =VLOOKUP(B10,Kompilirano!J:P,7,FALSE)/226/5 -> 0.78318584 | E10: =VLOOKUP(B10,Kompilirano!AM:AS,7,FALSE) -> 0.27 (0.01) | F10: =VLOOKUP(B10,Kompilirano!AW:BD,7,FALSE) -> 0.22 (0.01) | G10: =VLOOKUP(B10,Kompilirano!BG:BM,7,FALSE) -> 0.04 (0.00) | H10: =VLOOKUP(B10,Kompilirano!BQ:BW,7,FALSE) -> 0.07 (0.00)
B11: Second by Mikkelson | C11: =VLOOKUP(B11,Kompilirano!T:Z,7,FALSE)/226/5 -> 450.29469 | D11: =VLOOKUP(B11,Kompilirano!J:P,7,FALSE)/226/5 -> 0.46283186 | E11: =VLOOKUP(B11,Kompilirano!AM:AS,7,FALSE) -> 0.50 (0.01) | F11: =VLOOKUP(B11,Kompilirano!AW:BD,7,FALSE) -> 0.54 (0.04) | G11: =VLOOKUP(B11,Kompilirano!BG:BM,7,FALSE) -> 0.08 (0.00) | H11: =VLOOKUP(B11,Kompilirano!BQ:BW,7,FALSE) -> 0.05 (0.00)
B12: Second by Borufsen | C12: =VLOOKUP(B12,Kompilirano!T:Z,7,FALSE)/226/5 -> 449.17257 | D12: =VLOOKUP(B12,Kompilirano!J:P,7,FALSE)/226/5 -> 0.48141593 | E12: =VLOOKUP(B12,Kompilirano!AM:AS,7,FALSE) -> 0.49 (0.01) | F12: =VLOOKUP(B12,Kompilirano!AW:BD,7,FALSE) -> 0.52 (0.01) | G12: =VLOOKUP(B12,Kompilirano!BG:BM,7,FALSE) -> 0.07 (0.00) | H12: =VLOOKUP(B12,Kompilirano!BQ:BW,7,FALSE) -> 0.04 (0.00)
B13: Second by Rowsam | C13: =VLOOKUP(B13,Kompilirano!T:Z,7,FALSE)/226/5 -> 449.06637 | D13: =VLOOKUP(B13,Kompilirano!J:P,7,FALSE)/226/5 -> 0.50530973 | E13: =VLOOKUP(B13,Kompilirano!AM:AS,7,FALSE) -> 0.43 (0.01) | F13: =VLOOKUP(B13,Kompilirano!AW:BD,7,FALSE) -> 0.49 (0.01) | G13: =VLOOKUP(B13,Kompilirano!BG:BM,7,FALSE) -> 0.07 (0.00) | H13: =VLOOKUP(B13,Kompilirano!BQ:BW,7,FALSE) -> 0.05 (0.01)
B14: Omega TFT | C14: =VLOOKUP(B14,Kompilirano!T:Z,7,FALSE)/226/5 -> 448.26195 | D14: =VLOOKUP(B14,Kompilirano!J:P,7,FALSE)/226/5 -> 0.8380531 | E14: =VLOOKUP(B14,Kompilirano!AM:AS,7,FALSE) -> 0.30 (0.01) | F14: =VLOOKUP(B14,Kompilirano!AW:BD,7,FALSE) -> 0.16 (0.01) | G14: =VLOOKUP(B14,Kompilirano!BG:BM,7,FALSE) -> 0.05 (0.00) | H14: =VLOOKUP(B14,Kompilirano!BQ:BW,7,FALSE) -> 0.09 (0.00)
B15: DoubleCrosser | C15: =VLOOKUP(B15,Kompilirano!T:Z,7,FALSE)/226/5 -> 447.68496 | D15: =VLOOKUP(B15,Kompilirano!J:P,7,FALSE)/226/5 -> 0.71238938 | E15: =VLOOKUP(B15,Kompilirano!AM:AS,7,FALSE) -> 0.29 (0.00) | F15: =VLOOKUP(B15,Kompilirano!AW:BD,7,FALSE) -> 0.29 (0.01) | G15: =VLOOKUP(B15,Kompilirano!BG:BM,7,FALSE) -> 0.04 (0.00) | H15: =VLOOKUP(B15,Kompilirano!BQ:BW,7,FALSE) -> 0.06 (0.00)
... B230: EasyGo | C230: =VLOOKUP(B230,Kompilirano!T:Z,7,FALSE)/226/5 -> 378.77965 | D230: =VLOOKUP(B230,Kompilirano!J:P,7,FALSE)/226/5 -> 0.084955752 | E230: =VLOOKUP(B230,Kompilirano!AM:AS,7,FALSE) -> 0.89 (0.00) | F230: =VLOOKUP(B230,Kompilirano!AW:BD,7,FALSE) -> 0.92 (0.01) | G230: =VLOOKUP(B230,Kompilirano!BG:BM,7,FALSE) -> 0.11 (0.00) | H230: =VLOOKUP(B230,Kompilirano!BQ:BW,7,FALSE) -> -0.09 (0.00)

Sheet Kompilirano
A2: Name | B2: Rank 1 | C2: Rank 2 | D2: Rank 3 | E2: Rank 4 | F2: Rank 5 | G2: Avg | J2: Name | K2: Wins 1 | L2: Wins 2 | M2: Wins 3 | N2: Wins 4 | O2: Wins 5 | Q2: Avg | T2: Name | U2: Total Score 1 | V2: Total Score 2 | W2: Total Score 3 | X2: Total Score 4 | Y2: Total Score 5 | AA2: Avg | AC2: Name | AD2: #Cooperations 1 | AE2: #Cooperations 2 | AF2: #Cooperations 3 | AG2: #Cooperations 4 | AH2: #Cooperations 5 | AI2: Avg | AM2: Name | AN2: CoopRating 1 | AO2: CoopRating 2 | AP2: CoopRating 3 | AQ2: CoopRating 4 | AR2: CoopRating 5 | AT2: Avg | AU2: SD | AW2: Name | AX2: GP Rating 1 | AY2: GP Rating 2 | AZ2: GP Rating 3 | BA2: GP Rating 4 | BB2: GP Rating 5 | BD2: Avg | BG2: Name | BH2: EJ Rating 1 | BI2: EJ Rating 2 | BJ2: EJ Rating 3 | BK2: EJ Rating 4 | BL2: EJ Rating 5 | BN2: Avg | BQ2: Name | BR2: EM Rating 1 | BS2: EM Rating 2 | BT2: EM Rating 3 | BU2: EM Rating 4 | BV2: EM Rating 5 | BX2: Avg | BY2: SD
A3: Evolved FSM 6 | B3: =+VLOOKUP($A3,INDIRECT(Adrese!B$2),2,FALSE) -> 32 | C3: =+VLOOKUP($A3,INDIRECT(Adrese!C$2),2,FALSE) -> 23 | D3: =+VLOOKUP($A3,INDIRECT(Adrese!D$2),2,FALSE) -> 18 | E3: =+VLOOKUP($A3,INDIRECT(Adrese!E$2),2,FALSE) -> 16 | F3: =+VLOOKUP($A3,INDIRECT(Adrese!F$2),2,FALSE) -> 31 | G3: =AVERAGE(B3:F3) -> 24 | J3: Evolved FSM 6 | K3: =+VLOOKUP($A3,INDIRECT(Adrese!B$2),3,FALSE) -> 94 | L3: =+VLOOKUP($A3,INDIRECT(Adrese!C$2),3,FALSE) -> 97 | M3: =+VLOOKUP($A3,INDIRECT(Adrese!D$2),3,FALSE) -> 94 | N3: =+VLOOKUP($A3,INDIRECT(Adrese!E$2),3,FALSE) -> 103 | O3: =+VLOOKUP($A3,INDIRECT(Adrese!F$2),3,FALSE) -> 101 | P3: =SUM(K3:O3) -> 489 | Q3: =AVERAGE(K3:O3) -> 97.8 | T3: Evolved FSM 6 | U3: =+VLOOKUP($T3,INDIRECT(Adrese!B$2),4,FALSE) -> 98491 | V3: =+VLOOKUP($T3,INDIRECT(Adrese!C$2),4,FALSE) -> 99693 | W3: =+VLOOKUP($T3,INDIRECT(Adrese!D$2),4,FALSE) -> 100303 | X3: =+VLOOKUP($T3,INDIRECT(Adrese!E$2),4,FALSE) -> 100568 | Y3: =+VLOOKUP($T3,INDIRECT(Adrese!F$2),4,FALSE) -> 98948 | Z3: =SUM(U3:Y3) -> 498003 | AA3: =AVERAGE(U3:Y3) -> 99600.6 | AC3: Evolved FSM 6 | AD3: =+VLOOKUP($A3,INDIRECT(Adrese!B$2),5,FALSE) -> 18653 | AE3: =+VLOOKUP($A3,INDIRECT(Adrese!C$2),5,FALSE) -> 18834 | AF3: =+VLOOKUP($A3,INDIRECT(Adrese!D$2),5,FALSE) -> 18467 | AG3: =+VLOOKUP($A3,INDIRECT(Adrese!E$2),5,FALSE) -> 19073 | AH3: =+VLOOKUP($A3,INDIRECT(Adrese!F$2),5,FALSE) -> 19076 | AI3: =AVERAGE(AD3:AH3) -> 18820.6 | AM3: Evolved FSM 6 | AN3: =+VLOOKUP($A3,INDIRECT(Adrese!B$2),6,FALSE) -> 0.41037611 | AO3: =+VLOOKUP($A3,INDIRECT(Adrese!C$2),6,FALSE) -> 0.41442478 | AP3: =+VLOOKUP($A3,INDIRECT(Adrese!D$2),6,FALSE) -> 0.40688053 | AQ3: =+VLOOKUP($A3,INDIRECT(Adrese!E$2),6,FALSE) -> 0.41973451 | AR3: =+VLOOKUP($A3,INDIRECT(Adrese!F$2),6,FALSE) -> 0.41975664 | AS3: =TEXT(AT3,"0.00")&" ("&TEXT(AU3,"0.00")&")" -> 0.41 (0.01) | AT3: =AVERAGE(AN3:AR3) -> 0.41423451 | AU3: =_xlfn.STDEV.S(AN3:AR3) -> 0.0056953581 | AW3: Evolved FSM 6 | AX3: =+VLOOKUP($A3,INDIRECT(Adrese!B$2),7,FALSE) -> 0.5840708 | AY3: =+VLOOKUP($A3,INDIRECT(Adrese!C$2),7,FALSE) -> 0.57079646 | AZ3: =+VLOOKUP($A3,INDIRECT(Adrese!D$2),7,FALSE) -> 0.5840708 | BA3: =+VLOOKUP($A3,INDIRECT(Adrese!E$2),7,FALSE) -> 0.54424779 | BB3: =+VLOOKUP($A3,INDIRECT(Adrese!F$2),7,FALSE) -> 0.55309735 | BC3: =TEXT(BD3,"0.00")&" ("&TEXT(BE3,"0.00")&")" -> 0.57 (0.02) | BD3: =AVERAGE(AX3:BB3) -> 0.56725664 | BE3: =_xlfn.STDEV.S(AX3:BB3) -> 0.018082139 | BG3: Evolved FSM 6 | BH3: =+VLOOKUP($BG3,INDIRECT(Adrese!B$2),8,FALSE) -> 0.054178715 | BI3: =+VLOOKUP($BG3,INDIRECT(Adrese!C$2),8,FALSE) -> 0.054534917 | BJ3: =+VLOOKUP($BG3,INDIRECT(Adrese!D$2),8,FALSE) -> 0.053309972 | BK3: =+VLOOKUP($BG3,INDIRECT(Adrese!E$2),8,FALSE) -> 0.055244059 | BL3: =+VLOOKUP($BG3,INDIRECT(Adrese!F$2),8,FALSE) -> 0.054947224 | BM3: =TEXT(BN3,"0.00")&" ("&TEXT(BO3,"0.00")&")" -> 0.05 (0.00) | BN3: =AVERAGE(BH3:BL3) -> 0.054442977 | BO3: =_xlfn.STDEV.S(BH3:BL3) -> 0.00075132968 | BQ3: Evolved FSM 6 | BR3: =+VLOOKUP($BG3,INDIRECT(Adrese!B$2),9,FALSE) -> 0.016093678 | BS3: =+VLOOKUP($BG3,INDIRECT(Adrese!C$2),9,FALSE) -> 0.013274467 | BT3: =+VLOOKUP($BG3,INDIRECT(Adrese!D$2),9,FALSE) -> 0.013747513 | BU3: =+VLOOKUP($BG3,INDIRECT(Adrese!E$2),9,FALSE) -> 0.011887597 | BV3: =+VLOOKUP($BG3,INDIRECT(Adrese!F$2),9,FALSE) -> 0.011977203 | BW3: =TEXT(BX3,"0.00")&" ("&TEXT(BY3,"0.00")&")" -> 0.01 (0.00) | BX3: =AVERAGE(BR3:BV3) -> 0.013396092 | BY3: =_xlfn.STDEV.S(BR3:BV3) -> 0.0017105599
A4: Fuzzy | B4: =+VLOOKUP($A4,INDIRECT(Adrese!B$2),2,FALSE) -> 1 | C4: =+VLOOKUP($A4,INDIRECT(Adrese!C$2),2,FALSE) -> 3 | D4: =+VLOOKUP($A4,INDIRECT(Adrese!D$2),2,FALSE) -> 5 | E4: =+VLOOKUP($A4,INDIRECT(Adrese!E$2),2,FALSE) -> 2 | F4: =+VLOOKUP($A4,INDIRECT(Adrese!F$2),2,FALSE) -> 2 | G4: =AVERAGE(B4:F4) -> 2.6 | J4: Fuzzy | K4: =+VLOOKUP($A4,INDIRECT(Adrese!B$2),3,FALSE) -> 87 | L4: =+VLOOKUP($A4,INDIRECT(Adrese!C$2),3,FALSE) -> 94 | M4: =+VLOOKUP($A4,INDIRECT(Adrese!D$2),3,FALSE) -> 80 | N4: =+VLOOKUP($A4,INDIRECT(Adrese!E$2),3,FALSE) -> 94 | O4: =+VLOOKUP($A4,INDIRECT(Adrese!F$2),3,FALSE) -> 91 | P4: =SUM(K4:O4) -> 446 | Q4: =AVERAGE(K4:O4) -> 89.2 | T4: Fuzzy | U4: =+VLOOKUP($T4,INDIRECT(Adrese!B$2),4,FALSE) -> 105874 | V4: =+VLOOKUP($T4,INDIRECT(Adrese!C$2),4,FALSE) -> 104388 | W4: =+VLOOKUP($T4,INDIRECT(Adrese!D$2),4,FALSE) -> 104317 | X4: =+VLOOKUP($T4,INDIRECT(Adrese!E$2),4,FALSE) -> 106256 | Y4: =+VLOOKUP($T4,INDIRECT(Adrese!F$2),4,FALSE) -> 105622 | Z4: =SUM(U4:Y4) -> 526457 | AA4: =AVERAGE(U4:Y4) -> 105291.4 | AC4: Fuzzy | AD4: =+VLOOKUP($A4,INDIRECT(Adrese!B$2),5,FALSE) -> 21631 | AE4: =+VLOOKUP($A4,INDIRECT(Adrese!C$2),5,FALSE) -> 21162 | AF4: =+VLOOKUP($A4,INDIRECT(Adrese!D$2),5,FALSE) -> 21987 | AG4: =+VLOOKUP($A4,INDIRECT(Adrese!E$2),5,FALSE) -> 20920 | AH4: =+VLOOKUP($A4,INDIRECT(Adrese!F$2),5,FALSE) -> 22063 | AI4: =AVERAGE(AD4:AH4) -> 21552.6 | AM4: Fuzzy | AN4: =+VLOOKUP($A4,INDIRECT(Adrese!B$2),6,FALSE) -> 0.4765708 | AO4: =+VLOOKUP($A4,INDIRECT(Adrese!C$2),6,FALSE) -> 0.46553097 | AP4: =+VLOOKUP($A4,INDIRECT(Adrese!D$2),6,FALSE) -> 0.48340708 | AQ4: =+VLOOKUP($A4,INDIRECT(Adrese!E$2),6,FALSE) -> 0.45946903 | AR4: =+VLOOKUP($A4,INDIRECT(Adrese!F$2),6,FALSE) -> 0.48464602 | AS4: =TEXT(AT4,"0.00")&" ("&TEXT(AU4,"0.00")&")" -> 0.47 (0.01) | AT4: =AVERAGE(AN4:AR4) -> 0.47392478 | AU4: =_xlfn.STDEV.S(AN4:AR4) -> 0.011082477 | AW4: Fuzzy | AX4: =+VLOOKUP($A4,INDIRECT(Adrese!B$2),7,FALSE) -> 0.61504425 | AY4: =+VLOOKUP($A4,INDIRECT(Adrese!C$2),7,FALSE) -> 0.5840708 | AZ4: =+VLOOKUP($A4,INDIRECT(Adrese!D$2),7,FALSE) -> 0.6460177 | BA4: =+VLOOKUP($A4,INDIRECT(Adrese!E$2),7,FALSE) -> 0.5840708 | BB4: =+VLOOKUP($A4,INDIRECT(Adrese!F$2),7,FALSE) -> 0.59734513 | BC4: =TEXT(BD4,"0.00")&" ("&TEXT(BE4,"0.00")&")" -> 0.61 (0.03) | BD4: =AVERAGE(AX4:BB4) -> 0.60530973 | BE4: =_xlfn.STDEV.S(AX4:BB4) -> 0.026064914 | BG4: Fuzzy | BH4: =+VLOOKUP($BG4,INDIRECT(Adrese!B$2),8,FALSE) -> 0.060113026 | BI4: =+VLOOKUP($BG4,INDIRECT(Adrese!C$2),8,FALSE) -> 0.059590928 | BJ4: =+VLOOKUP($BG4,INDIRECT(Adrese!D$2),8,FALSE) -> 0.061123639 | BK4: =+VLOOKUP($BG4,INDIRECT(Adrese!E$2),8,FALSE) -> 0.05841857 | BL4: =+VLOOKUP($BG4,INDIRECT(Adrese!F$2),8,FALSE) -> 0.059850545 | BM4: =TEXT(BN4,"0.00")&" ("&TEXT(BO4,"0.00")&")" -> 0.06 (0.00) | BN4: =AVERAGE(BH4:BL4) -> 0.059819341 | BO4: =_xlfn.STDEV.S(BH4:BL4) -> 0.00097503176 | BQ4: Fuzzy | BR4: =+VLOOKUP($BG4,INDIRECT(Adrese!B$2),9,FALSE) -> -0.042943409 | BS4: =+VLOOKUP($BG4,INDIRECT(Adrese!C$2),9,FALSE) -> -0.036062513 | BT4: =+VLOOKUP($BG4,INDIRECT(Adrese!D$2),9,FALSE) -> -0.045176397 | BU4: =+VLOOKUP($BG4,INDIRECT(Adrese!E$2),9,FALSE) -> -0.044976746 | BV4: =+VLOOKUP($BG4,INDIRECT(Adrese!F$2),9,FALSE) -> -0.051672978 | BW4: =TEXT(BX4,"0.00")&" ("&TEXT(BY4,"0.00")&")" -> -0.04 (0.01) | BX4: =AVERAGE(BR4:BV4) -> -0.044166409 | BY4: =_xlfn.STDEV.S(BR4:BV4) -> 0.0055945097
A5: EvolvedLookerUp2_2_2 | B5: =+VLOOKUP($A5,INDIRECT(Adrese!B$2),2,FALSE) -> 160 | C5: =+VLOOKUP($A5,INDIRECT(Adrese!C$2),2,FALSE) -> 129 | D5: =+VLOOKUP($A5,INDIRECT(Adrese!D$2),2,FALSE) -> 165 | E5: =+VLOOKUP($A5,INDIRECT(Adrese!E$2),2,FALSE) -> 128 | F5: =+VLOOKUP($A5,INDIRECT(Adrese!F$2),2,FALSE) -> 156 | G5: =AVERAGE(B5:F5) -> 147.6 | J5: EvolvedLookerUp2_2_2 | K5: =+VLOOKUP($A5,INDIRECT(Adrese!B$2),3,FALSE) -> 91 | L5: =+VLOOKUP($A5,INDIRECT(Adrese!C$2),3,FALSE) -> 90 | M5: =+VLOOKUP($A5,INDIRECT(Adrese!D$2),3,FALSE) -> 89 | N5: =+VLOOKUP($A5,INDIRECT(Adrese!E$2),3,FALSE) -> 93 | O5: =+VLOOKUP($A5,INDIRECT(Adrese!F$2),3,FALSE) -> 92 | P5: =SUM(K5:O5) -> 455 | Q5: =AVERAGE(K5:O5) -> 91 | T5: EvolvedLookerUp2_2_2 | U5: =+VLOOKUP($T5,INDIRECT(Adrese!B$2),4,FALSE) -> 92860 | V5: =+VLOOKUP($T5,INDIRECT(Adrese!C$2),4,FALSE) -> 94391 | W5: =+VLOOKUP($T5,INDIRECT(Adrese!D$2),4,FALSE) -> 92020 | X5: =+VLOOKUP($T5,INDIRECT(Adrese!E$2),4,FALSE) -> 94433 | Y5: =+VLOOKUP($T5,INDIRECT(Adrese!F$2),4,FALSE) -> 93278 | Z5: =SUM(U5:Y5) -> 466982 | AA5: =AVERAGE(U5:Y5) -> 93396.4 | AC5: EvolvedLookerUp2_2_2 | AD5: =+VLOOKUP($A5,INDIRECT(Adrese!B$2),5,FALSE) -> 22096 | AE5: =+VLOOKUP($A5,INDIRECT(Adrese!C$2),5,FALSE) -> 22871 | AF5: =+VLOOKUP($A5,INDIRECT(Adrese!D$2),5,FALSE) -> 21970 | AG5: =+VLOOKUP($A5,INDIRECT(Adrese!E$2),5,FALSE) -> 22027 | AH5: =+VLOOKUP($A5,INDIRECT(Adrese!F$2),5,FALSE) -> 21926 | AI5: =AVERAGE(AD5:AH5) -> 22178 | AM5: EvolvedLookerUp2_2_2 | AN5: =+VLOOKUP($A5,INDIRECT(Adrese!B$2),6,FALSE) -> 0.4870354 | AO5: =+VLOOKUP($A5,INDIRECT(Adrese!C$2),6,FALSE) -> 0.50356195 | AP5: =+VLOOKUP($A5,INDIRECT(Adrese!D$2),6,FALSE) -> 0.48378319 | AQ5: =+VLOOKUP($A5,INDIRECT(Adrese!E$2),6,FALSE) -> 0.48504425 | AR5: =+VLOOKUP($A5,INDIRECT(Adrese!F$2),6,FALSE) -> 0.48269912 | AS5: =TEXT(AT5,"0.00")&" ("&TEXT(AU5,"0.00")&")" -> 0.49 (0.01) | AT5: =AVERAGE(AN5:AR5) -> 0.48842478 | AU5: =_xlfn.STDEV.S(AN5:AR5) -> 0.00861423 | AW5: EvolvedLookerUp2_2_2 | AX5: =+VLOOKUP($A5,INDIRECT(Adrese!B$2),7,FALSE) -> 0.59734513 | AY5: =+VLOOKUP($A5,INDIRECT(Adrese!C$2),7,FALSE) -> 0.60176991 | AZ5: =+VLOOKUP($A5,INDIRECT(Adrese!D$2),7,FALSE) -> 0.60619469 | BA5: =+VLOOKUP($A5,INDIRECT(Adrese!E$2),7,FALSE) -> 0.58849558 | BB5: =+VLOOKUP($A5,INDIRECT(Adrese!F$2),7,FALSE) -> 0.59292035 | BC5: =TEXT(BD5,"0.00")&" ("&TEXT(BE5,"0.00")&")" -> 0.60 (0.01) | BD5: =AVERAGE(AX5:BB5) -> 0.59734513 | BE5: =_xlfn.STDEV.S(AX5:BB5) -> 0.0069961895 | BG5: EvolvedLookerUp2_2_2 | BH5: =+VLOOKUP($BG5,INDIRECT(Adrese!B$2),8,FALSE) -> 0.06051287 | BI5: =+VLOOKUP($BG5,INDIRECT(Adrese!C$2),8,FALSE) -> 0.062661101 | BJ5: =+VLOOKUP($BG5,INDIRECT(Adrese!D$2),8,FALSE) -> 0.060619736 | BK5: =+VLOOKUP($BG5,INDIRECT(Adrese!E$2),8,FALSE) -> 0.060188604 | BL5: =+VLOOKUP($BG5,INDIRECT(Adrese!F$2),8,FALSE) -> 0.059851345 | BM5: =TEXT(BN5,"0.00")&" ("&TEXT(BO5,"0.00")&")" -> 0.06 (0.00) | BN5: =AVERAGE(BH5:BL5) -> 0.060766731 | BO5: =_xlfn.STDEV.S(BH5:BL5) -> 0.0011007784 | BQ5: EvolvedLookerUp2_2_2 | BR5: =+VLOOKUP($BG5,INDIRECT(Adrese!B$2),9,FALSE) -> -0.020244987 | BS5: =+VLOOKUP($BG5,INDIRECT(Adrese!C$2),9,FALSE) -> -0.028521358 | BT5: =+VLOOKUP($BG5,INDIRECT(Adrese!D$2),9,FALSE) -> -0.020853766 | BU5: =+VLOOKUP($BG5,INDIRECT(Adrese!E$2),9,FALSE) -> -0.023219528 | BV5: =+VLOOKUP($BG5,INDIRECT(Adrese!F$2),9,FALSE) -> -0.017620107 | BW5: =TEXT(BX5,"0.00")&" ("&TEXT(BY5,"0.00")&")" -> -0.02 (0.00) | BX5: =AVERAGE(BR5:BV5) -> -0.022091949 | BY5: =_xlfn.STDEV.S(BR5:BV5) -> 0.004109455
A6: Evolved HMM 5 | B6: =+VLOOKUP($A6,INDIRECT(Adrese!B$2),2,FALSE) -> 45 | C6: =+VLOOKUP($A6,INDIRECT(Adrese!C$2),2,FALSE) -> 45 | D6: =+VLOOKUP($A6,INDIRECT(Adrese!D$2),2,FALSE) -> 86 | E6: =+VLOOKUP($A6,INDIRECT(Adrese!E$2),2,FALSE) -> 92 | F6: =+VLOOKUP($A6,INDIRECT(Adrese!F$2),2,FALSE) -> 90 | G6: =AVERAGE(B6:F6) -> 71.6 | J6: Evolved HMM 5 | K6: =+VLOOKUP($A6,INDIRECT(Adrese!B$2),3,FALSE) -> 105 | L6: =+VLOOKUP($A6,INDIRECT(Adrese!C$2),3,FALSE) -> 107 | M6: =+VLOOKUP($A6,INDIRECT(Adrese!D$2),3,FALSE) -> 105 | N6: =+VLOOKUP($A6,INDIRECT(Adrese!E$2),3,FALSE) -> 101 | O6: =+VLOOKUP($A6,INDIRECT(Adrese!F$2),3,FALSE) -> 100 | P6: =SUM(K6:O6) -> 518 | Q6: =AVERAGE(K6:O6) -> 103.6 | T6: Evolved HMM 5 | U6: =+VLOOKUP($T6,INDIRECT(Adrese!B$2),4,FALSE) -> 97844 | V6: =+VLOOKUP($T6,INDIRECT(Adrese!C$2),4,FALSE) -> 97718 | W6: =+VLOOKUP($T6,INDIRECT(Adrese!D$2),4,FALSE) -> 96228 | X6: =+VLOOKUP($T6,INDIRECT(Adrese!E$2),4,FALSE) -> 95994 | Y6: =+VLOOKUP($T6,INDIRECT(Adrese!F$2),4,FALSE) -> 95938 | Z6: =SUM(U6:Y6) -> 483722 | AA6: =AVERAGE(U6:Y6) -> 96744.4 | AC6: Evolved HMM 5 | AD6: =+VLOOKUP($A6,INDIRECT(Adrese!B$2),5,FALSE) -> 15873 | AE6: =+VLOOKUP($A6,INDIRECT(Adrese!C$2),5,FALSE) -> 15566 | AF6: =+VLOOKUP($A6,INDIRECT(Adrese!D$2),5,FALSE) -> 15667 | AG6: =+VLOOKUP($A6,INDIRECT(Adrese!E$2),5,FALSE) -> 15471 | AH6: =+VLOOKUP($A6,INDIRECT(Adrese!F$2),5,FALSE) -> 15558 | AI6: =AVERAGE(AD6:AH6) -> 15627 | AM6: Evolved HMM 5 | AN6: =+VLOOKUP($A6,INDIRECT(Adrese!B$2),6,FALSE) -> 0.34893805 | AO6: =+VLOOKUP($A6,INDIRECT(Adrese!C$2),6,FALSE) -> 0.34276549 | AP6: =+VLOOKUP($A6,INDIRECT(Adrese!D$2),6,FALSE) -> 0.34471239 | AQ6: =+VLOOKUP($A6,INDIRECT(Adrese!E$2),6,FALSE) -> 0.34026549 | AR6: =+VLOOKUP($A6,INDIRECT(Adrese!F$2),6,FALSE) -> 0.3424115 | AS6: =TEXT(AT6,"0.00")&" ("&TEXT(AU6,"0.00")&")" -> 0.34 (0.00) | AT6: =AVERAGE(AN6:AR6) -> 0.34381858 | AU6: =_xlfn.STDEV.S(AN6:AR6) -> 0.0032680743 | AW6: Evolved HMM 5 | AX6: =+VLOOKUP($A6,INDIRECT(Adrese!B$2),7,FALSE) -> 0.53539823 | AY6: =+VLOOKUP($A6,INDIRECT(Adrese!C$2),7,FALSE) -> 0.52654867 | AZ6: =+VLOOKUP($A6,INDIRECT(Adrese!D$2),7,FALSE) -> 0.53539823 | BA6: =+VLOOKUP($A6,INDIRECT(Adrese!E$2),7,FALSE) -> 0.55309735 | BB6: =+VLOOKUP($A6,INDIRECT(Adrese!F$2),7,FALSE) -> 0.55752212 | BC6: =TEXT(BD6,"0.00")&" ("&TEXT(BE6,"0.00")&")" -> 0.54 (0.01) | BD6: =AVERAGE(AX6:BB6) -> 0.54159292 | BE6: =_xlfn.STDEV.S(AX6:BB6) -> 0.013126015 | BG6: Evolved HMM 5 | BH6: =+VLOOKUP($BG6,INDIRECT(Adrese!B$2),8,FALSE) -> 0.043087687 | BI6: =+VLOOKUP($BG6,INDIRECT(Adrese!C$2),8,FALSE) -> 0.04199285 | BJ6: =+VLOOKUP($BG6,INDIRECT(Adrese!D$2),8,FALSE) -> 0.042606709 | BK6: =+VLOOKUP($BG6,INDIRECT(Adrese!E$2),8,FALSE) -> 0.041904926 | BL6: =+VLOOKUP($BG6,INDIRECT(Adrese!F$2),8,FALSE) -> 0.04216712 | BM6: =TEXT(BN6,"0.00")&" ("&TEXT(BO6,"0.00")&")" -> 0.04 (0.00) | BN6: =AVERAGE(BH6:BL6) -> 0.042351858 | BO6: =_xlfn.STDEV.S(BH6:BL6) -> 0.00049222871 | BQ6: Evolved HMM 5 | BR6: =+VLOOKUP($BG6,INDIRECT(Adrese!B$2),9,FALSE) -> 0.0098277383 | BS6: =+VLOOKUP($BG6,INDIRECT(Adrese!C$2),9,FALSE) -> 0.0097544208 | BT6: =+VLOOKUP($BG6,INDIRECT(Adrese!D$2),9,FALSE) -> 0.013541547 | BU6: =+VLOOKUP($BG6,INDIRECT(Adrese!E$2),9,FALSE) -> 0.01274334 | BV6: =+VLOOKUP($BG6,INDIRECT(Adrese!F$2),9,FALSE) -> 0.010816961 | BW6: =TEXT(BX6,"0.00")&" ("&TEXT(BY6,"0.00")&")" -> 0.01 (0.00) | BX6: =AVERAGE(BR6:BV6) -> 0.011336801 | BY6: =_xlfn.STDEV.S(BR6:BV6) -> 0.0017241437
A7: Evolved FSM 16 | B7: =+VLOOKUP($A7,INDIRECT(Adrese!B$2),2,FALSE) -> 109 | C7: =+VLOOKUP($A7,INDIRECT(Adrese!C$2),2,FALSE) -> 92 | D7: =+VLOOKUP($A7,INDIRECT(Adrese!D$2),2,FALSE) -> 135 | E7: =+VLOOKUP($A7,INDIRECT(Adrese!E$2),2,FALSE) -> 112 | F7: =+VLOOKUP($A7,INDIRECT(Adrese!F$2),2,FALSE) -> 136 | G7: =AVERAGE(B7:F7) -> 116.8 | J7: Evolved FSM 16 | K7: =+VLOOKUP($A7,INDIRECT(Adrese!B$2),3,FALSE) -> 132 | L7: =+VLOOKUP($A7,INDIRECT(Adrese!C$2),3,FALSE) -> 136 | M7: =+VLOOKUP($A7,INDIRECT(Adrese!D$2),3,FALSE) -> 132 | N7: =+VLOOKUP($A7,INDIRECT(Adrese!E$2),3,FALSE) -> 131 | O7: =+VLOOKUP($A7,INDIRECT(Adrese!F$2),3,FALSE) -> 134 | P7: =SUM(K7:O7) -> 665 | Q7: =AVERAGE(K7:O7) -> 133 | T7: Evolved FSM 16 | U7: =+VLOOKUP($T7,INDIRECT(Adrese!B$2),4,FALSE) -> 95319 | V7: =+VLOOKUP($T7,INDIRECT(Adrese!C$2),4,FALSE) -> 95780 | W7: =+VLOOKUP($T7,INDIRECT(Adrese!D$2),4,FALSE) -> 94131 | X7: =+VLOOKUP($T7,INDIRECT(Adrese!E$2),4,FALSE) -> 95111 | Y7: =+VLOOKUP($T7,INDIRECT(Adrese!F$2),4,FALSE) -> 94186 | Z7: =SUM(U7:Y7) -> 474527 | AA7: =AVERAGE(U7:Y7) -> 94905.4 | AC7: Evolved FSM 16 | AD7: =+VLOOKUP($A7,INDIRECT(Adrese!B$2),5,FALSE) -> 13536 | AE7: =+VLOOKUP($A7,INDIRECT(Adrese!C$2),5,FALSE) -> 13505 | AF7: =+VLOOKUP($A7,INDIRECT(Adrese!D$2),5,FALSE) -> 14080 | AG7: =+VLOOKUP($A7,INDIRECT(Adrese!E$2),5,FALSE) -> 13351 | AH7: =+VLOOKUP($A7,INDIRECT(Adrese!F$2),5,FALSE) -> 13384 | AI7: =AVERAGE(AD7:AH7) -> 13571.2 | AM7: Evolved FSM 16 | AN7: =+VLOOKUP($A7,INDIRECT(Adrese!B$2),6,FALSE) -> 0.29785398 | AO7: =+VLOOKUP($A7,INDIRECT(Adrese!C$2),6,FALSE) -> 0.29825221 | AP7: =+VLOOKUP($A7,INDIRECT(Adrese!D$2),6,FALSE) -> 0.3099115 | AQ7: =+VLOOKUP($A7,INDIRECT(Adrese!E$2),6,FALSE) -> 0.29382743 | AR7: =+VLOOKUP($A7,INDIRECT(Adrese!F$2),6,FALSE) -> 0.2945354 | AS7: =TEXT(AT7,"0.00")&" ("&TEXT(AU7,"0.00")&")" -> 0.30 (0.01) | AT7: =AVERAGE(AN7:AR7) -> 0.29887611 | AU7: =_xlfn.STDEV.S(AN7:AR7) -> 0.0064719556 | AW7: Evolved FSM 16 | AX7: =+VLOOKUP($A7,INDIRECT(Adrese!B$2),7,FALSE) -> 0.4159292 | AY7: =+VLOOKUP($A7,INDIRECT(Adrese!C$2),7,FALSE) -> 0.39823009 | AZ7: =+VLOOKUP($A7,INDIRECT(Adrese!D$2),7,FALSE) -> 0.4159292 | BA7: =+VLOOKUP($A7,INDIRECT(Adrese!E$2),7,FALSE) -> 0.42035398 | BB7: =+VLOOKUP($A7,INDIRECT(Adrese!F$2),7,FALSE) -> 0.40707965 | BC7: =TEXT(BD7,"0.00")&" ("&TEXT(BE7,"0.00")&")" -> 0.41 (0.01) | BD7: =AVERAGE(AX7:BB7) -> 0.41150442 | BE7: =_xlfn.STDEV.S(AX7:BB7) -> 0.0088495575 | BG7: Evolved FSM 16 | BH7: =+VLOOKUP($BG7,INDIRECT(Adrese!B$2),8,FALSE) -> 0.033685306 | BI7: =+VLOOKUP($BG7,INDIRECT(Adrese!C$2),8,FALSE) -> 0.034468696 | BJ7: =+VLOOKUP($BG7,INDIRECT(Adrese!D$2),8,FALSE) -> 0.035320495 | BK7: =+VLOOKUP($BG7,INDIRECT(Adrese!E$2),8,FALSE) -> 0.033074265 | BL7: =+VLOOKUP($BG7,INDIRECT(Adrese!F$2),8,FALSE) -> 0.033274851 | BM7: =TEXT(BN7,"0.00")&" ("&TEXT(BO7,"0.00")&")" -> 0.03 (0.00) | BN7: =AVERAGE(BH7:BL7) -> 0.033964723 | BO7: =_xlfn.STDEV.S(BH7:BL7) -> 0.00092722968 | BQ7: Evolved FSM 16 | BR7: =+VLOOKUP($BG7,INDIRECT(Adrese!B$2),9,FALSE) -> 0.011684116 | BS7: =+VLOOKUP($BG7,INDIRECT(Adrese!C$2),9,FALSE) -> 0.017363551 | BT7: =+VLOOKUP($BG7,INDIRECT(Adrese!D$2),9,FALSE) -> 0.010706733 | BU7: =+VLOOKUP($BG7,INDIRECT(Adrese!E$2),9,FALSE) -> 0.016134367 | BV7: =+VLOOKUP($BG7,INDIRECT(Adrese!F$2),9,FALSE) -> 0.014780028 | BW7: =TEXT(BX7,"0.00")&" ("&TEXT(BY7,"0.00")&")" -> 0.01 (0.00) | BX7: =AVERAGE(BR7:BV7) -> 0.014133759 | BY7: =_xlfn.STDEV.S(BR7:BV7) -> 0.0028546848
A8: PSO Gambler 1_1_1 | B8: =+VLOOKUP($A8,INDIRECT(Adrese!B$2),2,FALSE) -> 115 | C8: =+VLOOKUP($A8,INDIRECT(Adrese!C$2),2,FALSE) -> 146 | D8: =+VLOOKUP($A8,INDIRECT(Adrese!D$2),2,FALSE) -> 59 | E8: =+VLOOKUP($A8,INDIRECT(Adrese!E$2),2,FALSE) -> 135 | F8: =+VLOOKUP($A8,INDIRECT(Adrese!F$2),2,FALSE) -> 130 | G8: =AVERAGE(B8:F8) -> 117 | J8: PSO Gambler 1_1_1 | K8: =+VLOOKUP($A8,INDIRECT(Adrese!B$2),3,FALSE) -> 130 | L8: =+VLOOKUP($A8,INDIRECT(Adrese!C$2),3,FALSE) -> 124 | M8: =+VLOOKUP($A8,INDIRECT(Adrese!D$2),3,FALSE) -> 140 | N8: =+VLOOKUP($A8,INDIRECT(Adrese!E$2),3,FALSE) -> 126 | O8: =+VLOOKUP($A8,INDIRECT(Adrese!F$2),3,FALSE) -> 128 | P8: =SUM(K8:O8) -> 648 | Q8: =AVERAGE(K8:O8) -> 129.6 | T8: PSO Gambler 1_1_1 | U8: =+VLOOKUP($T8,INDIRECT(Adrese!B$2),4,FALSE) -> 94832 | V8: =+VLOOKUP($T8,INDIRECT(Adrese!C$2),4,FALSE) -> 93758 | W8: =+VLOOKUP($T8,INDIRECT(Adrese!D$2),4,FALSE) -> 96915 | X8: =+VLOOKUP($T8,INDIRECT(Adrese!E$2),4,FALSE) -> 94274 | Y8: =+VLOOKUP($T8,INDIRECT(Adrese!F$2),4,FALSE) -> 94417 | Z8: =SUM(U8:Y8) -> 474196 | AA8: =AVERAGE(U8:Y8) -> 94839.2 | AC8: PSO Gambler 1_1_1 | AD8: =+VLOOKUP($A8,INDIRECT(Adrese!B$2),5,FALSE) -> 14251 | AE8: =+VLOOKUP($A8,INDIRECT(Adrese!C$2),5,FALSE) -> 14268 | AF8: =+VLOOKUP($A8,INDIRECT(Adrese!D$2),5,FALSE) -> 14256 | AG8: =+VLOOKUP($A8,INDIRECT(Adrese!E$2),5,FALSE) -> 14513 | AH8: =+VLOOKUP($A8,INDIRECT(Adrese!F$2),5,FALSE) -> 14710 | AI8: =AVERAGE(AD8:AH8) -> 14399.6 | AM8: PSO Gambler 1_1_1 | AN8: =+VLOOKUP($A8,INDIRECT(Adrese!B$2),6,FALSE) -> 0.3139823 | AO8: =+VLOOKUP($A8,INDIRECT(Adrese!C$2),6,FALSE) -> 0.3145354 | AP8: =+VLOOKUP($A8,INDIRECT(Adrese!D$2),6,FALSE) -> 0.31451327 | AQ8: =+VLOOKUP($A8,INDIRECT(Adrese!E$2),6,FALSE) -> 0.31929204 | AR8: =+VLOOKUP($A8,INDIRECT(Adrese!F$2),6,FALSE) -> 0.32429204 | AS8: =TEXT(AT8,"0.00")&" ("&TEXT(AU8,"0.00")&")" -> 0.32 (0.00) | AT8: =AVERAGE(AN8:AR8) -> 0.31732301 | AU8: =_xlfn.STDEV.S(AN8:AR8) -> 0.0044516881 | AW8: PSO Gambler 1_1_1 | AX8: =+VLOOKUP($A8,INDIRECT(Adrese!B$2),7,FALSE) -> 0.42477876 | AY8: =+VLOOKUP($A8,INDIRECT(Adrese!C$2),7,FALSE) -> 0.45132743 | AZ8: =+VLOOKUP($A8,INDIRECT(Adrese!D$2),7,FALSE) -> 0.38053097 | BA8: =+VLOOKUP($A8,INDIRECT(Adrese!E$2),7,FALSE) -> 0.44247788 | BB8: =+VLOOKUP($A8,INDIRECT(Adrese!F$2),7,FALSE) -> 0.43362832 | BC8: =TEXT(BD8,"0.00")&" ("&TEXT(BE8,"0.00")&")" -> 0.43 (0.03) | BD8: =AVERAGE(AX8:BB8) -> 0.42654867 | BE8: =_xlfn.STDEV.S(AX8:BB8) -> 0.02756179 | BG8: PSO Gambler 1_1_1 | BH8: =+VLOOKUP($BG8,INDIRECT(Adrese!B$2),8,FALSE) -> 0.042106992 | BI8: =+VLOOKUP($BG8,INDIRECT(Adrese!C$2),8,FALSE) -> 0.042093535 | BJ8: =+VLOOKUP($BG8,INDIRECT(Adrese!D$2),8,FALSE) -> 0.042441001 | BK8: =+VLOOKUP($BG8,INDIRECT(Adrese!E$2),8,FALSE) -> 0.042916204 | BL8: =+VLOOKUP($BG8,INDIRECT(Adrese!F$2),8,FALSE) -> 0.043383957 | BM8: =TEXT(BN8,"0.00")&" ("&TEXT(BO8,"0.00")&")" -> 0.04 (0.00) | BN8: =AVERAGE(BH8:BL8) -> 0.042588338 | BO8: =_xlfn.STDEV.S(BH8:BL8) -> 0.00055649289 | BQ8: PSO Gambler 1_1_1 | BR8: =+VLOOKUP($BG8,INDIRECT(Adrese!B$2),9,FALSE) -> 0.058446015 | BS8: =+VLOOKUP($BG8,INDIRECT(Adrese!C$2),9,FALSE) -> 0.056267381 | BT8: =+VLOOKUP($BG8,INDIRECT(Adrese!D$2),9,FALSE) -> 0.058094806 | BU8: =+VLOOKUP($BG8,INDIRECT(Adrese!E$2),9,FALSE) -> 0.057305355 | BV8: =+VLOOKUP($BG8,INDIRECT(Adrese!F$2),9,FALSE) -> 0.055455091 | BW8: =TEXT(BX8,"0.00")&" ("&TEXT(BY8,"0.00")&")" -> 0.06 (0.00) | BX8: =AVERAGE(BR8:BV8) -> 0.05711373 | BY8: =_xlfn.STDEV.S(BR8:BV8) -> 0.0012491601
A9: Evolved FSM 16 Noise 05 | B9: =+VLOOKUP($A9,INDIRECT(Adrese!B$2),2,FALSE) -> 9 | C9: =+VLOOKUP($A9,INDIRECT(Adrese!C$2),2,FALSE) -> 6 | D9: =+VLOOKUP($A9,INDIRECT(Adrese!D$2),2,FALSE) -> 6 | E9: =+VLOOKUP($A9,INDIRECT(Adrese!E$2),2,FALSE) -> 9 | F9: =+VLOOKUP($A9,INDIRECT(Adrese!F$2),2,FALSE) -> 13 | G9: =AVERAGE(B9:F9) -> 8.6 | J9: Evolved FSM 16 Noise 05 | K9: =+VLOOKUP($A9,INDIRECT(Adrese!B$2),3,FALSE) -> 112 | L9: =+VLOOKUP($A9,INDIRECT(Adrese!C$2),3,FALSE) -> 106 | M9: =+VLOOKUP($A9,INDIRECT(Adrese!D$2),3,FALSE) -> 111 | N9: =+VLOOKUP($A9,INDIRECT(Adrese!E$2),3,FALSE) -> 103 | O9: =+VLOOKUP($A9,INDIRECT(Adrese!F$2),3,FALSE) -> 100 | P9: =SUM(K9:O9) -> 532 | Q9: =AVERAGE(K9:O9) -> 106.4 | T9: Evolved FSM 16 Noise 05 | U9: =+VLOOKUP($T9,INDIRECT(Adrese!B$2),4,FALSE) -> 101553 | V9: =+VLOOKUP($T9,INDIRECT(Adrese!C$2),4,FALSE) -> 102979 | W9: =+VLOOKUP($T9,INDIRECT(Adrese!D$2),4,FALSE) -> 102943 | X9: =+VLOOKUP($T9,INDIRECT(Adrese!E$2),4,FALSE) -> 101701 | Y9: =+VLOOKUP($T9,INDIRECT(Adrese!F$2),4,FALSE) -> 101036 | Z9: =SUM(U9:Y9) -> 510212 | AA9: =AVERAGE(U9:Y9) -> 102042.4 | AC9: Evolved FSM 16 Noise 05 | AD9: =+VLOOKUP($A9,INDIRECT(Adrese!B$2),5,FALSE) -> 17311 | AE9: =+VLOOKUP($A9,INDIRECT(Adrese!C$2),5,FALSE) -> 17572 | AF9: =+VLOOKUP($A9,INDIRECT(Adrese!D$2),5,FALSE) -> 17730 | AG9: =+VLOOKUP($A9,INDIRECT(Adrese!E$2),5,FALSE) -> 17454 | AH9: =+VLOOKUP($A9,INDIRECT(Adrese!F$2),5,FALSE) -> 16725 | AI9: =AVERAGE(AD9:AH9) -> 17358.4 | AM9: Evolved FSM 16 Noise 05 | AN9: =+VLOOKUP($A9,INDIRECT(Adrese!B$2),6,FALSE) -> 0.38103982 | AO9: =+VLOOKUP($A9,INDIRECT(Adrese!C$2),6,FALSE) -> 0.38537611 | AP9: =+VLOOKUP($A9,INDIRECT(Adrese!D$2),6,FALSE) -> 0.38951327 | AQ9: =+VLOOKUP($A9,INDIRECT(Adrese!E$2),6,FALSE) -> 0.3835177 | AR9: =+VLOOKUP($A9,INDIRECT(Adrese!F$2),6,FALSE) -> 0.3680531 | AS9: =TEXT(AT9,"0.00")&" ("&TEXT(AU9,"0.00")&")" -> 0.38 (0.01) | AT9: =AVERAGE(AN9:AR9) -> 0.3815 | AU9: =_xlfn.STDEV.S(AN9:AR9) -> 0.0081292501 | AW9: Evolved FSM 16 Noise 05 | AX9: =+VLOOKUP($A9,INDIRECT(Adrese!B$2),7,FALSE) -> 0.50442478 | AY9: =+VLOOKUP($A9,INDIRECT(Adrese!C$2),7,FALSE) -> 0.53097345 | AZ9: =+VLOOKUP($A9,INDIRECT(Adrese!D$2),7,FALSE) -> 0.50884956 | BA9: =+VLOOKUP($A9,INDIRECT(Adrese!E$2),7,FALSE) -> 0.54424779 | BB9: =+VLOOKUP($A9,INDIRECT(Adrese!F$2),7,FALSE) -> 0.55752212 | BC9: =TEXT(BD9,"0.00")&" ("&TEXT(BE9,"0.00")&")" -> 0.53 (0.02) | BD9: =AVERAGE(AX9:BB9) -> 0.52920354 | BE9: =_xlfn.STDEV.S(AX9:BB9) -> 0.022691825 | BG9: Evolved FSM 16 Noise 05 | BH9: =+VLOOKUP($BG9,INDIRECT(Adrese!B$2),8,FALSE) -> 0.051134999 | BI9: =+VLOOKUP($BG9,INDIRECT(Adrese!C$2),8,FALSE) -> 0.052463261 | BJ9: =+VLOOKUP($BG9,INDIRECT(Adrese!D$2),8,FALSE) -> 0.052397249 | BK9: =+VLOOKUP($BG9,INDIRECT(Adrese!E$2),8,FALSE) -> 0.051703425 | BL9: =+VLOOKUP($BG9,INDIRECT(Adrese!F$2),8,FALSE) -> 0.049681957 | BM9: =TEXT(BN9,"0.00")&" ("&TEXT(BO9,"0.00")&")" -> 0.05 (0.00) | BN9: =AVERAGE(BH9:BL9) -> 0.051476178 | BO9: =_xlfn.STDEV.S(BH9:BL9) -> 0.0011412689 | BQ9: Evolved FSM 16 Noise 05 | BR9: =+VLOOKUP($BG9,INDIRECT(Adrese!B$2),9,FALSE) -> 0.025621923 | BS9: =+VLOOKUP($BG9,INDIRECT(Adrese!C$2),9,FALSE) -> 0.022904291 | BT9: =+VLOOKUP($BG9,INDIRECT(Adrese!D$2),9,FALSE) -> 0.020692666 | BU9: =+VLOOKUP($BG9,INDIRECT(Adrese!E$2),9,FALSE) -> 0.022229352 | BV9: =+VLOOKUP($BG9,INDIRECT(Adrese!F$2),9,FALSE) -> 0.031225783 | BW9: =TEXT(BX9,"0.00")&" ("&TEXT(BY9,"0.00")&")" -> 0.02 (0.00) | BX9: =AVERAGE(BR9:BV9) -> 0.024534803 | BY9: =_xlfn.STDEV.S(BR9:BV9) -> 0.0041438728
A10: Evolved ANN | B10: =+VLOOKUP($A10,INDIRECT(Adrese!B$2),2,FALSE) -> 6 | C10: =+VLOOKUP($A10,INDIRECT(Adrese!C$2),2,FALSE) -> 8 | D10: =+VLOOKUP($A10,INDIRECT(Adrese!D$2),2,FALSE) -> 10 | E10: =+VLOOKUP($A10,INDIRECT(Adrese!E$2),2,FALSE) -> 8 | F10: =+VLOOKUP($A10,INDIRECT(Adrese!F$2),2,FALSE) -> 10 | G10: =AVERAGE(B10:F10) -> 8.4 | J10: Evolved ANN | K10: =+VLOOKUP($A10,INDIRECT(Adrese!B$2),3,FALSE) -> 174 | L10: =+VLOOKUP($A10,INDIRECT(Adrese!C$2),3,FALSE) -> 178 | M10: =+VLOOKUP($A10,INDIRECT(Adrese!D$2),3,FALSE) -> 175 | N10: =+VLOOKUP($A10,INDIRECT(Adrese!E$2),3,FALSE) -> 177 | O10: =+VLOOKUP($A10,INDIRECT(Adrese!F$2),3,FALSE) -> 181 | P10: =SUM(K10:O10) -> 885 | Q10: =AVERAGE(K10:O10) -> 177 | T10: Evolved ANN | U10: =+VLOOKUP($T10,INDIRECT(Adrese!B$2),4,FALSE) -> 102638 | V10: =+VLOOKUP($T10,INDIRECT(Adrese!C$2),4,FALSE) -> 102203 | W10: =+VLOOKUP($T10,INDIRECT(Adrese!D$2),4,FALSE) -> 101729 | X10: =+VLOOKUP($T10,INDIRECT(Adrese!E$2),4,FALSE) -> 101771 | Y10: =+VLOOKUP($T10,INDIRECT(Adrese!F$2),4,FALSE) -> 101651 | Z10: =SUM(U10:Y10) -> 509992 | AA10: =AVERAGE(U10:Y10) -> 101998.4 | AC10: Evolved ANN | AD10: =+VLOOKUP($A10,INDIRECT(Adrese!B$2),5,FALSE) -> 13066 | AE10: =+VLOOKUP($A10,INDIRECT(Adrese!C$2),5,FALSE) -> 12012 | AF10: =+VLOOKUP($A10,INDIRECT(Adrese!D$2),5,FALSE) -> 13337 | AG10: =+VLOOKUP($A10,INDIRECT(Adrese!E$2),5,FALSE) -> 12169 | AH10: =+VLOOKUP($A10,INDIRECT(Adrese!F$2),5,FALSE) -> 12045 | AI10: =AVERAGE(AD10:AH10) -> 12525.8 | AM10: Evolved ANN | AN10: =+VLOOKUP($A10,INDIRECT(Adrese!B$2),6,FALSE) -> 0.28679204 | AO10: =+VLOOKUP($A10,INDIRECT(Adrese!C$2),6,FALSE) -> 0.2635177 | AP10: =+VLOOKUP($A10,INDIRECT(Adrese!D$2),6,FALSE) -> 0.29219027 | AQ10: =+VLOOKUP($A10,INDIRECT(Adrese!E$2),6,FALSE) -> 0.26783186 | AR10: =+VLOOKUP($A10,INDIRECT(Adrese!F$2),6,FALSE) -> 0.26382743 | AS10: =TEXT(AT10,"0.00")&" ("&TEXT(AU10,"0.00")&")" -> 0.27 (0.01) | AT10: =AVERAGE(AN10:AR10) -> 0.27483186 | AU10: =_xlfn.STDEV.S(AN10:AR10) -> 0.01362413 | AW10: Evolved ANN | AX10: =+VLOOKUP($A10,INDIRECT(Adrese!B$2),7,FALSE) -> 0.2300885 | AY10: =+VLOOKUP($A10,INDIRECT(Adrese!C$2),7,FALSE) -> 0.21238938 | AZ10: =+VLOOKUP($A10,INDIRECT(Adrese!D$2),7,FALSE) -> 0.22566372 | BA10: =+VLOOKUP($A10,INDIRECT(Adrese!E$2),7,FALSE) -> 0.21681416 | BB10: =+VLOOKUP($A10,INDIRECT(Adrese!F$2),7,FALSE) -> 0.19911504 | BC10: =TEXT(BD10,"0.00")&" ("&TEXT(BE10,"0.00")&")" -> 0.22 (0.01) | BD10: =AVERAGE(AX10:BB10) -> 0.21681416 | BE10: =_xlfn.STDEV.S(AX10:BB10) -> 0.012117756 | BG10: Evolved ANN | BH10: =+VLOOKUP($BG10,INDIRECT(Adrese!B$2),8,FALSE) -> 0.042658931 | BI10: =+VLOOKUP($BG10,INDIRECT(Adrese!C$2),8,FALSE) -> 0.037994546 | BJ10: =+VLOOKUP($BG10,INDIRECT(Adrese!D$2),8,FALSE) -> 0.042781665 | BK10: =+VLOOKUP($BG10,INDIRECT(Adrese!E$2),8,FALSE) -> 0.039103434 | BL10: =+VLOOKUP($BG10,INDIRECT(Adrese!F$2),8,FALSE) -> 0.038177126 | BM10: =TEXT(BN10,"0.00")&" ("&TEXT(BO10,"0.00")&")" -> 0.04 (0.00) | BN10: =AVERAGE(BH10:BL10) -> 0.04014314 | BO10: =_xlfn.STDEV.S(BH10:BL10) -> 0.0023902758 | BQ10: Evolved ANN | BR10: =+VLOOKUP($BG10,INDIRECT(Adrese!B$2),9,FALSE) -> 0.066014802 | BS10: =+VLOOKUP($BG10,INDIRECT(Adrese!C$2),9,FALSE) -> 0.068860943 | BT10: =+VLOOKUP($BG10,INDIRECT(Adrese!D$2),9,FALSE) -> 0.059422968 | BU10: =+VLOOKUP($BG10,INDIRECT(Adrese!E$2),9,FALSE) -> 0.067460859 | BV10: =+VLOOKUP($BG10,INDIRECT(Adrese!F$2),9,FALSE) -> 0.069102334 | BW10: =TEXT(BX10,"0.00")&" ("&TEXT(BY10,"0.00")&")" -> 0.07 (0.00) | BX10: =AVERAGE(BR10:BV10) -> 0.066172381 | BY10: =_xlfn.STDEV.S(BR10:BV10) -> 0.0039702824
A11: Evolved ANN 5 | B11: =+VLOOKUP($A11,INDIRECT(Adrese!B$2),2,FALSE) -> 116 | C11: =+VLOOKUP($A11,INDIRECT(Adrese!C$2),2,FALSE) -> 78 | D11: =+VLOOKUP($A11,INDIRECT(Adrese!D$2),2,FALSE) -> 126 | E11: =+VLOOKUP($A11,INDIRECT(Adrese!E$2),2,FALSE) -> 97 | F11: =+VLOOKUP($A11,INDIRECT(Adrese!F$2),2,FALSE) -> 142 | G11: =AVERAGE(B11:F11) -> 111.8 | J11: Evolved ANN 5 | K11: =+VLOOKUP($A11,INDIRECT(Adrese!B$2),3,FALSE) -> 168 | L11: =+VLOOKUP($A11,INDIRECT(Adrese!C$2),3,FALSE) -> 173 | M11: =+VLOOKUP($A11,INDIRECT(Adrese!D$2),3,FALSE) -> 176 | N11: =+VLOOKUP($A11,INDIRECT(Adrese!E$2),3,FALSE) -> 181 | O11: =+VLOOKUP($A11,INDIRECT(Adrese!F$2),3,FALSE) -> 180 | P11: =SUM(K11:O11) -> 878 | Q11: =AVERAGE(K11:O11) -> 175.6 | T11: Evolved ANN 5 | U11: =+VLOOKUP($T11,INDIRECT(Adrese!B$2),4,FALSE) -> 94752 | V11: =+VLOOKUP($T11,INDIRECT(Adrese!C$2),4,FALSE) -> 96109 | W11: =+VLOOKUP($T11,INDIRECT(Adrese!D$2),4,FALSE) -> 94702 | X11: =+VLOOKUP($T11,INDIRECT(Adrese!E$2),4,FALSE) -> 95735 | Y11: =+VLOOKUP($T11,INDIRECT(Adrese!F$2),4,FALSE) -> 93934 | Z11: =SUM(U11:Y11) -> 475232 | AA11: =AVERAGE(U11:Y11) -> 95046.4 | AC11: Evolved ANN 5 | AD11: =+VLOOKUP($A11,INDIRECT(Adrese!B$2),5,FALSE) -> 13738 | AE11: =+VLOOKUP($A11,INDIRECT(Adrese!C$2),5,FALSE) -> 13870 | AF11: =+VLOOKUP($A11,INDIRECT(Adrese!D$2),5,FALSE) -> 14222 | AG11: =+VLOOKUP($A11,INDIRECT(Adrese!E$2),5,FALSE) -> 14429 | AH11: =+VLOOKUP($A11,INDIRECT(Adrese!F$2),5,FALSE) -> 13177 | AI11: =AVERAGE(AD11:AH11) -> 13887.2 | AM11: Evolved ANN 5 | AN11: =+VLOOKUP($A11,INDIRECT(Adrese!B$2),6,FALSE) -> 0.30265487 | AO11: =+VLOOKUP($A11,INDIRECT(Adrese!C$2),6,FALSE) -> 0.30639381 | AP11: =+VLOOKUP($A11,INDIRECT(Adrese!D$2),6,FALSE) -> 0.31362832 | AQ11: =+VLOOKUP($A11,INDIRECT(Adrese!E$2),6,FALSE) -> 0.31871681 | AR11: =+VLOOKUP($A11,INDIRECT(Adrese!F$2),6,FALSE) -> 0.29028761 | AS11: =TEXT(AT11,"0.00")&" ("&TEXT(AU11,"0.00")&")" -> 0.31 (0.01) | AT11: =AVERAGE(AN11:AR11) -> 0.30633628 | AU11: =_xlfn.STDEV.S(AN11:AR11) -> 0.010926657 | AW11: Evolved ANN 5 | AX11: =+VLOOKUP($A11,INDIRECT(Adrese!B$2),7,FALSE) -> 0.25663717 | AY11: =+VLOOKUP($A11,INDIRECT(Adrese!C$2),7,FALSE) -> 0.23451327 | AZ11: =+VLOOKUP($A11,INDIRECT(Adrese!D$2),7,FALSE) -> 0.22123894 | BA11: =+VLOOKUP($A11,INDIRECT(Adrese!E$2),7,FALSE) -> 0.19911504 | BB11: =+VLOOKUP($A11,INDIRECT(Adrese!F$2),7,FALSE) -> 0.20353982 | BC11: =TEXT(BD11,"0.00")&" ("&TEXT(BE11,"0.00")&")" -> 0.22 (0.02) | BD11: =AVERAGE(AX11:BB11) -> 0.22300885 | BE11: =_xlfn.STDEV.S(AX11:BB11) -> 0.023538825 | BG11: Evolved ANN 5 | BH11: =+VLOOKUP($BG11,INDIRECT(Adrese!B$2),8,FALSE) -> 0.044381422 | BI11: =+VLOOKUP($BG11,INDIRECT(Adrese!C$2),8,FALSE) -> 0.044251039 | BJ11: =+VLOOKUP($BG11,INDIRECT(Adrese!D$2),8,FALSE) -> 0.046205031 | BK11: =+VLOOKUP($BG11,INDIRECT(Adrese!E$2),8,FALSE) -> 0.047152722 | BL11: =+VLOOKUP($BG11,INDIRECT(Adrese!F$2),8,FALSE) -> 0.04186774 | BM11: =TEXT(BN11,"0.00")&" ("&TEXT(BO11,"0.00")&")" -> 0.04 (0.00) | BN11: =AVERAGE(BH11:BL11) -> 0.044771591 | BO11: =_xlfn.STDEV.S(BH11:BL11) -> 0.0020359329 | BQ11: Evolved ANN 5 | BR11: =+VLOOKUP($BG11,INDIRECT(Adrese!B$2),9,FALSE) -> 0.085792343 | BS11: =+VLOOKUP($BG11,INDIRECT(Adrese!C$2),9,FALSE) -> 0.0789381 | BT11: =+VLOOKUP($BG11,INDIRECT(Adrese!D$2),9,FALSE) -> 0.088065961 | BU11: =+VLOOKUP($BG11,INDIRECT(Adrese!E$2),9,FALSE) -> 0.088130969 | BV11: =+VLOOKUP($BG11,INDIRECT(Adrese!F$2),9,FALSE) -> 0.08868674 | BW11: =TEXT(BX11,"0.00")&" ("&TEXT(BY11,"0.00")&")" -> 0.09 (0.00) | BX11: =AVERAGE(BR11:BV11) -> 0.085922822 | BY11: =_xlfn.STDEV.S(BR11:BV11) -> 0.004059297
A12: Evolved FSM 4 | B12: =+VLOOKUP($A12,INDIRECT(Adrese!B$2),2,FALSE) -> 89 | C12: =+VLOOKUP($A12,INDIRECT(Adrese!C$2),2,FALSE) -> 115 | D12: =+VLOOKUP($A12,INDIRECT(Adrese!D$2),2,FALSE) -> 118 | E12: =+VLOOKUP($A12,INDIRECT(Adrese!E$2),2,FALSE) -> 123 | F12: =+VLOOKUP($A12,INDIRECT(Adrese!F$2),2,FALSE) -> 119 | G12: =AVERAGE(B12:F12) -> 112.8 | J12: Evolved FSM 4 | K12: =+VLOOKUP($A12,INDIRECT(Adrese!B$2),3,FALSE) -> 78 | L12: =+VLOOKUP($A12,INDIRECT(Adrese!C$2),3,FALSE) -> 80 | M12: =+VLOOKUP($A12,INDIRECT(Adrese!D$2),3,FALSE) -> 78 | N12: =+VLOOKUP($A12,INDIRECT(Adrese!E$2),3,FALSE) -> 75 | O12: =+VLOOKUP($A12,INDIRECT(Adrese!F$2),3,FALSE) -> 80 | P12: =SUM(K12:O12) -> 391 | Q12: =AVERAGE(K12:O12) -> 78.2 | T12: Evolved FSM 4 | U12: =+VLOOKUP($T12,INDIRECT(Adrese!B$2),4,FALSE) -> 96137 | V12: =+VLOOKUP($T12,INDIRECT(Adrese!C$2),4,FALSE) -> 95013 | W12: =+VLOOKUP($T12,INDIRECT(Adrese!D$2),4,FALSE) -> 94887 | X12: =+VLOOKUP($T12,INDIRECT(Adrese!E$2),4,FALSE) -> 94642 | Y12: =+VLOOKUP($T12,INDIRECT(Adrese!F$2),4,FALSE) -> 94879 | Z12: =SUM(U12:Y12) -> 475558 | AA12: =AVERAGE(U12:Y12) -> 95111.6 | AC12: Evolved FSM 4 | AD12: =+VLOOKUP($A12,INDIRECT(Adrese!B$2),5,FALSE) -> 23030 | AE12: =+VLOOKUP($A12,INDIRECT(Adrese!C$2),5,FALSE) -> 22811 | AF12: =+VLOOKUP($A12,INDIRECT(Adrese!D$2),5,FALSE) -> 22980 | AG12: =+VLOOKUP($A12,INDIRECT(Adrese!E$2),5,FALSE) -> 23112 | AH12: =+VLOOKUP($A12,INDIRECT(Adrese!F$2),5,FALSE) -> 23132 | AI12: =AVERAGE(AD12:AH12) -> 23013 | AM12: Evolved FSM 4 | AN12: =+VLOOKUP($A12,INDIRECT(Adrese!B$2),6,FALSE) -> 0.50705752 | AO12: =+VLOOKUP($A12,INDIRECT(Adrese!C$2),6,FALSE) -> 0.5024115 | AP12: =+VLOOKUP($A12,INDIRECT(Adrese!D$2),6,FALSE) -> 0.50615044 | AQ12: =+VLOOKUP($A12,INDIRECT(Adrese!E$2),6,FALSE) -> 0.5089823 | AR12: =+VLOOKUP($A12,INDIRECT(Adrese!F$2),6,FALSE) -> 0.50920354 | AS12: =TEXT(AT12,"0.00")&" ("&TEXT(AU12,"0.00")&")" -> 0.51 (0.00) | AT12: =AVERAGE(AN12:AR12) -> 0.50676106 | AU12: =_xlfn.STDEV.S(AN12:AR12) -> 0.0027513177 | AW12: Evolved FSM 4 | AX12: =+VLOOKUP($A12,INDIRECT(Adrese!B$2),7,FALSE) -> 0.65486726 | AY12: =+VLOOKUP($A12,INDIRECT(Adrese!C$2),7,FALSE) -> 0.6460177 | AZ12: =+VLOOKUP($A12,INDIRECT(Adrese!D$2),7,FALSE) -> 0.65486726 | BA12: =+VLOOKUP($A12,INDIRECT(Adrese!E$2),7,FALSE) -> 0.66814159 | BB12: =+VLOOKUP($A12,INDIRECT(Adrese!F$2),7,FALSE) -> 0.6460177 | BC12: =TEXT(BD12,"0.00")&" ("&TEXT(BE12,"0.00")&")" -> 0.65 (0.01) | BD12: =AVERAGE(AX12:BB12) -> 0.6539823 | BE12: =_xlfn.STDEV.S(AX12:BB12) -> 0.009068098 | BG12: Evolved FSM 4 | BH12: =+VLOOKUP($BG12,INDIRECT(Adrese!B$2),8,FALSE) -> 0.060226654 | BI12: =+VLOOKUP($BG12,INDIRECT(Adrese!C$2),8,FALSE) -> 0.059946124 | BJ12: =+VLOOKUP($BG12,INDIRECT(Adrese!D$2),8,FALSE) -> 0.060116515 | BK12: =+VLOOKUP($BG12,INDIRECT(Adrese!E$2),8,FALSE) -> 0.060635462 | BL12: =+VLOOKUP($BG12,INDIRECT(Adrese!F$2),8,FALSE) -> 0.061029651 | BM12: =TEXT(BN12,"0.00")&" ("&TEXT(BO12,"0.00")&")" -> 0.06 (0.00) | BN12: =AVERAGE(BH12:BL12) -> 0.060390881 | BO12: =_xlfn.STDEV.S(BH12:BL12) -> 0.00043815041 | BQ12: Evolved FSM 4 | BR12: =+VLOOKUP($BG12,INDIRECT(Adrese!B$2),9,FALSE) -> -0.048442539 | BS12: =+VLOOKUP($BG12,INDIRECT(Adrese!C$2),9,FALSE) -> -0.046715861 | BT12: =+VLOOKUP($BG12,INDIRECT(Adrese!D$2),9,FALSE) -> -0.047933453 | BU12: =+VLOOKUP($BG12,INDIRECT(Adrese!E$2),9,FALSE) -> -0.047176991 | BV12: =+VLOOKUP($BG12,INDIRECT(Adrese!F$2),9,FALSE) -> -0.045447799 | BW12: =TEXT(BX12,"0.00")&" ("&TEXT(BY12,"0.00")&")" -> -0.05 (0.00) | BX12: =AVERAGE(BR12:BV12) -> -0.047143329 | BY12: =_xlfn.STDEV.S(BR12:BV12) -> 0.0011587631
A13: PSO Gambler 2_2_2 | B13: =+VLOOKUP($A13,INDIRECT(Adrese!B$2),2,FALSE) -> 154 | C13: =+VLOOKUP($A13,INDIRECT(Adrese!C$2),2,FALSE) -> 122 | D13: =+VLOOKUP($A13,INDIRECT(Adrese!D$2),2,FALSE) -> 130 | E13: =+VLOOKUP($A13,INDIRECT(Adrese!E$2),2,FALSE) -> 143 | F13: =+VLOOKUP($A13,INDIRECT(Adrese!F$2),2,FALSE) -> 100 | G13: =AVERAGE(B13:F13) -> 129.8 | J13: PSO Gambler 2_2_2 | K13: =+VLOOKUP($A13,INDIRECT(Adrese!B$2),3,FALSE) -> 103 | L13: =+VLOOKUP($A13,INDIRECT(Adrese!C$2),3,FALSE) -> 102 | M13: =+VLOOKUP($A13,INDIRECT(Adrese!D$2),3,FALSE) -> 108 | N13: =+VLOOKUP($A13,INDIRECT(Adrese!E$2),3,FALSE) -> 108 | O13: =+VLOOKUP($A13,INDIRECT(Adrese!F$2),3,FALSE) -> 108 | P13: =SUM(K13:O13) -> 529 | Q13: =AVERAGE(K13:O13) -> 105.8 | T13: PSO Gambler 2_2_2 | U13: =+VLOOKUP($T13,INDIRECT(Adrese!B$2),4,FALSE) -> 93159 | V13: =+VLOOKUP($T13,INDIRECT(Adrese!C$2),4,FALSE) -> 94551 | W13: =+VLOOKUP($T13,INDIRECT(Adrese!D$2),4,FALSE) -> 94488 | X13: =+VLOOKUP($T13,INDIRECT(Adrese!E$2),4,FALSE) -> 94042 | Y13: =+VLOOKUP($T13,INDIRECT(Adrese!F$2),4,FALSE) -> 95404 | Z13: =SUM(U13:Y13) -> 471644 | AA13: =AVERAGE(U13:Y13) -> 94328.8 | AC13: PSO Gambler 2_2_2 | AD13: =+VLOOKUP($A13,INDIRECT(Adrese!B$2),5,FALSE) -> 15559 | AE13: =+VLOOKUP($A13,INDIRECT(Adrese!C$2),5,FALSE) -> 15550 | AF13: =+VLOOKUP($A13,INDIRECT(Adrese!D$2),5,FALSE) -> 15609 | AG13: =+VLOOKUP($A13,INDIRECT(Adrese!E$2),5,FALSE) -> 15653 | AH13: =+VLOOKUP($A13,INDIRECT(Adrese!F$2),5,FALSE) -> 15732 | AI13: =AVERAGE(AD13:AH13) -> 15620.6 | AM13: PSO Gambler 2_2_2 | AN13: =+VLOOKUP($A13,INDIRECT(Adrese!B$2),6,FALSE) -> 0.34227876 | AO13: =+VLOOKUP($A13,INDIRECT(Adrese!C$2),6,FALSE) -> 0.34207965 | AP13: =+VLOOKUP($A13,INDIRECT(Adrese!D$2),6,FALSE) -> 0.34314159 | AQ13: =+VLOOKUP($A13,INDIRECT(Adrese!E$2),6,FALSE) -> 0.34426991 | AR13: =+VLOOKUP($A13,INDIRECT(Adrese!F$2),6,FALSE) -> 0.3465708 | AS13: =TEXT(AT13,"0.00")&" ("&TEXT(AU13,"0.00")&")" -> 0.34 (0.00) | AT13: =AVERAGE(AN13:AR13) -> 0.34366814 | AU13: =_xlfn.STDEV.S(AN13:AR13) -> 0.0018383744 | AW13: PSO Gambler 2_2_2 | AX13: =+VLOOKUP($A13,INDIRECT(Adrese!B$2),7,FALSE) -> 0.54424779 | AY13: =+VLOOKUP($A13,INDIRECT(Adrese!C$2),7,FALSE) -> 0.54867257 | AZ13: =+VLOOKUP($A13,INDIRECT(Adrese!D$2),7,FALSE) -> 0.52212389 | BA13: =+VLOOKUP($A13,INDIRECT(Adrese!E$2),7,FALSE) -> 0.52212389 | BB13: =+VLOOKUP($A13,INDIRECT(Adrese!F$2),7,FALSE) -> 0.52212389 | BC13: =TEXT(BD13,"0.00")&" ("&TEXT(BE13,"0.00")&")" -> 0.53 (0.01) | BD13: =AVERAGE(AX13:BB13) -> 0.53185841 | BE13: =_xlfn.STDEV.S(AX13:BB13) -> 0.013421018 | BG13: PSO Gambler 2_2_2 | BH13: =+VLOOKUP($BG13,INDIRECT(Adrese!B$2),8,FALSE) -> 0.042873473 | BI13: =+VLOOKUP($BG13,INDIRECT(Adrese!C$2),8,FALSE) -> 0.042771059 | BJ13: =+VLOOKUP($BG13,INDIRECT(Adrese!D$2),8,FALSE) -> 0.042683639 | BK13: =+VLOOKUP($BG13,INDIRECT(Adrese!E$2),8,FALSE) -> 0.04317824 | BL13: =+VLOOKUP($BG13,INDIRECT(Adrese!F$2),8,FALSE) -> 0.042974491 | BM13: =TEXT(BN13,"0.00")&" ("&TEXT(BO13,"0.00")&")" -> 0.04 (0.00) | BN13: =AVERAGE(BH13:BL13) -> 0.042896181 | BO13: =_xlfn.STDEV.S(BH13:BL13) -> 0.00019172597 | BQ13: PSO Gambler 2_2_2 | BR13: =+VLOOKUP($BG13,INDIRECT(Adrese!B$2),9,FALSE) -> 0.021467997 | BS13: =+VLOOKUP($BG13,INDIRECT(Adrese!C$2),9,FALSE) -> 0.019288335 | BT13: =+VLOOKUP($BG13,INDIRECT(Adrese!D$2),9,FALSE) -> 0.018442687 | BU13: =+VLOOKUP($BG13,INDIRECT(Adrese!E$2),9,FALSE) -> 0.020560068 | BV13: =+VLOOKUP($BG13,INDIRECT(Adrese!F$2),9,FALSE) -> 0.017645694 | BW13: =TEXT(BX13,"0.00")&" ("&TEXT(BY13,"0.00")&")" -> 0.02 (0.00) | BX13: =AVERAGE(BR13:BV13) -> 0.019480956 | BY13: =_xlfn.STDEV.S(BR13:BV13) -> 0.0015488791
A14: PSO Gambler Mem1 | B14: =+VLOOKUP($A14,INDIRECT(Adrese!B$2),2,FALSE) -> 102 | C14: =+VLOOKUP($A14,INDIRECT(Adrese!C$2),2,FALSE) -> 160 | D14: =+VLOOKUP($A14,INDIRECT(Adrese!D$2),2,FALSE) -> 141 | E14: =+VLOOKUP($A14,INDIRECT(Adrese!E$2),2,FALSE) -> 90 | F14: =+VLOOKUP($A14,INDIRECT(Adrese!F$2),2,FALSE) -> 101 | G14: =AVERAGE(B14:F14) -> 118.8 | J14: PSO Gambler Mem1 | K14: =+VLOOKUP($A14,INDIRECT(Adrese!B$2),3,FALSE) -> 120 | L14: =+VLOOKUP($A14,INDIRECT(Adrese!C$2),3,FALSE) -> 107 | M14: =+VLOOKUP($A14,INDIRECT(Adrese!D$2),3,FALSE) -> 107 | N14: =+VLOOKUP($A14,INDIRECT(Adrese!E$2),3,FALSE) -> 109 | O14: =+VLOOKUP($A14,INDIRECT(Adrese!F$2),3,FALSE) -> 106 | P14: =SUM(K14:O14) -> 549 | Q14: =AVERAGE(K14:O14) -> 109.8 | T14: PSO Gambler Mem1 | U14: =+VLOOKUP($T14,INDIRECT(Adrese!B$2),4,FALSE) -> 95425 | V14: =+VLOOKUP($T14,INDIRECT(Adrese!C$2),4,FALSE) -> 93075 | W14: =+VLOOKUP($T14,INDIRECT(Adrese!D$2),4,FALSE) -> 94034 | X14: =+VLOOKUP($T14,INDIRECT(Adrese!E$2),4,FALSE) -> 96046 | Y14: =+VLOOKUP($T14,INDIRECT(Adrese!F$2),4,FALSE) -> 95382 | Z14: =SUM(U14:Y14) -> 473962 | AA14: =AVERAGE(U14:Y14) -> 94792.4 | AC14: PSO Gambler Mem1 | AD14: =+VLOOKUP($A14,INDIRECT(Adrese!B$2),5,FALSE) -> 17800 | AE14: =+VLOOKUP($A14,INDIRECT(Adrese!C$2),5,FALSE) -> 17291 | AF14: =+VLOOKUP($A14,INDIRECT(Adrese!D$2),5,FALSE) -> 16979 | AG14: =+VLOOKUP($A14,INDIRECT(Adrese!E$2),5,FALSE) -> 17880 | AH14: =+VLOOKUP($A14,INDIRECT(Adrese!F$2),5,FALSE) -> 17379 | AI14: =AVERAGE(AD14:AH14) -> 17465.8 | AM14: PSO Gambler Mem1 | AN14: =+VLOOKUP($A14,INDIRECT(Adrese!B$2),6,FALSE) -> 0.39223451 | AO14: =+VLOOKUP($A14,INDIRECT(Adrese!C$2),6,FALSE) -> 0.38030973 | AP14: =+VLOOKUP($A14,INDIRECT(Adrese!D$2),6,FALSE) -> 0.3744469 | AQ14: =+VLOOKUP($A14,INDIRECT(Adrese!E$2),6,FALSE) -> 0.39356195 | AR14: =+VLOOKUP($A14,INDIRECT(Adrese!F$2),6,FALSE) -> 0.38234513 | AS14: =TEXT(AT14,"0.00")&" ("&TEXT(AU14,"0.00")&")" -> 0.38 (0.01) | AT14: =AVERAGE(AN14:AR14) -> 0.38457965 | AU14: =_xlfn.STDEV.S(AN14:AR14) -> 0.0081421189 | AW14: PSO Gambler Mem1 | AX14: =+VLOOKUP($A14,INDIRECT(Adrese!B$2),7,FALSE) -> 0.46902655 | AY14: =+VLOOKUP($A14,INDIRECT(Adrese!C$2),7,FALSE) -> 0.52654867 | AZ14: =+VLOOKUP($A14,INDIRECT(Adrese!D$2),7,FALSE) -> 0.52654867 | BA14: =+VLOOKUP($A14,INDIRECT(Adrese!E$2),7,FALSE) -> 0.51769912 | BB14: =+VLOOKUP($A14,INDIRECT(Adrese!F$2),7,FALSE) -> 0.53097345 | BC14: =TEXT(BD14,"0.00")&" ("&TEXT(BE14,"0.00")&")" -> 0.51 (0.03) | BD14: =AVERAGE(AX14:BB14) -> 0.51415929 | BE14: =_xlfn.STDEV.S(AX14:BB14) -> 0.025686593 | BG14: PSO Gambler Mem1 | BH14: =+VLOOKUP($BG14,INDIRECT(Adrese!B$2),8,FALSE) -> 0.051957746 | BI14: =+VLOOKUP($BG14,INDIRECT(Adrese!C$2),8,FALSE) -> 0.050397256 | BJ14: =+VLOOKUP($BG14,INDIRECT(Adrese!D$2),8,FALSE) -> 0.049480937 | BK14: =+VLOOKUP($BG14,INDIRECT(Adrese!E$2),8,FALSE) -> 0.051963221 | BL14: =+VLOOKUP($BG14,INDIRECT(Adrese!F$2),8,FALSE) -> 0.050931345 | BM14: =TEXT(BN14,"0.00")&" ("&TEXT(BO14,"0.00")&")" -> 0.05 (0.00) | BN14: =AVERAGE(BH14:BL14) -> 0.050946101 | BO14: =_xlfn.STDEV.S(BH14:BL14) -> 0.0010613801 | BQ14: PSO Gambler Mem1 | BR14: =+VLOOKUP($BG14,INDIRECT(Adrese!B$2),9,FALSE) -> 0.034427549 | BS14: =+VLOOKUP($BG14,INDIRECT(Adrese!C$2),9,FALSE) -> 0.037202081 | BT14: =+VLOOKUP($BG14,INDIRECT(Adrese!D$2),9,FALSE) -> 0.037057001 | BU14: =+VLOOKUP($BG14,INDIRECT(Adrese!E$2),9,FALSE) -> 0.030049071 | BV14: =+VLOOKUP($BG14,INDIRECT(Adrese!F$2),9,FALSE) -> 0.033588775 | BW14: =TEXT(BX14,"0.00")&" ("&TEXT(BY14,"0.00")&")" -> 0.03 (0.00) | BX14: =AVERAGE(BR14:BV14) -> 0.034464895 | BY14: =_xlfn.STDEV.S(BR14:BV14) -> 0.0029359703
... A229: Defector | B229: =+VLOOKUP($A229,INDIRECT(Adrese!B$2),2,FALSE) -> 122 | C229: =+VLOOKUP($A229,INDIRECT(Adrese!C$2),2,FALSE) -> 98 | D229: =+VLOOKUP($A229,INDIRECT(Adrese!D$2),2,FALSE) -> 113 | E229: =+VLOOKUP($A229,INDIRECT(Adrese!E$2),2,FALSE) -> 99 | F229: =+VLOOKUP($A229,INDIRECT(Adrese!F$2),2,FALSE) -> 97 | G229: =AVERAGE(B229:F229) -> 105.8 | J229: Defector | K229: =+VLOOKUP($A229,INDIRECT(Adrese!B$2),3,FALSE) -> 200 | L229: =+VLOOKUP($A229,INDIRECT(Adrese!C$2),3,FALSE) -> 205 | M229: =+VLOOKUP($A229,INDIRECT(Adrese!D$2),3,FALSE) -> 203 | N229: =+VLOOKUP($A229,INDIRECT(Adrese!E$2),3,FALSE) -> 203 | O229: =+VLOOKUP($A229,INDIRECT(Adrese!F$2),3,FALSE) -> 210 | P229: =SUM(K229:O229) -> 1021 | Q229: =AVERAGE(K229:O229) -> 204.2 | T229: Defector | U229: =+VLOOKUP($T229,INDIRECT(Adrese!B$2),4,FALSE) -> 94583 | V229: =+VLOOKUP($T229,INDIRECT(Adrese!C$2),4,FALSE) -> 95620 | W229: =+VLOOKUP($T229,INDIRECT(Adrese!D$2),4,FALSE) -> 95408 | X229: =+VLOOKUP($T229,INDIRECT(Adrese!E$2),4,FALSE) -> 95523 | Y229: =+VLOOKUP($T229,INDIRECT(Adrese!F$2),4,FALSE) -> 95479 | Z229: =SUM(U229:Y229) -> 476613 | AA229: =AVERAGE(U229:Y229) -> 95322.6 | AC229: Defector | AD229: =+VLOOKUP($A229,INDIRECT(Adrese!B$2),5,FALSE) -> 4449 | AE229: =+VLOOKUP($A229,INDIRECT(Adrese!C$2),5,FALSE) -> 4549 | AF229: =+VLOOKUP($A229,INDIRECT(Adrese!D$2),5,FALSE) -> 4449 | AG229: =+VLOOKUP($A229,INDIRECT(Adrese!E$2),5,FALSE) -> 4457 | AH229: =+VLOOKUP($A229,INDIRECT(Adrese!F$2),5,FALSE) -> 4515 | AI229: =AVERAGE(AD229:AH229) -> 4483.8 | AM229: Defector | AN229: =+VLOOKUP($A229,INDIRECT(Adrese!B$2),6,FALSE) -> 0.097942478 | AO229: =+VLOOKUP($A229,INDIRECT(Adrese!C$2),6,FALSE) -> 0.10022124 | AP229: =+VLOOKUP($A229,INDIRECT(Adrese!D$2),6,FALSE) -> 0.098075221 | AQ229: =+VLOOKUP($A229,INDIRECT(Adrese!E$2),6,FALSE) -> 0.098119469 | AR229: =+VLOOKUP($A229,INDIRECT(Adrese!F$2),6,FALSE) -> 0.09949115 | AS229: =TEXT(AT229,"0.00")&" ("&TEXT(AU229,"0.00")&")" -> 0.10 (0.00) | AT229: =AVERAGE(AN229:AR229) -> 0.098769912 | AU229: =_xlfn.STDEV.S(AN229:AR229) -> 0.0010267489 | AW229: Defector | AX229: =+VLOOKUP($A229,INDIRECT(Adrese!B$2),7,FALSE) -> 0.11504425 | AY229: =+VLOOKUP($A229,INDIRECT(Adrese!C$2),7,FALSE) -> 0.092920354 | AZ229: =+VLOOKUP($A229,INDIRECT(Adrese!D$2),7,FALSE) -> 0.10176991 | BA229: =+VLOOKUP($A229,INDIRECT(Adrese!E$2),7,FALSE) -> 0.10176991 | BB229: =+VLOOKUP($A229,INDIRECT(Adrese!F$2),7,FALSE) -> 0.07079646 | BC229: =TEXT(BD229,"0.00")&" ("&TEXT(BE229,"0.00")&")" -> 0.10 (0.02) | BD229: =AVERAGE(AX229:BB229) -> 0.096460177 | BE229: =_xlfn.STDEV.S(AX229:BB229) -> 0.01637766 | BG229: Defector | BH229: =+VLOOKUP($BG229,INDIRECT(Adrese!B$2),8,FALSE) -> 0.012537706 | BI229: =+VLOOKUP($BG229,INDIRECT(Adrese!C$2),8,FALSE) -> 0.012778946 | BJ229: =+VLOOKUP($BG229,INDIRECT(Adrese!D$2),8,FALSE) -> 0.012479593 | BK229: =+VLOOKUP($BG229,INDIRECT(Adrese!E$2),8,FALSE) -> 0.01239393 | BL229: =+VLOOKUP($BG229,INDIRECT(Adrese!F$2),8,FALSE) -> 0.01270736 | BM229: =TEXT(BN229,"0.00")&" ("&TEXT(BO229,"0.00")&")" -> 0.01 (0.00) | BN229: =AVERAGE(BH229:BL229) -> 0.012579507 | BO229: =_xlfn.STDEV.S(BH229:BL229) -> 0.00015991496 | BQ229: Defector | BR229: =+VLOOKUP($BG229,INDIRECT(Adrese!B$2),9,FALSE) -> 0.096339907 | BS229: =+VLOOKUP($BG229,INDIRECT(Adrese!C$2),9,FALSE) -> 0.095846069 | BT229: =+VLOOKUP($BG229,INDIRECT(Adrese!D$2),9,FALSE) -> 0.096036381 | BU229: =+VLOOKUP($BG229,INDIRECT(Adrese!E$2),9,FALSE) -> 0.095414371 | BV229: =+VLOOKUP($BG229,INDIRECT(Adrese!F$2),9,FALSE) -> 0.095519653 | BW229: =TEXT(BX229,"0.00")&" ("&TEXT(BY229,"0.00")&")" -> 0.10 (0.00) | BX229: =AVERAGE(BR229:BV229) -> 0.095831276 | BY229: =_xlfn.STDEV.S(BR229:BV229) -> 0.00037812398

Sheet Svi
A1: Name | C1: #Wins | D1: TotalScore | E1: #Cooperations | F1: CooperationRating | G1: GoodPartnerRating | H1: EigenJesusRating | I1: EigenMosesRating
A2: Fuzzy | B2: 1 | C2: 87 | D2: 105874 | E2: 21631 | F2: 0.4765708 | G2: 0.61504425 | H2: 0.060113026 | I2: -0.042943409
A3: First by Downing | B3: 2 | C3: 142 | D3: 104728 | E3: 13283 | F3: 0.29331858 | G3: 0.37168142 | H3: 0.037931549 | I3: 0.015769813
A4: Evolved ANN 5 Noise 05 | B4: 3 | C4: 125 | D4: 104650 | E4: 19634 | F4: 0.4305531 | G4: 0.44690265 | H4: 0.064217354 | I4: 0.036288132
A5: Second by RichardHufford | B5: 4 | C5: 124 | D5: 104388 | E5: 15789 | F5: 0.34716814 | G5: 0.45132743 | H5: 0.047077287 | I5: 0.034631922
A6: Revised Downing | B6: 5 | C6: 129 | D6: 103071 | E6: 15267 | F6: 0.33683628 | G6: 0.42920354 | H6: 0.043015106 | I6: 0.0027414852
A7: Evolved ANN | B7: 6 | C7: 174 | D7: 102638 | E7: 13066 | F7: 0.28679204 | G7: 0.2300885 | H7: 0.042658931 | I7: 0.066014802
A8: Second by Rowsam | B8: 7 | C8: 114 | D8: 102153 | E8: 20487 | F8: 0.44935841 | G8: 0.49557522 | H8: 0.067618717 | I8: 0.03840161
A9: DoubleCrosser | B9: 8 | C9: 160 | D9: 102132 | E9: 13256 | F9: 0.29227876 | G9: 0.2920354 | H9: 0.040672672 | I9: 0.059792977
A10: Evolved FSM 16 Noise 05 | B10: 9 | C10: 112 | D10: 101553 | E10: 17311 | F10: 0.38103982 | G10: 0.50442478 | H10: 0.051134999 | I10: 0.025621923
A11: Omega TFT | B11: 10 | C11: 190 | D11: 101325 | E11: 13534 | F11: 0.29827434 | G11: 0.15929204 | H11: 0.045881134 | I11: 0.092684912
A12: Second by Mikkelson | B12: 11 | C12: 95 | D12: 101230 | E12: 22647 | F12: 0.49710177 | G12: 0.57964602 | H12: 0.076517754 | I12: 0.046355705
A13: Second by White | B13: 12 | C13: 35 | D13: 101005 | E13: 28268 | F13: 0.6215708 | G13: 0.84513274 | H13: 0.089851149 | I13: 0.013364757
... A228: EasyGo | B228: 227 | C228: 17 | D228: 85096 | E228: 40292 | F228: 0.88756637 | G228: 0.92477876 | H228: 0.11259223 | I228: -0.095561331
A230: Name | C230: #Wins | D230: TotalScore | E230: #Cooperations | F230: CooperationRating | G230: GoodPartnerRating | H230: EigenJesusRating | I230: EigenMosesRating
A231: Evolved ANN 5 Noise 05 | B231: 1 | C231: 124 | D231: 107813 | E231: 20561 | F231: 0.45311947 | G231: 0.45132743 | H231: 0.066555813 | I231: 0.021699577
A232: Revised Downing | B232: 2 | C232: 125 | D232: 105210 | E232: 15944 | F232: 0.3515708 | G232: 0.44690265 | H232: 0.045515903 | I232: -0.0026273773
A233: Fuzzy | B233: 3 | C233: 94 | D233: 104388 | E233: 21162 | F233: 0.46553097 | G233: 0.5840708 | H233: 0.059590928 | I233: -0.036062513
A234: First by Downing | B234: 4 | C234: 135 | D234: 103833 | E234: 13962 | F234: 0.30853982 | G234: 0.40265487 | H234: 0.040578097 | I234: 0.01441676
A235: Second by RichardHufford | B235: 5 | C235: 124 | D235: 103039 | E235: 15811 | F235: 0.3470354 | G235: 0.45132743 | H235: 0.047588275 | I235: 0.032969237
A236: Evolved FSM 16 Noise 05 | B236: 6 | C236: 106 | D236: 102979 | E236: 17572 | F236: 0.38537611 | G236: 0.53097345 | H236: 0.052463261 | I236: 0.022904291
A237: Second by Borufsen | B237: 7 | C237: 113 | D237: 102244 | E237: 22724 | F237: 0.49911504 | G237: 0.5 | H237: 0.071898425 | I237: 0.03089968
A238: Evolved ANN | B238: 8 | C238: 178 | D238: 102203 | E238: 12012 | F238: 0.2635177 | G238: 0.21238938 | H238: 0.037994546 | I238: 0.068860943
A239: Omega TFT | B239: 9 | C239: 191 | D239: 102080 | E239: 13882 | F239: 0.30650442 | G239: 0.15486726 | H239: 0.047087707 | I239: 0.084975083
A240: Second by White | B240: 10 | C240: 31 | D240: 101812 | E240: 29268 | F240: 0.64365044 | G240: 0.86283186 | H240: 0.092497399 | I240: 0.0056664337
A241: Second by Mikkelson | B241: 11 | C241: 99 | D241: 101784 | E241: 23045 | F241: 0.50586283 | G241: 0.5619469 | H241: 0.077797765 | I241: 0.043205632
A242: Second by GraaskampKatzen | B242: 12 | C242: 191 | D242: 101231 | E242: 12375 | F242: 0.27292035 | G242: 0.15486726 | H242: 0.042088111 | I242: 0.093960554
... A457: Cooperator Hunter | B457: 227 | C457: 20 | D457: 85869 | E457: 40663 | F457: 0.89577434 | G457: 0.91150442 | H457: 0.11393012 | I457: -0.095149244
A459: Name | C459: #Wins | D459: TotalScore | E459: #Cooperations | F459: CooperationRating | G459: GoodPartnerRating | H459: EigenJesusRating | I459: EigenMosesRating
A460: Evolved ANN 5 Noise 05 | B460: 1 | C460: 130 | D460: 107000 | E460: 20085 | F460: 0.44050885 | G460: 0.42477876 | H460: 0.065714055 | I460: 0.032058674
A461: Revised Downing | B461: 2 | C461: 125 | D461: 105403 | E461: 15116 | F461: 0.33316372 | G461: 0.44690265 | H461: 0.042303169 | I461: -0.00072508129
A462: Second by RichardHufford | B462: 3 | C462: 121 | D462: 105232 | E462: 15304 | F462: 0.33528761 | G462: 0.46460177 | H462: 0.045758573 | I462: 0.031831807
A463: First by Downing | B463: 4 | C463: 148 | D463: 104322 | E463: 13182 | F463: 0.29115044 | G463: 0.34513274 | H463: 0.037842857 | I463: 0.019432051
A464: Fuzzy | B464: 5 | C464: 80 | D464: 104317 | E464: 21987 | F464: 0.48340708 | G464: 0.6460177 | H464: 0.061123639 | I464: -0.045176397
A465: Evolved FSM 16 Noise 05 | B465: 6 | C465: 111 | D465: 102943 | E465: 17730 | F465: 0.38951327 | G465: 0.50884956 | H465: 0.052397249 | I465: 0.020692666
A466: DoubleCrosser | B466: 7 | C466: 159 | D466: 102637 | E466: 13022 | F466: 0.28734513 | G466: 0.29646018 | H466: 0.039680649 | I466: 0.052858425
A467: Second by Mikkelson | B467: 8 | C467: 108 | D467: 102376 | E467: 22891 | F467: 0.5025 | G467: 0.52212389 | H467: 0.0767148 | I467: 0.042234939
A468: Second by Rowsam | B468: 9 | C468: 115 | D468: 102073 | E468: 19925 | F468: 0.43681416 | G468: 0.49115044 | H468: 0.067247352 | I468: 0.053656155
A469: Evolved ANN | B469: 10 | C469: 175 | D469: 101729 | E469: 13337 | F469: 0.29219027 | G469: 0.22566372 | H469: 0.042781665 | I469: 0.059422968
A470: Omega TFT | B470: 11 | C470: 186 | D470: 101631 | E470: 12947 | F470: 0.28575221 | G470: 0.17699115 | H470: 0.043730592 | I470: 0.092634681
...

Sheet Adrese
B1: 1 | C1: 2 | D1: 3 | E1: 4 | F1: 5
B2: Svi!$A$2:$I$228 | C2: Svi!$A$231:$I$457 | D2: Svi!$A$460:$I$686 | E2: Svi!$A$689:$I$915 | F2: Svi!$A$918:$I$1144

Sheet Final
C2: Rank | D2: Avg. Score | E2: TotalScore | F2: #Wins | G2: #Cooperations | H2: Cooperation Rating | I2: Good Partner Rating | J2: Eigenjesus Rating | K2: Eigenmoses Rating
B3: Evolved ANN 5 Noise 05 | C3: =Kompilirano!G36 -> 1.4 | D3: =E3/227 -> 470.21762 | E3: =Kompilirano!AA36 -> 106739.4 | F3: =Kompilirano!Q36 -> 128 | G3: =Kompilirano!AI36 -> 20178 | H3: =Kompilirano!AT36 -> 0.44305752 | I3: =Kompilirano!BD36 -> 0.43362832 | J3: =Kompilirano!BN36 -> 0.065529907 | K3: =Kompilirano!BX36 -> 0.026170118
B4: Fuzzy | C4: =Kompilirano!G4 -> 2.6 | D4: =E4/227 -> 463.83877 | E4: =Kompilirano!AA4 -> 105291.4 | F4: =Kompilirano!Q4 -> 89.2 | G4: =Kompilirano!AI4 -> 21552.6 | H4: =Kompilirano!AT4 -> 0.47392478 | I4: =Kompilirano!BD4 -> 0.60530973 | J4: =Kompilirano!BN4 -> 0.059819341 | K4: =Kompilirano!BX4 -> -0.044166409
B5: Revised Downing | C5: =Kompilirano!G30 -> 3.2 | D5: =E5/227 -> 461.2467 | E5: =Kompilirano!AA30 -> 104703 | F5: =Kompilirano!Q30 -> 127 | G5: =Kompilirano!AI30 -> 15486.8 | H5: =Kompilirano!AT30 -> 0.34174779 | I5: =Kompilirano!BD30 -> 0.4380531 | J5: =Kompilirano!BN30 -> 0.043736229 | K5: =Kompilirano!BX30 -> -0.0016411565
B6: Second by RichardHufford | C6: =Kompilirano!G49 -> 3.8 | D6: =E6/227 -> 459.06079 | E6: =Kompilirano!AA49 -> 104206.8 | F6: =Kompilirano!Q49 -> 124 | G6: =Kompilirano!AI49 -> 15534.8 | H6: =Kompilirano!AT49 -> 0.3409115 | I6: =Kompilirano!BD49 -> 0.45132743 | J6: =Kompilirano!BN49 -> 0.046571561 | K6: =Kompilirano!BX49 -> 0.034961343
B7: First by Downing | C7: =Kompilirano!G143 -> 4 | D7: =E7/227 -> 457.18062 | E7: =Kompilirano!AA143 -> 103780 | F7: =Kompilirano!Q143 -> 140.4 | G7: =Kompilirano!AI143 -> 13415.4 | H7: =Kompilirano!AT143 -> 0.29634956 | I7: =Kompilirano!BD143 -> 0.37876106 | J7: =Kompilirano!BN143 -> 0.038557346 | K7: =Kompilirano!BX143 -> 0.016902736
