Workbook

Sheet FINAL FINAL
C2: Achievement | E2: Avg. Morality metrics
B3: Name | C3: Avg. Score | D3: Wins (%) | E3: Cooperation Rating (SD) | F3: Good Partner Rating (SD) | G3: Eigenjesus Rating (SD) | H3: Eigenmoses Rating (SD)
B4: Downing | C4: =VLOOKUP(B4,Kompilirano!T:Z,7,FALSE)/15/5 -> 452.48 | D4: =VLOOKUP(B4,Kompilirano!J:P,7,FALSE)/15/5 -> 0.54666667 | E4: =VLOOKUP(B4,Kompilirano!AM:AS,7,FALSE) -> 0.37 (0.02) | F4: =VLOOKUP(B4,Kompilirano!AW:BD,7,FALSE) -> 0.45 (0.09) | G4: =VLOOKUP(B4,Kompilirano!BG:BM,7,FALSE) -> 0.19 (0.01) | H4: =VLOOKUP(B4,Kompilirano!BQ:BW,7,FALSE) -> -0.10 (0.08)
B5: Fuzzy | C5: =VLOOKUP(B5,Kompilirano!T:Z,7,FALSE)/15/5 -> 446.76 | D5: =VLOOKUP(B5,Kompilirano!J:P,7,FALSE)/15/5 -> 0.29333333 | E5: =VLOOKUP(B5,Kompilirano!AM:AS,7,FALSE) -> 0.51 (0.05) | F5: =VLOOKUP(B5,Kompilirano!AW:BD,7,FALSE) -> 0.71 (0.06) | G5: =VLOOKUP(B5,Kompilirano!BG:BM,7,FALSE) -> 0.28 (0.03) | H5: =VLOOKUP(B5,Kompilirano!BQ:BW,7,FALSE) -> -0.25 (0.05)
B6: Tideman and Chieruzzi | C6: =VLOOKUP(B6,Kompilirano!T:Z,7,FALSE)/15/5 -> 430.05333 | D6: =VLOOKUP(B6,Kompilirano!J:P,7,FALSE)/15/5 -> 0.8 | E6: =VLOOKUP(B6,Kompilirano!AM:AS,7,FALSE) -> 0.32 (0.02) | F6: =VLOOKUP(B6,Kompilirano!AW:BD,7,FALSE) -> 0.20 (0.07) | G6: =VLOOKUP(B6,Kompilirano!BG:BM,7,FALSE) -> 0.20 (0.01) | H6: =VLOOKUP(B6,Kompilirano!BQ:BW,7,FALSE) -> 0.36 (0.03)
B7: Stein and Rapoport | C7: =VLOOKUP(B7,Kompilirano!T:Z,7,FALSE)/15/5 -> 429.70667 | D7: =VLOOKUP(B7,Kompilirano!J:P,7,FALSE)/15/5 -> 0.58666667 | E7: =VLOOKUP(B7,Kompilirano!AM:AS,7,FALSE) -> 0.33 (0.01) | F7: =VLOOKUP(B7,Kompilirano!AW:BD,7,FALSE) -> 0.41 (0.09) | G7: =VLOOKUP(B7,Kompilirano!BG:BM,7,FALSE) -> 0.20 (0.01) | H7: =VLOOKUP(B7,Kompilirano!BQ:BW,7,FALSE) -> 0.26 (0.01)
B8: Feld | C8: =VLOOKUP(B8,Kompilirano!T:Z,7,FALSE)/15/5 -> 429.6 | D8: =VLOOKUP(B8,Kompilirano!J:P,7,FALSE)/15/5 -> 0.6 | E8: =VLOOKUP(B8,Kompilirano!AM:AS,7,FALSE) -> 0.37 (0.02) | F8: =VLOOKUP(B8,Kompilirano!AW:BD,7,FALSE) -> 0.40 (0.00) | G8: =VLOOKUP(B8,Kompilirano!BG:BM,7,FALSE) -> 0.22 (0.01) | H8: =VLOOKUP(B8,Kompilirano!BQ:BW,7,FALSE) -> 0.29 (0.03)
B9: Grudger | C9: =VLOOKUP(B9,Kompilirano!T:Z,7,FALSE)/15/5 -> 422.76 | D9: =VLOOKUP(B9,Kompilirano!J:P,7,FALSE)/15/5 -> 0.92 | E9: =VLOOKUP(B9,Kompilirano!AM:AS,7,FALSE) -> 0.12 (0.00) | F9: =VLOOKUP(B9,Kompilirano!AW:BD,7,FALSE) -> 0.08 (0.06) | G9: =VLOOKUP(B9,Kompilirano!BG:BM,7,FALSE) -> 0.07 (0.00) | H9: =VLOOKUP(B9,Kompilirano!BQ:BW,7,FALSE) -> 0.32 (0.02)
B10: Joss | C10: =VLOOKUP(B10,Kompilirano!T:Z,7,FALSE)/15/5 -> 420.76 | D10: =VLOOKUP(B10,Kompilirano!J:P,7,FALSE)/15/5 -> 0.50666667 | E10: =VLOOKUP(B10,Kompilirano!AM:AS,7,FALSE) -> 0.42 (0.01) | F10: =VLOOKUP(B10,Kompilirano!AW:BD,7,FALSE) -> 0.49 (0.06) | G10: =VLOOKUP(B10,Kompilirano!BG:BM,7,FALSE) -> 0.25 (0.00) | H10: =VLOOKUP(B10,Kompilirano!BQ:BW,7,FALSE) -> 0.29 (0.02)
B11: Davis | C11: =VLOOKUP(B11,Kompilirano!T:Z,7,FALSE)/15/5 -> 419.38667 | D11: =VLOOKUP(B11,Kompilirano!J:P,7,FALSE)/15/5 -> 0.90666667 | E11: =VLOOKUP(B11,Kompilirano!AM:AS,7,FALSE) -> 0.15 (0.01) | F11: =VLOOKUP(B11,Kompilirano!AW:BD,7,FALSE) -> 0.09 (0.06) | G11: =VLOOKUP(B11,Kompilirano!BG:BM,7,FALSE) -> 0.08 (0.01) | H11: =VLOOKUP(B11,Kompilirano!BQ:BW,7,FALSE) -> 0.31 (0.01)
B12: Shubik | C12: =VLOOKUP(B12,Kompilirano!T:Z,7,FALSE)/15/5 -> 417.90667 | D12: =VLOOKUP(B12,Kompilirano!J:P,7,FALSE)/15/5 -> 0.66666667 | E12: =VLOOKUP(B12,Kompilirano!AM:AS,7,FALSE) -> 0.29 (0.01) | F12: =VLOOKUP(B12,Kompilirano!AW:BD,7,FALSE) -> 0.33 (0.07) | G12: =VLOOKUP(B12,Kompilirano!BG:BM,7,FALSE) -> 0.17 (0.01) | H12: =VLOOKUP(B12,Kompilirano!BQ:BW,7,FALSE) -> 0.31 (0.02)
B13: Tit For Tat | C13: =VLOOKUP(B13,Kompilirano!T:Z,7,FALSE)/15/5 -> 415.8 | D13: =VLOOKUP(B13,Kompilirano!J:P,7,FALSE)/15/5 -> 0.34666667 | E13: =VLOOKUP(B13,Kompilirano!AM:AS,7,FALSE) -> 0.46 (0.02) | F13: =VLOOKUP(B13,Kompilirano!AW:BD,7,FALSE) -> 0.65 (0.06) | G13: =VLOOKUP(B13,Kompilirano!BG:BM,7,FALSE) -> 0.28 (0.01) | H13: =VLOOKUP(B13,Kompilirano!BQ:BW,7,FALSE) -> 0.27 (0.02)
B14: Graaskamp | C14: =VLOOKUP(B14,Kompilirano!T:Z,7,FALSE)/15/5 -> 396.29333 | D14: =VLOOKUP(B14,Kompilirano!J:P,7,FALSE)/15/5 -> 0.54666667 | E14: =VLOOKUP(B14,Kompilirano!AM:AS,7,FALSE) -> 0.45 (0.05) | F14: =VLOOKUP(B14,Kompilirano!AW:BD,7,FALSE) -> 0.45 (0.06) | G14: =VLOOKUP(B14,Kompilirano!BG:BM,7,FALSE) -> 0.24 (0.02) | H14: =VLOOKUP(B14,Kompilirano!BQ:BW,7,FALSE) -> 0.08 (0.04)
B15: Tullock | C15: =VLOOKUP(B15,Kompilirano!T:Z,7,FALSE)/15/5 -> 395.2 | D15: =VLOOKUP(B15,Kompilirano!J:P,7,FALSE)/15/5 -> 0.54666667 | E15: =VLOOKUP(B15,Kompilirano!AM:AS,7,FALSE) -> 0.36 (0.03) | F15: =VLOOKUP(B15,Kompilirano!AW:BD,7,FALSE) -> 0.45 (0.06) | G15: =VLOOKUP(B15,Kompilirano!BG:BM,7,FALSE) -> 0.22 (0.01) | H15: =VLOOKUP(B15,Kompilirano!BQ:BW,7,FALSE) -> 0.30 (0.03)
... B19: Anonymous | C19: =VLOOKUP(B19,Kompilirano!T:Z,7,FALSE)/15/5 -> 339.73333 | D19: =VLOOKUP(B19,Kompilirano!J:P,7,FALSE)/15/5 -> 0.21333333 | E19: =VLOOKUP(B19,Kompilirano!AM:AS,7,FALSE) -> 0.50 (0.01) | F19: =VLOOKUP(B19,Kompilirano!AW:BD,7,FALSE) -> 0.79 (0.07) | G19: =VLOOKUP(B19,Kompilirano!BG:BM,7,FALSE) -> 0.27 (0.01) | H19: =VLOOKUP(B19,Kompilirano!BQ:BW,7,FALSE) -> 0.00 (0.01)

Sheet Kompilirano
A2: Name | B2: Rank 1 | C2: Rank 2 | D2: Rank 3 | E2: Rank 4 | F2: Rank 5 | G2: Avg | J2: Name | K2: Wins 1 | L2: Wins 2 | M2: Wins 3 | N2: Wins 4 | O2: Wins 5 | Q2: Avg | T2: Name | U2: Total Score 1 | V2: Total Score 2 | W2: Total Score 3 | X2: Total Score 4 | Y2: Total Score 5 | AA2: Avg | AB2: SD | AD2: Name | AE2: #Cooperations 1 | AF2: #Cooperations 2 | AG2: #Cooperations 3 | AH2: #Cooperations 4 | AI2: #Cooperations 5 | AJ2: Avg | AK2: SD | AM2: Name | AN2: CoopRating 1 | AO2: CoopRating 2 | AP2: CoopRating 3 | AQ2: CoopRating 4 | AR2: CoopRating 5 | AT2: Avg | AU2: sd | AW2: Name | AX2: GP Rating 1 | AY2: GP Rating 2 | AZ2: GP Rating 3 | BA2: GP Rating 4 | BB2: GP Rating 5 | BD2: Avg | BG2: Name | BH2: EJ Rating 1 | BI2: EJ Rating 2 | BJ2: EJ Rating 3 | BK2: EJ Rating 4 | BL2: EJ Rating 5 | BN2: Avg | BQ2: Name | BR2: EM Rating 1 | BS2: EM Rating 2 | BT2: EM Rating 3 | BU2: EM Rating 4 | BV2: EM Rating 5 | BX2: Avg
A3: Fuzzy | B3: =+VLOOKUP($A3,INDIRECT(Adrese!B$2),2,FALSE) -> 3 | C3: =+VLOOKUP($A3,INDIRECT(Adrese!C$2),2,FALSE) -> 2 | D3: =+VLOOKUP($A3,INDIRECT(Adrese!D$2),2,FALSE) -> 1 | E3: =+VLOOKUP($A3,INDIRECT(Adrese!E$2),2,FALSE) -> 1 | F3: =+VLOOKUP($A3,INDIRECT(Adrese!F$2),2,FALSE) -> 3 | G3: =AVERAGE(B3:F3) -> 2 | J3: Fuzzy | K3: =+VLOOKUP($A3,INDIRECT(Adrese!B$2),3,FALSE) -> 3 | L3: =+VLOOKUP($A3,INDIRECT(Adrese!C$2),3,FALSE) -> 5 | M3: =+VLOOKUP($A3,INDIRECT(Adrese!D$2),3,FALSE) -> 4 | N3: =+VLOOKUP($A3,INDIRECT(Adrese!E$2),3,FALSE) -> 5 | O3: =+VLOOKUP($A3,INDIRECT(Adrese!F$2),3,FALSE) -> 5 | P3: =SUM(K3:O3) -> 22 | Q3: =AVERAGE(K3:O3) -> 4.4 | T3: Fuzzy | U3: =+VLOOKUP($T3,INDIRECT(Adrese!B$2),4,FALSE) -> 6604 | V3: =+VLOOKUP($T3,INDIRECT(Adrese!C$2),4,FALSE) -> 6671 | W3: =+VLOOKUP($T3,INDIRECT(Adrese!D$2),4,FALSE) -> 6924 | X3: =+VLOOKUP($T3,INDIRECT(Adrese!E$2),4,FALSE) -> 6757 | Y3: =+VLOOKUP($T3,INDIRECT(Adrese!F$2),4,FALSE) -> 6551 | Z3: =SUM(U3:Y3) -> 33507 | AA3: =AVERAGE(U3:Y3) -> 6701.4 | AD3: Fuzzy | AE3: =+VLOOKUP($A3,INDIRECT(Adrese!B$2),5,FALSE) -> 1883 | AF3: =+VLOOKUP($A3,INDIRECT(Adrese!C$2),5,FALSE) -> 1397 | AG3: =+VLOOKUP($A3,INDIRECT(Adrese!D$2),5,FALSE) -> 1771 | AH3: =+VLOOKUP($A3,INDIRECT(Adrese!E$2),5,FALSE) -> 1674 | AI3: =+VLOOKUP($A3,INDIRECT(Adrese!F$2),5,FALSE) -> 1528 | AJ3: =AVERAGE(AE3:AI3) -> 1650.6 | AK3: =_xlfn.STDEV.S(AE3:AI3) -> 192.61179 | AM3: Fuzzy | AN3: =+VLOOKUP($A3,INDIRECT(Adrese!B$2),6,FALSE) -> 0.577 | AO3: =+VLOOKUP($A3,INDIRECT(Adrese!C$2),6,FALSE) -> 0.46133333 | AP3: =+VLOOKUP($A3,INDIRECT(Adrese!D$2),6,FALSE) -> 0.54833333 | AQ3: =+VLOOKUP($A3,INDIRECT(Adrese!E$2),6,FALSE) -> 0.508 | AR3: =+VLOOKUP($A3,INDIRECT(Adrese!F$2),6,FALSE) -> 0.45666667 | AS3: =TEXT(AT3,"0.00")&" ("&TEXT(AU3,"0.00")&")" -> 0.51 (0.05) | AT3: =AVERAGE(AN3:AR3) -> 0.51026667 | AU3: =_xlfn.STDEV.S(AN3:AR3) -> 0.052855884 | AW3: Fuzzy | AX3: =+VLOOKUP($A3,INDIRECT(Adrese!B$2),7,FALSE) -> 0.8 | AY3: =+VLOOKUP($A3,INDIRECT(Adrese!C$2),7,FALSE) -> 0.66666667 | AZ3: =+VLOOKUP($A3,INDIRECT(Adrese!D$2),7,FALSE) -> 0.73333333 | BA3: =+VLOOKUP($A3,INDIRECT(Adrese!E$2),7,FALSE) -> 0.66666667 | BB3: =+VLOOKUP($A3,INDIRECT(Adrese!F$2),7,FALSE) -> 0.66666667 | BC3: =TEXT(BD3,"0.00")&" ("&TEXT(BE3,"0.00")&")" -> 0.71 (0.06) | BD3: =AVERAGE(AX3:BB3) -> 0.70666667 | BE3: =_xlfn.STDEV.S(AX3:BB3) -> 0.059628479 | BG3: Fuzzy | BH3: =+VLOOKUP($BG3,INDIRECT(Adrese!B$2),8,FALSE) -> 0.30938308 | BI3: =+VLOOKUP($BG3,INDIRECT(Adrese!C$2),8,FALSE) -> 0.23557549 | BJ3: =+VLOOKUP($BG3,INDIRECT(Adrese!D$2),8,FALSE) -> 0.29334799 | BK3: =+VLOOKUP($BG3,INDIRECT(Adrese!E$2),8,FALSE) -> 0.28067026 | BL3: =+VLOOKUP($BG3,INDIRECT(Adrese!F$2),8,FALSE) -> 0.2654406 | BM3: =TEXT(BN3,"0.00")&" ("&TEXT(BO3,"0.00")&")" -> 0.28 (0.03) | BN3: =AVERAGE(BH3:BL3) -> 0.27688348 | BO3: =_xlfn.STDEV.S(BH3:BL3) -> 0.028191013 | BQ3: Fuzzy | BR3: =+VLOOKUP($BG3,INDIRECT(Adrese!B$2),9,FALSE) -> -0.26661263 | BS3: =+VLOOKUP($BG3,INDIRECT(Adrese!C$2),9,FALSE) -> -0.24621669 | BT3: =+VLOOKUP($BG3,INDIRECT(Adrese!D$2),9,FALSE) -> -0.29514666 | BU3: =+VLOOKUP($BG3,INDIRECT(Adrese!E$2),9,FALSE) -> -0.2596596 | BV3: =+VLOOKUP($BG3,INDIRECT(Adrese!F$2),9,FALSE) -> -0.16733923 | BW3: =TEXT(BX3,"0.00")&" ("&TEXT(BY3,"0.00")&")" -> -0.25 (0.05) | BX3: =AVERAGE(BR3:BV3) -> -0.24699496 | BY3: =_xlfn.STDEV.S(BR3:BV3) -> 0.047982999
A4: Stein and Rapoport | B4: =+VLOOKUP($A4,INDIRECT(Adrese!B$2),2,FALSE) -> 4 | C4: =+VLOOKUP($A4,INDIRECT(Adrese!C$2),2,FALSE) -> 3 | D4: =+VLOOKUP($A4,INDIRECT(Adrese!D$2),2,FALSE) -> 6 | E4: =+VLOOKUP($A4,INDIRECT(Adrese!E$2),2,FALSE) -> 4 | F4: =+VLOOKUP($A4,INDIRECT(Adrese!F$2),2,FALSE) -> 6 | G4: =AVERAGE(B4:F4) -> 4.6 | J4: Stein and Rapoport | K4: =+VLOOKUP($A4,INDIRECT(Adrese!B$2),3,FALSE) -> 8 | L4: =+VLOOKUP($A4,INDIRECT(Adrese!C$2),3,FALSE) -> 10 | M4: =+VLOOKUP($A4,INDIRECT(Adrese!D$2),3,FALSE) -> 7 | N4: =+VLOOKUP($A4,INDIRECT(Adrese!E$2),3,FALSE) -> 10 | O4: =+VLOOKUP($A4,INDIRECT(Adrese!F$2),3,FALSE) -> 9 | P4: =SUM(K4:O4) -> 44 | Q4: =AVERAGE(K4:O4) -> 8.8 | T4: Stein and Rapoport | U4: =+VLOOKUP($T4,INDIRECT(Adrese!B$2),4,FALSE) -> 6575 | V4: =+VLOOKUP($T4,INDIRECT(Adrese!C$2),4,FALSE) -> 6553 | W4: =+VLOOKUP($T4,INDIRECT(Adrese!D$2),4,FALSE) -> 6361 | X4: =+VLOOKUP($T4,INDIRECT(Adrese!E$2),4,FALSE) -> 6398 | Y4: =+VLOOKUP($T4,INDIRECT(Adrese!F$2),4,FALSE) -> 6341 | Z4: =SUM(U4:Y4) -> 32228 | AA4: =AVERAGE(U4:Y4) -> 6445.6 | AD4: Stein and Rapoport | AE4: =+VLOOKUP($A4,INDIRECT(Adrese!B$2),5,FALSE) -> 1069 | AF4: =+VLOOKUP($A4,INDIRECT(Adrese!C$2),5,FALSE) -> 1084 | AG4: =+VLOOKUP($A4,INDIRECT(Adrese!D$2),5,FALSE) -> 1063 | AH4: =+VLOOKUP($A4,INDIRECT(Adrese!E$2),5,FALSE) -> 1072 | AI4: =+VLOOKUP($A4,INDIRECT(Adrese!F$2),5,FALSE) -> 1030 | AJ4: =AVERAGE(AE4:AI4) -> 1063.6 | AK4: =_xlfn.STDEV.S(AE4:AI4) -> 20.280533 | AM4: Stein and Rapoport | AN4: =+VLOOKUP($A4,INDIRECT(Adrese!B$2),6,FALSE) -> 0.33033333 | AO4: =+VLOOKUP($A4,INDIRECT(Adrese!C$2),6,FALSE) -> 0.334 | AP4: =+VLOOKUP($A4,INDIRECT(Adrese!D$2),6,FALSE) -> 0.33333333 | AQ4: =+VLOOKUP($A4,INDIRECT(Adrese!E$2),6,FALSE) -> 0.33266667 | AR4: =+VLOOKUP($A4,INDIRECT(Adrese!F$2),6,FALSE) -> 0.31666667 | AS4: =TEXT(AT4,"0.00")&" ("&TEXT(AU4,"0.00")&")" -> 0.33 (0.01) | AT4: =AVERAGE(AN4:AR4) -> 0.3294 | AU4: =_xlfn.STDEV.S(AN4:AR4) -> 0.0072510534 | AW4: Stein and Rapoport | AX4: =+VLOOKUP($A4,INDIRECT(Adrese!B$2),7,FALSE) -> 0.46666667 | AY4: =+VLOOKUP($A4,INDIRECT(Adrese!C$2),7,FALSE) -> 0.33333333 | AZ4: =+VLOOKUP($A4,INDIRECT(Adrese!D$2),7,FALSE) -> 0.53333333 | BA4: =+VLOOKUP($A4,INDIRECT(Adrese!E$2),7,FALSE) -> 0.33333333 | BB4: =+VLOOKUP($A4,INDIRECT(Adrese!F$2),7,FALSE) -> 0.4 | BC4: =TEXT(BD4,"0.00")&" ("&TEXT(BE4,"0.00")&")" -> 0.41 (0.09) | BD4: =AVERAGE(AX4:BB4) -> 0.41333333 | BE4: =_xlfn.STDEV.S(AX4:BB4) -> 0.086922699 | BG4: Stein and Rapoport | BH4: =+VLOOKUP($BG4,INDIRECT(Adrese!B$2),8,FALSE) -> 0.19878996 | BI4: =+VLOOKUP($BG4,INDIRECT(Adrese!C$2),8,FALSE) -> 0.19941141 | BJ4: =+VLOOKUP($BG4,INDIRECT(Adrese!D$2),8,FALSE) -> 0.20372282 | BK4: =+VLOOKUP($BG4,INDIRECT(Adrese!E$2),8,FALSE) -> 0.20884472 | BL4: =+VLOOKUP($BG4,INDIRECT(Adrese!F$2),8,FALSE) -> 0.19252761 | BM4: =TEXT(BN4,"0.00")&" ("&TEXT(BO4,"0.00")&")" -> 0.20 (0.01) | BN4: =AVERAGE(BH4:BL4) -> 0.20065931 | BO4: =_xlfn.STDEV.S(BH4:BL4) -> 0.0060737593 | BQ4: Stein and Rapoport | BR4: =+VLOOKUP($BG4,INDIRECT(Adrese!B$2),9,FALSE) -> 0.25069571 | BS4: =+VLOOKUP($BG4,INDIRECT(Adrese!C$2),9,FALSE) -> 0.26211808 | BT4: =+VLOOKUP($BG4,INDIRECT(Adrese!D$2),9,FALSE) -> 0.27156113 | BU4: =+VLOOKUP($BG4,INDIRECT(Adrese!E$2),9,FALSE) -> 0.25457064 | BV4: =+VLOOKUP($BG4,INDIRECT(Adrese!F$2),9,FALSE) -> 0.23996111 | BW4: =TEXT(BX4,"0.00")&" ("&TEXT(BY4,"0.00")&")" -> 0.26 (0.01) | BX4: =AVERAGE(BR4:BV4) -> 0.25578133 | BY4: =_xlfn.STDEV.S(BR4:BV4) -> 0.011903418
A5: Grofman | B5: =+VLOOKUP($A5,INDIRECT(Adrese!B$2),2,FALSE) -> 13 | C5: =+VLOOKUP($A5,INDIRECT(Adrese!C$2),2,FALSE) -> 13 | D5: =+VLOOKUP($A5,INDIRECT(Adrese!D$2),2,FALSE) -> 15 | E5: =+VLOOKUP($A5,INDIRECT(Adrese!E$2),2,FALSE) -> 12 | F5: =+VLOOKUP($A5,INDIRECT(Adrese!F$2),2,FALSE) -> 15 | G5: =AVERAGE(B5:F5) -> 13.6 | J5: Grofman | K5: =+VLOOKUP($A5,INDIRECT(Adrese!B$2),3,FALSE) -> 2 | L5: =+VLOOKUP($A5,INDIRECT(Adrese!C$2),3,FALSE) -> 2 | M5: =+VLOOKUP($A5,INDIRECT(Adrese!D$2),3,FALSE) -> 1 | N5: =+VLOOKUP($A5,INDIRECT(Adrese!E$2),3,FALSE) -> 2 | O5: =+VLOOKUP($A5,INDIRECT(Adrese!F$2),3,FALSE) -> 1 | P5: =SUM(K5:O5) -> 8 | Q5: =AVERAGE(K5:O5) -> 1.6 | T5: Grofman | U5: =+VLOOKUP($T5,INDIRECT(Adrese!B$2),4,FALSE) -> 5486 | V5: =+VLOOKUP($T5,INDIRECT(Adrese!C$2),4,FALSE) -> 5518 | W5: =+VLOOKUP($T5,INDIRECT(Adrese!D$2),4,FALSE) -> 5174 | X5: =+VLOOKUP($T5,INDIRECT(Adrese!E$2),4,FALSE) -> 5810 | Y5: =+VLOOKUP($T5,INDIRECT(Adrese!F$2),4,FALSE) -> 5105 | Z5: =SUM(U5:Y5) -> 27093 | AA5: =AVERAGE(U5:Y5) -> 5418.6 | AD5: Grofman | AE5: =+VLOOKUP($A5,INDIRECT(Adrese!B$2),5,FALSE) -> 2058 | AF5: =+VLOOKUP($A5,INDIRECT(Adrese!C$2),5,FALSE) -> 2011 | AG5: =+VLOOKUP($A5,INDIRECT(Adrese!D$2),5,FALSE) -> 2006 | AH5: =+VLOOKUP($A5,INDIRECT(Adrese!E$2),5,FALSE) -> 2044 | AI5: =+VLOOKUP($A5,INDIRECT(Adrese!F$2),5,FALSE) -> 2048 | AJ5: =AVERAGE(AE5:AI5) -> 2033.4 | AK5: =_xlfn.STDEV.S(AE5:AI5) -> 23.362363 | AM5: Grofman | AN5: =+VLOOKUP($A5,INDIRECT(Adrese!B$2),6,FALSE) -> 0.63366667 | AO5: =+VLOOKUP($A5,INDIRECT(Adrese!C$2),6,FALSE) -> 0.624 | AP5: =+VLOOKUP($A5,INDIRECT(Adrese!D$2),6,FALSE) -> 0.61933333 | AQ5: =+VLOOKUP($A5,INDIRECT(Adrese!E$2),6,FALSE) -> 0.63133333 | AR5: =+VLOOKUP($A5,INDIRECT(Adrese!F$2),6,FALSE) -> 0.63166667 | AS5: =TEXT(AT5,"0.00")&" ("&TEXT(AU5,"0.00")&")" -> 0.63 (0.01) | AT5: =AVERAGE(AN5:AR5) -> 0.628 | AU5: =_xlfn.STDEV.S(AN5:AR5) -> 0.0060781944 | AW5: Grofman | AX5: =+VLOOKUP($A5,INDIRECT(Adrese!B$2),7,FALSE) -> 0.86666667 | AY5: =+VLOOKUP($A5,INDIRECT(Adrese!C$2),7,FALSE) -> 0.86666667 | AZ5: =+VLOOKUP($A5,INDIRECT(Adrese!D$2),7,FALSE) -> 0.93333333 | BA5: =+VLOOKUP($A5,INDIRECT(Adrese!E$2),7,FALSE) -> 0.86666667 | BB5: =+VLOOKUP($A5,INDIRECT(Adrese!F$2),7,FALSE) -> 0.93333333 | BC5: =TEXT(BD5,"0.00")&" ("&TEXT(BE5,"0.00")&")" -> 0.89 (0.04) | BD5: =AVERAGE(AX5:BB5) -> 0.89333333 | BE5: =_xlfn.STDEV.S(AX5:BB5) -> 0.036514837 | BG5: Grofman | BH5: =+VLOOKUP($BG5,INDIRECT(Adrese!B$2),8,FALSE) -> 0.35223434 | BI5: =+VLOOKUP($BG5,INDIRECT(Adrese!C$2),8,FALSE) -> 0.35101546 | BJ5: =+VLOOKUP($BG5,INDIRECT(Adrese!D$2),8,FALSE) -> 0.34533927 | BK5: =+VLOOKUP($BG5,INDIRECT(Adrese!E$2),8,FALSE) -> 0.35547721 | BL5: =+VLOOKUP($BG5,INDIRECT(Adrese!F$2),8,FALSE) -> 0.36007642 | BM5: =TEXT(BN5,"0.00")&" ("&TEXT(BO5,"0.00")&")" -> 0.35 (0.01) | BN5: =AVERAGE(BH5:BL5) -> 0.35282854 | BO5: =_xlfn.STDEV.S(BH5:BL5) -> 0.0054606968 | BQ5: Grofman | BR5: =+VLOOKUP($BG5,INDIRECT(Adrese!B$2),9,FALSE) -> -0.10689377 | BS5: =+VLOOKUP($BG5,INDIRECT(Adrese!C$2),9,FALSE) -> -0.10288188 | BT5: =+VLOOKUP($BG5,INDIRECT(Adrese!D$2),9,FALSE) -> -0.10536734 | BU5: =+VLOOKUP($BG5,INDIRECT(Adrese!E$2),9,FALSE) -> -0.10972572 | BV5: =+VLOOKUP($BG5,INDIRECT(Adrese!F$2),9,FALSE) -> -0.11203525 | BW5: =TEXT(BX5,"0.00")&" ("&TEXT(BY5,"0.00")&")" -> -0.11 (0.00) | BX5: =AVERAGE(BR5:BV5) -> -0.10738079 | BY5: =_xlfn.STDEV.S(BR5:BV5) -> 0.0035949293
A6: Tit For Tat | B6: =+VLOOKUP($A6,INDIRECT(Adrese!B$2),2,FALSE) -> 8 | C6: =+VLOOKUP($A6,INDIRECT(Adrese!C$2),2,FALSE) -> 11 | D6: =+VLOOKUP($A6,INDIRECT(Adrese!D$2),2,FALSE) -> 7 | E6: =+VLOOKUP($A6,INDIRECT(Adrese!E$2),2,FALSE) -> 9 | F6: =+VLOOKUP($A6,INDIRECT(Adrese!F$2),2,FALSE) -> 10 | G6: =AVERAGE(B6:F6) -> 9 | J6: Tit For Tat | K6: =+VLOOKUP($A6,INDIRECT(Adrese!B$2),3,FALSE) -> 5 | L6: =+VLOOKUP($A6,INDIRECT(Adrese!C$2),3,FALSE) -> 5 | M6: =+VLOOKUP($A6,INDIRECT(Adrese!D$2),3,FALSE) -> 6 | N6: =+VLOOKUP($A6,INDIRECT(Adrese!E$2),3,FALSE) -> 4 | O6: =+VLOOKUP($A6,INDIRECT(Adrese!F$2),3,FALSE) -> 6 | P6: =SUM(K6:O6) -> 26 | Q6: =AVERAGE(K6:O6) -> 5.2 | T6: Tit For Tat | U6: =+VLOOKUP($T6,INDIRECT(Adrese!B$2),4,FALSE) -> 6336 | V6: =+VLOOKUP($T6,INDIRECT(Adrese!C$2),4,FALSE) -> 6145 | W6: =+VLOOKUP($T6,INDIRECT(Adrese!D$2),4,FALSE) -> 6353 | X6: =+VLOOKUP($T6,INDIRECT(Adrese!E$2),4,FALSE) -> 6291 | Y6: =+VLOOKUP($T6,INDIRECT(Adrese!F$2),4,FALSE) -> 6060 | Z6: =SUM(U6:Y6) -> 31185 | AA6: =AVERAGE(U6:Y6) -> 6237 | AD6: Tit For Tat | AE6: =+VLOOKUP($A6,INDIRECT(Adrese!B$2),5,FALSE) -> 1539 | AF6: =+VLOOKUP($A6,INDIRECT(Adrese!C$2),5,FALSE) -> 1468 | AG6: =+VLOOKUP($A6,INDIRECT(Adrese!D$2),5,FALSE) -> 1528 | AH6: =+VLOOKUP($A6,INDIRECT(Adrese!E$2),5,FALSE) -> 1474 | AI6: =+VLOOKUP($A6,INDIRECT(Adrese!F$2),5,FALSE) -> 1405 | AJ6: =AVERAGE(AE6:AI6) -> 1482.8 | AK6: =_xlfn.STDEV.S(AE6:AI6) -> 53.737324 | AM6: Tit For Tat | AN6: =+VLOOKUP($A6,INDIRECT(Adrese!B$2),6,FALSE) -> 0.47833333 | AO6: =+VLOOKUP($A6,INDIRECT(Adrese!C$2),6,FALSE) -> 0.454 | AP6: =+VLOOKUP($A6,INDIRECT(Adrese!D$2),6,FALSE) -> 0.47766667 | AQ6: =+VLOOKUP($A6,INDIRECT(Adrese!E$2),6,FALSE) -> 0.46266667 | AR6: =+VLOOKUP($A6,INDIRECT(Adrese!F$2),6,FALSE) -> 0.43633333 | AS6: =TEXT(AT6,"0.00")&" ("&TEXT(AU6,"0.00")&")" -> 0.46 (0.02) | AT6: =AVERAGE(AN6:AR6) -> 0.4618 | AU6: =_xlfn.STDEV.S(AN6:AR6) -> 0.017573022 | AW6: Tit For Tat | AX6: =+VLOOKUP($A6,INDIRECT(Adrese!B$2),7,FALSE) -> 0.66666667 | AY6: =+VLOOKUP($A6,INDIRECT(Adrese!C$2),7,FALSE) -> 0.66666667 | AZ6: =+VLOOKUP($A6,INDIRECT(Adrese!D$2),7,FALSE) -> 0.6 | BA6: =+VLOOKUP($A6,INDIRECT(Adrese!E$2),7,FALSE) -> 0.73333333 | BB6: =+VLOOKUP($A6,INDIRECT(Adrese!F$2),7,FALSE) -> 0.6 | BC6: =TEXT(BD6,"0.00")&" ("&TEXT(BE6,"0.00")&")" -> 0.65 (0.06) | BD6: =AVERAGE(AX6:BB6) -> 0.65333333 | BE6: =_xlfn.STDEV.S(AX6:BB6) -> 0.055777335 | BG6: Tit For Tat | BH6: =+VLOOKUP($BG6,INDIRECT(Adrese!B$2),8,FALSE) -> 0.28840448 | BI6: =+VLOOKUP($BG6,INDIRECT(Adrese!C$2),8,FALSE) -> 0.27491114 | BJ6: =+VLOOKUP($BG6,INDIRECT(Adrese!D$2),8,FALSE) -> 0.28822655 | BK6: =+VLOOKUP($BG6,INDIRECT(Adrese!E$2),8,FALSE) -> 0.28273781 | BL6: =+VLOOKUP($BG6,INDIRECT(Adrese!F$2),8,FALSE) -> 0.2680909 | BM6: =TEXT(BN6,"0.00")&" ("&TEXT(BO6,"0.00")&")" -> 0.28 (0.01) | BN6: =AVERAGE(BH6:BL6) -> 0.28047417 | BO6: =_xlfn.STDEV.S(BH6:BL6) -> 0.0088375043 | BQ6: Tit For Tat | BR6: =+VLOOKUP($BG6,INDIRECT(Adrese!B$2),9,FALSE) -> 0.24351083 | BS6: =+VLOOKUP($BG6,INDIRECT(Adrese!C$2),9,FALSE) -> 0.25200801 | BT6: =+VLOOKUP($BG6,INDIRECT(Adrese!D$2),9,FALSE) -> 0.27186506 | BU6: =+VLOOKUP($BG6,INDIRECT(Adrese!E$2),9,FALSE) -> 0.26270822 | BV6: =+VLOOKUP($BG6,INDIRECT(Adrese!F$2),9,FALSE) -> 0.29627688 | BW6: =TEXT(BX6,"0.00")&" ("&TEXT(BY6,"0.00")&")" -> 0.27 (0.02) | BX6: =AVERAGE(BR6:BV6) -> 0.2652738 | BY6: =_xlfn.STDEV.S(BR6:BV6) -> 0.020376616
A7: Nydegger | B7: =+VLOOKUP($A7,INDIRECT(Adrese!B$2),2,FALSE) -> 14 | C7: =+VLOOKUP($A7,INDIRECT(Adrese!C$2),2,FALSE) -> 14 | D7: =+VLOOKUP($A7,INDIRECT(Adrese!D$2),2,FALSE) -> 13 | E7: =+VLOOKUP($A7,INDIRECT(Adrese!E$2),2,FALSE) -> 16 | F7: =+VLOOKUP($A7,INDIRECT(Adrese!F$2),2,FALSE) -> 13 | G7: =AVERAGE(B7:F7) -> 14 | J7: Nydegger | K7: =+VLOOKUP($A7,INDIRECT(Adrese!B$2),3,FALSE) -> 0 | L7: =+VLOOKUP($A7,INDIRECT(Adrese!C$2),3,FALSE) -> 1 | M7: =+VLOOKUP($A7,INDIRECT(Adrese!D$2),3,FALSE) -> 0 | N7: =+VLOOKUP($A7,INDIRECT(Adrese!E$2),3,FALSE) -> 0 | O7: =+VLOOKUP($A7,INDIRECT(Adrese!F$2),3,FALSE) -> 0 | P7: =SUM(K7:O7) -> 1 | Q7: =AVERAGE(K7:O7) -> 0.2 | T7: Nydegger | U7: =+VLOOKUP($T7,INDIRECT(Adrese!B$2),4,FALSE) -> 5456 | V7: =+VLOOKUP($T7,INDIRECT(Adrese!C$2),4,FALSE) -> 5448 | W7: =+VLOOKUP($T7,INDIRECT(Adrese!D$2),4,FALSE) -> 5437 | X7: =+VLOOKUP($T7,INDIRECT(Adrese!E$2),4,FALSE) -> 4915 | Y7: =+VLOOKUP($T7,INDIRECT(Adrese!F$2),4,FALSE) -> 5437 | Z7: =SUM(U7:Y7) -> 26693 | AA7: =AVERAGE(U7:Y7) -> 5338.6 | AD7: Nydegger | AE7: =+VLOOKUP($A7,INDIRECT(Adrese!B$2),5,FALSE) -> 2584 | AF7: =+VLOOKUP($A7,INDIRECT(Adrese!C$2),5,FALSE) -> 2637 | AG7: =+VLOOKUP($A7,INDIRECT(Adrese!D$2),5,FALSE) -> 2605 | AH7: =+VLOOKUP($A7,INDIRECT(Adrese!E$2),5,FALSE) -> 2646 | AI7: =+VLOOKUP($A7,INDIRECT(Adrese!F$2),5,FALSE) -> 2614 | AJ7: =AVERAGE(AE7:AI7) -> 2617.2 | AK7: =_xlfn.STDEV.S(AE7:AI7) -> 24.913852 | AM7: Nydegger | AN7: =+VLOOKUP($A7,INDIRECT(Adrese!B$2),6,FALSE) -> 0.80633333 | AO7: =+VLOOKUP($A7,INDIRECT(Adrese!C$2),6,FALSE) -> 0.82933333 | AP7: =+VLOOKUP($A7,INDIRECT(Adrese!D$2),6,FALSE) -> 0.81566667 | AQ7: =+VLOOKUP($A7,INDIRECT(Adrese!E$2),6,FALSE) -> 0.82966667 | AR7: =+VLOOKUP($A7,INDIRECT(Adrese!F$2),6,FALSE) -> 0.81966667 | AS7: =TEXT(AT7,"0.00")&" ("&TEXT(AU7,"0.00")&")" -> 0.82 (0.01) | AT7: =AVERAGE(AN7:AR7) -> 0.82013333 | AU7: =_xlfn.STDEV.S(AN7:AR7) -> 0.0098251379 | AW7: Nydegger | AX7: =+VLOOKUP($A7,INDIRECT(Adrese!B$2),7,FALSE) -> 1 | AY7: =+VLOOKUP($A7,INDIRECT(Adrese!C$2),7,FALSE) -> 0.93333333 | AZ7: =+VLOOKUP($A7,INDIRECT(Adrese!D$2),7,FALSE) -> 1 | BA7: =+VLOOKUP($A7,INDIRECT(Adrese!E$2),7,FALSE) -> 1 | BB7: =+VLOOKUP($A7,INDIRECT(Adrese!F$2),7,FALSE) -> 1 | BC7: =TEXT(BD7,"0.00")&" ("&TEXT(BE7,"0.00")&")" -> 0.99 (0.03) | BD7: =AVERAGE(AX7:BB7) -> 0.98666667 | BE7: =_xlfn.STDEV.S(AX7:BB7) -> 0.02981424 | BG7: Nydegger | BH7: =+VLOOKUP($BG7,INDIRECT(Adrese!B$2),8,FALSE) -> 0.43288072 | BI7: =+VLOOKUP($BG7,INDIRECT(Adrese!C$2),8,FALSE) -> 0.44961867 | BJ7: =+VLOOKUP($BG7,INDIRECT(Adrese!D$2),8,FALSE) -> 0.44040954 | BK7: =+VLOOKUP($BG7,INDIRECT(Adrese!E$2),8,FALSE) -> 0.4499193 | BL7: =+VLOOKUP($BG7,INDIRECT(Adrese!F$2),8,FALSE) -> 0.44879821 | BM7: =TEXT(BN7,"0.00")&" ("&TEXT(BO7,"0.00")&")" -> 0.44 (0.01) | BN7: =AVERAGE(BH7:BL7) -> 0.44432529 | BO7: =_xlfn.STDEV.S(BH7:BL7) -> 0.0075105135 | BQ7: Nydegger | BR7: =+VLOOKUP($BG7,INDIRECT(Adrese!B$2),9,FALSE) -> -0.27238595 | BS7: =+VLOOKUP($BG7,INDIRECT(Adrese!C$2),9,FALSE) -> -0.29589709 | BT7: =+VLOOKUP($BG7,INDIRECT(Adrese!D$2),9,FALSE) -> -0.2926108 | BU7: =+VLOOKUP($BG7,INDIRECT(Adrese!E$2),9,FALSE) -> -0.27674782 | BV7: =+VLOOKUP($BG7,INDIRECT(Adrese!F$2),9,FALSE) -> -0.2857389 | BW7: =TEXT(BX7,"0.00")&" ("&TEXT(BY7,"0.00")&")" -> -0.28 (0.01) | BX7: =AVERAGE(BR7:BV7) -> -0.28467611 | BY7: =_xlfn.STDEV.S(BR7:BV7) -> 0.010048698
A8: Tideman and Chieruzzi | B8: =+VLOOKUP($A8,INDIRECT(Adrese!B$2),2,FALSE) -> 2 | C8: =+VLOOKUP($A8,INDIRECT(Adrese!C$2),2,FALSE) -> 7 | D8: =+VLOOKUP($A8,INDIRECT(Adrese!D$2),2,FALSE) -> 8 | E8: =+VLOOKUP($A8,INDIRECT(Adrese!E$2),2,FALSE) -> 5 | F8: =+VLOOKUP($A8,INDIRECT(Adrese!F$2),2,FALSE) -> 2 | G8: =AVERAGE(B8:F8) -> 4.8 | J8: Tideman and Chieruzzi | K8: =+VLOOKUP($A8,INDIRECT(Adrese!B$2),3,FALSE) -> 13 | L8: =+VLOOKUP($A8,INDIRECT(Adrese!C$2),3,FALSE) -> 11 | M8: =+VLOOKUP($A8,INDIRECT(Adrese!D$2),3,FALSE) -> 13 | N8: =+VLOOKUP($A8,INDIRECT(Adrese!E$2),3,FALSE) -> 11 | O8: =+VLOOKUP($A8,INDIRECT(Adrese!F$2),3,FALSE) -> 12 | P8: =SUM(K8:O8) -> 60 | Q8: =AVERAGE(K8:O8) -> 12 | T8: Tideman and Chieruzzi | U8: =+VLOOKUP($T8,INDIRECT(Adrese!B$2),4,FALSE) -> 6616 | V8: =+VLOOKUP($T8,INDIRECT(Adrese!C$2),4,FALSE) -> 6321 | W8: =+VLOOKUP($T8,INDIRECT(Adrese!D$2),4,FALSE) -> 6281 | X8: =+VLOOKUP($T8,INDIRECT(Adrese!E$2),4,FALSE) -> 6367 | Y8: =+VLOOKUP($T8,INDIRECT(Adrese!F$2),4,FALSE) -> 6669 | Z8: =SUM(U8:Y8) -> 32254 | AA8: =AVERAGE(U8:Y8) -> 6450.8 | AD8: Tideman and Chieruzzi | AE8: =+VLOOKUP($A8,INDIRECT(Adrese!B$2),5,FALSE) -> 1009 | AF8: =+VLOOKUP($A8,INDIRECT(Adrese!C$2),5,FALSE) -> 964 | AG8: =+VLOOKUP($A8,INDIRECT(Adrese!D$2),5,FALSE) -> 964 | AH8: =+VLOOKUP($A8,INDIRECT(Adrese!E$2),5,FALSE) -> 1029 | AI8: =+VLOOKUP($A8,INDIRECT(Adrese!F$2),5,FALSE) -> 1058 | AJ8: =AVERAGE(AE8:AI8) -> 1004.8 | AK8: =_xlfn.STDEV.S(AE8:AI8) -> 41.118123 | AM8: Tideman and Chieruzzi | AN8: =+VLOOKUP($A8,INDIRECT(Adrese!B$2),6,FALSE) -> 0.325 | AO8: =+VLOOKUP($A8,INDIRECT(Adrese!C$2),6,FALSE) -> 0.308 | AP8: =+VLOOKUP($A8,INDIRECT(Adrese!D$2),6,FALSE) -> 0.306 | AQ8: =+VLOOKUP($A8,INDIRECT(Adrese!E$2),6,FALSE) -> 0.336 | AR8: =+VLOOKUP($A8,INDIRECT(Adrese!F$2),6,FALSE) -> 0.34066667 | AS8: =TEXT(AT8,"0.00")&" ("&TEXT(AU8,"0.00")&")" -> 0.32 (0.02) | AT8: =AVERAGE(AN8:AR8) -> 0.32313333 | AU8: =_xlfn.STDEV.S(AN8:AR8) -> 0.015803656 | AW8: Tideman and Chieruzzi | AX8: =+VLOOKUP($A8,INDIRECT(Adrese!B$2),7,FALSE) -> 0.13333333 | AY8: =+VLOOKUP($A8,INDIRECT(Adrese!C$2),7,FALSE) -> 0.26666667 | AZ8: =+VLOOKUP($A8,INDIRECT(Adrese!D$2),7,FALSE) -> 0.13333333 | BA8: =+VLOOKUP($A8,INDIRECT(Adrese!E$2),7,FALSE) -> 0.26666667 | BB8: =+VLOOKUP($A8,INDIRECT(Adrese!F$2),7,FALSE) -> 0.2 | BC8: =TEXT(BD8,"0.00")&" ("&TEXT(BE8,"0.00")&")" -> 0.20 (0.07) | BD8: =AVERAGE(AX8:BB8) -> 0.2 | BE8: =_xlfn.STDEV.S(AX8:BB8) -> 0.066666667 | BG8: Tideman and Chieruzzi | BH8: =+VLOOKUP($BG8,INDIRECT(Adrese!B$2),8,FALSE) -> 0.19581111 | BI8: =+VLOOKUP($BG8,INDIRECT(Adrese!C$2),8,FALSE) -> 0.18200419 | BJ8: =+VLOOKUP($BG8,INDIRECT(Adrese!D$2),8,FALSE) -> 0.19426647 | BK8: =+VLOOKUP($BG8,INDIRECT(Adrese!E$2),8,FALSE) -> 0.19969906 | BL8: =+VLOOKUP($BG8,INDIRECT(Adrese!F$2),8,FALSE) -> 0.20461261 | BM8: =TEXT(BN8,"0.00")&" ("&TEXT(BO8,"0.00")&")" -> 0.20 (0.01) | BN8: =AVERAGE(BH8:BL8) -> 0.19527869 | BO8: =_xlfn.STDEV.S(BH8:BL8) -> 0.0084288505 | BQ8: Tideman and Chieruzzi | BR8: =+VLOOKUP($BG8,INDIRECT(Adrese!B$2),9,FALSE) -> 0.35100026 | BS8: =+VLOOKUP($BG8,INDIRECT(Adrese!C$2),9,FALSE) -> 0.31533492 | BT8: =+VLOOKUP($BG8,INDIRECT(Adrese!D$2),9,FALSE) -> 0.35963894 | BU8: =+VLOOKUP($BG8,INDIRECT(Adrese!E$2),9,FALSE) -> 0.37276035 | BV8: =+VLOOKUP($BG8,INDIRECT(Adrese!F$2),9,FALSE) -> 0.39992574 | BW8: =TEXT(BX8,"0.00")&" ("&TEXT(BY8,"0.00")&")" -> 0.36 (0.03) | BX8: =AVERAGE(BR8:BV8) -> 0.35973204 | BY8: =_xlfn.STDEV.S(BR8:BV8) -> 0.030954111
A9: Shubik | B9: =+VLOOKUP($A9,INDIRECT(Adrese!B$2),2,FALSE) -> 10 | C9: =+VLOOKUP($A9,INDIRECT(Adrese!C$2),2,FALSE) -> 5 | D9: =+VLOOKUP($A9,INDIRECT(Adrese!D$2),2,FALSE) -> 12 | E9: =+VLOOKUP($A9,INDIRECT(Adrese!E$2),2,FALSE) -> 3 | F9: =+VLOOKUP($A9,INDIRECT(Adrese!F$2),2,FALSE) -> 4 | G9: =AVERAGE(B9:F9) -> 6.8 | J9: Shubik | K9: =+VLOOKUP($A9,INDIRECT(Adrese!B$2),3,FALSE) -> 10 | L9: =+VLOOKUP($A9,INDIRECT(Adrese!C$2),3,FALSE) -> 9 | M9: =+VLOOKUP($A9,INDIRECT(Adrese!D$2),3,FALSE) -> 9 | N9: =+VLOOKUP($A9,INDIRECT(Adrese!E$2),3,FALSE) -> 11 | O9: =+VLOOKUP($A9,INDIRECT(Adrese!F$2),3,FALSE) -> 11 | P9: =SUM(K9:O9) -> 50 | Q9: =AVERAGE(K9:O9) -> 10 | T9: Shubik | U9: =+VLOOKUP($T9,INDIRECT(Adrese!B$2),4,FALSE) -> 6030 | V9: =+VLOOKUP($T9,INDIRECT(Adrese!C$2),4,FALSE) -> 6409 | W9: =+VLOOKUP($T9,INDIRECT(Adrese!D$2),4,FALSE) -> 5952 | X9: =+VLOOKUP($T9,INDIRECT(Adrese!E$2),4,FALSE) -> 6405 | Y9: =+VLOOKUP($T9,INDIRECT(Adrese!F$2),4,FALSE) -> 6547 | Z9: =SUM(U9:Y9) -> 31343 | AA9: =AVERAGE(U9:Y9) -> 6268.6 | AD9: Shubik | AE9: =+VLOOKUP($A9,INDIRECT(Adrese!B$2),5,FALSE) -> 855 | AF9: =+VLOOKUP($A9,INDIRECT(Adrese!C$2),5,FALSE) -> 946 | AG9: =+VLOOKUP($A9,INDIRECT(Adrese!D$2),5,FALSE) -> 900 | AH9: =+VLOOKUP($A9,INDIRECT(Adrese!E$2),5,FALSE) -> 938 | AI9: =+VLOOKUP($A9,INDIRECT(Adrese!F$2),5,FALSE) -> 960 | AJ9: =AVERAGE(AE9:AI9) -> 919.8 | AK9: =_xlfn.STDEV.S(AE9:AI9) -> 42.499412 | AM9: Shubik | AN9: =+VLOOKUP($A9,INDIRECT(Adrese!B$2),6,FALSE) -> 0.273 | AO9: =+VLOOKUP($A9,INDIRECT(Adrese!C$2),6,FALSE) -> 0.28933333 | AP9: =+VLOOKUP($A9,INDIRECT(Adrese!D$2),6,FALSE) -> 0.28333333 | AQ9: =+VLOOKUP($A9,INDIRECT(Adrese!E$2),6,FALSE) -> 0.294 | AR9: =+VLOOKUP($A9,INDIRECT(Adrese!F$2),6,FALSE) -> 0.30433333 | AS9: =TEXT(AT9,"0.00")&" ("&TEXT(AU9,"0.00")&")" -> 0.29 (0.01) | AT9: =AVERAGE(AN9:AR9) -> 0.2888 | AU9: =_xlfn.STDEV.S(AN9:AR9) -> 0.011706124 | AW9: Shubik | AX9: =+VLOOKUP($A9,INDIRECT(Adrese!B$2),7,FALSE) -> 0.33333333 | AY9: =+VLOOKUP($A9,INDIRECT(Adrese!C$2),7,FALSE) -> 0.4 | AZ9: =+VLOOKUP($A9,INDIRECT(Adrese!D$2),7,FALSE) -> 0.4 | BA9: =+VLOOKUP($A9,INDIRECT(Adrese!E$2),7,FALSE) -> 0.26666667 | BB9: =+VLOOKUP($A9,INDIRECT(Adrese!F$2),7,FALSE) -> 0.26666667 | BC9: =TEXT(BD9,"0.00")&" ("&TEXT(BE9,"0.00")&")" -> 0.33 (0.07) | BD9: =AVERAGE(AX9:BB9) -> 0.33333333 | BE9: =_xlfn.STDEV.S(AX9:BB9) -> 0.066666667 | BG9: Shubik | BH9: =+VLOOKUP($BG9,INDIRECT(Adrese!B$2),8,FALSE) -> 0.16001717 | BI9: =+VLOOKUP($BG9,INDIRECT(Adrese!C$2),8,FALSE) -> 0.17865453 | BJ9: =+VLOOKUP($BG9,INDIRECT(Adrese!D$2),8,FALSE) -> 0.16715175 | BK9: =+VLOOKUP($BG9,INDIRECT(Adrese!E$2),8,FALSE) -> 0.17934655 | BL9: =+VLOOKUP($BG9,INDIRECT(Adrese!F$2),8,FALSE) -> 0.1869168 | BM9: =TEXT(BN9,"0.00")&" ("&TEXT(BO9,"0.00")&")" -> 0.17 (0.01) | BN9: =AVERAGE(BH9:BL9) -> 0.17441736 | BO9: =_xlfn.STDEV.S(BH9:BL9) -> 0.010707955 | BQ9: Shubik | BR9: =+VLOOKUP($BG9,INDIRECT(Adrese!B$2),9,FALSE) -> 0.3240484 | BS9: =+VLOOKUP($BG9,INDIRECT(Adrese!C$2),9,FALSE) -> 0.32713727 | BT9: =+VLOOKUP($BG9,INDIRECT(Adrese!D$2),9,FALSE) -> 0.29145077 | BU9: =+VLOOKUP($BG9,INDIRECT(Adrese!E$2),9,FALSE) -> 0.30468787 | BV9: =+VLOOKUP($BG9,INDIRECT(Adrese!F$2),9,FALSE) -> 0.32528087 | BW9: =TEXT(BX9,"0.00")&" ("&TEXT(BY9,"0.00")&")" -> 0.31 (0.02) | BX9: =AVERAGE(BR9:BV9) -> 0.31452104 | BY9: =_xlfn.STDEV.S(BR9:BV9) -> 0.015768973
A10: Grudger | B10: =+VLOOKUP($A10,INDIRECT(Adrese!B$2),2,FALSE) -> 7 | C10: =+VLOOKUP($A10,INDIRECT(Adrese!C$2),2,FALSE) -> 6 | D10: =+VLOOKUP($A10,INDIRECT(Adrese!D$2),2,FALSE) -> 3 | E10: =+VLOOKUP($A10,INDIRECT(Adrese!E$2),2,FALSE) -> 8 | F10: =+VLOOKUP($A10,INDIRECT(Adrese!F$2),2,FALSE) -> 9 | G10: =AVERAGE(B10:F10) -> 6.6 | J10: Grudger | K10: =+VLOOKUP($A10,INDIRECT(Adrese!B$2),3,FALSE) -> 13 | L10: =+VLOOKUP($A10,INDIRECT(Adrese!C$2),3,FALSE) -> 14 | M10: =+VLOOKUP($A10,INDIRECT(Adrese!D$2),3,FALSE) -> 15 | N10: =+VLOOKUP($A10,INDIRECT(Adrese!E$2),3,FALSE) -> 14 | O10: =+VLOOKUP($A10,INDIRECT(Adrese!F$2),3,FALSE) -> 13 | P10: =SUM(K10:O10) -> 69 | Q10: =AVERAGE(K10:O10) -> 13.8 | T10: Grudger | U10: =+VLOOKUP($T10,INDIRECT(Adrese!B$2),4,FALSE) -> 6347 | V10: =+VLOOKUP($T10,INDIRECT(Adrese!C$2),4,FALSE) -> 6330 | W10: =+VLOOKUP($T10,INDIRECT(Adrese!D$2),4,FALSE) -> 6494 | X10: =+VLOOKUP($T10,INDIRECT(Adrese!E$2),4,FALSE) -> 6302 | Y10: =+VLOOKUP($T10,INDIRECT(Adrese!F$2),4,FALSE) -> 6234 | Z10: =SUM(U10:Y10) -> 31707 | AA10: =AVERAGE(U10:Y10) -> 6341.4 | AD10: Grudger | AE10: =+VLOOKUP($A10,INDIRECT(Adrese!B$2),5,FALSE) -> 398 | AF10: =+VLOOKUP($A10,INDIRECT(Adrese!C$2),5,FALSE) -> 396 | AG10: =+VLOOKUP($A10,INDIRECT(Adrese!D$2),5,FALSE) -> 384 | AH10: =+VLOOKUP($A10,INDIRECT(Adrese!E$2),5,FALSE) -> 386 | AI10: =+VLOOKUP($A10,INDIRECT(Adrese!F$2),5,FALSE) -> 384 | AJ10: =AVERAGE(AE10:AI10) -> 389.6 | AK10: =_xlfn.STDEV.S(AE10:AI10) -> 6.8410526 | AM10: Grudger | AN10: =+VLOOKUP($A10,INDIRECT(Adrese!B$2),6,FALSE) -> 0.126 | AO10: =+VLOOKUP($A10,INDIRECT(Adrese!C$2),6,FALSE) -> 0.12433333 | AP10: =+VLOOKUP($A10,INDIRECT(Adrese!D$2),6,FALSE) -> 0.12 | AQ10: =+VLOOKUP($A10,INDIRECT(Adrese!E$2),6,FALSE) -> 0.12166667 | AR10: =+VLOOKUP($A10,INDIRECT(Adrese!F$2),6,FALSE) -> 0.12133333 | AS10: =TEXT(AT10,"0.00")&" ("&TEXT(AU10,"0.00")&")" -> 0.12 (0.00) | AT10: =AVERAGE(AN10:AR10) -> 0.12266667 | AU10: =_xlfn.STDEV.S(AN10:AR10) -> 0.0024381231 | AW10: Grudger | AX10: =+VLOOKUP($A10,INDIRECT(Adrese!B$2),7,FALSE) -> 0.13333333 | AY10: =+VLOOKUP($A10,INDIRECT(Adrese!C$2),7,FALSE) -> 0.066666667 | AZ10: =+VLOOKUP($A10,INDIRECT(Adrese!D$2),7,FALSE) -> 0 | BA10: =+VLOOKUP($A10,INDIRECT(Adrese!E$2),7,FALSE) -> 0.066666667 | BB10: =+VLOOKUP($A10,INDIRECT(Adrese!F$2),7,FALSE) -> 0.13333333 | BC10: =TEXT(BD10,"0.00")&" ("&TEXT(BE10,"0.00")&")" -> 0.08 (0.06) | BD10: =AVERAGE(AX10:BB10) -> 0.08 | BE10: =_xlfn.STDEV.S(AX10:BB10) -> 0.055777335 | BG10: Grudger | BH10: =+VLOOKUP($BG10,INDIRECT(Adrese!B$2),8,FALSE) -> 0.066918455 | BI10: =+VLOOKUP($BG10,INDIRECT(Adrese!C$2),8,FALSE) -> 0.068210668 | BJ10: =+VLOOKUP($BG10,INDIRECT(Adrese!D$2),8,FALSE) -> 0.065401634 | BK10: =+VLOOKUP($BG10,INDIRECT(Adrese!E$2),8,FALSE) -> 0.068610604 | BL10: =+VLOOKUP($BG10,INDIRECT(Adrese!F$2),8,FALSE) -> 0.064574264 | BM10: =TEXT(BN10,"0.00")&" ("&TEXT(BO10,"0.00")&")" -> 0.07 (0.00) | BN10: =AVERAGE(BH10:BL10) -> 0.066743125 | BO10: =_xlfn.STDEV.S(BH10:BL10) -> 0.0017446674 | BQ10: Grudger | BR10: =+VLOOKUP($BG10,INDIRECT(Adrese!B$2),9,FALSE) -> 0.3303294 | BS10: =+VLOOKUP($BG10,INDIRECT(Adrese!C$2),9,FALSE) -> 0.33929256 | BT10: =+VLOOKUP($BG10,INDIRECT(Adrese!D$2),9,FALSE) -> 0.30634312 | BU10: =+VLOOKUP($BG10,INDIRECT(Adrese!E$2),9,FALSE) -> 0.2908364 | BV10: =+VLOOKUP($BG10,INDIRECT(Adrese!F$2),9,FALSE) -> 0.31382643 | BW10: =TEXT(BX10,"0.00")&" ("&TEXT(BY10,"0.00")&")" -> 0.32 (0.02) | BX10: =AVERAGE(BR10:BV10) -> 0.31612558 | BY10: =_xlfn.STDEV.S(BR10:BV10) -> 0.019228773
A11: Davis | B11: =+VLOOKUP($A11,INDIRECT(Adrese!B$2),2,FALSE) -> 6 | C11: =+VLOOKUP($A11,INDIRECT(Adrese!C$2),2,FALSE) -> 9 | D11: =+VLOOKUP($A11,INDIRECT(Adrese!D$2),2,FALSE) -> 10 | E11: =+VLOOKUP($A11,INDIRECT(Adrese!E$2),2,FALSE) -> 7 | F11: =+VLOOKUP($A11,INDIRECT(Adrese!F$2),2,FALSE) -> 8 | G11: =AVERAGE(B11:F11) -> 8 | J11: Davis | K11: =+VLOOKUP($A11,INDIRECT(Adrese!B$2),3,FALSE) -> 14 | L11: =+VLOOKUP($A11,INDIRECT(Adrese!C$2),3,FALSE) -> 14 | M11: =+VLOOKUP($A11,INDIRECT(Adrese!D$2),3,FALSE) -> 12 | N11: =+VLOOKUP($A11,INDIRECT(Adrese!E$2),3,FALSE) -> 14 | O11: =+VLOOKUP($A11,INDIRECT(Adrese!F$2),3,FALSE) -> 14 | P11: =SUM(K11:O11) -> 68 | Q11: =AVERAGE(K11:O11) -> 13.6 | T11: Davis | U11: =+VLOOKUP($T11,INDIRECT(Adrese!B$2),4,FALSE) -> 6362 | V11: =+VLOOKUP($T11,INDIRECT(Adrese!C$2),4,FALSE) -> 6288 | W11: =+VLOOKUP($T11,INDIRECT(Adrese!D$2),4,FALSE) -> 6191 | X11: =+VLOOKUP($T11,INDIRECT(Adrese!E$2),4,FALSE) -> 6336 | Y11: =+VLOOKUP($T11,INDIRECT(Adrese!F$2),4,FALSE) -> 6277 | Z11: =SUM(U11:Y11) -> 31454 | AA11: =AVERAGE(U11:Y11) -> 6290.8 | AD11: Davis | AE11: =+VLOOKUP($A11,INDIRECT(Adrese!B$2),5,FALSE) -> 431 | AF11: =+VLOOKUP($A11,INDIRECT(Adrese!C$2),5,FALSE) -> 461 | AG11: =+VLOOKUP($A11,INDIRECT(Adrese!D$2),5,FALSE) -> 481 | AH11: =+VLOOKUP($A11,INDIRECT(Adrese!E$2),5,FALSE) -> 446 | AI11: =+VLOOKUP($A11,INDIRECT(Adrese!F$2),5,FALSE) -> 515 | AJ11: =AVERAGE(AE11:AI11) -> 466.8 | AK11: =_xlfn.STDEV.S(AE11:AI11) -> 32.683329 | AM11: Davis | AN11: =+VLOOKUP($A11,INDIRECT(Adrese!B$2),6,FALSE) -> 0.135 | AO11: =+VLOOKUP($A11,INDIRECT(Adrese!C$2),6,FALSE) -> 0.14466667 | AP11: =+VLOOKUP($A11,INDIRECT(Adrese!D$2),6,FALSE) -> 0.15033333 | AQ11: =+VLOOKUP($A11,INDIRECT(Adrese!E$2),6,FALSE) -> 0.13966667 | AR11: =+VLOOKUP($A11,INDIRECT(Adrese!F$2),6,FALSE) -> 0.162 | AS11: =TEXT(AT11,"0.00")&" ("&TEXT(AU11,"0.00")&")" -> 0.15 (0.01) | AT11: =AVERAGE(AN11:AR11) -> 0.14633333 | AU11: =_xlfn.STDEV.S(AN11:AR11) -> 0.010453601 | AW11: Davis | AX11: =+VLOOKUP($A11,INDIRECT(Adrese!B$2),7,FALSE) -> 0.066666667 | AY11: =+VLOOKUP($A11,INDIRECT(Adrese!C$2),7,FALSE) -> 0.066666667 | AZ11: =+VLOOKUP($A11,INDIRECT(Adrese!D$2),7,FALSE) -> 0.2 | BA11: =+VLOOKUP($A11,INDIRECT(Adrese!E$2),7,FALSE) -> 0.066666667 | BB11: =+VLOOKUP($A11,INDIRECT(Adrese!F$2),7,FALSE) -> 0.066666667 | BC11: =TEXT(BD11,"0.00")&" ("&TEXT(BE11,"0.00")&")" -> 0.09 (0.06) | BD11: =AVERAGE(AX11:BB11) -> 0.093333334 | BE11: =_xlfn.STDEV.S(AX11:BB11) -> 0.059628479 | BG11: Davis | BH11: =+VLOOKUP($BG11,INDIRECT(Adrese!B$2),8,FALSE) -> 0.071760179 | BI11: =+VLOOKUP($BG11,INDIRECT(Adrese!C$2),8,FALSE) -> 0.079228662 | BJ11: =+VLOOKUP($BG11,INDIRECT(Adrese!D$2),8,FALSE) -> 0.081852613 | BK11: =+VLOOKUP($BG11,INDIRECT(Adrese!E$2),8,FALSE) -> 0.078523502 | BL11: =+VLOOKUP($BG11,INDIRECT(Adrese!F$2),8,FALSE) -> 0.09373084 | BM11: =TEXT(BN11,"0.00")&" ("&TEXT(BO11,"0.00")&")" -> 0.08 (0.01) | BN11: =AVERAGE(BH11:BL11) -> 0.081019159 | BO11: =_xlfn.STDEV.S(BH11:BL11) -> 0.0080225366 | BQ11: Davis | BR11: =+VLOOKUP($BG11,INDIRECT(Adrese!B$2),9,FALSE) -> 0.3095544 | BS11: =+VLOOKUP($BG11,INDIRECT(Adrese!C$2),9,FALSE) -> 0.31539207 | BT11: =+VLOOKUP($BG11,INDIRECT(Adrese!D$2),9,FALSE) -> 0.30252062 | BU11: =+VLOOKUP($BG11,INDIRECT(Adrese!E$2),9,FALSE) -> 0.28188242 | BV11: =+VLOOKUP($BG11,INDIRECT(Adrese!F$2),9,FALSE) -> 0.3197563 | BW11: =TEXT(BX11,"0.00")&" ("&TEXT(BY11,"0.00")&")" -> 0.31 (0.01) | BX11: =AVERAGE(BR11:BV11) -> 0.30582116 | BY11: =_xlfn.STDEV.S(BR11:BV11) -> 0.014863414
A12: Graaskamp | B12: =+VLOOKUP($A12,INDIRECT(Adrese!B$2),2,FALSE) -> 11 | C12: =+VLOOKUP($A12,INDIRECT(Adrese!C$2),2,FALSE) -> 12 | D12: =+VLOOKUP($A12,INDIRECT(Adrese!D$2),2,FALSE) -> 11 | E12: =+VLOOKUP($A12,INDIRECT(Adrese!E$2),2,FALSE) -> 11 | F12: =+VLOOKUP($A12,INDIRECT(Adrese!F$2),2,FALSE) -> 11 | G12: =AVERAGE(B12:F12) -> 11.2 | J12: Graaskamp | K12: =+VLOOKUP($A12,INDIRECT(Adrese!B$2),3,FALSE) -> 9 | L12: =+VLOOKUP($A12,INDIRECT(Adrese!C$2),3,FALSE) -> 7 | M12: =+VLOOKUP($A12,INDIRECT(Adrese!D$2),3,FALSE) -> 9 | N12: =+VLOOKUP($A12,INDIRECT(Adrese!E$2),3,FALSE) -> 8 | O12: =+VLOOKUP($A12,INDIRECT(Adrese!F$2),3,FALSE) -> 8 | P12: =SUM(K12:O12) -> 41 | Q12: =AVERAGE(K12:O12) -> 8.2 | T12: Graaskamp | U12: =+VLOOKUP($T12,INDIRECT(Adrese!B$2),4,FALSE) -> 5927 | V12: =+VLOOKUP($T12,INDIRECT(Adrese!C$2),4,FALSE) -> 5801 | W12: =+VLOOKUP($T12,INDIRECT(Adrese!D$2),4,FALSE) -> 6101 | X12: =+VLOOKUP($T12,INDIRECT(Adrese!E$2),4,FALSE) -> 5976 | Y12: =+VLOOKUP($T12,INDIRECT(Adrese!F$2),4,FALSE) -> 5917 | Z12: =SUM(U12:Y12) -> 29722 | AA12: =AVERAGE(U12:Y12) -> 5944.4 | AD12: Graaskamp | AE12: =+VLOOKUP($A12,INDIRECT(Adrese!B$2),5,FALSE) -> 1469 | AF12: =+VLOOKUP($A12,INDIRECT(Adrese!C$2),5,FALSE) -> 1499 | AG12: =+VLOOKUP($A12,INDIRECT(Adrese!D$2),5,FALSE) -> 1390 | AH12: =+VLOOKUP($A12,INDIRECT(Adrese!E$2),5,FALSE) -> 1275 | AI12: =+VLOOKUP($A12,INDIRECT(Adrese!F$2),5,FALSE) -> 1465 | AJ12: =AVERAGE(AE12:AI12) -> 1419.6 | AK12: =_xlfn.STDEV.S(AE12:AI12) -> 90.265165 | AM12: Graaskamp | AN12: =+VLOOKUP($A12,INDIRECT(Adrese!B$2),6,FALSE) -> 0.46066667 | AO12: =+VLOOKUP($A12,INDIRECT(Adrese!C$2),6,FALSE) -> 0.486 | AP12: =+VLOOKUP($A12,INDIRECT(Adrese!D$2),6,FALSE) -> 0.44733333 | AQ12: =+VLOOKUP($A12,INDIRECT(Adrese!E$2),6,FALSE) -> 0.372 | AR12: =+VLOOKUP($A12,INDIRECT(Adrese!F$2),6,FALSE) -> 0.47666667 | AS12: =TEXT(AT12,"0.00")&" ("&TEXT(AU12,"0.00")&")" -> 0.45 (0.05) | AT12: =AVERAGE(AN12:AR12) -> 0.44853333 | AU12: =_xlfn.STDEV.S(AN12:AR12) -> 0.045280361 | AW12: Graaskamp | AX12: =+VLOOKUP($A12,INDIRECT(Adrese!B$2),7,FALSE) -> 0.4 | AY12: =+VLOOKUP($A12,INDIRECT(Adrese!C$2),7,FALSE) -> 0.53333333 | AZ12: =+VLOOKUP($A12,INDIRECT(Adrese!D$2),7,FALSE) -> 0.4 | BA12: =+VLOOKUP($A12,INDIRECT(Adrese!E$2),7,FALSE) -> 0.46666667 | BB12: =+VLOOKUP($A12,INDIRECT(Adrese!F$2),7,FALSE) -> 0.46666667 | BC12: =TEXT(BD12,"0.00")&" ("&TEXT(BE12,"0.00")&")" -> 0.45 (0.06) | BD12: =AVERAGE(AX12:BB12) -> 0.45333333 | BE12: =_xlfn.STDEV.S(AX12:BB12) -> 0.055777335 | BG12: Graaskamp | BH12: =+VLOOKUP($BG12,INDIRECT(Adrese!B$2),8,FALSE) -> 0.24600736 | BI12: =+VLOOKUP($BG12,INDIRECT(Adrese!C$2),8,FALSE) -> 0.25417691 | BJ12: =+VLOOKUP($BG12,INDIRECT(Adrese!D$2),8,FALSE) -> 0.23748644 | BK12: =+VLOOKUP($BG12,INDIRECT(Adrese!E$2),8,FALSE) -> 0.20329159 | BL12: =+VLOOKUP($BG12,INDIRECT(Adrese!F$2),8,FALSE) -> 0.23829393 | BM12: =TEXT(BN12,"0.00")&" ("&TEXT(BO12,"0.00")&")" -> 0.24 (0.02) | BN12: =AVERAGE(BH12:BL12) -> 0.23585125 | BO12: =_xlfn.STDEV.S(BH12:BL12) -> 0.019414868 | BQ12: Graaskamp | BR12: =+VLOOKUP($BG12,INDIRECT(Adrese!B$2),9,FALSE) -> 0.12071043 | BS12: =+VLOOKUP($BG12,INDIRECT(Adrese!C$2),9,FALSE) -> 0.039577625 | BT12: =+VLOOKUP($BG12,INDIRECT(Adrese!D$2),9,FALSE) -> 0.067056684 | BU12: =+VLOOKUP($BG12,INDIRECT(Adrese!E$2),9,FALSE) -> 0.12234299 | BV12: =+VLOOKUP($BG12,INDIRECT(Adrese!F$2),9,FALSE) -> 0.03067376 | BW12: =TEXT(BX12,"0.00")&" ("&TEXT(BY12,"0.00")&")" -> 0.08 (0.04) | BX12: =AVERAGE(BR12:BV12) -> 0.076072298 | BY12: =_xlfn.STDEV.S(BR12:BV12) -> 0.043611093
A13: Downing | B13: =+VLOOKUP($A13,INDIRECT(Adrese!B$2),2,FALSE) -> 1 | C13: =+VLOOKUP($A13,INDIRECT(Adrese!C$2),2,FALSE) -> 1 | D13: =+VLOOKUP($A13,INDIRECT(Adrese!D$2),2,FALSE) -> 2 | E13: =+VLOOKUP($A13,INDIRECT(Adrese!E$2),2,FALSE) -> 2 | F13: =+VLOOKUP($A13,INDIRECT(Adrese!F$2),2,FALSE) -> 1 | G13: =AVERAGE(B13:F13) -> 1.4 | J13: Downing | K13: =+VLOOKUP($A13,INDIRECT(Adrese!B$2),3,FALSE) -> 10 | L13: =+VLOOKUP($A13,INDIRECT(Adrese!C$2),3,FALSE) -> 7 | M13: =+VLOOKUP($A13,INDIRECT(Adrese!D$2),3,FALSE) -> 9 | N13: =+VLOOKUP($A13,INDIRECT(Adrese!E$2),3,FALSE) -> 7 | O13: =+VLOOKUP($A13,INDIRECT(Adrese!F$2),3,FALSE) -> 8 | P13: =SUM(K13:O13) -> 41 | Q13: =AVERAGE(K13:O13) -> 8.2 | T13: Downing | U13: =+VLOOKUP($T13,INDIRECT(Adrese!B$2),4,FALSE) -> 6999 | V13: =+VLOOKUP($T13,INDIRECT(Adrese!C$2),4,FALSE) -> 6836 | W13: =+VLOOKUP($T13,INDIRECT(Adrese!D$2),4,FALSE) -> 6533 | X13: =+VLOOKUP($T13,INDIRECT(Adrese!E$2),4,FALSE) -> 6707 | Y13: =+VLOOKUP($T13,INDIRECT(Adrese!F$2),4,FALSE) -> 6861 | Z13: =SUM(U13:Y13) -> 33936 | AA13: =AVERAGE(U13:Y13) -> 6787.2 | AD13: Downing | AE13: =+VLOOKUP($A13,INDIRECT(Adrese!B$2),5,FALSE) -> 1150 | AF13: =+VLOOKUP($A13,INDIRECT(Adrese!C$2),5,FALSE) -> 1168 | AG13: =+VLOOKUP($A13,INDIRECT(Adrese!D$2),5,FALSE) -> 1010 | AH13: =+VLOOKUP($A13,INDIRECT(Adrese!E$2),5,FALSE) -> 1210 | AI13: =+VLOOKUP($A13,INDIRECT(Adrese!F$2),5,FALSE) -> 1143 | AJ13: =AVERAGE(AE13:AI13) -> 1136.2 | AK13: =_xlfn.STDEV.S(AE13:AI13) -> 75.201064 | AM13: Downing | AN13: =+VLOOKUP($A13,INDIRECT(Adrese!B$2),6,FALSE) -> 0.37633333 | AO13: =+VLOOKUP($A13,INDIRECT(Adrese!C$2),6,FALSE) -> 0.38233333 | AP13: =+VLOOKUP($A13,INDIRECT(Adrese!D$2),6,FALSE) -> 0.33066667 | AQ13: =+VLOOKUP($A13,INDIRECT(Adrese!E$2),6,FALSE) -> 0.397 | AR13: =+VLOOKUP($A13,INDIRECT(Adrese!F$2),6,FALSE) -> 0.37333333 | AS13: =TEXT(AT13,"0.00")&" ("&TEXT(AU13,"0.00")&")" -> 0.37 (0.02) | AT13: =AVERAGE(AN13:AR13) -> 0.37193333 | AU13: =_xlfn.STDEV.S(AN13:AR13) -> 0.024803001 | AW13: Downing | AX13: =+VLOOKUP($A13,INDIRECT(Adrese!B$2),7,FALSE) -> 0.33333333 | AY13: =+VLOOKUP($A13,INDIRECT(Adrese!C$2),7,FALSE) -> 0.53333333 | AZ13: =+VLOOKUP($A13,INDIRECT(Adrese!D$2),7,FALSE) -> 0.4 | BA13: =+VLOOKUP($A13,INDIRECT(Adrese!E$2),7,FALSE) -> 0.53333333 | BB13: =+VLOOKUP($A13,INDIRECT(Adrese!F$2),7,FALSE) -> 0.46666667 | BC13: =TEXT(BD13,"0.00")&" ("&TEXT(BE13,"0.00")&")" -> 0.45 (0.09) | BD13: =AVERAGE(AX13:BB13) -> 0.45333333 | BE13: =_xlfn.STDEV.S(AX13:BB13) -> 0.086922699 | BG13: Downing | BH13: =+VLOOKUP($BG13,INDIRECT(Adrese!B$2),8,FALSE) -> 0.20187439 | BI13: =+VLOOKUP($BG13,INDIRECT(Adrese!C$2),8,FALSE) -> 0.20066647 | BJ13: =+VLOOKUP($BG13,INDIRECT(Adrese!D$2),8,FALSE) -> 0.1788608 | BK13: =+VLOOKUP($BG13,INDIRECT(Adrese!E$2),8,FALSE) -> 0.1994263 | BL13: =+VLOOKUP($BG13,INDIRECT(Adrese!F$2),8,FALSE) -> 0.19247477 | BM13: =TEXT(BN13,"0.00")&" ("&TEXT(BO13,"0.00")&")" -> 0.19 (0.01) | BN13: =AVERAGE(BH13:BL13) -> 0.19466055 | BO13: =_xlfn.STDEV.S(BH13:BL13) -> 0.0095555289 | BQ13: Downing | BR13: =+VLOOKUP($BG13,INDIRECT(Adrese!B$2),9,FALSE) -> -0.025397345 | BS13: =+VLOOKUP($BG13,INDIRECT(Adrese!C$2),9,FALSE) -> -0.085535749 | BT13: =+VLOOKUP($BG13,INDIRECT(Adrese!D$2),9,FALSE) -> -0.014203884 | BU13: =+VLOOKUP($BG13,INDIRECT(Adrese!E$2),9,FALSE) -> -0.20513938 | BV13: =+VLOOKUP($BG13,INDIRECT(Adrese!F$2),9,FALSE) -> -0.15145339 | BW13: =TEXT(BX13,"0.00")&" ("&TEXT(BY13,"0.00")&")" -> -0.10 (0.08) | BX13: =AVERAGE(BR13:BV13) -> -0.096345948 | BY13: =_xlfn.STDEV.S(BR13:BV13) -> 0.081808806
A14: Feld | B14: =+VLOOKUP($A14,INDIRECT(Adrese!B$2),2,FALSE) -> 5 | C14: =+VLOOKUP($A14,INDIRECT(Adrese!C$2),2,FALSE) -> 4 | D14: =+VLOOKUP($A14,INDIRECT(Adrese!D$2),2,FALSE) -> 4 | E14: =+VLOOKUP($A14,INDIRECT(Adrese!E$2),2,FALSE) -> 6 | F14: =+VLOOKUP($A14,INDIRECT(Adrese!F$2),2,FALSE) -> 5 | G14: =AVERAGE(B14:F14) -> 4.8 | J14: Feld | K14: =+VLOOKUP($A14,INDIRECT(Adrese!B$2),3,FALSE) -> 9 | L14: =+VLOOKUP($A14,INDIRECT(Adrese!C$2),3,FALSE) -> 9 | M14: =+VLOOKUP($A14,INDIRECT(Adrese!D$2),3,FALSE) -> 9 | N14: =+VLOOKUP($A14,INDIRECT(Adrese!E$2),3,FALSE) -> 9 | O14: =+VLOOKUP($A14,INDIRECT(Adrese!F$2),3,FALSE) -> 9 | P14: =SUM(K14:O14) -> 45 | Q14: =AVERAGE(K14:O14) -> 9 | T14: Feld | U14: =+VLOOKUP($T14,INDIRECT(Adrese!B$2),4,FALSE) -> 6446 | V14: =+VLOOKUP($T14,INDIRECT(Adrese!C$2),4,FALSE) -> 6479 | W14: =+VLOOKUP($T14,INDIRECT(Adrese!D$2),4,FALSE) -> 6469 | X14: =+VLOOKUP($T14,INDIRECT(Adrese!E$2),4,FALSE) -> 6341 | Y14: =+VLOOKUP($T14,INDIRECT(Adrese!F$2),4,FALSE) -> 6485 | Z14: =SUM(U14:Y14) -> 32220 | AA14: =AVERAGE(U14:Y14) -> 6444 | AD14: Feld | AE14: =+VLOOKUP($A14,INDIRECT(Adrese!B$2),5,FALSE) -> 1168 | AF14: =+VLOOKUP($A14,INDIRECT(Adrese!C$2),5,FALSE) -> 1224 | AG14: =+VLOOKUP($A14,INDIRECT(Adrese!D$2),5,FALSE) -> 1166 | AH14: =+VLOOKUP($A14,INDIRECT(Adrese!E$2),5,FALSE) -> 1078 | AI14: =+VLOOKUP($A14,INDIRECT(Adrese!F$2),5,FALSE) -> 1129 | AJ14: =AVERAGE(AE14:AI14) -> 1153 | AK14: =_xlfn.STDEV.S(AE14:AI14) -> 53.935146 | AM14: Feld | AN14: =+VLOOKUP($A14,INDIRECT(Adrese!B$2),6,FALSE) -> 0.36966667 | AO14: =+VLOOKUP($A14,INDIRECT(Adrese!C$2),6,FALSE) -> 0.38733333 | AP14: =+VLOOKUP($A14,INDIRECT(Adrese!D$2),6,FALSE) -> 0.36466667 | AQ14: =+VLOOKUP($A14,INDIRECT(Adrese!E$2),6,FALSE) -> 0.34166667 | AR14: =+VLOOKUP($A14,INDIRECT(Adrese!F$2),6,FALSE) -> 0.36233333 | AS14: =TEXT(AT14,"0.00")&" ("&TEXT(AU14,"0.00")&")" -> 0.37 (0.02) | AT14: =AVERAGE(AN14:AR14) -> 0.36513333 | AU14: =_xlfn.STDEV.S(AN14:AR14) -> 0.016371723 | AW14: Feld | AX14: =+VLOOKUP($A14,INDIRECT(Adrese!B$2),7,FALSE) -> 0.4 | AY14: =+VLOOKUP($A14,INDIRECT(Adrese!C$2),7,FALSE) -> 0.4 | AZ14: =+VLOOKUP($A14,INDIRECT(Adrese!D$2),7,FALSE) -> 0.4 | BA14: =+VLOOKUP($A14,INDIRECT(Adrese!E$2),7,FALSE) -> 0.4 | BB14: =+VLOOKUP($A14,INDIRECT(Adrese!F$2),7,FALSE) -> 0.4 | BC14: =TEXT(BD14,"0.00")&" ("&TEXT(BE14,"0.00")&")" -> 0.40 (0.00) | BD14: =AVERAGE(AX14:BB14) -> 0.4 | BE14: =_xlfn.STDEV.S(AX14:BB14) -> 0 | BG14: Feld | BH14: =+VLOOKUP($BG14,INDIRECT(Adrese!B$2),8,FALSE) -> 0.21528111 | BI14: =+VLOOKUP($BG14,INDIRECT(Adrese!C$2),8,FALSE) -> 0.22846783 | BJ14: =+VLOOKUP($BG14,INDIRECT(Adrese!D$2),8,FALSE) -> 0.21546304 | BK14: =+VLOOKUP($BG14,INDIRECT(Adrese!E$2),8,FALSE) -> 0.20611634 | BL14: =+VLOOKUP($BG14,INDIRECT(Adrese!F$2),8,FALSE) -> 0.2143077 | BM14: =TEXT(BN14,"0.00")&" ("&TEXT(BO14,"0.00")&")" -> 0.22 (0.01) | BN14: =AVERAGE(BH14:BL14) -> 0.2159272 | BO14: =_xlfn.STDEV.S(BH14:BL14) -> 0.0080121157 | BQ14: Feld | BR14: =+VLOOKUP($BG14,INDIRECT(Adrese!B$2),9,FALSE) -> 0.27083659 | BS14: =+VLOOKUP($BG14,INDIRECT(Adrese!C$2),9,FALSE) -> 0.28901493 | BT14: =+VLOOKUP($BG14,INDIRECT(Adrese!D$2),9,FALSE) -> 0.27962775 | BU14: =+VLOOKUP($BG14,INDIRECT(Adrese!E$2),9,FALSE) -> 0.29861816 | BV14: =+VLOOKUP($BG14,INDIRECT(Adrese!F$2),9,FALSE) -> 0.33562264 | BW14: =TEXT(BX14,"0.00")&" ("&TEXT(BY14,"0.00")&")" -> 0.29 (0.03) | BX14: =AVERAGE(BR14:BV14) -> 0.29474401 | BY14: =_xlfn.STDEV.S(BR14:BV14) -> 0.025094622
... A18: Random | B18: =+VLOOKUP($A18,INDIRECT(Adrese!B$2),2,FALSE) -> 15 | C18: =+VLOOKUP($A18,INDIRECT(Adrese!C$2),2,FALSE) -> 15 | D18: =+VLOOKUP($A18,INDIRECT(Adrese!D$2),2,FALSE) -> 16 | E18: =+VLOOKUP($A18,INDIRECT(Adrese!E$2),2,FALSE) -> 14 | F18: =+VLOOKUP($A18,INDIRECT(Adrese!F$2),2,FALSE) -> 16 | G18: =AVERAGE(B18:F18) -> 15.2 | J18: Random | K18: =+VLOOKUP($A18,INDIRECT(Adrese!B$2),3,FALSE) -> 4 | L18: =+VLOOKUP($A18,INDIRECT(Adrese!C$2),3,FALSE) -> 4 | M18: =+VLOOKUP($A18,INDIRECT(Adrese!D$2),3,FALSE) -> 4 | N18: =+VLOOKUP($A18,INDIRECT(Adrese!E$2),3,FALSE) -> 2 | O18: =+VLOOKUP($A18,INDIRECT(Adrese!F$2),3,FALSE) -> 3 | P18: =SUM(K18:O18) -> 17 | Q18: =AVERAGE(K18:O18) -> 3.4 | T18: Random | U18: =+VLOOKUP($T18,INDIRECT(Adrese!B$2),4,FALSE) -> 5358 | V18: =+VLOOKUP($T18,INDIRECT(Adrese!C$2),4,FALSE) -> 5047 | W18: =+VLOOKUP($T18,INDIRECT(Adrese!D$2),4,FALSE) -> 5088 | X18: =+VLOOKUP($T18,INDIRECT(Adrese!E$2),4,FALSE) -> 5095 | Y18: =+VLOOKUP($T18,INDIRECT(Adrese!F$2),4,FALSE) -> 4956 | Z18: =SUM(U18:Y18) -> 25544 | AA18: =AVERAGE(U18:Y18) -> 5108.8 | AD18: Random | AE18: =+VLOOKUP($A18,INDIRECT(Adrese!B$2),5,FALSE) -> 1615 | AF18: =+VLOOKUP($A18,INDIRECT(Adrese!C$2),5,FALSE) -> 1566 | AG18: =+VLOOKUP($A18,INDIRECT(Adrese!D$2),5,FALSE) -> 1606 | AH18: =+VLOOKUP($A18,INDIRECT(Adrese!E$2),5,FALSE) -> 1610 | AI18: =+VLOOKUP($A18,INDIRECT(Adrese!F$2),5,FALSE) -> 1627 | AJ18: =AVERAGE(AE18:AI18) -> 1604.8 | AK18: =_xlfn.STDEV.S(AE18:AI18) -> 23.080295 | AM18: Random | AN18: =+VLOOKUP($A18,INDIRECT(Adrese!B$2),6,FALSE) -> 0.503 | AO18: =+VLOOKUP($A18,INDIRECT(Adrese!C$2),6,FALSE) -> 0.48866667 | AP18: =+VLOOKUP($A18,INDIRECT(Adrese!D$2),6,FALSE) -> 0.502 | AQ18: =+VLOOKUP($A18,INDIRECT(Adrese!E$2),6,FALSE) -> 0.504 | AR18: =+VLOOKUP($A18,INDIRECT(Adrese!F$2),6,FALSE) -> 0.51033333 | AS18: =TEXT(AT18,"0.00")&" ("&TEXT(AU18,"0.00")&")" -> 0.50 (0.01) | AT18: =AVERAGE(AN18:AR18) -> 0.5016 | AU18: =_xlfn.STDEV.S(AN18:AR18) -> 0.0079281493 | AW18: Random | AX18: =+VLOOKUP($A18,INDIRECT(Adrese!B$2),7,FALSE) -> 0.73333333 | AY18: =+VLOOKUP($A18,INDIRECT(Adrese!C$2),7,FALSE) -> 0.73333333 | AZ18: =+VLOOKUP($A18,INDIRECT(Adrese!D$2),7,FALSE) -> 0.73333333 | BA18: =+VLOOKUP($A18,INDIRECT(Adrese!E$2),7,FALSE) -> 0.86666667 | BB18: =+VLOOKUP($A18,INDIRECT(Adrese!F$2),7,FALSE) -> 0.8 | BC18: =TEXT(BD18,"0.00")&" ("&TEXT(BE18,"0.00")&")" -> 0.77 (0.06) | BD18: =AVERAGE(AX18:BB18) -> 0.77333333 | BE18: =_xlfn.STDEV.S(AX18:BB18) -> 0.05962848 | BG18: Random | BH18: =+VLOOKUP($BG18,INDIRECT(Adrese!B$2),8,FALSE) -> 0.26728888 | BI18: =+VLOOKUP($BG18,INDIRECT(Adrese!C$2),8,FALSE) -> 0.27011524 | BJ18: =+VLOOKUP($BG18,INDIRECT(Adrese!D$2),8,FALSE) -> 0.27568793 | BK18: =+VLOOKUP($BG18,INDIRECT(Adrese!E$2),8,FALSE) -> 0.27757743 | BL18: =+VLOOKUP($BG18,INDIRECT(Adrese!F$2),8,FALSE) -> 0.2789896 | BM18: =TEXT(BN18,"0.00")&" ("&TEXT(BO18,"0.00")&")" -> 0.27 (0.01) | BN18: =AVERAGE(BH18:BL18) -> 0.27393182 | BO18: =_xlfn.STDEV.S(BH18:BL18) -> 0.0050162363 | BQ18: Random | BR18: =+VLOOKUP($BG18,INDIRECT(Adrese!B$2),9,FALSE) -> -0.020742887 | BS18: =+VLOOKUP($BG18,INDIRECT(Adrese!C$2),9,FALSE) -> 0.023602671 | BT18: =+VLOOKUP($BG18,INDIRECT(Adrese!D$2),9,FALSE) -> -0.008058328 | BU18: =+VLOOKUP($BG18,INDIRECT(Adrese!E$2),9,FALSE) -> 0.007694456 | BV18: =+VLOOKUP($BG18,INDIRECT(Adrese!F$2),9,FALSE) -> -0.01629945 | BW18: =TEXT(BX18,"0.00")&" ("&TEXT(BY18,"0.00")&")" -> 0.00 (0.02) | BX18: =AVERAGE(BR18:BV18) -> -0.0027607076 | BY18: =_xlfn.STDEV.S(BR18:BV18) -> 0.018296579

Sheet Svi
A1: Name | C1: #Wins | D1: TotalScore | E1: #Cooperations | F1: CooperationRating | G1: GoodPartnerRating | H1: EigenJesusRating | I1: EigenMosesRating
A2: Downing | B2: 1 | C2: 10 | D2: 6999 | E2: 1150 | F2: 0.37633333 | G2: 0.33333333 | H2: 0.20187439 | I2: -0.025397345
A3: Tideman and Chieruzzi | B3: 2 | C3: 13 | D3: 6616 | E3: 1009 | F3: 0.325 | G3: 0.13333333 | H3: 0.19581111 | I3: 0.35100026
A4: Fuzzy | B4: 3 | C4: 3 | D4: 6604 | E4: 1883 | F4: 0.577 | G4: 0.8 | H4: 0.30938308 | I4: -0.26661263
A5: Stein and Rapoport | B5: 4 | C5: 8 | D5: 6575 | E5: 1069 | F5: 0.33033333 | G5: 0.46666667 | H5: 0.19878996 | I5: 0.25069571
A6: Feld | B6: 5 | C6: 9 | D6: 6446 | E6: 1168 | F6: 0.36966667 | G6: 0.4 | H6: 0.21528111 | I6: 0.27083659
A7: Davis | B7: 6 | C7: 14 | D7: 6362 | E7: 431 | F7: 0.135 | G7: 0.066666667 | H7: 0.071760179 | I7: 0.3095544
A8: Grudger | B8: 7 | C8: 13 | D8: 6347 | E8: 398 | F8: 0.126 | G8: 0.13333333 | H8: 0.066918455 | I8: 0.3303294
A9: Tit For Tat | B9: 8 | C9: 5 | D9: 6336 | E9: 1539 | F9: 0.47833333 | G9: 0.66666667 | H9: 0.28840448 | I9: 0.24351083
A10: Joss | B10: 9 | C10: 9 | D10: 6307 | E10: 1290 | F10: 0.40833333 | G10: 0.4 | H10: 0.24376542 | I10: 0.30270967
A11: Shubik | B11: 10 | C11: 10 | D11: 6030 | E11: 855 | F11: 0.273 | G11: 0.33333333 | H11: 0.16001717 | I11: 0.3240484
A12: Graaskamp | B12: 11 | C12: 9 | D12: 5927 | E12: 1469 | F12: 0.46066667 | G12: 0.4 | H12: 0.24600736 | I12: 0.12071043
A13: Tullock | B13: 12 | C13: 7 | D13: 5862 | E13: 1088 | F13: 0.34566667 | G13: 0.53333333 | H13: 0.2125018 | I13: 0.32729822
... A17: Anonymous | B17: 16 | C17: 2 | D17: 4808 | E17: 1617 | F17: 0.50466667 | G17: 0.86666667 | H17: 0.27003128 | I17: -0.0156665
A19: Name | C19: #Wins | D19: TotalScore | E19: #Cooperations | F19: CooperationRating | G19: GoodPartnerRating | H19: EigenJesusRating | I19: EigenMosesRating
A20: Downing | B20: 1 | C20: 7 | D20: 6836 | E20: 1168 | F20: 0.38233333 | G20: 0.53333333 | H20: 0.20066647 | I20: -0.085535749
A21: Fuzzy | B21: 2 | C21: 5 | D21: 6671 | E21: 1397 | F21: 0.46133333 | G21: 0.66666667 | H21: 0.23557549 | I21: -0.24621669
A22: Stein and Rapoport | B22: 3 | C22: 10 | D22: 6553 | E22: 1084 | F22: 0.334 | G22: 0.33333333 | H22: 0.19941141 | I22: 0.26211808
A23: Feld | B23: 4 | C23: 9 | D23: 6479 | E23: 1224 | F23: 0.38733333 | G23: 0.4 | H23: 0.22846783 | I23: 0.28901493
A24: Shubik | B24: 5 | C24: 9 | D24: 6409 | E24: 946 | F24: 0.28933333 | G24: 0.4 | H24: 0.17865453 | I24: 0.32713727
A25: Grudger | B25: 6 | C25: 14 | D25: 6330 | E25: 396 | F25: 0.12433333 | G25: 0.066666667 | H25: 0.068210668 | I25: 0.33929256
A26: Tideman and Chieruzzi | B26: 7 | C26: 11 | D26: 6321 | E26: 964 | F26: 0.308 | G26: 0.26666667 | H26: 0.18200419 | I26: 0.31533492
A27: Joss | B27: 8 | C27: 7 | D27: 6307 | E27: 1330 | F27: 0.419 | G27: 0.53333333 | H27: 0.25198524 | I27: 0.30284437
A28: Davis | B28: 9 | C28: 14 | D28: 6288 | E28: 461 | F28: 0.14466667 | G28: 0.066666667 | H28: 0.079228662 | I28: 0.31539207
A29: Tullock | B29: 10 | C29: 9 | D29: 6160 | E29: 1222 | F29: 0.395 | G29: 0.4 | H29: 0.23649095 | I29: 0.32137182
A30: Tit For Tat | B30: 11 | C30: 5 | D30: 6145 | E30: 1468 | F30: 0.454 | G30: 0.66666667 | H30: 0.27491114 | I30: 0.25200801
A31: Graaskamp | B31: 12 | C31: 7 | D31: 5801 | E31: 1499 | F31: 0.486 | G31: 0.53333333 | H31: 0.25417691 | I31: 0.039577625
... A35: Anonymous | B35: 16 | C35: 4 | D35: 5036 | E35: 1621 | F35: 0.50766667 | G35: 0.73333333 | H35: 0.27993616 | I35: 0.003620274
A37: Name | C37: #Wins | D37: TotalScore | E37: #Cooperations | F37: CooperationRating | G37: GoodPartnerRating | H37: EigenJesusRating | I37: EigenMosesRating
A38: Fuzzy | B38: 1 | C38: 4 | D38: 6924 | E38: 1771 | F38: 0.54833333 | G38: 0.73333333 | H38: 0.29334799 | I38: -0.29514666
A39: Downing | B39: 2 | C39: 9 | D39: 6533 | E39: 1010 | F39: 0.33066667 | G39: 0.4 | H39: 0.1788608 | I39: -0.014203884
A40: Grudger | B40: 3 | C40: 15 | D40: 6494 | E40: 384 | F40: 0.12 | G40: 0 | H40: 0.065401634 | I40: 0.30634312
A41: Feld | B41: 4 | C41: 9 | D41: 6469 | E41: 1166 | F41: 0.36466667 | G41: 0.4 | H41: 0.21546304 | I41: 0.27962775
A42: Joss | B42: 5 | C42: 8 | D42: 6377 | E42: 1342 | F42: 0.42266667 | G42: 0.46666667 | H42: 0.25255805 | I42: 0.30392065
A43: Stein and Rapoport | B43: 6 | C43: 7 | D43: 6361 | E43: 1063 | F43: 0.33333333 | G43: 0.53333333 | H43: 0.20372282 | I43: 0.27156113
A44: Tit For Tat | B44: 7 | C44: 6 | D44: 6353 | E44: 1528 | F44: 0.47766667 | G44: 0.6 | H44: 0.28822655 | I44: 0.27186506
A45: Tideman and Chieruzzi | B45: 8 | C45: 13 | D45: 6281 | E45: 964 | F45: 0.306 | G45: 0.13333333 | H45: 0.19426647 | I45: 0.35963894
A46: Tullock | B46: 9 | C46: 9 | D46: 6192 | E46: 1229 | F46: 0.38933333 | G46: 0.4 | H46: 0.23558586 | I46: 0.30582661
A47: Davis | B47: 10 | C47: 12 | D47: 6191 | E47: 481 | F47: 0.15033333 | G47: 0.2 | H47: 0.081852613 | I47: 0.30252062
A48: Graaskamp | B48: 11 | C48: 9 | D48: 6101 | E48: 1390 | F48: 0.44733333 | G48: 0.4 | H48: 0.23748644 | I48: 0.067056684
...

Sheet Adrese
B1: 1 | C1: 2 | D1: 3 | E1: 4 | F1: 5
B2: Svi!$A$2:$I$17 | C2: Svi!$A$20:$I$35 | D2: Svi!$A$38:$I$53 | E2: Svi!$A$56:$I$71 | F2: Svi!$A$74:$I$89

Sheet Final
C2: Rank | D2: Avg. Score | E2: TotalScore | F2: #Wins | G2: #Cooperations | H2: Cooperation Rating | I2: Good Partner Rating | J2: Eigenjesus Rating | K2: Eigenmoses Rating
B3: First by Downing | C3: =Kompilirano!G13 -> 1.4 | D3: =E3/16 -> 424.2 | E3: =Kompilirano!AA13 -> 6787.2 | F3: =Kompilirano!Q13 -> 8.2 | G3: =Kompilirano!AJ13 -> 1136.2 | H3: =Kompilirano!AT13 -> 0.37193333 | I3: =Kompilirano!BD13 -> 0.45333333 | J3: =Kompilirano!BN13 -> 0.19466055 | K3: =Kompilirano!BX13 -> -0.096345948
B4: Fuzzy | C4: =Kompilirano!G3 -> 2 | D4: =E4/16 -> 418.8375 | E4: =Kompilirano!AA3 -> 6701.4 | F4: =Kompilirano!Q3 -> 4.4 | G4: =Kompilirano!AJ3 -> 1650.6 | H4: =Kompilirano!AT3 -> 0.51026667 | I4: =Kompilirano!BD3 -> 0.70666667 | J4: =Kompilirano!BN3 -> 0.27688348 | K4: =Kompilirano!BX3 -> -0.24699496
B5: First by Tideman and Chieruzzi | C5: =Kompilirano!G8 -> 4.8 | D5: =E5/16 -> 403.175 | E5: =Kompilirano!AA8 -> 6450.8 | F5: =Kompilirano!Q8 -> 12 | G5: =Kompilirano!AJ8 -> 1004.8 | H5: =Kompilirano!AT8 -> 0.32313333 | I5: =Kompilirano!BD8 -> 0.2 | J5: =Kompilirano!BN8 -> 0.19527869 | K5: =Kompilirano!BX8 -> 0.35973204
B6: First by Stein and Rapoport | C6: =Kompilirano!G4 -> 4.6 | D6: =E6/16 -> 402.85 | E6: =Kompilirano!AA4 -> 6445.6 | F6: =Kompilirano!Q4 -> 8.8 | G6: =Kompilirano!AJ4 -> 1063.6 | H6: =Kompilirano!AT4 -> 0.3294 | I6: =Kompilirano!BD4 -> 0.41333333 | J6: =Kompilirano!BN4 -> 0.20065931 | K6: =Kompilirano!BX4 -> 0.25578133
B7: First by Feld | C7: =Kompilirano!G14 -> 4.8 | D7: =E7/16 -> 402.75 | E7: =Kompilirano!AA14 -> 6444 | F7: =Kompilirano!Q14 -> 9 | G7: =Kompilirano!AJ14 -> 1153 | H7: =Kompilirano!AT14 -> 0.36513333 | I7: =Kompilirano!BD14 -> 0.4 | J7: =Kompilirano!BN14 -> 0.2159272 | K7: =Kompilirano!BX14 -> 0.29474401
B8: Grudger | C8: =Kompilirano!G10 -> 6.6 | D8: =E8/16 -> 396.3375 | E8: =Kompilirano!AA10 -> 6341.4 | F8: =Kompilirano!Q10 -> 13.8 | G8: =Kompilirano!AJ10 -> 389.6 | H8: =Kompilirano!AT10 -> 0.12266667 | I8: =Kompilirano!BD10 -> 0.08 | J8: =Kompilirano!BN10 -> 0.066743125 | K8: =Kompilirano!BX10 -> 0.31612558
B9: First by Joss | C9: =Kompilirano!G15 -> 7.8 | D9: =E9/16 -> 394.4625 | E9: =Kompilirano!AA15 -> 6311.4 | F9: =Kompilirano!Q15 -> 7.6 | G9: =Kompilirano!AJ15 -> 1326.4 | H9: =Kompilirano!AT15 -> 0.41786667 | I9: =Kompilirano!BD15 -> 0.49333333 | J9: =Kompilirano!BN15 -> 0.25134306 | K9: =Kompilirano!BX15 -> 0.29191764
B10: First by Davis | C10: =Kompilirano!G11 -> 8 | D10: =E10/16 -> 393.175 | E10: =Kompilirano!AA11 -> 6290.8 | F10: =Kompilirano!Q11 -> 13.6 | G10: =Kompilirano!AJ11 -> 466.8 | H10: =Kompilirano!AT11 -> 0.14633333 | I10: =Kompilirano!BD11 -> 0.093333334 | J10: =Kompilirano!BN11 -> 0.081019159 | K10: =Kompilirano!BX11 -> 0.30582116
B11: First by Shubik | C11: =Kompilirano!G9 -> 6.8 | D11: =E11/16 -> 391.7875 | E11: =Kompilirano!AA9 -> 6268.6 | F11: =Kompilirano!Q9 -> 10 | G11: =Kompilirano!AJ9 -> 919.8 | H11: =Kompilirano!AT9 -> 0.2888 | I11: =Kompilirano!BD9 -> 0.33333333 | J11: =Kompilirano!BN9 -> 0.17441736 | K11: =Kompilirano!BX9 -> 0.31452104
B12: Tit For Tat | C12: =Kompilirano!G6 -> 9 | D12: =E12/16 -> 389.8125 | E12: =Kompilirano!AA6 -> 6237 | F12: =Kompilirano!Q6 -> 5.2 | G12: =Kompilirano!AJ6 -> 1482.8 | H12: =Kompilirano!AT6 -> 0.4618 | I12: =Kompilirano!BD6 -> 0.65333333 | J12: =Kompilirano!BN6 -> 0.28047417 | K12: =Kompilirano!BX6 -> 0.2652738
B13: First by Graaskamp | C13: =Kompilirano!G12 -> 11.2 | D13: =E13/16 -> 371.525 | E13: =Kompilirano!AA12 -> 5944.4 | F13: =Kompilirano!Q12 -> 8.2 | G13: =Kompilirano!AJ12 -> 1419.6 | H13: =Kompilirano!AT12 -> 0.44853333 | I13: =Kompilirano!BD12 -> 0.45333333 | J13: =Kompilirano!BN12 -> 0.23585125 | K13: =Kompilirano!BX12 -> 0.076072298
